<?xml version="1.0" ?>
<!-- =================================================================================== -->
<!-- |    This document was autogenerated by xacro from robots/kevin_std.urdf.xacro    | -->
<!-- |    EDITING THIS FILE BY HAND IS NOT RECOMMENDED                                 | -->
<!-- =================================================================================== -->
<robot name="kevin">
  <!-- ***************** -->
  <!-- Imported elements -->
  <!-- ***************** -->
  <!-- First we import all posible elements defined in the urdf.xacro files. All these elements are defined as macro:xacros -->
  <!-- Source: https://en.wikipedia.org/wiki/List_of_moments_of_inertia-->
  <!-- source en.wikipedia.org/wiki/List_of_moments_of_inertia-->
  <!-- This file unifies all sensors that can be used on simulation, defined as xacro:macros -->
  <!-- <xacro:macro name="sensor_ultrasonic_a21_gazebo">
    <gazebo reference="${prefix}_link">
			<xacro:if value="${gpu}">
        <xacro:property name="ray_type" value="gpu_ray" />
        <xacro:property name="plugin_lib" value="libgazebo_ros_gpu_laser.so" />
      </xacro:if>
      <xacro:unless value="${gpu}">
        <xacro:property name="ray_type" value="ray" />
        <xacro:property name="plugin_lib" value="libgazebo_ros_laser.so" />
      </xacro:unless>
			<sensor type="${ray_type}" name="${prefix}_sensor">
				<pose>0 0 0 0 0 0</pose>
				<visualize>false</visualize>
				<update_rate>40</update_rate>
				<ray>
					<scan>
						<horizontal>
							<samples>1081</samples>
							<resolution>1</resolution>
							<min_angle>${min_angle}</min_angle>
							<max_angle>${max_angle}</max_angle>
						</horizontal>
					</scan>
					<range>
						<min>0.06</min>
						<max>20.0</max>
						<! resolution>0.004363323</resolution >
						<resolution>0.004359297</resolution>
						<! resolution>0.001</resolution >
					</range>
					<noise>
						<type>gaussian</type>
						<mean>0.0</mean>
						<stddev>0.01</stddev>
					</noise>
				</ray>
				<plugin name="${prefix}_controller" filename="${plugin_lib}">
					<topicName>${prefix_topic}/scan</topicName>
					<frameName>/${prefix}_link</frameName>
				</plugin>
			</sensor>
	</gazebo>
  </xacro:macro>
  -->
  <!-- Includes -->
  <!-- Includes -->
  <!-- Gazebo ros control pluggins -->
  <!-- <xacro:ros2_control namespace="robot" config_controllers="''"/> -->
  <!-- BASE FOOTPRINT -->
  <link name="robot_base_footprint"/>
  <joint name="robot_base_footprint_joint" type="fixed">
    <parent link="robot_base_footprint"/>
    <child link="robot_base_link"/>
    <origin rpy="0 0 0" xyz="0 0 0.07"/>
  </joint>
  <!-- BASE LINK -->
  <link name="robot_base_link">
    <visual>
      <origin rpy="1.5707963267948966 0 1.5707963267948966" xyz="0 0 0.0945"/>
      <geometry>
        <box size="0.5 0.2 0.55"/>
      </geometry>
      <material name="darkgrey">
        <color rgba="0.45 0.45 0.45 1"/>
      </material>
    </visual>
    <collision>
      <origin rpy="1.5707963267948966 0 1.5707963267948966" xyz="0 0 0.0945"/>
      <geometry>
        <box size="0.5 0.2 0.55"/>
      </geometry>
    </collision>
    <inertial>
      <origin rpy="0 0 0" xyz="-0.07 0 0.10"/>
      <mass value="49.0"/>
      <inertia ixx="1.15" ixy="0.0" ixz="0.0" iyy="1.68" iyz="0.0" izz="2.25"/>
    </inertial>
  </link>
  <joint name="robot_imu_base_joint" type="fixed">
    <axis xyz="1 0 0"/>
    <origin rpy="0 0 0" xyz="0.182 0.0855 0.1265"/>
    <parent link="robot_base_link"/>
    <child link="robot_imu_base_link"/>
  </joint>
  <link name="robot_imu_base_link">
    
  </link>
  <joint name="robot_imu_joint" type="fixed">
    <axis xyz="1 0 0"/>
    <origin xyz="0.00671 0.0047 0.0059"/>
    <parent link="robot_imu_base_link"/>
    <child link="robot_imu_link"/>
  </joint>
  <link name="robot_imu_link">
	  </link>
  <gazebo reference="robot_imu_base_link">
    <material>Gazebo/Red</material>
  </gazebo>
  <gazebo>
    <plugin filename="libhector_gazebo_ros_imu.so" name="robot_imu_controller">
      <alwaysOn>true</alwaysOn>
      <topicName>imu/data</topicName>
      <serviceName>robot_imuimu/service</serviceName>
      <bodyName>robot_imu_link</bodyName>
      <frameId>robot_imu_link</frameId>
      <updateRate>50.0</updateRate>
      <gaussianNoise>0.00</gaussianNoise>
      <yawOffset>0.0</yawOffset>
      <yawDrift>0.0</yawDrift>
      <yawGaussianNoise>0.0</yawGaussianNoise>
      <!-- angular velocities parameters -->
      <rateOffset>0.0 0.0 0.0</rateOffset>
      <rateDrift>0.0 0.0 0.0</rateDrift>
      <rateGaussianNoise>0.0 0.0 0.0</rateGaussianNoise>
      <!-- linear accelerations parameters -->
      <accelOffset>0.0 0.0 0.0</accelOffset>
      <accelDrift>0.0 0.0 0.0</accelDrift>
      <accelGaussianNoise>0.0 0.0 0.0</accelGaussianNoise>
    </plugin>
  </gazebo>
 
  <!-- 2d laser -->
  <!-- <xacro:sensor_sick_nanoscan3 prefix="${prefix}front_laser" parent="${prefix}base_link" max_angle="${radians(120)}" min_angle="${radians(-120)}" gpu="false">
        <origin xyz="0.26226 0.0 0.1705" rpy="0 ${M_PI} ${M_PI}"/>
      </xacro:sensor_sick_nanoscan3> -->
  <joint name="robot_housing_joint" type="fixed">
    <parent link="robot_base_link"/>
    <child link="robot_housing_link"/>
    <origin rpy="0 0 0" xyz="-0.04 -0.0045 -0.067"/>
  </joint>
  <joint name="robot_housing_joint2" type="fixed">
    <parent link="robot_base_link"/>
    <child link="robot_housing_link_bottom"/>
    <origin rpy="0 0 0" xyz="-0.04 -0.0045 -0.067"/>
  </joint>
  <link name="robot_housing_link">
    <visual>
      <origin rpy="0 0 -1.5707963267948966" xyz="-0.1 0 0.8"/>
      <geometry>
        <box size="0.55 0.3 1"/>
      </geometry>
      <material name="white">
        <color rgba="0.85 0.85 0.85 1"/>
      </material>
    </visual>
    <collision>
      <origin rpy="0 0 -1.5707963267948966" xyz="-0.1 0 0.8"/>
      <geometry>
        <box size="0.55 0.3 1"/>
      </geometry>
    </collision>
  </link>
  <link name="robot_housing_link_bottom">
    <visual>
      <origin rpy="0 0 -1.5707963267948966" xyz="0 0 0.48"/>
      <geometry>
        <box size="0.55 0.5 0.47"/>
      </geometry>
      <material name="white">
        <color rgba="0.85 0.85 0.85 1"/>
      </material>
    </visual>
    <collision>
      <origin rpy="0 0 -1.5707963267948966" xyz="0 0 0.48"/>
      <geometry>
        <box size="0.55 0.5 0.47"/>
      </geometry>
    </collision>
  </link>
  <joint name="robot_safety_button_joint" type="fixed">
    <parent link="robot_housing_link"/>
    <child link="robot_safety_button_link"/>
    <origin rpy="0 0 0" xyz="0.09 0.06 1.13"/>
  </joint>
  <link name="robot_safety_button_link">
    <collision>
      <origin rpy="0 0 0" xyz="0 0 0"/>
      <geometry>
        <box size="0.04 0.05 0.05"/>
      </geometry>
    </collision>
  </link>
  <!-- Materials -->
  <material name="white">
    <color rgba="1 1 1 1"/>
  </material>
  <material name="aluminum">
    <color rgba="0.6 0.6 0.6 1"/>
  </material>
  <joint name="robot_arm_base_joint" type="fixed">
    <parent link="robot_base_link"/>
    <child link="robot_arm_base_link"/>
    <origin rpy="0 0 0" xyz="-0.095 0.1544 0.6495"/>
  </joint>
  <link name="robot_arm_base_link">
    <visual>
      <origin rpy="0 0 0" xyz="0.076 0 0.555"/>
      <geometry>
       <box size="0.125 0.20 1.1"/>
      </geometry>
      <material name="white"/>
    </visual>
    <collision>
      <!-- <origin xyz="0.025 0 0.555" rpy="0 0 0"/> -->
      <origin rpy="0 0 0" xyz="0.076 0 0.555"/>
      <geometry>
        <!-- <box size="0.19 0.17 1.1"/> -->
        <box size="0.125 0.20 1.1"/>
      </geometry>
    </collision>
    <inertial>
      <origin rpy="0 0 0" xyz="0.076 0 0.555"/>
      <mass value="1"/>
      <inertia ixx="0.001666666666666667" ixy="0" ixz="0" iyy="0.001666666666666667" iyz="0" izz="0.001666666666666667"/>
    </inertial>
  </link>
  <joint name="robot_arm_column_joint" type="prismatic">
    <parent link="robot_arm_base_link"/>
    <child link="robot_arm_column_link"/>
    <axis xyz="0 0 1"/>
    <origin rpy="0 0 0" xyz="0.03005 -0.0198 0.17535"/>
    <limit effort="10000.0" lower="0.0015" upper="0.7015" velocity="1.0"/>
    <dynamics damping="0.01" friction="0.1"/>
  </joint>
  <link name="robot_arm_column_link">
    <visual>
      <origin rpy="0 0 0" xyz="0.162 0.03 0.06"/>
      <geometry>
        <box size="0.13 0.1 0.08"/>
      </geometry>
      <material name="white"/>
    </visual>
    <collision>
      <origin rpy="0 0 0" xyz="0.162 0.03 0.06"/>
      <geometry>
        <box size="0.13 0.1 0.08"/>
      </geometry>
    </collision>
    <inertial>
      <origin rpy="0 0 0" xyz="0.162 0.03 0.06"/>
      <mass value="1"/>
      <inertia ixx="0.001666666666666667" ixy="0" ixz="0" iyy="0.001666666666666667" iyz="0" izz="0.001666666666666667"/>
    </inertial>
  </link>
  <joint name="robot_arm_controller_origin_joint" type="fixed">
    <parent link="robot_arm_base_link"/>
    <child link="robot_arm_controller_origin_link"/>
    <origin rpy="0 0 0" xyz="0.203 0 0.094"/>
  </joint>
  <link name="robot_arm_controller_origin_link"/>
  <joint name="robot_arm_inner_joint" type="revolute">
    <parent link="robot_arm_column_link"/>
    <child link="robot_arm_inner_link"/>
    <axis xyz="0 0 1"/>
    <origin rpy="0 0 0" xyz="0.173001 0.02 0.0235"/>
    <limit effort="7000.0" lower="-1.5707963267948966" upper="1.5707963267948966" velocity="1.5707963267948966"/>
    <dynamics damping="0.01" friction="0.1"/>
  </joint>
  <link name="robot_arm_inner_link">
    <visual>
      <origin rpy="0 0 0" xyz="0.15 0 -0.04"/>
      <geometry>
        <box size="0.30 0.12 0.07"/>
      </geometry>
      <material name="white"/>
    </visual>
    <collision>
      <!-- <origin xyz="0 0 0" rpy="0 0 0"/> -->
      <origin rpy="0 0 0" xyz="0.15 0 -0.04"/>
      <geometry>
        <box size="0.30 0.12 0.07"/>
      </geometry>
    </collision>
    <inertial>
      <origin rpy="0 0 0" xyz="0 0 0"/>
      <mass value="1"/>
      <inertia ixx="0.001666666666666667" ixy="0" ixz="0" iyy="0.001666666666666667" iyz="0" izz="0.001666666666666667"/>
    </inertial>
  </link>
  <joint name="robot_arm_outer_joint" type="revolute">
    <parent link="robot_arm_inner_link"/>
    <child link="robot_arm_outer_link"/>
    <axis xyz="0 0 1"/>
    <origin rpy="0 0 0" xyz="0.302 0 -0.072285"/>
    <limit effort="7000.0" lower="0.2617993877991494" upper="6.021385919380437" velocity="3.141592653589793"/>
    <dynamics damping="0.01" friction="0.1"/>
  </joint>
  <link name="robot_arm_outer_link">
    <visual>
      <origin rpy="0 0 0" xyz="0.145 0 -0.01"/>
      <geometry>
        <box size="0.29 0.07 0.04"/>
      </geometry>
      <material name="white"/>
    </visual>
    <collision>
      <!-- <origin xyz="0 0 0" rpy="0 0 0"/> -->
      <origin rpy="0 0 0" xyz="0.145 0 -0.01"/>
      <geometry>
        <box size="0.29 0.07 0.04"/>
      </geometry>
    </collision>
    <inertial>
      <origin rpy="0 0 0" xyz="0.145 0 -0.01"/>
      <mass value="1"/>
      <inertia ixx="0.001666666666666667" ixy="0" ixz="0" iyy="0.001666666666666667" iyz="0" izz="0.001666666666666667"/>
    </inertial>
  </link>
  <joint name="robot_arm_wrist_joint" type="revolute">
    <parent link="robot_arm_outer_link"/>
    <child link="robot_arm_wrist_link"/>
    <axis xyz="0 0 1"/>
    <origin rpy="0 0 0" xyz="0.289 0 -0.032942"/>
    <limit effort="7000.0" lower="-16.755160819145562" upper="16.755160819145562" velocity="6.283185307179586"/>
    <dynamics damping="0.01" friction="0.1"/>
  </joint>
  <link name="robot_arm_wrist_link">
    <visual>
      <origin rpy="0 0 0" xyz="0 0 -0.025"/>
      <geometry>
         <box size="0.132 0.132 0.05"/>
      </geometry>
      <material name="white"/>
    </visual>
    <collision>
      <!-- <origin xyz="0 0 0" rpy="0 0 0"/> -->
      <origin rpy="0 0 0" xyz="0 0 -0.025"/>
      <geometry>
        <box size="0.132 0.132 0.05"/>
      </geometry>
    </collision>
    <inertial>
      <origin rpy="0 0 0" xyz="0 0 -0.025"/>
      <mass value="1"/>
      <inertia ixx="0.001666666666666667" ixy="0" ixz="0" iyy="0.001666666666666667" iyz="0" izz="0.001666666666666667"/>
    </inertial>
  </link>
  <joint name="robot_arm_camera_base_joint" type="fixed">
    <parent link="robot_arm_wrist_link"/>
    <child link="robot_arm_camera_base_link"/>
    <origin rpy="-1.5707963267948966 0 0" xyz="-0.018 0.0375 -0.025"/>
  </joint>
  <link name="robot_arm_camera_base_link"/>
  <joint name="robot_arm_camera_link_joint" type="fixed">
    <parent link="robot_arm_camera_base_link"/>
    <child link="robot_arm_camera_link"/>
    <origin rpy="1.5707963267948966 0 0" xyz="-0.025 0 0.0145"/>
  </joint>
  <link name="robot_arm_camera_link"/>
  <joint name="robot_arm_camera_optical_joint" type="fixed">
    <parent link="robot_arm_camera_link"/>
    <child link="robot_arm_camera_optical_link"/>
    <origin rpy="0 -1.5707963267948966 0" xyz="0.0 0.0 0.0"/>
  </joint>
  <link name="robot_arm_camera_optical_link"/>
  <joint name="robot_arm_camera_view_joint" type="fixed">
    <parent link="robot_arm_camera_link"/>
    <child link="robot_arm_camera_view_link"/>
    <origin rpy="0 0 3.141592653589793" xyz="-0.09 0 0"/>
  </joint>
  <link name="robot_arm_camera_view_link"/>
  <!-- GRIPPER FINGERS -->
  <joint name="robot_arm_tool_base_joint" type="fixed">
    <parent link="robot_arm_wrist_link"/>
    <child link="robot_arm_tool_base_link"/>
    <origin rpy="0.0 0.0 0.0" xyz="0.0918 0.0 -0.04269"/>
  </joint>
  <link name="robot_arm_tool_base_link"/>
  <joint name="robot_arm_tool_joint" type="fixed">
    <parent link="robot_arm_tool_base_link"/>
    <child link="robot_arm_tool_link"/>
    <origin rpy="0.0 0.0 0.0" xyz="0.078573 0.0 -0.03"/>
  </joint>
  <link name="robot_arm_tool_link"/>
  <joint name="robot_arm_gripper_joint" type="prismatic">
    <parent link="robot_arm_wrist_link"/>
    <child link="robot_arm_left_finger_link"/>
    <axis xyz="0 1 0"/>
    <origin rpy="0 0 0" xyz="0.078573 0 -0.04269"/>
    <limit effort="1000.0" lower="0.035" upper="0.0675" velocity="1.5"/>
    <dynamics damping="0.7" friction="0.1"/>
  </joint>
  <link name="robot_arm_left_finger_link">
    <visual>
      <origin rpy="0 0 0" xyz="0.09 0.003 -0.01"/>
      <geometry>
        <box size="0.22 0.017 0.017"/>
      </geometry>
      <material name="aluminum"/>
    </visual>
    <collision>
      <origin rpy="0 0 0" xyz="0.09 0.003 -0.01"/>
      <geometry>
        <box size="0.22 0.017 0.017"/>
      </geometry>
    </collision>
    <inertial>
      <origin rpy="0 0 0" xyz="0.09 0.003 -0.01"/>
      <mass value="1"/>
      <inertia ixx="0.001666666666666667" ixy="0" ixz="0" iyy="0.001666666666666667" iyz="0" izz="0.001666666666666667"/>
    </inertial>
  </link>
  <joint name="robot_arm_gripper_mirror_joint" type="prismatic">
    <parent link="robot_arm_wrist_link"/>
    <child link="robot_arm_right_finger_link"/>
    <axis xyz="0 -1 0"/>
    <origin rpy="0 0 0" xyz="0.078573 0 -0.04269"/>
    <limit effort="1000.0" lower="0.035" upper="0.0675" velocity="1.5"/>
    <mimic joint="robot_arm_gripper_joint" multiplier="1"/>
  </joint>
  <link name="robot_arm_right_finger_link">
    <visual>
      <origin rpy="0 0 0" xyz="0.09 -0.003 -0.01"/>
      <geometry>
        <box size="0.22 0.017 0.017"/>
      </geometry>
      <material name="aluminum"/>
    </visual>
    <collision>
      <origin rpy="0 0 0" xyz="0.09 -0.003 -0.01"/>
      <geometry>
        <box size="0.22 0.017 0.017"/>
      </geometry>
    </collision>
    <inertial>
      <origin rpy="0 0 0" xyz="0.09 -0.003 -0.01"/>
      <mass value="1"/>
      <inertia ixx="0.001666666666666667" ixy="0" ixz="0" iyy="0.001666666666666667" iyz="0" izz="0.001666666666666667"/>
    </inertial>
  </link>
  <!-- Transmission -->
  <transmission name="robot_arm_column_transmission">
    <type>transmission_interface/SimpleTransmission</type>
    <joint name="robot_arm_column_joint">
      <hardwareInterface>hardware_interface/EffortJointInterface</hardwareInterface>
    </joint>
    <actuator name="robot_arm_column_motor">
      <mechanicalReduction>1</mechanicalReduction>
    </actuator>
  </transmission>
  <transmission name="robot_arm_inner_transmission">
    <type>transmission_interface/SimpleTransmission</type>
    <joint name="robot_arm_inner_joint">
      <hardwareInterface>hardware_interface/EffortJointInterface</hardwareInterface>
    </joint>
    <actuator name="robot_arm_inner_motor">
      <mechanicalReduction>1</mechanicalReduction>
    </actuator>
  </transmission>
  <transmission name="robot_arm_outer_transmission">
    <type>transmission_interface/SimpleTransmission</type>
    <joint name="robot_arm_outer_joint">
      <hardwareInterface>hardware_interface/EffortJointInterface</hardwareInterface>
    </joint>
    <actuator name="robot_arm_outer_motor">
      <mechanicalReduction>1</mechanicalReduction>
    </actuator>
  </transmission>
  <transmission name="robot_arm_wrist_transmission">
    <type>transmission_interface/SimpleTransmission</type>
    <joint name="robot_arm_wrist_joint">
      <hardwareInterface>hardware_interface/EffortJointInterface</hardwareInterface>
    </joint>
    <actuator name="robot_arm_wrist_motor">
      <mechanicalReduction>1</mechanicalReduction>
    </actuator>
  </transmission>
  <transmission name="robot_arm_gripper_transmission">
    <type>transmission_interface/SimpleTransmission</type>
    <joint name="robot_arm_gripper_joint">
      <hardwareInterface>hardware_interface/EffortJointInterface</hardwareInterface>
    </joint>
    <actuator name="robot_arm_gripper_motor">
      <mechanicalReduction>1</mechanicalReduction>
    </actuator>
  </transmission>
  <joint name="robot_top_rgbd_camera_base_joint" type="fixed">
    <origin rpy="1.5707963267948966 0 0" xyz="0.0131 0.05609 1.1484"/>
    <parent link="robot_base_link"/>
    <child link="robot_top_rgbd_camera_base_link"/>
  </joint>
  <link name="robot_top_rgbd_camera_base_link"/>
  <!-- camera body, with origin at bottom screw mount -->
  
  
  <joint name="robot_top_3d_laser_base_joint" type="fixed">
    <origin rpy="-1.5707963267948966 0 -1.7016960206944713" xyz="-0.05503 -0.17575 1.16009"/>
    <parent link="robot_base_link"/>
    <child link="robot_top_3d_laser_base_link"/>
  </joint>
  <link name="robot_top_3d_laser_base_link">
    <visual>
      <!-- origin xyz="0 0 0" rpy="0 0 1.5708"/ -->
      <origin rpy="0 0 1.5708" xyz="0 0 0.07"/>
      <geometry>
       <box size="0.05 0.05 0.05"/>
      </geometry>
      <material name="blackgray_color">
        <color rgba="0.25 0.25 0.25 1"/>
      </material>
    </visual>
    <collision>
      <origin rpy="0 0 1.5708" xyz="0 0 0.07"/>
      <geometry>
        <box size="0.05 0.05 0.05"/>
      </geometry>
    </collision>
    <inertial>
      <!-- The following are not reliable values, and should not be used for modeling -->
      <mass value="0.92"/>
      <origin xyz="0 0 0.055"/>
      <inertia ixx="0.0018722766666666665" ixy="0" ixz="0" iyy="0.0018722766666666665" iyz="0" izz="0.0018892200000000003"/>
    </inertial>
  </link>
  <joint name="robot_top_3d_laser_joint" type="fixed">
    <parent link="robot_top_3d_laser_base_link"/>
    <child link="robot_top_3d_laser_link"/>
    <origin rpy="0 0 0" xyz="0 0 0.09427"/>
  </joint>
  <link name="robot_top_3d_laser_link"/>
  <gazebo reference="robot_top_3d_laser_base_link">
    <visual>
      <material>
        <ambient>0.5 0.5 0.5 1.0</ambient>
        <diffuse>0.250754 0.250754 0.250754 1.0</diffuse>
        <specular>0.2508273 0.2508273 0.2508273 1.0</specular>
        <emissive>0.0 0.0 0.0 0.0</emissive>
      </material>
    </visual>
  </gazebo>
  <gazebo reference="robot_top_3d_laser_link">
    <visual>
      <material>
        <ambient>1.2 0.2 0.2 1.0</ambient>
        <diffuse>0.250754 0.250754 0.250754 1.0</diffuse>
        <specular>0.2508273 0.2508273 0.2508273 1.0</specular>
        <emissive>0.0 0.0 0.0 0.0</emissive>
      </material>
    </visual>
    <sensor name="robot_top_3d_laser_sensor" type="gpu_ray">
      <pose>0 0 0 0 0 0.0</pose>
      <visualize>false</visualize>
      <update_rate>30</update_rate>
      <ray>
        <scan>
          <horizontal>
            <!-- for a high quality simulation -->
            <samples>720</samples>
            <min_angle>-3.141592653589793</min_angle>
            <max_angle>3.141592653589793</max_angle>
          </horizontal>
          <vertical>
            <samples>32</samples>
            <min_angle>-0.08726646259971647</min_angle>
            <!-- bpearl has 90 degrees of vertical field of view-->
            <max_angle> 1.2217304763960306</max_angle>
          </vertical>
        </scan>
        <range>
          <min>0.12</min>
          <max>10</max>
          <resolution>0.01</resolution>
        </range>
        <noise>
          <type>none</type>
        </noise>
      </ray>
      <plugin filename="libgazebo_ros_velodyne_gpu_laser.so" name="robot_top_3d_laser_controller">
        <topicName>top_3d_laser/points</topicName>
        <frameName>/robot_top_3d_laser_link</frameName>
        <gaussianNoise>0.008</gaussianNoise>
      </plugin>
    </sensor>
  </gazebo>
</robot>

