<?xml version="1.0"?>
<robot name="rollin_justin">
 <!-- Definition of base_footprint -> base_link -->
  <link name="base_footprint">
    <visual>
      <origin rpy="0 0 0" xyz="0 0 0"/>
      <geometry>
        <box size="0.01 0.01 0.01"/>
      </geometry>
      <material name="White"/>
    </visual>
    <collision>
      <origin rpy="0 0 0" xyz="0 0 0"/>
      <geometry>
        <box size="0.001 0.001 0.001"/>
      </geometry>
    </collision>
  </link>
  <!-- JOINT to define base_footprint -->
  <joint name="base_footprint_joint" type="fixed">
    <!--
			Explanation of the calculations to find base_link relative
			to /base_footprint.

			/base_footprint is on the floor, exactly in the center of the four wheels to
			simplify the odometry and FK/IK calculations of the base.
			Orientation: X pointing forward, and Z up.

			/base_link is on the front left upper corner of the main alu enclosure.
			with the same orientation as /base_footprint

			X:  wheel-axis to wheel-axis distance = 789.5mm.
			Distance front wheel axis to plane where base_link is: 139.5mm
			X = 789.5/2 - 139.5 = 255.25mm

			Y:  main alu enclosure is 450mm wide, and the
			center of the wheels is also the center of the alu enclosure,
			so half is Y = 225mm.

			Z:   base_link is at the top of a 120mm plate.
			The wheels are aligned with the center of the plate.
			The wheels are 8", so base_link is
			Z = 60+4*25.4mm = 161.6mm (above the floor).
			-->
    <origin rpy="0 0 0" xyz="0.25525 0.225 0.1616"/>
    <parent link="base_footprint"/>
    <child link="base_link"/>
  </joint>
  <joint name="torso1_joint" type="revolute">
    <parent link="base_link"/>
    <child link="torso1"/>
    <origin rpy="0  0  0" xyz="0      0      0.6939"/>
    <axis xyz="0  0  1"/>
    <limit effort="150.0" lower="-1.74533" upper="3.31613" velocity="0.85"/>
  </joint>
  <joint name="torso2_joint" type="revolute">
    <parent link="torso1"/>
    <child link="torso2"/>
    <origin rpy="-1.57079 -1.57079  0" xyz="0  0  0"/>
    <axis xyz="0  0  1"/>
    <limit effort="150.0" lower="-1.22173" upper="0.52360" velocity="0.85"/>
  </joint>
  <joint name="torso3_joint" type="revolute">
    <parent link="torso2"/>
    <child link="torso3"/>
    <origin rpy="0  0  0" xyz="0.3  0   0"/>
    <axis xyz="0  0  1"/>
    <limit effort="150.0" lower="0.174533" upper="2.33874" velocity="0.85"/>
  </joint>
  <joint name="torso4_joint" type="revolute">
    <parent link="torso3"/>
    <child link="torso4"/>
    <origin rpy="0  0  0" xyz="0.3  0   0"/>
    <axis xyz="0  0  1"/>
    <limit effort="150.0" lower="-1.57" upper="0.0" velocity="0.85"/>
  </joint>
  <joint name="head1_joint" type="revolute">
    <parent link="torso4"/>
    <child link="head1"/>
    <origin rpy="1.57079  0       1.57079" xyz="0.235  0.088  0"/>
    <axis xyz="0  0  1"/>
    <limit effort="150.0" lower="-0.785398" upper="0.785398" velocity="0.85"/>
  </joint>
  <joint name="head2_joint" type="revolute">
    <parent link="head1"/>
    <child link="head2"/>
    <origin rpy="-1.57079  0       0" xyz="0  0  0"/>
    <axis xyz="0  0  1"/>
    <limit effort="150.0" lower="-0.436332" upper="0.785398" velocity="0.85"/>
  </joint>
  <joint name="left_arm1_joint" type="revolute">
    <parent link="torso4"/>
    <child link="left_arm1"/>
    <origin rpy="-3.14159  0.52359  0" xyz="0.19   0.088  0.256"/>
    <axis xyz="0  0  1"/>
    <limit effort="150.0" lower="-2.96706" upper="2.96706" velocity="0.85"/>
  </joint>
  <joint name="left_arm2_joint" type="revolute">
    <parent link="left_arm1"/>
    <child link="left_arm2"/>
    <origin rpy="1.57079  0       0" xyz="0  0  0"/>
    <axis xyz="0  0  1"/>
    <limit effort="150.0" lower="-2.0944" upper="2.0944" velocity="0.85"/>
  </joint>
  <joint name="left_arm3_joint" type="revolute">
    <parent link="left_arm2"/>
    <child link="left_arm3"/>
    <origin rpy="-2.87979 -1.57079  1.30899" xyz="0  -0.4  0"/>
    <axis xyz="0  0 1"/>
    <limit effort="150.0" lower="-2.96706" upper="2.96706" velocity="0.85"/>
  </joint>
  <joint name="left_arm4_joint" type="revolute">
    <parent link="left_arm3"/>
    <child link="left_arm4"/>
    <origin rpy="1.57079  0       0" xyz="0  0  0"/>
    <axis xyz="0 0 1"/>
    <limit effort="150.0" lower="-2.0944" upper="2.0944" velocity="0.85"/>
  </joint>
  <joint name="left_arm5_joint" type="revolute">
    <parent link="left_arm4"/>
    <child link="left_arm5"/>
    <origin rpy="-1.57079  0       0" xyz="0   -0.39  0"/>
    <axis xyz="0 0 1"/>
    <limit effort="150.0" lower="-2.96706" upper="2.96706" velocity="0.85"/>
  </joint>
  <joint name="left_arm6_joint" type="revolute">
    <parent link="left_arm5"/>
    <child link="left_arm6"/>
    <origin rpy="-0.71372  1.57079  0.85707" xyz="0  0  0"/>
    <axis xyz="0 0 1"/>
    <limit effort="150.0" lower="-0.785398" upper="1.39626" velocity="0.85"/>
  </joint>
  <joint name="left_arm7_joint" type="revolute">
    <parent link="left_arm6"/>
    <child link="left_arm7"/>
    <origin rpy="-1.11887 -1.57079 -0.45192" xyz="0  0  0"/>
    <axis xyz="0 0 1"/>
    <limit effort="150.0" lower="-0.785398" upper="2.35619" velocity="0.85"/>
  </joint>
  <joint name="left_palm_joint" type="fixed">
    <parent link="left_arm7"/>
    <child link="left_palm"/>
    <origin rpy="1.57079 0.0 3.14159" xyz="0  0.1011  0"/>
  </joint>
  <joint name="left_1thumb_base_joint" type="fixed">
    <parent link="left_arm7"/>
    <child link="left_1thumb_base"/>
    <origin rpy="1.34429  0.02834  2.14927" xyz="-0.0504  0.2029 -0.0462"/>
    <axis xyz="0 0 1"/>
  </joint>
  <joint name="left_1thumb1_joint" type="revolute">
    <parent link="left_1thumb_base"/>
    <child link="left_1thumb1"/>
    <axis xyz="0 0 1"/>
    <limit effort="3.5" lower="-0.523599" upper="0.523599" velocity="0.85"/>
  </joint>
  <joint name="left_1thumb2_joint" type="revolute">
    <parent link="left_1thumb1"/>
    <child link="left_1thumb2"/>
    <origin rpy="1.57079  0       0" xyz="0  0  0"/>
    <axis xyz="0 0 1"/>
    <limit effort="3.5" lower="-0.349066" upper="1.50098" velocity="0.85"/>
  </joint>
  <joint name="left_1thumb3_joint" type="revolute">
    <parent link="left_1thumb2"/>
    <child link="left_1thumb3"/>
    <origin rpy="0  0  0" xyz="0.075  0     0"/>
    <axis xyz="0 0 1"/>
    <limit effort="1.75" lower="-0.174533" upper="1.76278" velocity="0.85"/>
  </joint>
  <joint name="left_1thumb4_joint" type="revolute">
    <parent link="left_1thumb3"/>
    <child link="left_1thumb4"/>
    <origin rpy="0       0      -1.57079" xyz="0.03999  0       0"/>
    <axis xyz="0 0 1"/>
    <limit effort="1.75" lower="-0.174533" upper="1.76278" velocity="0.85"/>
    <mimic joint="left_1thumb3_joint" multiplier="1" offset="0"/>
  </joint>
  <joint name="left_2tip_base_joint" type="fixed">
    <parent link="left_arm7"/>
    <child link="left_2tip_base"/>
    <origin rpy="-1.69632 -0.11527  1.36803" xyz="0.0482  0.2409 -0.0236"/>
    <axis xyz="0 0 1"/>
  </joint>
  <joint name="left_2tip1_joint" type="revolute">
    <parent link="left_2tip_base"/>
    <child link="left_2tip1"/>
    <axis xyz="0 0 1"/>
    <limit effort="3.5" lower="-0.523599" upper="0.523599" velocity="0.85"/>
  </joint>
  <joint name="left_2tip2_joint" type="revolute">
    <parent link="left_2tip1"/>
    <child link="left_2tip2"/>
    <origin rpy="1.57079  0       0" xyz="0  0  0"/>
    <axis xyz="0 0 1"/>
    <limit effort="3.5" lower="-0.349066" upper="1.50098" velocity="0.85"/>
  </joint>
  <joint name="left_2tip3_joint" type="revolute">
    <parent link="left_2tip2"/>
    <child link="left_2tip3"/>
    <origin rpy="0  0  0" xyz="0.075  0     0"/>
    <axis xyz="0 0 1"/>
    <limit effort="1.75" lower="-0.174533" upper="1.76278" velocity="0.85"/>
  </joint>
  <joint name="left_2tip4_joint" type="revolute">
    <parent link="left_2tip3"/>
    <child link="left_2tip4"/>
    <origin rpy="0       0      -1.57079" xyz="0.04  0    0"/>
    <axis xyz="0 0 1"/>
    <limit effort="1.75" lower="-0.174533" upper="1.76278" velocity="0.85"/>
    <mimic joint="left_2tip3_joint" multiplier="1.0" offset="0"/>
  </joint>
  <joint name="left_3middle_base_joint" type="fixed">
    <parent link="left_arm7"/>
    <child link="left_3middle_base"/>
    <origin rpy="-1.69632 -0.11527  1.36803" xyz="0.0469   0.2353   0.01629"/>
    <axis xyz="0 0 1"/>
  </joint>
  <joint name="left_3middle1_joint" type="revolute">
    <parent link="left_3middle_base"/>
    <child link="left_3middle1"/>
    <axis xyz="0 0 1"/>
    <limit effort="3.5" lower="-0.523599" upper="0.523599" velocity="0.85"/>
  </joint>
  <joint name="left_3middle2_joint" type="revolute">
    <parent link="left_3middle1"/>
    <child link="left_3middle2"/>
    <origin rpy="1.57079  0       0" xyz="0  0  0"/>
    <axis xyz="0 0 1"/>
    <limit effort="3.5" lower="-0.349066" upper="1.50098" velocity="0.85"/>
  </joint>
  <joint name="left_3middle3_joint" type="revolute">
    <parent link="left_3middle2"/>
    <child link="left_3middle3"/>
    <origin rpy="0  0  0" xyz="0.07499  0       0"/>
    <axis xyz="0 0 1"/>
    <limit effort="1.75" lower="-0.174533" upper="1.76278" velocity="0.85"/>
  </joint>
  <joint name="left_3middle4_joint" type="revolute">
    <parent link="left_3middle3"/>
    <child link="left_3middle4"/>
    <origin rpy="0       0      -1.57079" xyz="0.04  0    0"/>
    <axis xyz="0 0 1"/>
    <limit effort="1.75" lower="-0.174533" upper="1.76278" velocity="0.85"/>
    <mimic joint="left_3middle3_joint" multiplier="1" offset="0"/>
  </joint>
  <joint name="left_4ring_base_joint" type="fixed">
    <parent link="left_arm7"/>
    <child link="left_4ring_base"/>
    <origin rpy="-1.69632 -0.11527  1.36803" xyz="0.0374  0.2299  0.0623"/>
    <axis xyz="0 0 1"/>
  </joint>
  <joint name="left_4ring1_joint" type="revolute">
    <parent link="left_4ring_base"/>
    <child link="left_4ring1"/>
    <axis xyz="0 0 1"/>
    <limit effort="3.5" lower="-0.523599" upper="0.523599" velocity="0.85"/>
  </joint>
  <joint name="left_4ring2_joint" type="revolute">
    <parent link="left_4ring1"/>
    <child link="left_4ring2"/>
    <origin rpy="1.57079  0       0" xyz="0  0  0"/>
    <axis xyz="0 0 1"/>
    <limit effort="3.5" lower="-0.349066" upper="1.50098" velocity="0.85"/>
  </joint>
  <joint name="left_4ring3_joint" type="revolute">
    <parent link="left_4ring2"/>
    <child link="left_4ring3"/>
    <origin rpy="0  0  0" xyz="0.075  0     0"/>
    <axis xyz="0 0 1"/>
    <limit effort="1.75" lower="-0.174533" upper="1.76278" velocity="0.85"/>
  </joint>
  <joint name="left_4ring4_joint" type="revolute">
    <parent link="left_4ring3"/>
    <child link="left_4ring4"/>
    <origin rpy="0       0      -1.57079" xyz="0.04  0    0"/>
    <axis xyz="0 0 1"/>
    <limit effort="1.75" lower="-0.174533" upper="1.76278" velocity="0.85"/>
    <mimic joint="left_4ring3_joint" multiplier="1" offset="0"/>
  </joint>
  <joint name="right_arm1_joint" type="revolute">
    <parent link="torso4"/>
    <child link="right_arm1"/>
    <origin rpy="3.14159  0.52359  3.14159" xyz="0.19   0.088 -0.256"/>
    <axis xyz="0 0 1"/>
    <limit effort="150.0" lower="-2.96706" upper="2.96706" velocity="0.85"/>
  </joint>
  <joint name="right_arm2_joint" type="revolute">
    <parent link="right_arm1"/>
    <child link="right_arm2"/>
    <origin rpy="1.57079  0       0" xyz="0  0  0"/>
    <axis xyz="0 0 1"/>
    <limit effort="150.0" lower="-2.0944" upper="2.0944" velocity="0.85"/>
  </joint>
  <joint name="right_arm3_joint" type="revolute">
    <parent link="right_arm2"/>
    <child link="right_arm3"/>
    <origin rpy="0.35435 -1.57079 -1.92515" xyz="0   0.4  0"/>
    <axis xyz="0 0 1"/>
    <limit effort="150.0" lower="-2.96706" upper="2.96706" velocity="0.85"/>
  </joint>
  <joint name="right_arm4_joint" type="revolute">
    <parent link="right_arm3"/>
    <child link="right_arm4"/>
    <origin rpy="1.57079  0       0" xyz="0  0  0"/>
    <axis xyz="0 0 1"/>
    <limit effort="150.0" lower="-2.0944" upper="2.0944" velocity="0.85"/>
  </joint>
  <joint name="right_arm5_joint" type="revolute">
    <parent link="right_arm4"/>
    <child link="right_arm5"/>
    <origin rpy="1.57079  0      -3.14159" xyz="0    0.39  0"/>
    <axis xyz="0 0 1"/>
    <limit effort="150.0" lower="-2.96706" upper="2.96706" velocity="0.85"/>
  </joint>
  <joint name="right_arm6_joint" type="revolute">
    <parent link="right_arm5"/>
    <child link="right_arm6"/>
    <origin rpy="0.39796 -1.57079  1.17283" xyz="0  0  0"/>
    <axis xyz="0 0 1"/>
    <limit effort="150.0" lower="-0.785398" upper="1.39626" velocity="0.85"/>
  </joint>
  <joint name="right_arm7_joint" type="revolute">
    <parent link="right_arm6"/>
    <child link="right_arm7"/>
    <origin rpy="1.59992  1.57079  0.02912" xyz="0  0  0"/>
    <axis xyz="0 0 1"/>
    <limit effort="150.0" lower="-0.785398" upper="2.35619" velocity="0.85"/>
  </joint>
  <joint name="right_palm_joint" type="fixed">
    <parent link="right_arm7"/>
    <child link="right_palm"/>
    <origin rpy="1.57079 0.0 3.14159" xyz="0  0.1011  0"/>
  </joint>
  <joint name="right_1thumb_base_joint" type="fixed">
    <parent link="right_arm7"/>
    <child link="right_1thumb_base"/>
    <origin rpy="1.79407 -0.02832  2.14923" xyz="-0.0504  0.2029  0.0462"/>
    <axis xyz="0 0 1"/>
  </joint>
  <joint name="right_1thumb1_joint" type="revolute">
    <parent link="right_1thumb_base"/>
    <child link="right_1thumb1"/>
    <axis xyz="0 0 1"/>
    <limit effort="3.5" lower="-0.523599" upper="0.523599" velocity="0.85"/>
  </joint>
  <joint name="right_1thumb2_joint" type="revolute">
    <parent link="right_1thumb1"/>
    <child link="right_1thumb2"/>
    <origin rpy="1.57079  0       0" xyz="0  0  0"/>
    <axis xyz="0 0 1"/>
    <limit effort="3.5" lower="-0.349066" upper="1.50098" velocity="0.85"/>
  </joint>
  <joint name="right_1thumb3_joint" type="revolute">
    <parent link="right_1thumb2"/>
    <child link="right_1thumb3"/>
    <origin rpy="0  0  0" xyz="0.075  0     0"/>
    <axis xyz="0 0 1"/>
    <limit effort="1.75" lower="-0.174533" upper="1.76278" velocity="0.85"/>
  </joint>
  <joint name="right_1thumb4_joint" type="revolute">
    <parent link="right_1thumb3"/>
    <child link="right_1thumb4"/>
    <origin rpy="0       0      -1.57079" xyz="0.04  0    0"/>
    <axis xyz="0 0 1"/>
    <limit effort="1.75" lower="-0.174533" upper="1.76278" velocity="0.85"/>
    <mimic joint="right_1thumb3_joint" multiplier="1.0" offset="0"/>
  </joint>
  <joint name="right_3middle_base_joint" type="fixed">
    <parent link="right_arm7"/>
    <child link="right_3middle_base"/>
    <origin rpy="-1.44842  0.11516  1.36812" xyz="0.0469   0.2353  -0.01629"/>
    <axis xyz="0 0 1"/>
  </joint>
  <joint name="right_3middle1_joint" type="revolute">
    <parent link="right_3middle_base"/>
    <child link="right_3middle1"/>
    <axis xyz="0 0 1"/>
    <limit effort="3.5" lower="-0.523599" upper="0.523599" velocity="0.85"/>
  </joint>
  <joint name="right_3middle2_joint" type="revolute">
    <parent link="right_3middle1"/>
    <child link="right_3middle2"/>
    <origin rpy="1.57079  0       0" xyz="0  0  0"/>
    <axis xyz="0 0 1"/>
    <limit effort="3.5" lower="-0.349066" upper="1.50098" velocity="0.85"/>
  </joint>
  <joint name="right_3middle3_joint" type="revolute">
    <parent link="right_3middle2"/>
    <child link="right_3middle3"/>
    <origin rpy="0  0  0" xyz="0.075  0     0"/>
    <axis xyz="0 0 1"/>
    <limit effort="1.75" lower="-0.174533" upper="1.76278" velocity="0.85"/>
  </joint>
  <joint name="right_3middle4_joint" type="revolute">
    <parent link="right_3middle3"/>
    <child link="right_3middle4"/>
    <origin rpy="0       0      -1.57079" xyz="0.04  0    0"/>
    <axis xyz="0 0 1"/>
    <limit effort="1.75" lower="-0.174533" upper="1.76278" velocity="0.85"/>
    <mimic joint="right_3middle3_joint" multiplier="1.0" offset="0"/>
  </joint>
  <joint name="right_4ring_base_joint" type="fixed">
    <parent link="right_arm7"/>
    <child link="right_4ring_base"/>
    <origin rpy="-1.44842  0.11516  1.36812" xyz="0.0374  0.2299 -0.0623"/>
    <axis xyz="0 0 1"/>
  </joint>
  <joint name="right_4ring1_joint" type="revolute">
    <parent link="right_4ring_base"/>
    <child link="right_4ring1"/>
    <axis xyz="0 0 1"/>
    <limit effort="3.5" lower="-0.523599" upper="0.523599" velocity="0.85"/>
  </joint>
  <joint name="right_4ring2_joint" type="revolute">
    <parent link="right_4ring1"/>
    <child link="right_4ring2"/>
    <origin rpy="1.57079  0       0" xyz="0  0  0"/>
    <axis xyz="0 0 1"/>
    <limit effort="3.5" lower="-0.349066" upper="1.50098" velocity="0.85"/>
  </joint>
  <joint name="right_4ring3_joint" type="revolute">
    <parent link="right_4ring2"/>
    <child link="right_4ring3"/>
    <origin rpy="0  0  0" xyz="0.075  0     0"/>
    <axis xyz="0 0 1"/>
    <limit effort="1.75" lower="-0.174533" upper="1.76278" velocity="0.85"/>
  </joint>
  <joint name="right_4ring4_joint" type="revolute">
    <parent link="right_4ring3"/>
    <child link="right_4ring4"/>
    <origin rpy="0       0      -1.57079" xyz="0.04  0    0"/>
    <axis xyz="0 0 1"/>
    <limit effort="1.75" lower="-0.174533" upper="1.76278" velocity="0.85"/>
    <mimic joint="right_4ring3_joint" multiplier="1.0" offset="0"/>
  </joint>
  <joint name="right_2tip_base_joint" type="fixed">
    <parent link="right_arm7"/>
    <child link="right_2tip_base"/>
    <origin rpy="-1.44842  0.11516  1.36812" xyz="0.0482  0.2409  0.0236"/>
    <axis xyz="0 0 1"/>
  </joint>
  <joint name="right_2tip1_joint" type="revolute">
    <parent link="right_2tip_base"/>
    <child link="right_2tip1"/>
    <axis xyz="0 0 1"/>
    <limit effort="3.5" lower="-0.523599" upper="0.523599" velocity="0.85"/>
  </joint>
  <joint name="right_2tip2_joint" type="revolute">
    <parent link="right_2tip1"/>
    <child link="right_2tip2"/>
    <origin rpy="1.57079  0       0" xyz="0  0  0"/>
    <axis xyz="0 0 1"/>
    <limit effort="3.5" lower="-0.349066" upper="1.50098" velocity="0.85"/>
  </joint>
  <joint name="right_2tip3_joint" type="revolute">
    <parent link="right_2tip2"/>
    <child link="right_2tip3"/>
    <origin rpy="0  0  0" xyz="0.075  0     0"/>
    <axis xyz="0 0 1"/>
    <limit effort="1.75" lower="-0.174533" upper="1.76278" velocity="0.85"/>
  </joint>
  <joint name="right_2tip4_joint" type="revolute">
    <parent link="right_2tip3"/>
    <child link="right_2tip4"/>
    <origin rpy="0       0      -1.57079" xyz="0.04  0    0"/>
    <axis xyz="0 0 1"/>
    <limit effort="1.75" lower="-0.174533" upper="1.76278" velocity="0.85"/>
    <mimic joint="right_2tip3_joint" multiplier="1.0" offset="0"/>
  </joint>
  <joint name="r_gripper_tool_joint" type="fixed">
    <origin rpy="0 0 0" xyz="0.0 0.0 0.13" />
    <parent link="right_palm" />
    <child link="r_gripper_tool_frame" />
  </joint>
  <link name="r_gripper_tool_frame"><inertial><mass value="0.1" /><origin rpy="0 0 0" xyz="0 0 0" /><inertia ixx="0.01" ixy="0" ixz="0" iyy="0.01" iyz="0" izz="0.01" /></inertial></link>
  <joint name="l_gripper_tool_joint" type="fixed">
    <origin rpy="0 0 0" xyz="0.0 0 0.13" />
    <parent link="left_palm" />
    <child link="l_gripper_tool_frame" />
  </joint>
  <link name="l_gripper_tool_frame"><inertial><mass value="0.1" /><origin rpy="0 0 0" xyz="0 0 0" /><inertia ixx="0.01" ixy="0" ixz="0" iyy="0.01" iyz="0" izz="0.01" /></inertial></link>
  <link name="base_link">
    <inertial>
      <mass value="145"/>
      <origin rpy="0 -0 0" xyz="-0.0002822 -0.0000164307 0.295663"/>
      <inertia ixx="19" ixy="-3" ixz="-1" iyy="21" iyz="0" izz="6"/>
    </inertial>
    <visual name="base">
      <origin rpy="0  0  0" xyz="0  0  0"/>
      <geometry>
        <mesh filename="package://iai_dlr_rollin_justin/mjcf/rollin-justin/meshes/stl/base.stl" scale="1 1 1"/>
      </geometry>
    </visual>
    <collision name="base">
      <origin rpy="0  0  0" xyz="0  0  0"/>
      <geometry>
        <mesh filename="package://iai_dlr_rollin_justin/mjcf/rollin-justin/meshes/stl/base.stl" scale="1 1 1"/>
      </geometry>
    </collision>
  </link>
  <link name="torso1">
    <inertial>
      <mass value="4.554854"/>
      <origin rpy="0 0 0" xyz="-0.0638413 0.0127 -0.0328232"/>
      <inertia ixx="0.029416341" ixy="0.0013815574" ixz="0.0064370704" iyy="0.022660076" iyz="-0.0019979594" izz="0.029707633"/>
    </inertial>
    <visual name="torso1_vis_ShapeIndexedFaceSet_visual">
      <origin rpy="0  0  0" xyz="0  0  0"/>
      <geometry>
        <mesh filename="package://iai_dlr_rollin_justin/mjcf/rollin-justin/meshes/stl/torso1.stl" scale="1 1 1"/>
      </geometry>
    </visual>
    <collision name="torso1_vis_ShapeIndexedFaceSet_collision">
      <origin rpy="0  0  0" xyz="0      0      0.0"/>
      <geometry>
        <mesh filename="package://iai_dlr_rollin_justin/mjcf/rollin-justin/meshes/stl/torso1.stl" scale="1 1 1"/>
      </geometry>
    </collision>
  </link>
  <link name="torso2">
    <inertial>
      <mass value="5.4703718"/>
      <origin rpy="0 0 0" xyz="0.21859133 -0.013019641 0.0062231342"/>
      <inertia ixx="0.034258791" ixy="-0.0043096145" ixz="-0.0019014484" iyy="0.094431416" iyz="-0.0012349292" izz="0.072968793"/>
    </inertial>
    <collision name="torso2_vis_ShapeIndexedFaceSet_coll">
      <origin rpy="0  0  0" xyz="0  0  0"/>
      <geometry>
        <mesh filename="package://iai_dlr_rollin_justin/mjcf/rollin-justin/meshes/stl/torso2.stl" scale="1 1 1"/>
      </geometry>
    </collision>
    <visual name="torso2_vis_ShapeIndexedFaceSet_visual">
      <origin rpy="0  0  0" xyz="0  0  0"/>
      <geometry>
        <mesh filename="package://iai_dlr_rollin_justin/mjcf/rollin-justin/meshes/stl/torso2.stl" scale="1 1 1"/>
      </geometry>
    </visual>
  </link>
  <link name="torso3">
    <inertial>
      <mass value="2.9250956"/>
      <origin rpy="0 0 0" xyz="0.15320139 -0.022720538 0.0019282567"/>
      <inertia ixx="0.021025459" ixy="-0.00015098276" ixz="0.000079909895" iyy="0.051821556" iyz="-0.00065335454" izz="0.038951050"/>
    </inertial>
    <collision name="torso3_vis_ShapeIndexedFaceSet_coll">
      <origin rpy="0  0  0" xyz="0  0  0"/>
      <geometry>
        <mesh filename="package://iai_dlr_rollin_justin/mjcf/rollin-justin/meshes/stl/torso3.stl" scale="1 1 1"/>
      </geometry>
    </collision>
    <visual name="torso3_vis_ShapeIndexedFaceSet_visual">
      <origin rpy="0  0  0" xyz="0  0  0"/>
      <geometry>
        <mesh filename="package://iai_dlr_rollin_justin/mjcf/rollin-justin/meshes/stl/torso3.stl" scale="1 1 1"/>
      </geometry>
    </visual>
  </link>
  <link name="torso4">
    <inertial>
      <mass value="5.7594877"/>
      <origin rpy="0 0 0" xyz="0.053666155 0.013429498 -0.00068257189"/>
      <inertia ixx="0.039626044" ixy="0.0046320581" ixz="-0.000078895790" iyy="0.041545868" iyz="-0.0019776437" izz="0.025545478"/>
    </inertial>
    <collision name="torso4_vis_ShapeIndexedFaceSet_coll">
      <origin rpy="0  0  0" xyz="0  0  0"/>
      <geometry>
        <mesh filename="package://iai_dlr_rollin_justin/mjcf/rollin-justin/meshes/stl/torso4.stl" scale="1 1 1"/>
      </geometry>
    </collision>
    <visual name="torso4_vis_ShapeIndexedFaceSet_visual">
      <origin rpy="0  0  0" xyz="0  0  0"/>
      <geometry>
        <mesh filename="package://iai_dlr_rollin_justin/mjcf/rollin-justin/meshes/stl/torso4.stl" scale="1 1 1"/>
      </geometry>
    </visual>
  </link>
  <link name="head1">
    <inertial>
      <mass value="2"/>
      <origin rpy="0 -0 0" xyz="0 0 0"/>
      <inertia ixx="1" ixy="0" ixz="0" iyy="1" iyz="0" izz="1"/>
    </inertial>
    <visual name="head1_vis_ShapeIndexedFaceSet_visual">
      <origin rpy="0  0  0" xyz="0  0  0"/>
      <geometry>
        <mesh filename="package://iai_dlr_rollin_justin/mjcf/rollin-justin/meshes/stl/head1.stl" scale="1 1 1"/>
      </geometry>
    </visual>
    <collision name="head1_vis_ShapeIndexedFaceSet_collision">
      <origin rpy="0  0  0" xyz="0     0     0.055"/>
      <geometry>
        <mesh filename="package://iai_dlr_rollin_justin/mjcf/rollin-justin/meshes/stl/head1.stl" scale="1 1 1"/>
      </geometry>
    </collision>
  </link>
  <link name="head2">
    <inertial>
      <mass value="3"/>
      <origin rpy="0 -0 0" xyz="0 0 0"/>
      <inertia ixx="1" ixy="0" ixz="0" iyy="1" iyz="0" izz="1"/>
    </inertial>
    <visual name="head2_vis_ShapeIndexedFaceSet.002_visual">
      <origin rpy="0  0  0" xyz="0  0  0"/>
      <geometry>
        <mesh filename="package://iai_dlr_rollin_justin/mjcf/rollin-justin/meshes/stl/head2.stl" scale="1 1 1"/>
      </geometry>
    </visual>
    <collision name="head2_vis_ShapeIndexedFaceSet.002_collision">
      <origin rpy="0  0  0" xyz="0  0  0"/>
      <geometry>
        <mesh filename="package://iai_dlr_rollin_justin/mjcf/rollin-justin/meshes/stl/head2.stl" scale="1 1 1"/>
      </geometry>
    </collision>
  </link>
  <link name="left_arm1">
    <inertial>
      <mass value="2.6371"/>
      <origin rpy="0 0 0" xyz="0.0 -0.02029 0.045943"/>
      <inertia ixx="0.01711" ixy="0.00000" ixz="0.00000" iyy="0.01682" iyz="-0.00165" izz="0.00452"/>
    </inertial>
    <collision name="left_arm1_vis_ShapeIndexedFaceSet.002_coll">
      <origin rpy="0  0  0" xyz="0  0  0"/>
      <geometry>
        <mesh filename="package://iai_dlr_rollin_justin/mjcf/rollin-justin/meshes/stl/left_arm1.stl" scale="1 1 1"/>
      </geometry>
    </collision>
    <visual name="left_arm1_vis_ShapeIndexedFaceSet.002_visual">
      <origin rpy="0  0  0" xyz="0  0  0"/>
      <geometry>
        <mesh filename="package://iai_dlr_rollin_justin/mjcf/rollin-justin/meshes/stl/left_arm1.stl" scale="1 1 1"/>
      </geometry>
    </visual>
  </link>
  <link name="left_arm2">
    <inertial>
      <mass value="2.3261934"/>
      <origin rpy="0 0 0" xyz="0.0 -0.11406 -0.016447"/>
      <inertia ixx="0.01997" ixy="0.00000" ixz="0.00000" iyy="0.00447" iyz="0.00359" izz="0.01921"/>
    </inertial>
    <collision name="left_arm2_vis_ShapeIndexedFaceSet.002_coll">
      <origin rpy="0  0  0" xyz="0  0  0"/>
      <geometry>
        <mesh filename="package://iai_dlr_rollin_justin/mjcf/rollin-justin/meshes/stl/left_arm2.stl" scale="1 1 1"/>
      </geometry>
    </collision>
    <visual name="left_arm2_vis_ShapeIndexedFaceSet.002_visual">
      <origin rpy="0  0  0" xyz="0  0  0"/>
      <geometry>
        <mesh filename="package://iai_dlr_rollin_justin/mjcf/rollin-justin/meshes/stl/left_arm2.stl" scale="1 1 1"/>
      </geometry>
    </visual>
  </link>
  <link name="left_arm3">
    <inertial>
      <mass value="2.293"/>
      <origin rpy="0 0 0" xyz="0.0 -0.018013 0.05394"/>
      <inertia ixx="0.01692" ixy="0.00000" ixz="0.00000" iyy="0.01644" iyz="-0.00163" izz="0.00424"/>
    </inertial>
    <collision name="left_arm3_vis_ShapeIndexedFaceSet.002_coll">
      <origin rpy="0  0  0" xyz="0  0  0"/>
      <geometry>
        <mesh filename="package://iai_dlr_rollin_justin/mjcf/rollin-justin/meshes/stl/left_arm3.stl" scale="1 1 1"/>
      </geometry>
    </collision>
    <visual name="left_arm3_vis_ShapeIndexedFaceSet.002_visual">
      <origin rpy="0  0  0" xyz="0  0  0"/>
      <geometry>
        <mesh filename="package://iai_dlr_rollin_justin/mjcf/rollin-justin/meshes/stl/left_arm3.stl" scale="1 1 1"/>
      </geometry>
    </visual>
  </link>
  <link name="left_arm4">
    <inertial>
      <mass value="2.2036950"/>
      <origin rpy="0 0 0" xyz="0.0 -0.11374 -0.013669"/>
      <inertia ixx="0.02052" ixy="0.00000" ixz="0.00000" iyy="0.00451" iyz="0.00372" izz="0.01972"/>
    </inertial>
    <collision name="left_arm4_vis_ShapeIndexedFaceSet.002_coll">
      <origin rpy="0  0  0" xyz="0  0  0"/>
      <geometry>
        <mesh filename="package://iai_dlr_rollin_justin/mjcf/rollin-justin/meshes/stl/left_arm4.stl" scale="1 1 1"/>
      </geometry>
    </collision>
    <visual name="left_arm4_vis_ShapeIndexedFaceSet.002_visual">
      <origin rpy="0  0  0" xyz="0  0  0"/>
      <geometry>
        <mesh filename="package://iai_dlr_rollin_justin/mjcf/rollin-justin/meshes/stl/left_arm4.stl" scale="1 1 1"/>
      </geometry>
    </visual>
  </link>
  <link name="left_arm5">
    <inertial>
      <mass value="0.7010105"/>
      <origin rpy="0 0 0" xyz="0.0 -0.021901 0.10562"/>
      <inertia ixx="0.00541" ixy="0.00000" ixz="0.00000" iyy="0.00505" iyz="-0.00140" izz="0.00210"/>
    </inertial>
    <collision name="left_arm5_vis_ShapeIndexedFaceSet_coll">
      <origin rpy="0  0  0" xyz="0  0  0"/>
      <geometry>
        <mesh filename="package://iai_dlr_rollin_justin/mjcf/rollin-justin/meshes/stl/left_arm5.stl" scale="1 1 1"/>
      </geometry>
    </collision>
    <visual name="left_arm5_vis_ShapeIndexedFaceSet_visual">
      <origin rpy="0  0  0" xyz="0  0  0"/>
      <geometry>
        <mesh filename="package://iai_dlr_rollin_justin/mjcf/rollin-justin/meshes/stl/left_arm5.stl" scale="1 1 1"/>
      </geometry>
    </visual>
  </link>
  <link name="left_arm6">
    <inertial>
      <mass value="1.6742"/>
      <origin rpy="0 0 0" xyz="0.0 0.0072564 0.005791"/>
      <inertia ixx="0.00324" ixy="0.00000" ixz="0.00000" iyy="0.00308" iyz="0.00000" izz="0.00297"/>
    </inertial>
    <collision name="left_arm6_vis_ShapeIndexedFaceSet_coll">
      <origin rpy="0  0  0" xyz="0  0  0"/>
      <geometry>
        <mesh filename="package://iai_dlr_rollin_justin/mjcf/rollin-justin/meshes/stl/left_arm6.stl" scale="1 1 1"/>
      </geometry>
    </collision>
    <visual name="left_arm6_vis_ShapeIndexedFaceSet_visual">
      <origin rpy="0  0  0" xyz="0  0  0"/>
      <geometry>
        <mesh filename="package://iai_dlr_rollin_justin/mjcf/rollin-justin/meshes/stl/left_arm6.stl" scale="1 1 1"/>
      </geometry>
    </visual>
  </link>
  <link name="left_arm7">
    <inertial>
      <mass value="0.270"/>
      <origin rpy="0 0 -0" xyz="0.071939 0.0 -0.023387"/>
      <inertia ixx="0.00096" ixy="0.00000" ixz="0.00083" iyy="0.00226" iyz="0.00000" izz="0.00176"/>
    </inertial>
    <collision name="left_arm7_vis_ShapeIndexedFaceSet_coll">
      <origin rpy="0  0  0" xyz="0  0  0"/>
      <geometry>
        <mesh filename="package://iai_dlr_rollin_justin/mjcf/rollin-justin/meshes/stl/left_arm7.stl" scale="1 1 1"/>
      </geometry>
    </collision>
    <visual name="left_arm7_vis_ShapeIndexedFaceSet_visual">
      <origin rpy="0  0  0" xyz="0  0  0"/>
      <geometry>
        <mesh filename="package://iai_dlr_rollin_justin/mjcf/rollin-justin/meshes/stl/left_arm7.stl" scale="1 1 1"/>
      </geometry>
    </visual>
  </link>
  <link name="left_palm">
    <inertial>
      <mass value="1.40"/>
      <origin rpy="0 0 0" xyz="0.0015 0.0115 0.1066"/>
      <inertia ixx="3.4657189e-02" ixy="-4.8421020e-03" ixz="-1.7680628e-03" iyy="1.5089606e-02" iyz="1.7375485e-03" izz="8.5636015e-03"/>
    </inertial>
  </link>
  <link name="left_3middle_base">
    <inertial>
      <mass value="0.05"/>
      <origin rpy="0  0  0" xyz="0  0  0"/>
      <inertia ixx="0.1" ixy="0" ixz="0" iyy="0.1" iyz="0" izz="0.1"/>
    </inertial>
    <collision name="left_3middle1_visual">
      <origin rpy="0  0  0" xyz="0  0  0"/>
      <geometry>
        <mesh filename="package://iai_dlr_rollin_justin/mjcf/rollin-justin/meshes/stl/finger-base.stl" scale="1 1 1"/>
      </geometry>
    </collision>
    <visual name="left_3middle1_visual">
      <origin rpy="0  0  0" xyz="0  0  0"/>
      <geometry>
        <mesh filename="package://iai_dlr_rollin_justin/mjcf/rollin-justin/meshes/stl/finger-base.stl" scale="1 1 1"/>
      </geometry>
    </visual>
  </link>
  <link name="left_3middle1"/>
  <link name="left_3middle2">
    <inertial>
      <mass value="0.05"/>
      <origin rpy="0 -0 0" xyz="0 0 0"/>
      <inertia ixx="0.1" ixy="0" ixz="0" iyy="0.1" iyz="0" izz="0.1"/>
    </inertial>
    <collision name="left_3middle2_coll">
      <origin rpy="0  0  0" xyz="0  0  0"/>
      <geometry>
        <mesh filename="package://iai_dlr_rollin_justin/mjcf/rollin-justin/meshes/stl/finger-phaprox.stl" scale="1 1 1"/>
      </geometry>
    </collision>
    <visual name="finger_phaprox_visual">
      <origin rpy="0  0  0" xyz="0  0  0"/>
      <geometry>
        <mesh filename="package://iai_dlr_rollin_justin/mjcf/rollin-justin/meshes/stl/finger-phaprox.stl" scale="1 1 1"/>
      </geometry>
    </visual>
  </link>
  <link name="left_3middle3">
    <inertial>
      <mass value="0.05"/>
      <origin rpy="0 -0 0" xyz="0 0 0"/>
      <inertia ixx="0.1" ixy="0" ixz="0" iyy="0.1" iyz="0" izz="0.1"/>
    </inertial>
    <collision name="left_3middle3_coll">
      <origin rpy="0  0  0" xyz="0  0  0"/>
      <geometry>
        <mesh filename="package://iai_dlr_rollin_justin/mjcf/rollin-justin/meshes/stl/finger-phamed.stl" scale="1 1 1"/>
      </geometry>
    </collision>
    <visual name="left_3middle3_vis_ShapeIndexedFaceSet.015_visual">
      <origin rpy="0  0  0" xyz="0  0  0"/>
      <geometry>
        <mesh filename="package://iai_dlr_rollin_justin/mjcf/rollin-justin/meshes/stl/finger-phamed.stl" scale="1 1 1"/>
      </geometry>
    </visual>
  </link>
  <link name="left_3middle4">
    <inertial>
      <mass value="0.05"/>
      <origin rpy="0 -0 0" xyz="0 0 0"/>
      <inertia ixx="0.1" ixy="0" ixz="0" iyy="0.1" iyz="0" izz="0.1"/>
    </inertial>
    <collision name="left_3middle4_coll">
      <origin rpy="0  0  0" xyz="0  0  0"/>
      <geometry>
	<mesh filename="package://iai_dlr_rollin_justin/mjcf/rollin-justin/meshes/stl/hii2_geh_phadist_gesamt_asm.stl" scale="1 1 1"/>
      </geometry>
    </collision>
    <visual name="left_3middle4_vis_ShapeIndexedFaceSet.020_visual">
      <origin rpy="0  0  0" xyz="0  0  0"/>
      <geometry>
	<mesh filename="package://iai_dlr_rollin_justin/mjcf/rollin-justin/meshes/stl/hii2_geh_phadist_gesamt_asm.stl" scale="1 1 1"/>
      </geometry>
    </visual>
  </link>
  <link name="left_4ring_base">
    <inertial>
      <mass value="0.05"/>
      <origin rpy="0  0  0" xyz="0  0  0"/>
      <inertia ixx="0.1" ixy="0" ixz="0" iyy="0.1" iyz="0" izz="0.1"/>
    </inertial>
    <visual name="left_4ring1_visual">
      <origin rpy="0  0  0" xyz="0  0  0"/>
      <geometry>
        <mesh filename="package://iai_dlr_rollin_justin/mjcf/rollin-justin/meshes/stl/finger-base.stl" scale="1 1 1"/>
      </geometry>
    </visual>
  </link>
  <link name="left_4ring1"/>
  <link name="left_4ring2">
    <inertial>
      <mass value="0.05"/>
      <origin rpy="0 -0 0" xyz="0 0 0"/>
      <inertia ixx="0.1" ixy="0" ixz="0" iyy="0.1" iyz="0" izz="0.1"/>
    </inertial>
    <collision name="left_4ring2_coll">
      <origin rpy="0  0  0" xyz="0  0  0"/>
      <geometry>
        <mesh filename="package://iai_dlr_rollin_justin/mjcf/rollin-justin/meshes/stl/finger-phaprox.stl" scale="1 1 1"/>
      </geometry>
    </collision>
    <visual name="left_4ring2_visual">
      <origin rpy="0  0  0" xyz="0  0  0"/>
      <geometry>
        <mesh filename="package://iai_dlr_rollin_justin/mjcf/rollin-justin/meshes/stl/finger-phaprox.stl" scale="1 1 1"/>
      </geometry>
    </visual>
  </link>
  <link name="left_4ring3">
    <inertial>
      <mass value="0.05"/>
      <origin rpy="0 0 0" xyz="0 0 0"/>
      <inertia ixx="0.1" ixy="0" ixz="0" iyy="0.1" iyz="0" izz="0.1"/>
    </inertial>
    <collision name="left_4ring3_coll">
      <origin rpy="0  0  0" xyz="0  0  0"/>
      <geometry>
        <mesh filename="package://iai_dlr_rollin_justin/mjcf/rollin-justin/meshes/stl/finger-phamed.stl" scale="1 1 1"/>
      </geometry>
    </collision>
    <visual name="left_4ring3_visual">
      <origin rpy="0  0  0" xyz="0  0  0"/>
      <geometry>
        <mesh filename="package://iai_dlr_rollin_justin/mjcf/rollin-justin/meshes/stl/finger-phamed.stl" scale="1 1 1"/>
      </geometry>
    </visual>
  </link>
  <link name="left_4ring4">
    <inertial>
      <mass value="0.05"/>
      <origin rpy="0 -0 0" xyz="0 0 0"/>
      <inertia ixx="0.1" ixy="0" ixz="0" iyy="0.1" iyz="0" izz="0.1"/>
    </inertial>
    <collision name="left_4ring4_coll">
      <origin rpy="0  0  0" xyz="0  0  0"/>
      <geometry>
        <mesh filename="package://iai_dlr_rollin_justin/mjcf/rollin-justin/meshes/stl/hii2_geh_phadist_gesamt_asm.stl" scale="1 1 1"/>
      </geometry>
    </collision>
    <visual name="left_4ring4_visual">
      <origin rpy="0  0  0" xyz="0  0  0"/>
      <geometry>
        <mesh filename="package://iai_dlr_rollin_justin/mjcf/rollin-justin/meshes/stl/hii2_geh_phadist_gesamt_asm.stl" scale="1 1 1"/>
      </geometry>
    </visual>
  </link>
  <link name="left_1thumb_base">
    <inertial>
      <mass value="0.05"/>
      <origin rpy="0  0  0" xyz="0  0  0"/>
      <inertia ixx="0.1" ixy="0" ixz="0" iyy="0.1" iyz="0" izz="0.1"/>
    </inertial>
    <visual name="left_1thumb1_visual">
      <origin rpy="0  0  0" xyz="0  0  0"/>
      <geometry>
        <mesh filename="package://iai_dlr_rollin_justin/mjcf/rollin-justin/meshes/stl/finger-base.stl" scale="1 1 1"/>
      </geometry>
    </visual>
  </link>
  <link name="left_1thumb1"/>
  <link name="left_1thumb2">
    <inertial>
      <mass value="0.05"/>
      <origin rpy="0 -0 0" xyz="0 0 0"/>
      <inertia ixx="0.1" ixy="0" ixz="0" iyy="0.1" iyz="0" izz="0.1"/>
    </inertial>
    <collision name="left_1thumb2_coll">
      <origin rpy="0  0  0" xyz="0  0  0"/>
      <geometry>
        <mesh filename="package://iai_dlr_rollin_justin/mjcf/rollin-justin/meshes/stl/finger-phaprox.stl" scale="1 1 1"/>
      </geometry>
    </collision>
    <visual name="left_1thumb2_visual">
      <origin rpy="0  0  0" xyz="0  0  0"/>
      <geometry>
        <mesh filename="package://iai_dlr_rollin_justin/mjcf/rollin-justin/meshes/stl/finger-phaprox.stl" scale="1 1 1"/>
      </geometry>
    </visual>
  </link>
  <link name="left_1thumb3">
    <inertial>
      <mass value="0.05"/>
      <origin rpy="0 -0 0" xyz="0 0 0"/>
      <inertia ixx="0.1" ixy="0" ixz="0" iyy="0.1" iyz="0" izz="0.1"/>
    </inertial>
    <collision name="left_1thumb3_coll">
      <origin rpy="0  0  0" xyz="0  0  0"/>
      <geometry>
        <mesh filename="package://iai_dlr_rollin_justin/mjcf/rollin-justin/meshes/stl/finger-phamed.stl" scale="1 1 1"/>
      </geometry>
    </collision>
    <visual name="left_1thumb3_visual">
      <origin rpy="0  0  0" xyz="0  0  0"/>
      <geometry>
        <mesh filename="package://iai_dlr_rollin_justin/mjcf/rollin-justin/meshes/stl/finger-phamed.stl" scale="1 1 1"/>
      </geometry>
    </visual>
  </link>
  <link name="left_1thumb4">
    <inertial>
      <mass value="0.05"/>
      <origin rpy="0 -0 0" xyz="0 0 0"/>
      <inertia ixx="0.1" ixy="0" ixz="0" iyy="0.1" iyz="0" izz="0.1"/>
    </inertial>
    <collision name="left_1thumb4_coll">
      <origin rpy="0  0  0" xyz="0  0  0"/>
      <geometry>
        <mesh filename="package://iai_dlr_rollin_justin/mjcf/rollin-justin/meshes/stl/hii2_geh_phadist_gesamt_asm.stl" scale="1 1 1"/>
      </geometry>
    </collision>
    <visual name="left_1thumb4_visual">
      <origin rpy="0  0  0" xyz="0  0  0"/>
      <geometry>
        <mesh filename="package://iai_dlr_rollin_justin/mjcf/rollin-justin/meshes/stl/hii2_geh_phadist_gesamt_asm.stl" scale="1 1 1"/>
      </geometry>
    </visual>
  </link>
  <link name="left_2tip_base">
    <inertial>
      <mass value="0.05"/>
      <origin rpy="0  0  0" xyz="0  0  0"/>
      <inertia ixx="0.1" ixy="0" ixz="0" iyy="0.1" iyz="0" izz="0.1"/>
    </inertial>
    <visual name="left_2tip1_visual">
      <origin rpy="0  0  0" xyz="0  0  0"/>
      <geometry>
        <mesh filename="package://iai_dlr_rollin_justin/mjcf/rollin-justin/meshes/stl/finger-base.stl" scale="1 1 1"/>
      </geometry>
    </visual>
  </link>
  <link name="left_2tip1"/>
  <link name="left_2tip2">
    <inertial>
      <mass value="0.05"/>
      <origin rpy="0 -0 0" xyz="0 0 0"/>
      <inertia ixx="0.1" ixy="0" ixz="0" iyy="0.1" iyz="0" izz="0.1"/>
    </inertial>
    <collision name="left_2tip2_coll">
      <origin rpy="0  0  0" xyz="0  0  0"/>
      <geometry>
        <mesh filename="package://iai_dlr_rollin_justin/mjcf/rollin-justin/meshes/stl/finger-phaprox.stl" scale="1 1 1"/>
      </geometry>
    </collision>
    <visual name="left_2tip2_visual">
      <origin rpy="0  0  0" xyz="0  0  0"/>
      <geometry>
        <mesh filename="package://iai_dlr_rollin_justin/mjcf/rollin-justin/meshes/stl/finger-phaprox.stl" scale="1 1 1"/>
      </geometry>
    </visual>
  </link>
  <link name="left_2tip3">
    <inertial>
      <mass value="0.05"/>
      <origin rpy="0 -0 0" xyz="0 0 0"/>
      <inertia ixx="0.1" ixy="0" ixz="0" iyy="0.1" iyz="0" izz="0.1"/>
    </inertial>
    <collision name="left_2tip3_coll">
      <origin rpy="0  0  0" xyz="0  0  0"/>
      <geometry>
        <mesh filename="package://iai_dlr_rollin_justin/mjcf/rollin-justin/meshes/stl/finger-phamed.stl" scale="1 1 1"/>
      </geometry>
    </collision>
    <visual name="left_2tip3_visual">
      <origin rpy="0  0  0" xyz="0  0  0"/>
      <geometry>
        <mesh filename="package://iai_dlr_rollin_justin/mjcf/rollin-justin/meshes/stl/finger-phamed.stl" scale="1 1 1"/>
      </geometry>
    </visual>
  </link>
  <link name="left_2tip4">
    <inertial>
      <mass value="0.05"/>
      <origin rpy="0 -0 0" xyz="0 0 0"/>
      <inertia ixx="0.1" ixy="0" ixz="0" iyy="0.1" iyz="0" izz="0.1"/>
    </inertial>
    <collision name="left_2tip4_coll">
      <origin rpy="0  0  0" xyz="0  0  0"/>
      <geometry>
        <mesh filename="package://iai_dlr_rollin_justin/mjcf/rollin-justin/meshes/stl/hii2_geh_phadist_gesamt_asm.stl" scale="1 1 1"/>
      </geometry>
    </collision>
    <visual name="left_2tip4_visual">
      <origin rpy="0  0  0" xyz="0  0  0"/>
      <geometry>
        <mesh filename="package://iai_dlr_rollin_justin/mjcf/rollin-justin/meshes/stl/hii2_geh_phadist_gesamt_asm.stl" scale="1 1 1"/>
      </geometry>
    </visual>
  </link>
  <link name="right_arm1">
    <inertial>
      <mass value="2.6371"/>
      <origin rpy="0 0 0" xyz="0.0 0.02029 -0.04594"/>
      <inertia ixx="0.01711" ixy="0.00000" ixz="0.00000" iyy="0.01682" iyz="-0.00165" izz="0.00452"/>
    </inertial>
    <collision name="right_arm1_coll">
      <origin rpy="0  0  0" xyz="0  0  0"/>
      <geometry>
        <mesh filename="package://iai_dlr_rollin_justin/mjcf/rollin-justin/meshes/stl/right_arm1.stl" scale="1 1 1"/>
      </geometry>
    </collision>
    <visual name="right_arm1_visual">
      <origin rpy="0  0  0" xyz="0  0  0"/>
      <geometry>
        <mesh filename="package://iai_dlr_rollin_justin/mjcf/rollin-justin/meshes/stl/right_arm1.stl" scale="1 1 1"/>
      </geometry>
    </visual>
  </link>
  <link name="right_arm2">
    <inertial>
      <mass value="2.3261934"/>
      <origin rpy="0 0 0" xyz="0 0.11406 0.01645"/>
      <inertia ixx="0.01997" ixy="0.00000" ixz="0.00000" iyy="0.00447" iyz="0.00359" izz="0.01921"/>
    </inertial>
    <collision name="right_arm2_coll">
      <origin rpy="0  0  0" xyz="0  0  0"/>
      <geometry>
        <mesh filename="package://iai_dlr_rollin_justin/mjcf/rollin-justin/meshes/stl/right_arm2.stl" scale="1 1 1"/>
      </geometry>
    </collision>
    <visual name="right_arm2_visual">
      <origin rpy="0  0  0" xyz="0  0  0"/>
      <geometry>
        <mesh filename="package://iai_dlr_rollin_justin/mjcf/rollin-justin/meshes/stl/right_arm2.stl" scale="1 1 1"/>
      </geometry>
    </visual>
  </link>
  <link name="right_arm3">
    <inertial>
      <mass value="2.293"/>
      <origin rpy="0 0 0" xyz="0 0.01801 -0.05394"/>
      <inertia ixx="0.01692" ixy="0.00000" ixz="0.00000" iyy="0.01644" iyz="-0.00163" izz="0.00424"/>
    </inertial>
    <collision name="right_arm3_coll">
      <origin rpy="0  0  0" xyz="0  0  0"/>
      <geometry>
        <mesh filename="package://iai_dlr_rollin_justin/mjcf/rollin-justin/meshes/stl/right_arm3.stl" scale="1 1 1"/>
      </geometry>
    </collision>
    <visual name="right_arm3_visual">
      <origin rpy="0  0  0" xyz="0  0  0"/>
      <geometry>
        <mesh filename="package://iai_dlr_rollin_justin/mjcf/rollin-justin/meshes/stl/right_arm3.stl" scale="1 1 1"/>
      </geometry>
    </visual>
  </link>
  <link name="right_arm4">
    <inertial>
      <mass value="2.203695"/>
      <origin rpy="0 0 0" xyz="0 0.11374 0.01367"/>
      <inertia ixx="0.02052" ixy="0.00000" ixz="0.00000" iyy="0.00451" iyz="0.00372" izz="0.01972"/>
    </inertial>
    <collision name="right_arm4_coll">
      <origin rpy="0  0  0" xyz="0  0  0"/>
      <geometry>
        <mesh filename="package://iai_dlr_rollin_justin/mjcf/rollin-justin/meshes/stl/right_arm4.stl" scale="1 1 1"/>
      </geometry>
    </collision>
    <visual name="right_arm4_visual">
      <origin rpy="0  0  0" xyz="0  0  0"/>
      <geometry>
        <mesh filename="package://iai_dlr_rollin_justin/mjcf/rollin-justin/meshes/stl/right_arm4.stl" scale="1 1 1"/>
      </geometry>
    </visual>
  </link>
  <link name="right_arm5">
    <inertial>
      <mass value="0.7010105"/>
      <origin rpy="0 0 0" xyz="0 0.02190 -0.10562"/>
      <inertia ixx="0.00541" ixy="0.00000" ixz="0.00000" iyy="0.00505" iyz="-0.00140" izz="0.00210"/>
    </inertial>
    <collision name="right_arm5_coll">
      <origin rpy="0  0  0" xyz="0  0  0"/>
      <geometry>
        <mesh filename="package://iai_dlr_rollin_justin/mjcf/rollin-justin/meshes/stl/right_arm5.stl" scale="1 1 1"/>
      </geometry>
    </collision>
    <visual name="right_arm5_visual">
      <origin rpy="0  0  0" xyz="0  0  0"/>
      <geometry>
        <mesh filename="package://iai_dlr_rollin_justin/mjcf/rollin-justin/meshes/stl/right_arm5.stl" scale="1 1 1"/>
      </geometry>
    </visual>
  </link>
  <link name="right_arm6">
    <inertial>
      <mass value="1.6742"/>
      <origin rpy="0 -0 0" xyz="0 -0.00726 -0.00579"/>
      <inertia ixx="0.00324" ixy="0.00000" ixz="0.00000" iyy="0.00308" iyz="0.00000" izz="0.00297"/>
    </inertial>
    <collision name="right_arm6_coll">
      <origin rpy="0  0  0" xyz="0  0  0"/>
      <geometry>
        <mesh filename="package://iai_dlr_rollin_justin/mjcf/rollin-justin/meshes/stl/right_arm6.stl" scale="1 1 1"/>
      </geometry>
    </collision>
    <visual name="right_arm6_visual">
      <origin rpy="0  0  0" xyz="0  0  0"/>
      <geometry>
        <mesh filename="package://iai_dlr_rollin_justin/mjcf/rollin-justin/meshes/stl/right_arm6.stl" scale="1 1 1"/>
      </geometry>
    </visual>
  </link>
  <link name="right_arm7">
    <inertial>
      <mass value="0.270"/>
      <origin rpy="0 0 -0" xyz="0.07194 0 0.02339"/>
      <inertia ixx="0.00324" ixy="0.00000" ixz="0.00000" iyy="0.00308" iyz="0.00000" izz="0.00297"/>
    </inertial>
    <collision name="right_arm7_coll">
      <origin rpy="0  0  0" xyz="0  0  0"/>
      <geometry>
        <mesh filename="package://iai_dlr_rollin_justin/mjcf/rollin-justin/meshes/stl/right_arm7.stl" scale="1 1 1"/>
      </geometry>
    </collision>
    <visual name="right_arm7_visual">
      <origin rpy="0  0  0" xyz="0  0  0"/>
      <geometry>
        <mesh filename="package://iai_dlr_rollin_justin/mjcf/rollin-justin/meshes/stl/right_arm7.stl" scale="1 1 1"/>
      </geometry>
    </visual>
  </link>
  <link name="right_palm">
    <inertial>
      <mass value="1.40"/>
      <origin rpy="0 0 0" xyz="0.0015 -0.0115 0.1066"/>
      <inertia ixx="3.4657189e-02" ixy="-4.8421020e-03" ixz="-1.7680628e-03" iyy="1.5089606e-02" iyz="1.7375485e-03" izz="8.5636015e-03"/>
    </inertial>
  </link>
  <link name="right_3middle_base">
    <inertial>
      <mass value="0.05"/>
      <origin rpy="0  0  0" xyz="0  0  0"/>
      <inertia ixx="0.1" ixy="0" ixz="0" iyy="0.1" iyz="0" izz="0.1"/>
    </inertial>
    <visual name="right_3middle1_visual">
      <origin rpy="0  0  0" xyz="0  0  0"/>
      <geometry>
        <mesh filename="package://iai_dlr_rollin_justin/mjcf/rollin-justin/meshes/stl/finger-base.stl" scale="1 1 1"/>
      </geometry>
    </visual>
  </link>
  <link name="right_3middle1"/>
  <link name="right_3middle2">
    <inertial>
      <mass value="0.03"/>
      <origin rpy="0 -0 0" xyz="0 0 0"/>
      <inertia ixx="0.1" ixy="0" ixz="0" iyy="0.1" iyz="0" izz="0.1"/>
    </inertial>
    <collision name="right_3middle2_coll">
      <origin rpy="0  0  0" xyz="0  0  0"/>
      <geometry>
        <mesh filename="package://iai_dlr_rollin_justin/mjcf/rollin-justin/meshes/stl/finger-phaprox.stl" scale="1 1 1"/>
      </geometry>
    </collision>
    <visual name="right_3middle2_visual">
      <origin rpy="0  0  0" xyz="0  0  0"/>
      <geometry>
        <mesh filename="package://iai_dlr_rollin_justin/mjcf/rollin-justin/meshes/stl/finger-phaprox.stl" scale="1 1 1"/>
      </geometry>
    </visual>
  </link>
  <link name="right_3middle3">
    <inertial>
      <mass value="0.03"/>
      <origin rpy="0 -0 0" xyz="0 0 0"/>
      <inertia ixx="0.1" ixy="0" ixz="0" iyy="0.1" iyz="0" izz="0.1"/>
    </inertial>
    <collision name="right_3middle3_coll">
      <origin rpy="0  0  0" xyz="0  0  0"/>
      <geometry>
        <mesh filename="package://iai_dlr_rollin_justin/mjcf/rollin-justin/meshes/stl/finger-phamed.stl" scale="1 1 1"/>
      </geometry>
    </collision>
    <visual name="right_3middle3_visual">
      <origin rpy="0  0  0" xyz="0  0  0"/>
      <geometry>
        <mesh filename="package://iai_dlr_rollin_justin/mjcf/rollin-justin/meshes/stl/finger-phamed.stl" scale="1 1 1"/>
      </geometry>
    </visual>
  </link>
  <link name="right_3middle4">
    <inertial>
      <mass value="0.03"/>
      <origin rpy="0 -0 0" xyz="0 0 0"/>
      <inertia ixx="0.1" ixy="0" ixz="0" iyy="0.1" iyz="0" izz="0.1"/>
    </inertial>
    <collision name="right_3middle4_coll">
      <origin rpy="0  0  0" xyz="0  0  0"/>
      <geometry>
        <mesh filename="package://iai_dlr_rollin_justin/mjcf/rollin-justin/meshes/stl/hii2_geh_phadist_gesamt_asm.stl" scale="1 1 1"/>
      </geometry>
    </collision>
    <visual name="right_3middle4_visual">
      <origin rpy="0  0  0" xyz="0  0  0"/>
      <geometry>
        <mesh filename="package://iai_dlr_rollin_justin/mjcf/rollin-justin/meshes/stl/hii2_geh_phadist_gesamt_asm.stl" scale="1 1 1"/>
      </geometry>
    </visual>
  </link>
  <link name="right_4ring_base">
    <inertial>
      <mass value="0.05"/>
      <origin rpy="0  0  0" xyz="0  0  0"/>
      <inertia ixx="0.1" ixy="0" ixz="0" iyy="0.1" iyz="0" izz="0.1"/>
    </inertial>
    <visual name="right_4ring1_visual">
      <origin rpy="0  0  0" xyz="0  0  0"/>
      <geometry>
        <mesh filename="package://iai_dlr_rollin_justin/mjcf/rollin-justin/meshes/stl/finger-base.stl" scale="1 1 1"/>
      </geometry>
    </visual>
  </link>
  <link name="right_4ring1"/>
  <link name="right_4ring2">
    <inertial>
      <mass value="0.03"/>
      <origin rpy="0 -0 0" xyz="0 0 0"/>
      <inertia ixx="0.1" ixy="0" ixz="0" iyy="0.1" iyz="0" izz="0.1"/>
    </inertial>
    <collision name="right_4ring2_coll">
      <origin rpy="0  0  0" xyz="0  0  0"/>
      <geometry>
        <mesh filename="package://iai_dlr_rollin_justin/mjcf/rollin-justin/meshes/stl/finger-phaprox.stl" scale="1 1 1"/>
      </geometry>
    </collision>
    <visual name="right_4ring2_visual">
      <origin rpy="0  0  0" xyz="0  0  0"/>
      <geometry>
        <mesh filename="package://iai_dlr_rollin_justin/mjcf/rollin-justin/meshes/stl/finger-phaprox.stl" scale="1 1 1"/>
      </geometry>
    </visual>
  </link>
  <link name="right_4ring3">
    <inertial>
      <mass value="0.03"/>
      <origin rpy="0 -0 0" xyz="0 0 0"/>
      <inertia ixx="0.1" ixy="0" ixz="0" iyy="0.1" iyz="0" izz="0.1"/>
    </inertial>
    <collision name="right_4ring3_coll">
      <origin rpy="0  0  0" xyz="0  0  0"/>
      <geometry>
        <mesh filename="package://iai_dlr_rollin_justin/mjcf/rollin-justin/meshes/stl/finger-phamed.stl" scale="1 1 1"/>
      </geometry>
    </collision>
    <visual name="right_4ring3_visual">
      <origin rpy="0  0  0" xyz="0  0  0"/>
      <geometry>
        <mesh filename="package://iai_dlr_rollin_justin/mjcf/rollin-justin/meshes/stl/finger-phamed.stl" scale="1 1 1"/>
      </geometry>
    </visual>
  </link>
  <link name="right_4ring4">
    <inertial>
      <mass value="0.03"/>
      <origin rpy="0 -0 0" xyz="0 0 0"/>
      <inertia ixx="0.1" ixy="0" ixz="0" iyy="0.1" iyz="0" izz="0.1"/>
    </inertial>
    <collision name="right_4ring4_coll">
      <origin rpy="0  0  0" xyz="0  0  0"/>
      <geometry>
        <mesh filename="package://iai_dlr_rollin_justin/mjcf/rollin-justin/meshes/stl/hii2_geh_phadist_gesamt_asm.stl" scale="1 1 1"/>
      </geometry>
    </collision>
    <visual name="right_4ring4_visual">
      <origin rpy="0  0  0" xyz="0  0  0"/>
      <geometry>
        <mesh filename="package://iai_dlr_rollin_justin/mjcf/rollin-justin/meshes/stl/hii2_geh_phadist_gesamt_asm.stl" scale="1 1 1"/>
      </geometry>
    </visual>
  </link>
  <link name="right_1thumb_base">
    <inertial>
      <mass value="0.05"/>
      <origin rpy="0  0  0" xyz="0  0  0"/>
      <inertia ixx="0.1" ixy="0" ixz="0" iyy="0.1" iyz="0" izz="0.1"/>
    </inertial>
    <visual name="right_1thumb1_visual">
      <origin rpy="0  0  0" xyz="0  0  0"/>
      <geometry>
        <mesh filename="package://iai_dlr_rollin_justin/mjcf/rollin-justin/meshes/stl/finger-base.stl" scale="1 1 1"/>
      </geometry>
    </visual>
  </link>
  <link name="right_1thumb1"/>
  <link name="right_1thumb2">
    <inertial>
      <mass value="0.03"/>
      <origin rpy="0 -0 0" xyz="0 0 0"/>
      <inertia ixx="0.1" ixy="0" ixz="0" iyy="0.1" iyz="0" izz="0.1"/>
    </inertial>
    <collision name="right_1thumb2_coll">
      <origin rpy="0  0  0" xyz="0  0  0"/>
      <geometry>
        <mesh filename="package://iai_dlr_rollin_justin/mjcf/rollin-justin/meshes/stl/finger-phaprox.stl" scale="1 1 1"/>
      </geometry>
    </collision>
    <visual name="right_1thumb2_visual">
      <origin rpy="0  0  0" xyz="0  0  0"/>
      <geometry>
        <mesh filename="package://iai_dlr_rollin_justin/mjcf/rollin-justin/meshes/stl/finger-phaprox.stl" scale="1 1 1"/>
      </geometry>
    </visual>
  </link>
  <link name="right_1thumb3">
    <inertial>
      <mass value="0.03"/>
      <origin rpy="0 -0 0" xyz="0 0 0"/>
      <inertia ixx="0.1" ixy="0" ixz="0" iyy="0.1" iyz="0" izz="0.1"/>
    </inertial>
    <collision name="right_1thumb3_coll">
      <origin rpy="0  0  0" xyz="0  0  0"/>
      <geometry>
        <mesh filename="package://iai_dlr_rollin_justin/mjcf/rollin-justin/meshes/stl/finger-phamed.stl" scale="1 1 1"/>
      </geometry>
    </collision>
    <visual name="right_1thumb3_visual">
      <origin rpy="0  0  0" xyz="0  0  0"/>
      <geometry>
        <mesh filename="package://iai_dlr_rollin_justin/mjcf/rollin-justin/meshes/stl/finger-phamed.stl" scale="1 1 1"/>
      </geometry>
    </visual>
  </link>
  <link name="right_1thumb4">
    <inertial>
      <mass value="0.03"/>
      <origin rpy="0 -0 0" xyz="0 0 0"/>
      <inertia ixx="0.1" ixy="0" ixz="0" iyy="0.1" iyz="0" izz="0.1"/>
    </inertial>
    <collision name="right_1thumb4_coll">
      <origin rpy="0  0  0" xyz="0  0  0"/>
      <geometry>
        <mesh filename="package://iai_dlr_rollin_justin/mjcf/rollin-justin/meshes/stl/hii2_geh_phadist_gesamt_asm.stl" scale="1 1 1"/>
      </geometry>
    </collision>
    <visual name="right_1thumb4_visual">
      <origin rpy="0  0  0" xyz="0  0  0"/>
      <geometry>
        <mesh filename="package://iai_dlr_rollin_justin/mjcf/rollin-justin/meshes/stl/hii2_geh_phadist_gesamt_asm.stl" scale="1 1 1"/>
      </geometry>
    </visual>
  </link>
  <link name="right_2tip_base">
    <inertial>
      <mass value="0.05"/>
      <origin rpy="0  0  0" xyz="0  0  0"/>
      <inertia ixx="0.1" ixy="0" ixz="0" iyy="0.1" iyz="0" izz="0.1"/>
    </inertial>
    <visual name="right_2tip1_visual">
      <origin rpy="0  0  0" xyz="0  0  0"/>
      <geometry>
        <mesh filename="package://iai_dlr_rollin_justin/mjcf/rollin-justin/meshes/stl/finger-base.stl" scale="1 1 1"/>
      </geometry>
    </visual>
  </link>
  <link name="right_2tip1"/>
  <link name="right_2tip2">
    <inertial>
      <mass value="0.03"/>
      <origin rpy="0 -0 0" xyz="0 0 0"/>
      <inertia ixx="0.1" ixy="0" ixz="0" iyy="0.1" iyz="0" izz="0.1"/>
    </inertial>
    <collision name="right_2tip2_coll">
      <origin rpy="0  0  0" xyz="0  0  0"/>
      <geometry>
        <mesh filename="package://iai_dlr_rollin_justin/mjcf/rollin-justin/meshes/stl/finger-phaprox.stl" scale="1 1 1"/>
      </geometry>
    </collision>
    <visual name="right_2tip2_visual">
      <origin rpy="0  0  0" xyz="0  0  0"/>
      <geometry>
        <mesh filename="package://iai_dlr_rollin_justin/mjcf/rollin-justin/meshes/stl/finger-phaprox.stl" scale="1 1 1"/>
      </geometry>
    </visual>
  </link>
  <link name="right_2tip3">
    <inertial>
      <mass value="0.03"/>
      <origin rpy="0 -0 0" xyz="0 0 0"/>
      <inertia ixx="0.1" ixy="0" ixz="0" iyy="0.1" iyz="0" izz="0.1"/>
    </inertial>
    <collision name="right_2tip3_coll">
      <origin rpy="0  0  0" xyz="0  0  0"/>
      <geometry>
        <mesh filename="package://iai_dlr_rollin_justin/mjcf/rollin-justin/meshes/stl/finger-phamed.stl" scale="1 1 1"/>
      </geometry>
    </collision>
    <visual name="right_2tip3_visual">
      <origin rpy="0  0  0" xyz="0  0  0"/>
      <geometry>
        <mesh filename="package://iai_dlr_rollin_justin/mjcf/rollin-justin/meshes/stl/finger-phamed.stl" scale="1 1 1"/>
      </geometry>
    </visual>
  </link>
  <link name="right_2tip4">
    <inertial>
      <mass value="0.05"/>
      <origin rpy="0 -0 0" xyz="0 0 0"/>
      <inertia ixx="0.1" ixy="0" ixz="0" iyy="0.1" iyz="0" izz="0.1"/>
    </inertial>
    <collision name="right_2tip4_coll">
      <origin rpy="0  0  0" xyz="0  0  0"/>
      <geometry>
        <mesh filename="package://iai_dlr_rollin_justin/mjcf/rollin-justin/meshes/stl/hii2_geh_phadist_gesamt_asm.stl" scale="1 1 1"/>
      </geometry>
    </collision>
    <visual name="right_2tip4_visual">
      <origin rpy="0  0  0" xyz="0  0  0"/>
      <geometry>
        <mesh filename="package://iai_dlr_rollin_justin/mjcf/rollin-justin/meshes/stl/hii2_geh_phadist_gesamt_asm.stl" scale="1 1 1"/>
      </geometry>
    </visual>
  </link>
</robot>