<?xml version="1.0" ?>
<robot name="apartment_root" version="1.0">
  <link name="apartment_root"/>
  <joint name="envelope_root_joint" type="fixed">
    <origin xyz="8.85 1.75 0.0" rpy="0.0 -0.0 0.0"/>
    <parent link="apartment_root"/>
    <child link="envelope_root"/>
  </joint>
  <link name="envelope_root"/>
  <joint name="wall1_joint" type="fixed">
    <origin xyz="0.0 0.0 -0.2" rpy="0.0 -0.0 0.0"/>
    <parent link="envelope_root"/>
    <child link="wall1"/>
  </joint>
  <link name="wall1">
    <collision name="wall1_collision_0">
      <origin xyz="0.505224 -1.81425 1.73439" rpy="0.0 -0.0 0.0"/>
      <geometry>
        <box size="18.76044 0.1285 3.0517"/>
      </geometry>
    </collision>
  </link>
  <joint name="wall2_joint" type="fixed">
    <origin xyz="0.0 0.0 -0.2" rpy="0.0 -0.0 0.0"/>
    <parent link="envelope_root"/>
    <child link="wall2"/>
  </joint>
  <link name="wall2">
    <collision name="wall2_collision_0">
      <origin xyz="-8.875 0.713447 1.73439" rpy="0.0 -0.0 0.0"/>
      <geometry>
        <box size="0.189552 4.9669 3.0517"/>
      </geometry>
    </collision>
  </link>
  <joint name="wall3_joint" type="fixed">
    <origin xyz="0.0 0.0 -0.2" rpy="0.0 -0.0 0.0"/>
    <parent link="envelope_root"/>
    <child link="wall3"/>
  </joint>
  <link name="wall3">
    <collision name="wall3_collision_0">
      <origin xyz="-4.63823 3.27776 1.73439" rpy="0.0 -0.0 0.0"/>
      <geometry>
        <box size="8.47354 0.1285 3.0517"/>
      </geometry>
    </collision>
    <collision name="wall3_collision_1">
      <origin xyz="5.87824 3.27776 1.73439" rpy="0.0 -0.0 0.0"/>
      <geometry>
        <box size="8.2886 0.1285 3.0517"/>
      </geometry>
    </collision>
  </link>
  <joint name="wall4_joint" type="fixed">
    <origin xyz="0.0 0.0 -0.2" rpy="0.0 -0.0 0.0"/>
    <parent link="envelope_root"/>
    <child link="wall4"/>
  </joint>
  <link name="wall4">
    <collision name="wall4_collision_0">
      <origin xyz="9.98022 0.713447 1.73439" rpy="0.0 -0.0 0.0"/>
      <geometry>
        <box size="0.189552 4.9669 3.0517"/>
      </geometry>
    </collision>
  </link>
  <joint name="windows_joint" type="fixed">
    <origin xyz="0.0 0.0 -0.2" rpy="0.0 -0.0 0.0"/>
    <parent link="envelope_root"/>
    <child link="windows"/>
  </joint>
  <link name="windows"/>
  <joint name="window4_frame_joint" type="fixed">
    <origin xyz="0.671098 3.37273 1.52145" rpy="0.0 0.0 -1.5707963267948966"/>
    <parent link="envelope_root"/>
    <child link="window4_frame"/>
  </joint>
  <link name="window4_frame">
    <collision name="window4_frame_collision_0">
      <origin xyz="0.0 0.0 1.42883" rpy="0.0 -0.0 0.0"/>
      <geometry>
        <box size="0.02 2.1354 0.185552"/>
      </geometry>
    </collision>
    <collision name="window4_frame_collision_2">
      <origin xyz="0.0 0.0 -1.49481" rpy="0.0 -0.0 0.0"/>
      <geometry>
        <box size="0.02 2.1354 0.053592"/>
      </geometry>
    </collision>
    <collision name="window4_frame_collision_3">
      <origin xyz="0.0 0.992126 0.0" rpy="0.0 -0.0 0.0"/>
      <geometry>
        <box size="0.02 0.151148 3.04322"/>
      </geometry>
    </collision>
    <collision name="window4_frame_collision_4">
      <origin xyz="0.0 -0.992126 0.0" rpy="0.0 -0.0 0.0"/>
      <geometry>
        <box size="0.02 0.151148 3.04322"/>
      </geometry>
    </collision>
    <collision name="window4_frame_collision_1">
      <origin xyz="0.0 0.0 0.795222" rpy="0.0 -0.0 0.0"/>
      <geometry>
        <box size="0.02 2.1354 0.37828"/>
      </geometry>
    </collision>
    <collision name="window4_frame_collision_5">
      <origin xyz="0.0 0.0 0.0" rpy="0.0 -0.0 0.0"/>
      <geometry>
        <box size="0.02 0.146252 3.04322"/>
      </geometry>
    </collision>
  </link>
  <joint name="window4_right_joint" type="revolute">
    <origin xyz="0.0 -0.9165520071983337 -0.4254710078239441" rpy="0.0 -0.0 0.0"/>
    <axis xyz="0 0 -1"/>
    <parent link="window4_frame"/>
    <child link="window4_right"/>
    <limit effort="1000" lower="0.0" upper="1.5708000552204227" velocity="1000"/>
  </joint>
  <link name="window4_right">
    <collision name="window4_right_collision_0">
      <origin xyz="0.0 0.421713 0.0" rpy="0.0 -0.0 0.0"/>
      <geometry>
        <box size="0.02 0.843426 2.0631"/>
      </geometry>
    </collision>
  </link>
  <joint name="window4_right_handle_rotation_joint" type="revolute">
    <origin xyz="0.009999999776482582 0.834106981754303 0.0" rpy="0.0 -0.0 0.0"/>
    <axis xyz="-1 0 0"/>
    <parent link="window4_right"/>
    <child link="window4_right_handle_rotation"/>
    <limit effort="1000" lower="0.0" upper="1.5708000552204227" velocity="1000"/>
  </joint>
  <link name="window4_right_handle_rotation"/>
  <joint name="window4_right_handle_joint" type="fixed">
    <origin xyz="0.067235 0.0 -0.057755" rpy="0.0 -0.0 0.0"/>
    <parent link="window4_right_handle_rotation"/>
    <child link="window4_right_handle"/>
  </joint>
  <link name="window4_right_handle">
    <collision name="window4_right_handle_collision_1">
      <origin xyz="0.0 0.0 0.0" rpy="0.0 -0.0 0.0"/>
      <geometry>
        <cylinder radius="0.008" length="0.131626"/>
      </geometry>
    </collision>
    <collision name="window4_right_handle_collision_2">
      <origin xyz="-0.018476 0.0 -0.057813" rpy="-0.0 1.5707963267948966 0.0"/>
      <geometry>
        <cylinder radius="0.008" length="0.052952"/>
      </geometry>
    </collision>
    <collision name="window4_right_handle_collision_0">
      <origin xyz="-0.029618 0.0 0.057814" rpy="-0.0 1.5707963267948966 0.0"/>
      <geometry>
        <cylinder radius="0.008" length="0.075236"/>
      </geometry>
    </collision>
  </link>
  <joint name="window4_left_joint" type="revolute">
    <origin xyz="0.0016199999954551458 0.9291120171546936 -0.4254710078239441" rpy="0.0 -0.0 0.0"/>
    <axis xyz="0 0 1"/>
    <parent link="window4_frame"/>
    <child link="window4_left"/>
    <limit effort="1000" lower="0.0" upper="1.5708000552204227" velocity="1000"/>
  </joint>
  <link name="window4_left">
    <collision name="window4_left_collision_0">
      <origin xyz="0.0 -0.43203 0.0" rpy="0.0 -0.0 0.0"/>
      <geometry>
        <box size="0.02 0.86406 2.0631"/>
      </geometry>
    </collision>
  </link>
  <joint name="window4_left_handle_rotation_joint" type="revolute">
    <origin xyz="0.009999999776482582 -0.834106981754303 0.0" rpy="0.0 -0.0 0.0"/>
    <axis xyz="1 0 0"/>
    <parent link="window4_left"/>
    <child link="window4_left_handle_rotation"/>
    <limit effort="1000" lower="0.0" upper="1.5708000552204227" velocity="1000"/>
  </joint>
  <link name="window4_left_handle_rotation"/>
  <joint name="window4_left_handle_joint" type="fixed">
    <origin xyz="0.067235 0.0 -0.057755" rpy="0.0 -0.0 0.0"/>
    <parent link="window4_left_handle_rotation"/>
    <child link="window4_left_handle"/>
  </joint>
  <link name="window4_left_handle">
    <collision name="window4_left_handle_collision_2">
      <origin xyz="-0.018476 0.0 -0.057813" rpy="-0.0 1.5707963267948966 0.0"/>
      <geometry>
        <cylinder radius="0.008" length="0.052952"/>
      </geometry>
    </collision>
    <collision name="window4_left_handle_collision_1">
      <origin xyz="0.0 0.0 0.0" rpy="0.0 -0.0 0.0"/>
      <geometry>
        <cylinder radius="0.008" length="0.131626"/>
      </geometry>
    </collision>
    <collision name="window4_left_handle_collision_0">
      <origin xyz="-0.029618 0.0 0.057814" rpy="-0.0 1.5707963267948966 0.0"/>
      <geometry>
        <cylinder radius="0.008" length="0.075236"/>
      </geometry>
    </collision>
  </link>
  <joint name="kitchen_root_joint" type="fixed">
    <origin xyz="0.0 0.0 0.0" rpy="0.0 -0.0 0.0"/>
    <parent link="apartment_root"/>
    <child link="kitchen_root"/>
  </joint>
  <link name="kitchen_root"/>
  <joint name="kitchen1_root_joint" type="fixed">
    <origin xyz="0.0 0.0 0.0" rpy="0.0 -0.0 0.0"/>
    <parent link="kitchen_root"/>
    <child link="kitchen1_root"/>
  </joint>
  <link name="kitchen1_root"/>
  <joint name="cabinet1_joint" type="fixed">
    <origin xyz="0.28463219 1.46675873 1.11440605" rpy="0.0 -0.0 3.141592653589793"/>
    <parent link="kitchen1_root"/>
    <child link="cabinet1"/>
  </joint>
  <link name="cabinet1">
    <collision name="cabinet1_collision_0">
      <origin xyz="0.010499 -0.3 0.05" rpy="0.0 -0.0 0.0"/>
      <geometry>
        <box size="0.55494 0.019 2.12778"/>
      </geometry>
    </collision>
    <collision name="cabinet1_collision_4">
      <origin xyz="-0.254976 -0.009901 1.06578" rpy="0.0 -0.0 0.0"/>
      <geometry>
        <box size="0.016 0.561938 0.064"/>
      </geometry>
    </collision>
    <collision name="cabinet1_collision_5">
      <origin xyz="0.0055 -0.009901 1.10578" rpy="0.0 -0.0 0.0"/>
      <geometry>
        <box size="0.540942 0.561938 0.016"/>
      </geometry>
    </collision>
    <collision name="cabinet1_collision_1">
      <origin xyz="0.010499 0.280469 0.05" rpy="0.0 -0.0 0.0"/>
      <geometry>
        <box size="0.55494 0.019 2.12778"/>
      </geometry>
    </collision>
    <collision name="cabinet1_collision_3">
      <origin xyz="0.0 0.299967 0.0" rpy="0.0 -0.0 0.0"/>
      <geometry>
        <box size="0.575938 0.02092 2.22776"/>
      </geometry>
    </collision>
    <collision name="cabinet1_collision_2">
      <origin xyz="0.271973 -0.009901 0.041995" rpy="0.0 -0.0 0.0"/>
      <geometry>
        <box size="0.008 0.561938 2.11178"/>
      </geometry>
    </collision>
    <collision name="cabinet1_collision_6">
      <origin xyz="0.0005 -0.009901 0.249501" rpy="0.0 -0.0 0.0"/>
      <geometry>
        <box size="0.540942 0.561938 0.015"/>
      </geometry>
    </collision>
  </link>
  <joint name="cabinet1_shelf1_joint" type="fixed">
    <origin xyz="0.009901 0.0005 0.56" rpy="0.0 -0.0 0.0"/>
    <parent link="cabinet1"/>
    <child link="cabinet1_shelf1"/>
  </joint>
  <link name="cabinet1_shelf1">
    <collision name="cabinet1_shelf1_collision_0">
      <origin xyz="0.0 0.0 0.0" rpy="0.0 -0.0 0.0"/>
      <geometry>
        <box size="0.561938 0.534942 0.015"/>
      </geometry>
    </collision>
  </link>
  <joint name="cabinet1_shelf2_joint" type="fixed">
    <origin xyz="0.009901 0.0005 0.249501" rpy="0.0 -0.0 0.0"/>
    <parent link="cabinet1"/>
    <child link="cabinet1_shelf2"/>
  </joint>
  <link name="cabinet1_shelf2">
    <collision name="cabinet1_shelf2_collision_0">
      <origin xyz="0.0 0.0 0.0" rpy="0.0 -0.0 0.0"/>
      <geometry>
        <box size="0.534942 0.561938 0.015"/>
      </geometry>
    </collision>
  </link>
  <joint name="cabinet1_door_joint" type="revolute">
    <origin xyz="-0.2800000011920929 0.2800000011920929 0.6769999861717224" rpy="0.0 -0.0 0.0"/>
    <axis xyz="0 0 -1"/>
    <parent link="cabinet1"/>
    <child link="cabinet1_door"/>
    <limit effort="1000" lower="0.0" upper="1.5707963267948966" velocity="1000"/>
  </joint>
  <link name="cabinet1_door">
    <collision name="cabinet1_door_collision_0">
      <origin xyz="0.0 -0.285091 0.0" rpy="0.0 -0.0 0.0"/>
      <geometry>
        <box size="0.019 0.596936 0.86681"/>
      </geometry>
    </collision>
  </link>
  <joint name="cabinet1_door_handle_joint" type="fixed">
    <origin xyz="-0.03598882 -0.46315559 -0.38983368" rpy="1.5707963267948966 -0.0 0.0"/>
    <parent link="cabinet1_door"/>
    <child link="cabinet1_door_handle"/>
  </joint>
  <link name="cabinet1_door_handle">
    <collision name="cabinet1_door_handle_collision_1">
      <origin xyz="0.0164985 0.0 -0.08" rpy="0.0 -0.0 0.0"/>
      <geometry>
        <box size="0.02 0.013 0.013"/>
      </geometry>
    </collision>
    <collision name="cabinet1_door_handle_collision_2">
      <origin xyz="0.0 0.0 0.0" rpy="0.0 -0.0 0.0"/>
      <geometry>
        <box size="0.013 0.013 0.173032"/>
      </geometry>
    </collision>
    <collision name="cabinet1_door_handle_collision_0">
      <origin xyz="0.0164985 0.0 0.08" rpy="0.0 -0.0 0.0"/>
      <geometry>
        <box size="0.02 0.013 0.013"/>
      </geometry>
    </collision>
  </link>
  <joint name="cabinet1_drawer1_joint" type="prismatic">
    <origin xyz="-0.04679017886519432 -0.01122014969587326 -0.4865850806236267" rpy="0.0 -0.0 0.0"/>
    <axis xyz="-1 0 0"/>
    <parent link="cabinet1"/>
    <child link="cabinet1_drawer1"/>
    <limit effort="1000" lower="0.0" upper="0.44999998807907104" velocity="1000"/>
  </joint>
  <link name="cabinet1_drawer1">
    <collision name="cabinet1_drawer1_collision_3">
      <origin xyz="0.021336 -0.26865 -0.078968" rpy="0.0 -0.0 0.0"/>
      <geometry>
        <box size="0.4917 0.0158442 0.083496"/>
      </geometry>
    </collision>
    <collision name="cabinet1_drawer1_collision_1">
      <origin xyz="0.021336 -0.26865 0.0412455" rpy="0.0 -0.0 0.0"/>
      <geometry>
        <box size="0.4917 0.0158442 0.0223924"/>
      </geometry>
    </collision>
    <collision name="cabinet1_drawer1_collision_2">
      <origin xyz="0.021336 0.26865 0.0412455" rpy="0.0 -0.0 0.0"/>
      <geometry>
        <box size="0.4917 0.0158442 0.0223924"/>
      </geometry>
    </collision>
    <collision name="cabinet1_drawer1_collision_6">
      <origin xyz="0.26 0.0 -0.038" rpy="0.0 -0.0 0.0"/>
      <geometry>
        <box size="0.01865384 0.52364 0.16887"/>
      </geometry>
    </collision>
    <collision name="cabinet1_drawer1_collision_5">
      <origin xyz="0.021399 0.0 -0.114232" rpy="0.0 -0.0 0.0"/>
      <geometry>
        <box size="0.49156 0.52364 0.016"/>
      </geometry>
    </collision>
    <collision name="cabinet1_drawer1_collision_4">
      <origin xyz="0.021336 0.26865 -0.0941" rpy="0.0 -0.0 0.0"/>
      <geometry>
        <box size="0.4917 0.0158442 0.053098"/>
      </geometry>
    </collision>
    <collision name="cabinet1_drawer1_collision_0">
      <origin xyz="-0.233977 0.0 0.0" rpy="0.0 -0.0 0.0"/>
      <geometry>
        <box size="0.019 0.596936 0.262972"/>
      </geometry>
    </collision>
  </link>
  <joint name="cabinet1_drawer1_handle_joint" type="fixed">
    <origin xyz="-0.26831836 0.00091816 0.08401428" rpy="1.5707963267948966 -0.0 0.0"/>
    <parent link="cabinet1_drawer1"/>
    <child link="cabinet1_drawer1_handle"/>
  </joint>
  <link name="cabinet1_drawer1_handle">
    <collision name="cabinet1_drawer1_handle_collision_0">
      <origin xyz="0.0164985 0.0 0.08" rpy="0.0 -0.0 0.0"/>
      <geometry>
        <box size="0.02 0.013 0.013"/>
      </geometry>
    </collision>
    <collision name="cabinet1_drawer1_handle_collision_2">
      <origin xyz="0.0 0.0 0.0" rpy="0.0 -0.0 0.0"/>
      <geometry>
        <box size="0.013 0.013 0.173032"/>
      </geometry>
    </collision>
    <collision name="cabinet1_drawer1_handle_collision_1">
      <origin xyz="0.0164985 0.0 -0.08" rpy="0.0 -0.0 0.0"/>
      <geometry>
        <box size="0.02 0.013 0.013"/>
      </geometry>
    </collision>
  </link>
  <joint name="cabinet1_drawer2_joint" type="prismatic">
    <origin xyz="-0.04600000008940697 -0.010999999940395355 -0.8159999847412109" rpy="0.0 -0.0 0.0"/>
    <axis xyz="-1 0 0"/>
    <parent link="cabinet1"/>
    <child link="cabinet1_drawer2"/>
    <limit effort="1000" lower="0.0" upper="0.44999998807907104" velocity="1000"/>
  </joint>
  <link name="cabinet1_drawer2">
    <collision name="cabinet1_drawer2_collision_6">
      <origin xyz="0.26 0.0 -0.0797358" rpy="0.0 -0.0 0.0"/>
      <geometry>
        <box size="0.01865384 0.52364 0.1517224"/>
      </geometry>
    </collision>
    <collision name="cabinet1_drawer2_collision_4">
      <origin xyz="0.021336 0.26865 -0.12854" rpy="0.0 -0.0 0.0"/>
      <geometry>
        <box size="0.4917 0.0158442 0.083502"/>
      </geometry>
    </collision>
    <collision name="cabinet1_drawer2_collision_5">
      <origin xyz="0.021399 0.0 -0.16226" rpy="0.0 -0.0 0.0"/>
      <geometry>
        <box size="0.49156 0.52364 0.016"/>
      </geometry>
    </collision>
    <collision name="cabinet1_drawer2_collision_2">
      <origin xyz="0.021336 0.26865 -0.0084109" rpy="0.0 -0.0 0.0"/>
      <geometry>
        <box size="0.4917 0.0158442 0.0223924"/>
      </geometry>
    </collision>
    <collision name="cabinet1_drawer2_collision_0">
      <origin xyz="-0.233977 0.0 0.0" rpy="0.0 -0.0 0.0"/>
      <geometry>
        <box size="0.019 0.596936 0.39428"/>
      </geometry>
    </collision>
    <collision name="cabinet1_drawer2_collision_3">
      <origin xyz="0.021336 -0.26865 -0.12854" rpy="0.0 -0.0 0.0"/>
      <geometry>
        <box size="0.4917 0.0158442 0.083502"/>
      </geometry>
    </collision>
    <collision name="cabinet1_drawer2_collision_1">
      <origin xyz="0.021336 -0.26865 -0.0084109" rpy="0.0 -0.0 0.0"/>
      <geometry>
        <box size="0.4917 0.0158442 0.0223924"/>
      </geometry>
    </collision>
  </link>
  <joint name="cabinet1_drawer2_handle_joint" type="fixed">
    <origin xyz="-0.26948316 -0.00145845 0.150606" rpy="1.5707963267948966 -0.0 0.0"/>
    <parent link="cabinet1_drawer2"/>
    <child link="cabinet1_drawer2_handle"/>
  </joint>
  <link name="cabinet1_drawer2_handle">
    <collision name="cabinet1_drawer2_handle_collision_2">
      <origin xyz="0.0 0.0 0.0" rpy="0.0 -0.0 0.0"/>
      <geometry>
        <box size="0.013 0.013 0.173032"/>
      </geometry>
    </collision>
    <collision name="cabinet1_drawer2_handle_collision_1">
      <origin xyz="0.0164985 0.0 -0.08" rpy="0.0 -0.0 0.0"/>
      <geometry>
        <box size="0.02 0.013 0.013"/>
      </geometry>
    </collision>
    <collision name="cabinet1_drawer2_handle_collision_0">
      <origin xyz="0.0164985 0.0 0.08" rpy="0.0 -0.0 0.0"/>
      <geometry>
        <box size="0.02 0.013 0.013"/>
      </geometry>
    </collision>
  </link>
  <joint name="oven_joint" type="fixed">
    <origin xyz="-0.27395857 -0.0123597 -0.3426725" rpy="0.0 -0.0 0.0"/>
    <parent link="cabinet1"/>
    <child link="oven"/>
  </joint>
  <link name="oven">
    <collision name="oven_collision_3">
      <origin xyz="0.264778 0.264104 0.288951" rpy="0.0 -0.0 0.0"/>
      <geometry>
        <box size="0.545666 0.054902 0.586022"/>
      </geometry>
    </collision>
    <collision name="oven_collision_1">
      <origin xyz="0.264778 0.003055 0.018039" rpy="0.0 -0.0 0.0"/>
      <geometry>
        <box size="0.545666 0.58989 0.045598"/>
      </geometry>
    </collision>
    <collision name="oven_collision_4">
      <origin xyz="0.5 -0.003055 0.288951" rpy="0.0 -0.0 0.0"/>
      <geometry>
        <box size="0.074784 0.58989 0.586022"/>
      </geometry>
    </collision>
    <collision name="oven_collision_0">
      <origin xyz="0.264778 0.003055 0.50654" rpy="0.0 -0.0 0.0"/>
      <geometry>
        <box size="0.545666 0.58989 0.150842"/>
      </geometry>
    </collision>
    <collision name="oven_collision_2">
      <origin xyz="0.264778 0.2675 0.288951" rpy="0.0 -0.0 0.0"/>
      <geometry>
        <box size="0.545666 0.059 0.586022"/>
      </geometry>
    </collision>
  </link>
  <joint name="oven_door_joint" type="revolute">
    <origin xyz="0.0 0.0 0.0" rpy="1.5707963267948968 1.5707963267948963 0.0"/>
    <axis xyz="0 0 1"/>
    <parent link="oven"/>
    <child link="oven_door"/>
    <limit effort="1000" lower="0.0" upper="1.5707963267948966" velocity="1000"/>
  </joint>
  <link name="oven_door">
    <collision name="oven_door_collision_0">
      <origin xyz="-0.226757 0.005395 -0.002993" rpy="0.0 -0.0 0.0"/>
      <geometry>
        <box size="0.471696 0.036998 0.590588"/>
      </geometry>
    </collision>
  </link>
  <joint name="cabinet2_joint" type="fixed">
    <origin xyz="0.27990936 1.97705429 1.16238914" rpy="0.0 -0.0 3.141592653589793"/>
    <parent link="kitchen1_root"/>
    <child link="cabinet2"/>
  </joint>
  <link name="cabinet2">
    <collision name="cabinet2_collision_3">
      <origin xyz="0.005897 0.0 0.975845" rpy="0.0 -0.0 0.0"/>
      <geometry>
        <box size="0.554718 0.367764 0.016"/>
      </geometry>
    </collision>
    <collision name="cabinet2_collision_0">
      <origin xyz="0.005897 0.191979 0.0" rpy="0.0 -0.0 0.0"/>
      <geometry>
        <box size="0.554718 0.016 2.12768"/>
      </geometry>
    </collision>
    <collision name="cabinet2_collision_1">
      <origin xyz="0.005897 -0.191979 0.0" rpy="0.0 -0.0 0.0"/>
      <geometry>
        <box size="0.554718 0.016 2.12768"/>
      </geometry>
    </collision>
    <collision name="cabinet2_collision_2">
      <origin xyz="0.005897 0.0 1.05584" rpy="0.0 -0.0 0.0"/>
      <geometry>
        <box size="0.554718 0.367764 0.016"/>
      </geometry>
    </collision>
    <collision name="cabinet2_collision_4">
      <origin xyz="0.005897 0.0 -1.05594" rpy="0.0 -0.0 0.0"/>
      <geometry>
        <box size="0.554718 0.367764 0.016"/>
      </geometry>
    </collision>
    <collision name="cabinet2_collision_6">
      <origin xyz="0.267372 0.0 0.0" rpy="0.0 -0.0 0.0"/>
      <geometry>
        <box size="0.008 0.367764 2.09568"/>
      </geometry>
    </collision>
    <collision name="cabinet2_collision_5">
      <origin xyz="-0.26039 0.0 1.01584" rpy="0.0 -0.0 0.0"/>
      <geometry>
        <box size="0.014374 0.367764 0.063992"/>
      </geometry>
    </collision>
  </link>
  <joint name="cabinet2_door_joint" type="revolute">
    <origin xyz="-0.2843214273452759 0.18657000362873077 0.0010586499702185392" rpy="0.0 -0.0 0.0"/>
    <axis xyz="0 0 -1"/>
    <parent link="cabinet2"/>
    <child link="cabinet2_door"/>
    <limit effort="1000" lower="0.0" upper="1.5707963267948966" velocity="1000"/>
  </joint>
  <link name="cabinet2_door">
    <collision name="cabinet2_door_collision_0">
      <origin xyz="-0.000653 -0.185074 0.0" rpy="0.0 -0.0 0.0"/>
      <geometry>
        <box size="0.019 0.396958 2.12276"/>
      </geometry>
    </collision>
  </link>
  <joint name="cabinet2_door_handle_joint" type="fixed">
    <origin xyz="-0.02184994 -0.25886013 -0.10518866" rpy="1.5707963267948966 -0.0 0.0"/>
    <parent link="cabinet2_door"/>
    <child link="cabinet2_door_handle"/>
  </joint>
  <link name="cabinet2_door_handle">
    <collision name="cabinet2_door_handle_collision_1">
      <origin xyz="0.0164985 0.0 -0.08" rpy="0.0 -0.0 0.0"/>
      <geometry>
        <box size="0.02 0.013 0.013"/>
      </geometry>
    </collision>
    <collision name="cabinet2_door_handle_collision_0">
      <origin xyz="0.0164985 0.0 0.08" rpy="0.0 -0.0 0.0"/>
      <geometry>
        <box size="0.02 0.013 0.013"/>
      </geometry>
    </collision>
    <collision name="cabinet2_door_handle_collision_2">
      <origin xyz="0.0 0.0 0.0" rpy="0.0 -0.0 0.0"/>
      <geometry>
        <box size="0.013 0.013 0.173032"/>
      </geometry>
    </collision>
  </link>
  <joint name="cabinet2_shelf_joint" type="fixed">
    <origin xyz="-0.00337784 0.00043732 0.79036064" rpy="0.0 -0.0 0.0"/>
    <parent link="cabinet2"/>
    <child link="cabinet2_shelf"/>
  </joint>
  <link name="cabinet2_shelf">
    <collision name="cabinet2_shelf_collision_0">
      <origin xyz="0.0 0.0 0.004951" rpy="0.0 -0.0 0.0"/>
      <geometry>
        <box size="0.482948 0.367958 0.015"/>
      </geometry>
    </collision>
  </link>
  <joint name="cabinet2_drawer1_joint" type="prismatic">
    <origin xyz="-0.004647749941796064 0.001345379976555705 0.5804620981216431" rpy="0.0 -0.0 0.0"/>
    <axis xyz="-1 0 0"/>
    <parent link="cabinet2"/>
    <child link="cabinet2_drawer1"/>
    <limit effort="1000" lower="0.0" upper="0.44999998807907104" velocity="1000"/>
  </joint>
  <link name="cabinet2_drawer1">
    <collision name="cabinet2_drawer1_collision_4">
      <origin xyz="-0.003984 0.0 -0.039746" rpy="0.0 -0.0 0.0"/>
      <geometry>
        <box size="0.494978 0.361962 0.021498"/>
      </geometry>
    </collision>
    <collision name="cabinet2_drawer1_collision_1">
      <origin xyz="0.235441 0.0 0.0" rpy="0.0 -0.0 0.0"/>
      <geometry>
        <box size="0.016128 0.361962 0.10099"/>
      </geometry>
    </collision>
    <collision name="cabinet2_drawer1_collision_0">
      <origin xyz="-0.242975 0.0 0.0" rpy="0.0 -0.0 0.0"/>
      <geometry>
        <box size="0.017 0.361962 0.10099"/>
      </geometry>
    </collision>
    <collision name="cabinet2_drawer1_collision_3">
      <origin xyz="-0.003984 -0.170578 0.0" rpy="0.0 -0.0 0.0"/>
      <geometry>
        <box size="0.494978 0.016 0.10099"/>
      </geometry>
    </collision>
    <collision name="cabinet2_drawer1_collision_2">
      <origin xyz="-0.003984 0.170578 0.0" rpy="0.0 -0.0 0.0"/>
      <geometry>
        <box size="0.494978 0.016 0.10099"/>
      </geometry>
    </collision>
  </link>
  <joint name="cabinet2_drawer2_joint" type="prismatic">
    <origin xyz="-0.004647749941796064 -0.001345379976555705 0.422749400138855" rpy="0.0 -0.0 0.0"/>
    <axis xyz="-1 0 0"/>
    <parent link="cabinet2"/>
    <child link="cabinet2_drawer2"/>
    <limit effort="1000" lower="0.0" upper="0.44999998807907104" velocity="1000"/>
  </joint>
  <link name="cabinet2_drawer2">
    <collision name="cabinet2_drawer2_collision_3">
      <origin xyz="-0.242869 -0.148428 0.0" rpy="0.0 -0.0 0.0"/>
      <geometry>
        <box size="0.016786 0.064882 0.18198"/>
      </geometry>
    </collision>
    <collision name="cabinet2_drawer2_collision_0">
      <origin xyz="-0.242374 0.0 -0.042" rpy="0.0 -0.0 0.0"/>
      <geometry>
        <box size="0.013796 0.361962 0.098"/>
      </geometry>
    </collision>
    <collision name="cabinet2_drawer2_collision_7">
      <origin xyz="-0.003984 0.170578 -0.043743" rpy="0.0 -0.0 0.0"/>
      <geometry>
        <box size="0.494978 0.016 0.087106"/>
      </geometry>
    </collision>
    <collision name="cabinet2_drawer2_collision_8">
      <origin xyz="-0.003984 -0.170578 -0.043743" rpy="0.0 -0.0 0.0"/>
      <geometry>
        <box size="0.494978 0.016 0.087106"/>
      </geometry>
    </collision>
    <collision name="cabinet2_drawer2_collision_2">
      <origin xyz="-0.242869 0.148428 0.0" rpy="0.0 -0.0 0.0"/>
      <geometry>
        <box size="0.016786 0.064882 0.18198"/>
      </geometry>
    </collision>
    <collision name="cabinet2_drawer2_collision_1">
      <origin xyz="-0.242374 0.0 0.060843" rpy="0.0 -0.0 0.0"/>
      <geometry>
        <box size="0.013796 0.361962 0.020298"/>
      </geometry>
    </collision>
    <collision name="cabinet2_drawer2_collision_6">
      <origin xyz="-0.003984 -0.170578 0.075342" rpy="0.0 -0.0 0.0"/>
      <geometry>
        <box size="0.494978 0.016 0.023298"/>
      </geometry>
    </collision>
    <collision name="cabinet2_drawer2_collision_9">
      <origin xyz="-0.003984 0.0 -0.080242" rpy="0.0 -0.0 0.0"/>
      <geometry>
        <box size="0.494978 0.361962 0.021498"/>
      </geometry>
    </collision>
    <collision name="cabinet2_drawer2_collision_4">
      <origin xyz="0.235441 0.0 0.0" rpy="0.0 -0.0 0.0"/>
      <geometry>
        <box size="0.016128 0.361962 0.181758"/>
      </geometry>
    </collision>
    <collision name="cabinet2_drawer2_collision_5">
      <origin xyz="-0.003984 0.170578 0.075342" rpy="0.0 -0.0 0.0"/>
      <geometry>
        <box size="0.494978 0.016 0.023298"/>
      </geometry>
    </collision>
  </link>
  <joint name="cabinet2_drawer3_joint" type="prismatic">
    <origin xyz="-0.004647749941796064 -0.001345379976555705 0.14289650321006775" rpy="0.0 -0.0 0.0"/>
    <axis xyz="-1 0 0"/>
    <parent link="cabinet2"/>
    <child link="cabinet2_drawer3"/>
    <limit effort="1000" lower="0.0" upper="0.44999998807907104" velocity="1000"/>
  </joint>
  <link name="cabinet2_drawer3">
    <collision name="cabinet2_drawer3_collision_1">
      <origin xyz="-0.242374 0.0 0.060843" rpy="0.0 -0.0 0.0"/>
      <geometry>
        <box size="0.013796 0.361962 0.020298"/>
      </geometry>
    </collision>
    <collision name="cabinet2_drawer3_collision_5">
      <origin xyz="-0.003984 0.170578 0.075342" rpy="0.0 -0.0 0.0"/>
      <geometry>
        <box size="0.494978 0.016 0.023298"/>
      </geometry>
    </collision>
    <collision name="cabinet2_drawer3_collision_0">
      <origin xyz="-0.242374 0.0 -0.042" rpy="0.0 -0.0 0.0"/>
      <geometry>
        <box size="0.013796 0.361962 0.098"/>
      </geometry>
    </collision>
    <collision name="cabinet2_drawer3_collision_7">
      <origin xyz="-0.003984 0.170578 -0.043743" rpy="0.0 -0.0 0.0"/>
      <geometry>
        <box size="0.494978 0.016 0.087106"/>
      </geometry>
    </collision>
    <collision name="cabinet2_drawer3_collision_9">
      <origin xyz="-0.003984 0.0 -0.080242" rpy="0.0 -0.0 0.0"/>
      <geometry>
        <box size="0.494978 0.361962 0.021498"/>
      </geometry>
    </collision>
    <collision name="cabinet2_drawer3_collision_8">
      <origin xyz="-0.003984 -0.170578 -0.043743" rpy="0.0 -0.0 0.0"/>
      <geometry>
        <box size="0.494978 0.016 0.087106"/>
      </geometry>
    </collision>
    <collision name="cabinet2_drawer3_collision_3">
      <origin xyz="-0.242869 -0.148428 0.0" rpy="0.0 -0.0 0.0"/>
      <geometry>
        <box size="0.016786 0.064882 0.18198"/>
      </geometry>
    </collision>
    <collision name="cabinet2_drawer3_collision_2">
      <origin xyz="-0.242869 0.148428 0.0" rpy="0.0 -0.0 0.0"/>
      <geometry>
        <box size="0.016786 0.064882 0.18198"/>
      </geometry>
    </collision>
    <collision name="cabinet2_drawer3_collision_4">
      <origin xyz="0.235441 0.0 0.0" rpy="0.0 -0.0 0.0"/>
      <geometry>
        <box size="0.016128 0.361962 0.181758"/>
      </geometry>
    </collision>
    <collision name="cabinet2_drawer3_collision_6">
      <origin xyz="-0.003984 -0.170578 0.075342" rpy="0.0 -0.0 0.0"/>
      <geometry>
        <box size="0.494978 0.016 0.023298"/>
      </geometry>
    </collision>
  </link>
  <joint name="cabinet2_drawer4_joint" type="prismatic">
    <origin xyz="-0.004647749941796064 0.001345379976555705 -0.24243712425231934" rpy="0.0 -0.0 0.0"/>
    <axis xyz="-1 0 0"/>
    <parent link="cabinet2"/>
    <child link="cabinet2_drawer4"/>
    <limit effort="1000" lower="0.0" upper="0.44999998807907104" velocity="1000"/>
  </joint>
  <link name="cabinet2_drawer4">
    <collision name="cabinet2_drawer4_collision_4">
      <origin xyz="0.235441 0.0 0.0" rpy="0.0 -0.0 0.0"/>
      <geometry>
        <box size="0.016128 0.361962 0.181758"/>
      </geometry>
    </collision>
    <collision name="cabinet2_drawer4_collision_6">
      <origin xyz="-0.003984 -0.170578 0.075342" rpy="0.0 -0.0 0.0"/>
      <geometry>
        <box size="0.494978 0.016 0.023298"/>
      </geometry>
    </collision>
    <collision name="cabinet2_drawer4_collision_1">
      <origin xyz="-0.242374 0.0 0.060843" rpy="0.0 -0.0 0.0"/>
      <geometry>
        <box size="0.013796 0.361962 0.020298"/>
      </geometry>
    </collision>
    <collision name="cabinet2_drawer4_collision_8">
      <origin xyz="-0.003984 -0.170578 -0.043743" rpy="0.0 -0.0 0.0"/>
      <geometry>
        <box size="0.494978 0.016 0.087106"/>
      </geometry>
    </collision>
    <collision name="cabinet2_drawer4_collision_5">
      <origin xyz="-0.003984 0.170578 0.075342" rpy="0.0 -0.0 0.0"/>
      <geometry>
        <box size="0.494978 0.016 0.023298"/>
      </geometry>
    </collision>
    <collision name="cabinet2_drawer4_collision_7">
      <origin xyz="-0.003984 0.170578 -0.043743" rpy="0.0 -0.0 0.0"/>
      <geometry>
        <box size="0.494978 0.016 0.087106"/>
      </geometry>
    </collision>
    <collision name="cabinet2_drawer4_collision_3">
      <origin xyz="-0.242869 -0.148428 0.0" rpy="0.0 -0.0 0.0"/>
      <geometry>
        <box size="0.016786 0.064882 0.18198"/>
      </geometry>
    </collision>
    <collision name="cabinet2_drawer4_collision_0">
      <origin xyz="-0.242374 0.0 -0.042" rpy="0.0 -0.0 0.0"/>
      <geometry>
        <box size="0.013796 0.361962 0.098"/>
      </geometry>
    </collision>
    <collision name="cabinet2_drawer4_collision_9">
      <origin xyz="-0.003984 0.0 -0.080242" rpy="0.0 -0.0 0.0"/>
      <geometry>
        <box size="0.494978 0.361962 0.021498"/>
      </geometry>
    </collision>
    <collision name="cabinet2_drawer4_collision_2">
      <origin xyz="-0.242869 0.148428 0.0" rpy="0.0 -0.0 0.0"/>
      <geometry>
        <box size="0.016786 0.064882 0.18198"/>
      </geometry>
    </collision>
  </link>
  <joint name="cabinet2_drawer5_joint" type="prismatic">
    <origin xyz="-0.004647749941796064 0.001345379976555705 -0.5180959105491638" rpy="0.0 -0.0 0.0"/>
    <axis xyz="-1 0 0"/>
    <parent link="cabinet2"/>
    <child link="cabinet2_drawer5"/>
    <limit effort="1000" lower="0.0" upper="0.44999998807907104" velocity="1000"/>
  </joint>
  <link name="cabinet2_drawer5">
    <collision name="cabinet2_drawer5_collision_7">
      <origin xyz="-0.003984 0.170578 -0.043743" rpy="0.0 -0.0 0.0"/>
      <geometry>
        <box size="0.494978 0.016 0.087106"/>
      </geometry>
    </collision>
    <collision name="cabinet2_drawer5_collision_4">
      <origin xyz="0.235441 0.0 0.0" rpy="0.0 -0.0 0.0"/>
      <geometry>
        <box size="0.016128 0.361962 0.181758"/>
      </geometry>
    </collision>
    <collision name="cabinet2_drawer5_collision_5">
      <origin xyz="-0.003984 0.170578 0.075342" rpy="0.0 -0.0 0.0"/>
      <geometry>
        <box size="0.494978 0.016 0.023298"/>
      </geometry>
    </collision>
    <collision name="cabinet2_drawer5_collision_2">
      <origin xyz="-0.242869 0.148428 0.0" rpy="0.0 -0.0 0.0"/>
      <geometry>
        <box size="0.016786 0.064882 0.18198"/>
      </geometry>
    </collision>
    <collision name="cabinet2_drawer5_collision_1">
      <origin xyz="-0.242374 0.0 0.060843" rpy="0.0 -0.0 0.0"/>
      <geometry>
        <box size="0.013796 0.361962 0.020298"/>
      </geometry>
    </collision>
    <collision name="cabinet2_drawer5_collision_0">
      <origin xyz="-0.242374 0.0 -0.042" rpy="0.0 -0.0 0.0"/>
      <geometry>
        <box size="0.013796 0.361962 0.098"/>
      </geometry>
    </collision>
    <collision name="cabinet2_drawer5_collision_8">
      <origin xyz="-0.003984 -0.170578 -0.043743" rpy="0.0 -0.0 0.0"/>
      <geometry>
        <box size="0.494978 0.016 0.087106"/>
      </geometry>
    </collision>
    <collision name="cabinet2_drawer5_collision_9">
      <origin xyz="-0.003984 0.0 -0.080242" rpy="0.0 -0.0 0.0"/>
      <geometry>
        <box size="0.494978 0.361962 0.021498"/>
      </geometry>
    </collision>
    <collision name="cabinet2_drawer5_collision_3">
      <origin xyz="-0.242869 -0.148428 0.0" rpy="0.0 -0.0 0.0"/>
      <geometry>
        <box size="0.016786 0.064882 0.18198"/>
      </geometry>
    </collision>
    <collision name="cabinet2_drawer5_collision_6">
      <origin xyz="-0.003984 -0.170578 0.075342" rpy="0.0 -0.0 0.0"/>
      <geometry>
        <box size="0.494978 0.016 0.023298"/>
      </geometry>
    </collision>
  </link>
  <joint name="cabinet2_drawer6_joint" type="prismatic">
    <origin xyz="-0.004647749941796064 0.001345379976555705 -0.9551920294761658" rpy="0.0 -0.0 0.0"/>
    <axis xyz="-1 0 0"/>
    <parent link="cabinet2"/>
    <child link="cabinet2_drawer6"/>
    <limit effort="1000" lower="0.0" upper="0.44999998807907104" velocity="1000"/>
  </joint>
  <link name="cabinet2_drawer6">
    <collision name="cabinet2_drawer6_collision_3">
      <origin xyz="-0.242869 -0.148428 0.0" rpy="0.0 -0.0 0.0"/>
      <geometry>
        <box size="0.016786 0.064882 0.18198"/>
      </geometry>
    </collision>
    <collision name="cabinet2_drawer6_collision_6">
      <origin xyz="-0.003984 -0.170578 0.075342" rpy="0.0 -0.0 0.0"/>
      <geometry>
        <box size="0.494978 0.016 0.023298"/>
      </geometry>
    </collision>
    <collision name="cabinet2_drawer6_collision_5">
      <origin xyz="-0.003984 0.170578 0.075342" rpy="0.0 -0.0 0.0"/>
      <geometry>
        <box size="0.494978 0.016 0.023298"/>
      </geometry>
    </collision>
    <collision name="cabinet2_drawer6_collision_2">
      <origin xyz="-0.242869 0.148428 0.0" rpy="0.0 -0.0 0.0"/>
      <geometry>
        <box size="0.016786 0.064882 0.18198"/>
      </geometry>
    </collision>
    <collision name="cabinet2_drawer6_collision_1">
      <origin xyz="-0.242374 0.0 0.060843" rpy="0.0 -0.0 0.0"/>
      <geometry>
        <box size="0.013796 0.361962 0.020298"/>
      </geometry>
    </collision>
    <collision name="cabinet2_drawer6_collision_7">
      <origin xyz="-0.003984 0.170578 -0.043743" rpy="0.0 -0.0 0.0"/>
      <geometry>
        <box size="0.494978 0.016 0.087106"/>
      </geometry>
    </collision>
    <collision name="cabinet2_drawer6_collision_9">
      <origin xyz="-0.003984 0.0 -0.080242" rpy="0.0 -0.0 0.0"/>
      <geometry>
        <box size="0.494978 0.361962 0.021498"/>
      </geometry>
    </collision>
    <collision name="cabinet2_drawer6_collision_8">
      <origin xyz="-0.003984 -0.170578 -0.043743" rpy="0.0 -0.0 0.0"/>
      <geometry>
        <box size="0.494978 0.016 0.087106"/>
      </geometry>
    </collision>
    <collision name="cabinet2_drawer6_collision_4">
      <origin xyz="0.235441 0.0 0.0" rpy="0.0 -0.0 0.0"/>
      <geometry>
        <box size="0.016128 0.361962 0.181758"/>
      </geometry>
    </collision>
    <collision name="cabinet2_drawer6_collision_0">
      <origin xyz="-0.242374 0.0 -0.042" rpy="0.0 -0.0 0.0"/>
      <geometry>
        <box size="0.013796 0.361962 0.098"/>
      </geometry>
    </collision>
  </link>
  <joint name="cabinet3_joint" type="fixed">
    <origin xyz="0.27498539 2.47989822 1.16287888" rpy="0.0 -0.0 3.141592653589793"/>
    <parent link="kitchen1_root"/>
    <child link="cabinet3"/>
  </joint>
  <link name="cabinet3">
    <collision name="cabinet3_collision_5">
      <origin xyz="0.003155 0.0 -0.980943" rpy="0.0 -0.0 0.0"/>
      <geometry>
        <box size="0.554386 0.572134 0.016"/>
      </geometry>
    </collision>
    <collision name="cabinet3_collision_0">
      <origin xyz="0.003155 -0.291968 0.0" rpy="0.0 -0.0 0.0"/>
      <geometry>
        <box size="0.554386 0.02 2.12764"/>
      </geometry>
    </collision>
    <collision name="cabinet3_collision_8">
      <origin xyz="-0.262453 0.0 0.857803" rpy="0.0 -0.0 0.0"/>
      <geometry>
        <box size="0.0209188 0.572134 0.06"/>
      </geometry>
    </collision>
    <collision name="cabinet3_collision_9">
      <origin xyz="-0.262453 0.0 0.857803" rpy="0.0 -0.0 0.0"/>
      <geometry>
        <box size="0.0209188 0.572134 0.06"/>
      </geometry>
    </collision>
    <collision name="cabinet3_collision_6">
      <origin xyz="0.003155 0.0 -1.05594" rpy="0.0 -0.0 0.0"/>
      <geometry>
        <box size="0.554386 0.572134 0.016"/>
      </geometry>
    </collision>
    <collision name="cabinet3_collision_10">
      <origin xyz="-0.264485 -0.20788 -1.02629" rpy="0.0 -0.0 0.0"/>
      <geometry>
        <box size="0.016 0.147984 0.074692"/>
      </geometry>
    </collision>
    <collision name="cabinet3_collision_3">
      <origin xyz="0.003155 0.0 0.895854" rpy="0.0 -0.0 0.0"/>
      <geometry>
        <box size="0.554386 0.572134 0.016"/>
      </geometry>
    </collision>
    <collision name="cabinet3_collision_2">
      <origin xyz="0.003155 0.0 1.05584" rpy="0.0 -0.0 0.0"/>
      <geometry>
        <box size="0.554386 0.572134 0.016"/>
      </geometry>
    </collision>
    <collision name="cabinet3_collision_4">
      <origin xyz="0.003155 0.0 0.819863" rpy="0.0 -0.0 0.0"/>
      <geometry>
        <box size="0.554386 0.572134 0.016"/>
      </geometry>
    </collision>
    <collision name="cabinet3_collision_1">
      <origin xyz="0.003155 0.291968 0.0" rpy="0.0 -0.0 0.0"/>
      <geometry>
        <box size="0.554386 0.02 2.12764"/>
      </geometry>
    </collision>
    <collision name="cabinet3_collision_7">
      <origin xyz="-0.262453 0.0 0.975825" rpy="0.0 -0.0 0.0"/>
      <geometry>
        <box size="0.0209188 0.572134 0.14402"/>
      </geometry>
    </collision>
  </link>
  <joint name="fridge_door1_joint" type="revolute">
    <origin xyz="-0.29725900292396545 0.29914525151252747 0.2567399740219116" rpy="0.0 -0.0 0.0"/>
    <axis xyz="0 0 -1"/>
    <parent link="cabinet3"/>
    <child link="fridge_door1"/>
    <limit effort="1000" lower="0.0" upper="1.5707963267948966" velocity="1000"/>
  </joint>
  <link name="fridge_door1">
    <collision name="fridge_door1_collision_1">
      <origin xyz="0.03605 -0.295455 -0.001115" rpy="0.0 -0.0 0.0"/>
      <geometry>
        <box size="0.025 0.553734 0.988894"/>
      </geometry>
    </collision>
    <collision name="fridge_door1_collision_0">
      <origin xyz="0.006948 -0.297325 0.139709" rpy="0.0 -0.0 0.0"/>
      <geometry>
        <box size="0.018554 0.596492 1.336678"/>
      </geometry>
    </collision>
  </link>
  <joint name="fridge_door1_handle_joint" type="fixed">
    <origin xyz="-0.02799103 -0.46534321 -0.3616" rpy="1.5707963267948966 -0.0 0.0"/>
    <parent link="fridge_door1"/>
    <child link="fridge_door1_handle"/>
  </joint>
  <link name="fridge_door1_handle">
    <collision name="fridge_door1_handle_collision_1">
      <origin xyz="0.0164985 0.0 -0.08" rpy="0.0 -0.0 0.0"/>
      <geometry>
        <box size="0.02 0.013 0.013"/>
      </geometry>
    </collision>
    <collision name="fridge_door1_handle_collision_0">
      <origin xyz="0.0164985 0.0 0.08" rpy="0.0 -0.0 0.0"/>
      <geometry>
        <box size="0.02 0.013 0.013"/>
      </geometry>
    </collision>
    <collision name="fridge_door1_handle_collision_2">
      <origin xyz="0.0 0.0 0.0" rpy="0.0 -0.0 0.0"/>
      <geometry>
        <box size="0.013 0.013 0.173032"/>
      </geometry>
    </collision>
  </link>
  <joint name="fridge_door_tray1_joint" type="fixed">
    <origin xyz="0.10379066 -0.29726078 -0.01565247" rpy="0.0 -0.0 0.0"/>
    <parent link="fridge_door1"/>
    <child link="fridge_door_tray1"/>
  </joint>
  <link name="fridge_door_tray1">
    <collision name="fridge_door_tray1_collision_4">
      <origin xyz="0.0 0.0 -0.047166" rpy="0.0 -0.0 0.0"/>
      <geometry>
        <box size="0.10942 0.421854 0.002"/>
      </geometry>
    </collision>
    <collision name="fridge_door_tray1_collision_3">
      <origin xyz="0.0 -0.209978 0.0" rpy="0.0 -0.0 0.0"/>
      <geometry>
        <box size="0.10942 0.002 0.095574"/>
      </geometry>
    </collision>
    <collision name="fridge_door_tray1_collision_2">
      <origin xyz="0.0 0.209978 0.0" rpy="0.0 -0.0 0.0"/>
      <geometry>
        <box size="0.10942 0.002 0.095574"/>
      </geometry>
    </collision>
    <collision name="fridge_door_tray1_collision_0">
      <origin xyz="0.054273 0.0 0.0" rpy="0.0 -0.0 0.0"/>
      <geometry>
        <box size="0.002 0.421854 0.095574"/>
      </geometry>
    </collision>
    <collision name="fridge_door_tray1_collision_1">
      <origin xyz="-0.054273 0.0 0.0" rpy="0.0 -0.0 0.0"/>
      <geometry>
        <box size="0.002 0.421854 0.095574"/>
      </geometry>
    </collision>
  </link>
  <joint name="fridge_door_tray2_joint" type="fixed">
    <origin xyz="0.10176933 -0.29847088 0.22387222" rpy="0.0 -0.0 0.0"/>
    <parent link="fridge_door1"/>
    <child link="fridge_door_tray2"/>
  </joint>
  <link name="fridge_door_tray2">
    <collision name="fridge_door_tray2_collision_4">
      <origin xyz="0.0 0.0 -0.025903" rpy="0.0 -0.0 0.0"/>
      <geometry>
        <box size="0.109988 0.421954 0.002"/>
      </geometry>
    </collision>
    <collision name="fridge_door_tray2_collision_2">
      <origin xyz="0.0 0.209978 0.0" rpy="0.0 -0.0 0.0"/>
      <geometry>
        <box size="0.109988 0.002 0.053802"/>
      </geometry>
    </collision>
    <collision name="fridge_door_tray2_collision_0">
      <origin xyz="0.054019 0.0 0.0" rpy="0.0 -0.0 0.0"/>
      <geometry>
        <box size="0.002 0.421954 0.053802"/>
      </geometry>
    </collision>
    <collision name="fridge_door_tray2_collision_1">
      <origin xyz="-0.054019 0.0 0.0" rpy="0.0 -0.0 0.0"/>
      <geometry>
        <box size="0.002 0.421954 0.053802"/>
      </geometry>
    </collision>
    <collision name="fridge_door_tray2_collision_3">
      <origin xyz="0.0 -0.209978 0.0" rpy="0.0 -0.0 0.0"/>
      <geometry>
        <box size="0.109988 0.002 0.053802"/>
      </geometry>
    </collision>
  </link>
  <joint name="fridge_egg_tray_joint" type="fixed">
    <origin xyz="-0.00226576 0.0853089 0.00069855" rpy="0.0 -0.0 0.0"/>
    <parent link="fridge_door_tray2"/>
    <child link="fridge_egg_tray"/>
  </joint>
  <link name="fridge_egg_tray"/>
  <joint name="fridge_door2_joint" type="revolute">
    <origin xyz="-0.29725900292396545 0.2990896999835968 -0.6380078792572021" rpy="0.0 -0.0 0.0"/>
    <axis xyz="0 0 -1"/>
    <parent link="cabinet3"/>
    <child link="fridge_door2"/>
    <limit effort="1000" lower="0.0" upper="1.5707963267948966" velocity="1000"/>
  </joint>
  <link name="fridge_door2">
    <collision name="fridge_door2_collision_1">
      <origin xyz="0.03605 -0.295455 0.019366" rpy="0.0 -0.0 0.0"/>
      <geometry>
        <box size="0.025 0.553734 0.622332"/>
      </geometry>
    </collision>
    <collision name="fridge_door2_collision_0">
      <origin xyz="0.006948 -0.297325 -0.028308" rpy="0.0 -0.0 0.0"/>
      <geometry>
        <box size="0.018554 0.596492 0.78594"/>
      </geometry>
    </collision>
  </link>
  <joint name="fridge_door2_handle_joint" type="fixed">
    <origin xyz="0.02804657 -0.46538265 0.31786839" rpy="1.5707963267948966 -0.0 0.0"/>
    <parent link="fridge_door2"/>
    <child link="fridge_door2_handle"/>
  </joint>
  <link name="fridge_door2_handle">
    <collision name="fridge_door2_handle_collision_0">
      <origin xyz="0.0164985 0.0 0.08" rpy="0.0 -0.0 0.0"/>
      <geometry>
        <box size="0.02 0.013 0.013"/>
      </geometry>
    </collision>
    <collision name="fridge_door2_handle_collision_1">
      <origin xyz="0.0164985 0.0 -0.08" rpy="0.0 -0.0 0.0"/>
      <geometry>
        <box size="0.02 0.013 0.013"/>
      </geometry>
    </collision>
    <collision name="fridge_door2_handle_collision_2">
      <origin xyz="0.0 0.0 0.0" rpy="0.0 -0.0 0.0"/>
      <geometry>
        <box size="0.013 0.013 0.173032"/>
      </geometry>
    </collision>
  </link>
  <joint name="fridge_base_joint" type="fixed">
    <origin xyz="-0.01918092 -0.00292496 -0.0816938" rpy="0.0 -0.0 0.0"/>
    <parent link="cabinet3"/>
    <child link="fridge_base"/>
  </joint>
  <link name="fridge_base">
    <collision name="fridge_base_collision_5">
      <origin xyz="-0.029351 0.0 0.839695" rpy="0.0 -0.0 0.0"/>
      <geometry>
        <box size="0.392848 0.469566 0.07542"/>
      </geometry>
    </collision>
    <collision name="fridge_base_collision_2">
      <origin xyz="-0.029351 -0.223235 -0.561142" rpy="0.0 -0.0 0.0"/>
      <geometry>
        <box size="0.392848 0.024554 0.636392"/>
      </geometry>
    </collision>
    <collision name="fridge_base_collision_6">
      <origin xyz="-0.029351 0.0 0.224975" rpy="0.0 -0.0 0.0"/>
      <geometry>
        <box size="0.392848 0.469566 0.025"/>
      </geometry>
    </collision>
    <collision name="fridge_base_collision_7">
      <origin xyz="-0.029351 0.0 -0.18398" rpy="0.0 -0.0 0.0"/>
      <geometry>
        <box size="0.392848 0.469566 0.11793"/>
      </geometry>
    </collision>
    <collision name="fridge_base_collision_0">
      <origin xyz="0.016051 -0.257778 0.0" rpy="0.0 -0.0 0.0"/>
      <geometry>
        <box size="0.483652 0.043244 1.75881"/>
      </geometry>
    </collision>
    <collision name="fridge_base_collision_9">
      <origin xyz="0.159364 0.0 0.339754" rpy="0.0 -0.0 0.0"/>
      <geometry>
        <box size="0.01564 0.469566 0.929316"/>
      </geometry>
    </collision>
    <collision name="fridge_base_collision_4">
      <origin xyz="0.011034 0.0 0.855407" rpy="0.0 -0.0 0.0"/>
      <geometry>
        <box size="0.49339 0.556434 0.047996"/>
      </geometry>
    </collision>
    <collision name="fridge_base_collision_10">
      <origin xyz="0.199778 0.0 -0.524221" rpy="0.0 -0.0 0.0"/>
      <geometry>
        <box size="0.116796 0.469566 0.56255"/>
      </geometry>
    </collision>
    <collision name="fridge_base_collision_3">
      <origin xyz="-0.029351 0.223235 -0.561142" rpy="0.0 -0.0 0.0"/>
      <geometry>
        <box size="0.392848 0.024554 0.636392"/>
      </geometry>
    </collision>
    <collision name="fridge_base_collision_8">
      <origin xyz="-0.029351 0.0 -0.842617" rpy="0.0 -0.0 0.0"/>
      <geometry>
        <box size="0.392848 0.469566 0.073576"/>
      </geometry>
    </collision>
    <collision name="fridge_base_collision_1">
      <origin xyz="0.016051 0.257778 0.0" rpy="0.0 -0.0 0.0"/>
      <geometry>
        <box size="0.483652 0.043244 1.75881"/>
      </geometry>
    </collision>
  </link>
  <joint name="fridge_shelf1_joint" type="fixed">
    <origin xyz="-0.00102744 0.00204316 0.54545097" rpy="0.0 -0.0 0.0"/>
    <parent link="fridge_base"/>
    <child link="fridge_shelf1"/>
  </joint>
  <link name="fridge_shelf1">
    <collision name="fridge_shelf1_collision_0">
      <origin xyz="0.0 0.0 0.0" rpy="0.0 -0.0 0.0"/>
      <geometry>
        <box size="0.267982 0.468268 0.009088"/>
      </geometry>
    </collision>
  </link>
  <joint name="fridge_shelf2_joint" type="fixed">
    <origin xyz="-0.00102744 0.00204316 0.41123558" rpy="0.0 -0.0 0.0"/>
    <parent link="fridge_base"/>
    <child link="fridge_shelf2"/>
  </joint>
  <link name="fridge_shelf2">
    <collision name="fridge_shelf2_collision_0">
      <origin xyz="0.0 0.0 0.0" rpy="0.0 -0.0 0.0"/>
      <geometry>
        <box size="0.267982 0.468268 0.009088"/>
      </geometry>
    </collision>
  </link>
  <joint name="fridge_drawer1_joint" type="prismatic">
    <origin xyz="-0.01209005992859602 0.002235949970781803 0.11025719344615936" rpy="0.0 -0.0 0.0"/>
    <axis xyz="-1 0 0"/>
    <parent link="fridge_base"/>
    <child link="fridge_drawer1"/>
    <limit effort="1000" lower="0.0" upper="0.30000001192092896" velocity="1000"/>
  </joint>
  <link name="fridge_drawer1">
    <collision name="fridge_drawer1_collision_2">
      <origin xyz="0.16468 0.0 0.0" rpy="0.0 -0.0 0.0"/>
      <geometry>
        <box size="0.004246 0.454234 0.164152"/>
      </geometry>
    </collision>
    <collision name="fridge_drawer1_collision_4">
      <origin xyz="0.0 -0.217307 0.0" rpy="0.0 -0.0 0.0"/>
      <geometry>
        <box size="0.343522 0.01966 0.164152"/>
      </geometry>
    </collision>
    <collision name="fridge_drawer1_collision_1">
      <origin xyz="-0.169309 0.0 -0.034598" rpy="0.0 -0.0 0.0"/>
      <geometry>
        <box size="0.002896 0.454234 0.095728"/>
      </geometry>
    </collision>
    <collision name="fridge_drawer1_collision_0">
      <origin xyz="-0.169309 0.0 0.070506" rpy="0.0 -0.0 0.0"/>
      <geometry>
        <box size="0.005 0.454234 0.023842"/>
      </geometry>
    </collision>
    <collision name="fridge_drawer1_collision_3">
      <origin xyz="0.0 0.217307 0.0" rpy="0.0 -0.0 0.0"/>
      <geometry>
        <box size="0.343522 0.01966 0.164152"/>
      </geometry>
    </collision>
    <collision name="fridge_drawer1_collision_5">
      <origin xyz="0.0 0.0 -0.080999" rpy="0.0 -0.0 0.0"/>
      <geometry>
        <box size="0.343522 0.454234 0.002744"/>
      </geometry>
    </collision>
  </link>
  <joint name="fridge_drawer2_joint" type="prismatic">
    <origin xyz="-0.015483410097658634 -0.001988109899684787 -0.04961249977350235" rpy="0.0 -0.0 0.0"/>
    <axis xyz="-1 0 0"/>
    <parent link="fridge_base"/>
    <child link="fridge_drawer2"/>
    <limit effort="1000" lower="0.0" upper="0.30000001192092896" velocity="1000"/>
  </joint>
  <link name="fridge_drawer2">
    <collision name="fridge_drawer2_collision_3">
      <origin xyz="0.0 0.217307 0.0" rpy="0.0 -0.0 0.0"/>
      <geometry>
        <box size="0.343522 0.01966 0.137882"/>
      </geometry>
    </collision>
    <collision name="fridge_drawer2_collision_1">
      <origin xyz="-0.169309 0.0 -0.036775" rpy="0.0 -0.0 0.0"/>
      <geometry>
        <box size="0.002896 0.454234 0.064222"/>
      </geometry>
    </collision>
    <collision name="fridge_drawer2_collision_4">
      <origin xyz="0.0 -0.217307 0.0" rpy="0.0 -0.0 0.0"/>
      <geometry>
        <box size="0.343522 0.01966 0.137882"/>
      </geometry>
    </collision>
    <collision name="fridge_drawer2_collision_0">
      <origin xyz="-0.169309 0.0 0.057007" rpy="0.0 -0.0 0.0"/>
      <geometry>
        <box size="0.005 0.454234 0.023602"/>
      </geometry>
    </collision>
    <collision name="fridge_drawer2_collision_2">
      <origin xyz="0.16468 0.0 0.0" rpy="0.0 -0.0 0.0"/>
      <geometry>
        <box size="0.004246 0.454234 0.137882"/>
      </geometry>
    </collision>
    <collision name="fridge_drawer2_collision_5">
      <origin xyz="0.0 0.0 -0.066161" rpy="0.0 -0.0 0.0"/>
      <geometry>
        <box size="0.343522 0.454234 0.002744"/>
      </geometry>
    </collision>
  </link>
  <joint name="fridge_drawer3_joint" type="prismatic">
    <origin xyz="-0.032656989991664886 0.0025189900770783424 -0.3561762869358063" rpy="0.0 -0.0 0.0"/>
    <axis xyz="-1 0 0"/>
    <parent link="fridge_base"/>
    <child link="fridge_drawer3"/>
    <limit effort="1000" lower="0.0" upper="0.30000001192092896" velocity="1000"/>
  </joint>
  <link name="fridge_drawer3">
    <collision name="fridge_drawer3_collision_4">
      <origin xyz="-0.004962 -0.197083 0.0" rpy="0.0 -0.0 0.0"/>
      <geometry>
        <box size="0.32289 0.01464 0.19183"/>
      </geometry>
    </collision>
    <collision name="fridge_drawer3_collision_0">
      <origin xyz="-0.165482 0.0 0.083453" rpy="0.0 -0.0 0.0"/>
      <geometry>
        <box size="0.002 0.408956 0.024924"/>
      </geometry>
    </collision>
    <collision name="fridge_drawer3_collision_5">
      <origin xyz="-0.004962 0.0 -0.095072" rpy="0.0 -0.0 0.0"/>
      <geometry>
        <box size="0.32289 0.408956 0.001822"/>
      </geometry>
    </collision>
    <collision name="fridge_drawer3_collision_1">
      <origin xyz="-0.165482 0.0 -0.037113" rpy="0.0 -0.0 0.0"/>
      <geometry>
        <box size="0.002 0.408956 0.11774"/>
      </geometry>
    </collision>
    <collision name="fridge_drawer3_collision_2">
      <origin xyz="0.154928 0.0 0.0" rpy="0.0 -0.0 0.0"/>
      <geometry>
        <box size="0.00311 0.408956 0.19183"/>
      </geometry>
    </collision>
    <collision name="fridge_drawer3_collision_3">
      <origin xyz="-0.004962 0.197083 0.0" rpy="0.0 -0.0 0.0"/>
      <geometry>
        <box size="0.32289 0.01464 0.19183"/>
      </geometry>
    </collision>
  </link>
  <joint name="fridge_drawer4_joint" type="prismatic">
    <origin xyz="-0.028852229937911034 0.00508168013766408 -0.5329980254173279" rpy="0.0 -0.0 0.0"/>
    <axis xyz="-1 0 0"/>
    <parent link="fridge_base"/>
    <child link="fridge_drawer4"/>
    <limit effort="1000" lower="0.0" upper="0.30000001192092896" velocity="1000"/>
  </joint>
  <link name="fridge_drawer4">
    <collision name="fridge_drawer4_collision_1">
      <origin xyz="-0.165482 0.0 -0.035978" rpy="0.0 -0.0 0.0"/>
      <geometry>
        <box size="0.002 0.408956 0.08"/>
      </geometry>
    </collision>
    <collision name="fridge_drawer4_collision_5">
      <origin xyz="0.0 0.0 -0.074992" rpy="0.0 -0.0 0.0"/>
      <geometry>
        <box size="0.332816 0.408956 0.002"/>
      </geometry>
    </collision>
    <collision name="fridge_drawer4_collision_0">
      <origin xyz="-0.165482 0.0 0.063456" rpy="0.0 -0.0 0.0"/>
      <geometry>
        <box size="0.002 0.408956 0.024924"/>
      </geometry>
    </collision>
    <collision name="fridge_drawer4_collision_4">
      <origin xyz="0.0 -0.196311 0.0" rpy="0.0 -0.0 0.0"/>
      <geometry>
        <box size="0.332816 0.016 0.151834"/>
      </geometry>
    </collision>
    <collision name="fridge_drawer4_collision_3">
      <origin xyz="0.0 0.196311 0.0" rpy="0.0 -0.0 0.0"/>
      <geometry>
        <box size="0.332816 0.016 0.151834"/>
      </geometry>
    </collision>
    <collision name="fridge_drawer4_collision_2">
      <origin xyz="0.155483 0.0 0.0" rpy="0.0 -0.0 0.0"/>
      <geometry>
        <box size="0.002 0.408956 0.151834"/>
      </geometry>
    </collision>
  </link>
  <joint name="fridge_drawer5_joint" type="prismatic">
    <origin xyz="-0.06480766087770462 0.0 -0.7127871513366699" rpy="0.0 -0.0 0.0"/>
    <axis xyz="-1 0 0"/>
    <parent link="fridge_base"/>
    <child link="fridge_drawer5"/>
    <limit effort="1000" lower="0.0" upper="0.30000001192092896" velocity="1000"/>
  </joint>
  <link name="fridge_drawer5">
    <collision name="fridge_drawer5_collision_1">
      <origin xyz="-0.118669 0.0 -0.03813" rpy="0.0 -0.0 0.0"/>
      <geometry>
        <box size="0.002 0.408808 0.110706"/>
      </geometry>
    </collision>
    <collision name="fridge_drawer5_collision_0">
      <origin xyz="-0.120488 0.0 0.08099" rpy="0.0 -0.0 0.0"/>
      <geometry>
        <box size="0.002 0.408808 0.024998"/>
      </geometry>
    </collision>
    <collision name="fridge_drawer5_collision_4">
      <origin xyz="0.0 -0.196942 0.0" rpy="0.0 -0.0 0.0"/>
      <geometry>
        <box size="0.240842 0.014922 0.151834"/>
      </geometry>
    </collision>
    <collision name="fridge_drawer5_collision_3">
      <origin xyz="0.0 0.196942 0.0" rpy="0.0 -0.0 0.0"/>
      <geometry>
        <box size="0.240842 0.014922 0.151834"/>
      </geometry>
    </collision>
    <collision name="fridge_drawer5_collision_2">
      <origin xyz="0.108269 0.0 0.0" rpy="0.0 -0.0 0.0"/>
      <geometry>
        <box size="0.006434 0.408808 0.151834"/>
      </geometry>
    </collision>
    <collision name="fridge_drawer5_collision_5">
      <origin xyz="0.0 0.0 -0.09249" rpy="0.0 -0.0 0.0"/>
      <geometry>
        <box size="0.240842 0.408808 0.002"/>
      </geometry>
    </collision>
  </link>
  <joint name="cabinet4_joint" type="fixed">
    <origin xyz="0.18224365 3.29388123 1.82711395" rpy="0.0 -0.0 3.141592653589793"/>
    <parent link="kitchen1_root"/>
    <child link="cabinet4"/>
  </joint>
  <link name="cabinet4">
    <collision name="cabinet4_collision_2">
      <origin xyz="0.01 -0.481997 0.0" rpy="0.0 -0.0 0.0"/>
      <geometry>
        <box size="0.349962 0.016 0.797816"/>
      </geometry>
    </collision>
    <collision name="cabinet4_collision_0">
      <origin xyz="0.168984 0.010048 0.0" rpy="0.0 -0.0 0.0"/>
      <geometry>
        <box size="0.01 0.967896 0.76582"/>
      </geometry>
    </collision>
    <collision name="cabinet4_collision_1">
      <origin xyz="0.01 0.501898 0.0" rpy="0.0 -0.0 0.0"/>
      <geometry>
        <box size="0.349962 0.016 0.797816"/>
      </geometry>
    </collision>
    <collision name="cabinet4_collision_3">
      <origin xyz="0.0 -0.5 0.0" rpy="0.0 -0.0 0.0"/>
      <geometry>
        <box size="0.369738 0.02 0.797816"/>
      </geometry>
    </collision>
    <collision name="cabinet4_collision_5">
      <origin xyz="0.004 0.010048 -0.391007" rpy="0.0 -0.0 0.0"/>
      <geometry>
        <box size="0.337962 0.967896 0.016"/>
      </geometry>
    </collision>
    <collision name="cabinet4_collision_4">
      <origin xyz="0.004 0.010048 0.390908" rpy="0.0 -0.0 0.0"/>
      <geometry>
        <box size="0.337962 0.967896 0.016"/>
      </geometry>
    </collision>
  </link>
  <joint name="cabinet4_door1_joint" type="fixed">
    <origin xyz="-0.17226107 0.00837158 0.19916718" rpy="0.0 -0.0 0.0"/>
    <parent link="cabinet4"/>
    <child link="cabinet4_door1"/>
  </joint>
  <link name="cabinet4_door1">
    <collision name="cabinet4_door1_collision_0">
      <origin xyz="-0.002895 0.0 0.0" rpy="0.0 -0.0 0.0"/>
      <geometry>
        <box size="0.019 0.994892 0.395736"/>
      </geometry>
    </collision>
  </link>
  <joint name="cabinet4_door2_joint" type="fixed">
    <origin xyz="-0.15042921 0.0093109 -0.19994873" rpy="0.0 -0.0 0.0"/>
    <parent link="cabinet4"/>
    <child link="cabinet4_door2"/>
  </joint>
  <link name="cabinet4_door2">
    <collision name="cabinet4_door2_collision_0">
      <origin xyz="-0.025359 0.0 0.0" rpy="0.0 -0.0 0.0"/>
      <geometry>
        <box size="0.019 0.994892 0.395736"/>
      </geometry>
    </collision>
  </link>
  <joint name="cabinet4_door2_handle_joint" type="fixed">
    <origin xyz="-0.06103859 -0.01415195 -0.13357088" rpy="1.5707963267948966 -0.0 0.0"/>
    <parent link="cabinet4_door2"/>
    <child link="cabinet4_door2_handle"/>
  </joint>
  <link name="cabinet4_door2_handle">
    <collision name="cabinet4_door2_handle_collision_1">
      <origin xyz="0.0164985 0.0 -0.08" rpy="0.0 -0.0 0.0"/>
      <geometry>
        <box size="0.02 0.013 0.013"/>
      </geometry>
    </collision>
    <collision name="cabinet4_door2_handle_collision_0">
      <origin xyz="0.0164985 0.0 0.08" rpy="0.0 -0.0 0.0"/>
      <geometry>
        <box size="0.02 0.013 0.013"/>
      </geometry>
    </collision>
    <collision name="cabinet4_door2_handle_collision_2">
      <origin xyz="0.0 0.0 0.0" rpy="0.0 -0.0 0.0"/>
      <geometry>
        <box size="0.013 0.013 0.173032"/>
      </geometry>
    </collision>
  </link>
  <joint name="cabinet4_shelf1_joint" type="fixed">
    <origin xyz="0.00833792 -0.01016479 0.12500641" rpy="0.0 -0.0 0.0"/>
    <parent link="cabinet4"/>
    <child link="cabinet4_shelf1"/>
  </joint>
  <link name="cabinet4_shelf1">
    <collision name="cabinet4_shelf1_collision_0">
      <origin xyz="0.0 0.0 0.0" rpy="0.0 -0.0 0.0"/>
      <geometry>
        <box size="0.307078 0.967896 0.008084"/>
      </geometry>
    </collision>
  </link>
  <joint name="cabinet4_shelf2_joint" type="fixed">
    <origin xyz="0.00833792 -0.01016479 -0.09840179" rpy="0.0 -0.0 0.0"/>
    <parent link="cabinet4"/>
    <child link="cabinet4_shelf2"/>
  </joint>
  <link name="cabinet4_shelf2">
    <collision name="cabinet4_shelf2_collision_0">
      <origin xyz="0.0 0.0 0.0" rpy="0.0 -0.0 0.0"/>
      <geometry>
        <box size="0.307078 0.967896 0.008084"/>
      </geometry>
    </collision>
  </link>
  <joint name="counter_wall_joint" type="fixed">
    <origin xyz="0.28142776 3.29494293 0.90892097" rpy="0.0 -0.0 3.141592653589793"/>
    <parent link="kitchen1_root"/>
    <child link="counter_wall"/>
  </joint>
  <link name="counter_wall">
    <collision name="counter_wall_collision_0">
      <origin xyz="0.0 0.0 0.0" rpy="0.0 -0.0 0.0"/>
      <geometry>
        <box size="0.599 1.031064 0.026778"/>
      </geometry>
    </collision>
  </link>
  <joint name="cabinet5_joint" type="fixed">
    <origin xyz="0.27476608 3.08411682 0.49420666" rpy="0.0 -0.0 3.141592653589793"/>
    <parent link="kitchen1_root"/>
    <child link="cabinet5"/>
  </joint>
  <link name="cabinet5">
    <collision name="cabinet5_collision_2">
      <origin xyz="0.0 0.0 -0.391006" rpy="0.0 -0.0 0.0"/>
      <geometry>
        <box size="0.55452 0.568134 0.016"/>
      </geometry>
    </collision>
    <collision name="cabinet5_collision_1">
      <origin xyz="0.0 -0.291968 0.0" rpy="0.0 -0.0 0.0"/>
      <geometry>
        <box size="0.55452 0.016 0.798012"/>
      </geometry>
    </collision>
    <collision name="cabinet5_collision_4">
      <origin xyz="0.261473 0.0 0.0" rpy="0.0 -0.0 0.0"/>
      <geometry>
        <box size="0.008 0.568134 0.76582"/>
      </geometry>
    </collision>
    <collision name="cabinet5_collision_3">
      <origin xyz="0.217476 0.0 0.390909" rpy="0.0 -0.0 0.0"/>
      <geometry>
        <box size="0.08 0.568134 0.016"/>
      </geometry>
    </collision>
    <collision name="cabinet5_collision_0">
      <origin xyz="0.0 0.291968 0.0" rpy="0.0 -0.0 0.0"/>
      <geometry>
        <box size="0.55452 0.016 0.798012"/>
      </geometry>
    </collision>
  </link>
  <joint name="cabinet5_drawer1_joint" type="prismatic">
    <origin xyz="-0.05262698978185654 -0.0010002600029110909 0.3317783772945404" rpy="0.0 -0.0 0.0"/>
    <axis xyz="-1 0 0"/>
    <parent link="cabinet5"/>
    <child link="cabinet5_drawer1"/>
    <limit effort="1000" lower="0.0" upper="0.44999998807907104" velocity="1000"/>
  </joint>
  <link name="cabinet5_drawer1">
    <collision name="cabinet5_drawer1_collision_1">
      <origin xyz="0.021031 -0.270267 -0.01336" rpy="0.0 -0.0 0.0"/>
      <geometry>
        <box size="0.491014 0.016 0.085266"/>
      </geometry>
    </collision>
    <collision name="cabinet5_drawer1_collision_4">
      <origin xyz="0.021031 0.0 -0.047595" rpy="0.0 -0.0 0.0"/>
      <geometry>
        <box size="0.491014 0.539608 0.015"/>
      </geometry>
    </collision>
    <collision name="cabinet5_drawer1_collision_3">
      <origin xyz="0.260372 0.0 -0.01336" rpy="0.0 -0.0 0.0"/>
      <geometry>
        <box size="0.016 0.539608 0.085266"/>
      </geometry>
    </collision>
    <collision name="cabinet5_drawer1_collision_0">
      <origin xyz="0.021031 0.270267 -0.01336" rpy="0.0 -0.0 0.0"/>
      <geometry>
        <box size="0.491014 0.016 0.085266"/>
      </geometry>
    </collision>
    <collision name="cabinet5_drawer1_collision_2">
      <origin xyz="-0.233977 0.0 0.0" rpy="0.0 -0.0 0.0"/>
      <geometry>
        <box size="0.019 0.596936 0.129986"/>
      </geometry>
    </collision>
  </link>
  <joint name="cabinet5_drawer1_handle_joint" type="fixed">
    <origin xyz="-0.26980946 0.00142363 0.01676949" rpy="1.5707963267948966 -0.0 0.0"/>
    <parent link="cabinet5_drawer1"/>
    <child link="cabinet5_drawer1_handle"/>
  </joint>
  <link name="cabinet5_drawer1_handle">
    <collision name="cabinet5_drawer1_handle_collision_2">
      <origin xyz="0.0 0.0 0.0" rpy="0.0 -0.0 0.0"/>
      <geometry>
        <box size="0.013 0.013 0.173032"/>
      </geometry>
    </collision>
    <collision name="cabinet5_drawer1_handle_collision_1">
      <origin xyz="0.0164985 0.0 -0.08" rpy="0.0 -0.0 0.0"/>
      <geometry>
        <box size="0.02 0.013 0.013"/>
      </geometry>
    </collision>
    <collision name="cabinet5_drawer1_handle_collision_0">
      <origin xyz="0.0164985 0.0 0.08" rpy="0.0 -0.0 0.0"/>
      <geometry>
        <box size="0.02 0.013 0.013"/>
      </geometry>
    </collision>
  </link>
  <joint name="cabinet5_drawer2_joint" type="prismatic">
    <origin xyz="-0.05303763970732689 -0.0007915199967101216 0.13372458517551422" rpy="0.0 -0.0 0.0"/>
    <axis xyz="-1 0 0"/>
    <parent link="cabinet5"/>
    <child link="cabinet5_drawer2"/>
    <limit effort="1000" lower="0.0" upper="0.44999998807907104" velocity="1000"/>
  </joint>
  <link name="cabinet5_drawer2">
    <collision name="cabinet5_drawer2_collision_0">
      <origin xyz="0.021031 0.270267 0.041246" rpy="0.0 -0.0 0.0"/>
      <geometry>
        <box size="0.491014 0.016 0.023298"/>
      </geometry>
    </collision>
    <collision name="cabinet5_drawer2_collision_6">
      <origin xyz="0.021031 0.0 -0.113735" rpy="0.0 -0.0 0.0"/>
      <geometry>
        <box size="0.491014 0.539608 0.016"/>
      </geometry>
    </collision>
    <collision name="cabinet5_drawer2_collision_2">
      <origin xyz="0.021031 0.270267 -0.078968" rpy="0.0 -0.0 0.0"/>
      <geometry>
        <box size="0.491014 0.016 0.083496"/>
      </geometry>
    </collision>
    <collision name="cabinet5_drawer2_collision_3">
      <origin xyz="0.021031 -0.270267 -0.078968" rpy="0.0 -0.0 0.0"/>
      <geometry>
        <box size="0.491014 0.016 0.083496"/>
      </geometry>
    </collision>
    <collision name="cabinet5_drawer2_collision_1">
      <origin xyz="0.021031 -0.270267 0.041246" rpy="0.0 -0.0 0.0"/>
      <geometry>
        <box size="0.491014 0.016 0.023298"/>
      </geometry>
    </collision>
    <collision name="cabinet5_drawer2_collision_5">
      <origin xyz="0.260372 0.0 -0.037996" rpy="0.0 -0.0 0.0"/>
      <geometry>
        <box size="0.016 0.539608 0.168982"/>
      </geometry>
    </collision>
    <collision name="cabinet5_drawer2_collision_4">
      <origin xyz="-0.233977 0.0 0.0" rpy="0.0 -0.0 0.0"/>
      <geometry>
        <box size="0.019 0.596936 0.26275"/>
      </geometry>
    </collision>
  </link>
  <joint name="cabinet5_drawer2_handle_joint" type="fixed">
    <origin xyz="-0.2707106 0.00106413 0.08500843" rpy="1.5707963267948966 -0.0 0.0"/>
    <parent link="cabinet5_drawer2"/>
    <child link="cabinet5_drawer2_handle"/>
  </joint>
  <link name="cabinet5_drawer2_handle">
    <collision name="cabinet5_drawer2_handle_collision_1">
      <origin xyz="0.0164985 0.0 -0.08" rpy="0.0 -0.0 0.0"/>
      <geometry>
        <box size="0.02 0.013 0.013"/>
      </geometry>
    </collision>
    <collision name="cabinet5_drawer2_handle_collision_0">
      <origin xyz="0.0164985 0.0 0.08" rpy="0.0 -0.0 0.0"/>
      <geometry>
        <box size="0.02 0.013 0.013"/>
      </geometry>
    </collision>
    <collision name="cabinet5_drawer2_handle_collision_2">
      <origin xyz="0.0 0.0 0.0" rpy="0.0 -0.0 0.0"/>
      <geometry>
        <box size="0.013 0.013 0.173032"/>
      </geometry>
    </collision>
  </link>
  <joint name="cabinet5_drawer3_joint" type="prismatic">
    <origin xyz="-0.05345087870955467 -0.0007555100019089878 -0.19566689431667328" rpy="0.0 -0.0 0.0"/>
    <axis xyz="-1 0 0"/>
    <parent link="cabinet5"/>
    <child link="cabinet5_drawer3"/>
    <limit effort="1000" lower="0.0" upper="0.44999998807907104" velocity="1000"/>
  </joint>
  <link name="cabinet5_drawer3">
    <collision name="cabinet5_drawer3_collision_0">
      <origin xyz="0.021031 0.270267 -0.00926" rpy="0.0 -0.0 0.0"/>
      <geometry>
        <box size="0.491014 0.016 0.023276"/>
      </geometry>
    </collision>
    <collision name="cabinet5_drawer3_collision_6">
      <origin xyz="0.021031 0.0 -0.164582" rpy="0.0 -0.0 0.0"/>
      <geometry>
        <box size="0.491014 0.539608 0.016"/>
      </geometry>
    </collision>
    <collision name="cabinet5_drawer3_collision_3">
      <origin xyz="0.021031 -0.270267 -0.129424" rpy="0.0 -0.0 0.0"/>
      <geometry>
        <box size="0.491014 0.016 0.083422"/>
      </geometry>
    </collision>
    <collision name="cabinet5_drawer3_collision_2">
      <origin xyz="0.021031 0.270267 -0.129424" rpy="0.0 -0.0 0.0"/>
      <geometry>
        <box size="0.491014 0.016 0.083422"/>
      </geometry>
    </collision>
    <collision name="cabinet5_drawer3_collision_5">
      <origin xyz="0.260372 0.0 -0.088821" rpy="0.0 -0.0 0.0"/>
      <geometry>
        <box size="0.016 0.539608 0.16821"/>
      </geometry>
    </collision>
    <collision name="cabinet5_drawer3_collision_1">
      <origin xyz="0.021031 -0.270267 -0.00926" rpy="0.0 -0.0 0.0"/>
      <geometry>
        <box size="0.491014 0.016 0.023276"/>
      </geometry>
    </collision>
    <collision name="cabinet5_drawer3_collision_4">
      <origin xyz="-0.233977 0.0 0.0" rpy="0.0 -0.0 0.0"/>
      <geometry>
        <box size="0.019 0.596936 0.395734"/>
      </geometry>
    </collision>
  </link>
  <joint name="cabinet5_drawer3_handle_joint" type="fixed">
    <origin xyz="-0.26888186 0.00102875 0.15027037" rpy="1.5707963267948966 -0.0 0.0"/>
    <parent link="cabinet5_drawer3"/>
    <child link="cabinet5_drawer3_handle"/>
  </joint>
  <link name="cabinet5_drawer3_handle">
    <collision name="cabinet5_drawer3_handle_collision_0">
      <origin xyz="0.0164985 0.0 0.08" rpy="0.0 -0.0 0.0"/>
      <geometry>
        <box size="0.02 0.013 0.013"/>
      </geometry>
    </collision>
    <collision name="cabinet5_drawer3_handle_collision_1">
      <origin xyz="0.0164985 0.0 -0.08" rpy="0.0 -0.0 0.0"/>
      <geometry>
        <box size="0.02 0.013 0.013"/>
      </geometry>
    </collision>
    <collision name="cabinet5_drawer3_handle_collision_2">
      <origin xyz="0.0 0.0 0.0" rpy="0.0 -0.0 0.0"/>
      <geometry>
        <box size="0.013 0.013 0.173032"/>
      </geometry>
    </collision>
  </link>
  <joint name="cabinet6_joint" type="fixed">
    <origin xyz="0.27476608 3.5838385 0.49420666" rpy="0.0 -0.0 3.141592653589793"/>
    <parent link="kitchen1_root"/>
    <child link="cabinet6"/>
  </joint>
  <link name="cabinet6">
    <collision name="cabinet6_collision_4">
      <origin xyz="0.261473 0.0 0.0" rpy="0.0 -0.0 0.0"/>
      <geometry>
        <box size="0.008 0.369666 0.76582"/>
      </geometry>
    </collision>
    <collision name="cabinet6_collision_3">
      <origin xyz="0.217476 0.0 0.390909" rpy="0.0 -0.0 0.0"/>
      <geometry>
        <box size="0.08 0.369666 0.016"/>
      </geometry>
    </collision>
    <collision name="cabinet6_collision_1">
      <origin xyz="0.0 -0.191779 0.0" rpy="0.0 -0.0 0.0"/>
      <geometry>
        <box size="0.55452 0.016 0.798012"/>
      </geometry>
    </collision>
    <collision name="cabinet6_collision_0">
      <origin xyz="0.0 0.191779 0.0" rpy="0.0 -0.0 0.0"/>
      <geometry>
        <box size="0.55452 0.016 0.798012"/>
      </geometry>
    </collision>
    <collision name="cabinet6_collision_2">
      <origin xyz="0.0 0.0 -0.391006" rpy="0.0 -0.0 0.0"/>
      <geometry>
        <box size="0.55452 0.369666 0.016"/>
      </geometry>
    </collision>
  </link>
  <joint name="cabinet6_drawer1_joint" type="prismatic">
    <origin xyz="-0.053295981138944626 -0.0003264900005888194 0.3317783772945404" rpy="0.0 -0.0 0.0"/>
    <axis xyz="-1 0 0"/>
    <parent link="cabinet6"/>
    <child link="cabinet6_drawer1"/>
    <limit effort="1000" lower="0.0" upper="0.44999998807907104" velocity="1000"/>
  </joint>
  <link name="cabinet6_drawer1">
    <collision name="cabinet6_drawer1_collision_3">
      <origin xyz="0.260372 0.0 -0.01336" rpy="0.0 -0.0 0.0"/>
      <geometry>
        <box size="0.016 0.357644 0.085266"/>
      </geometry>
    </collision>
    <collision name="cabinet6_drawer1_collision_4">
      <origin xyz="0.021031 0.0 -0.047595" rpy="0.0 -0.0 0.0"/>
      <geometry>
        <box size="0.491014 0.357644 0.015"/>
      </geometry>
    </collision>
    <collision name="cabinet6_drawer1_collision_0">
      <origin xyz="0.021031 0.170562 -0.01336" rpy="0.0 -0.0 0.0"/>
      <geometry>
        <box size="0.491014 0.016 0.085266"/>
      </geometry>
    </collision>
    <collision name="cabinet6_drawer1_collision_1">
      <origin xyz="0.021031 -0.170562 -0.01336" rpy="0.0 -0.0 0.0"/>
      <geometry>
        <box size="0.491014 0.016 0.085266"/>
      </geometry>
    </collision>
    <collision name="cabinet6_drawer1_collision_2">
      <origin xyz="-0.233977 0.0 0.0" rpy="0.0 -0.0 0.0"/>
      <geometry>
        <box size="0.019 0.397734 0.129986"/>
      </geometry>
    </collision>
  </link>
  <joint name="cabinet6_drawer1_handle_joint" type="fixed">
    <origin xyz="-0.26662336 -0.00124599 0.0172039" rpy="1.5707963267948966 -0.0 0.0"/>
    <parent link="cabinet6_drawer1"/>
    <child link="cabinet6_drawer1_handle"/>
  </joint>
  <link name="cabinet6_drawer1_handle">
    <collision name="cabinet6_drawer1_handle_collision_0">
      <origin xyz="0.0164985 0.0 0.08" rpy="0.0 -0.0 0.0"/>
      <geometry>
        <box size="0.02 0.013 0.013"/>
      </geometry>
    </collision>
    <collision name="cabinet6_drawer1_handle_collision_2">
      <origin xyz="0.0 0.0 0.0" rpy="0.0 -0.0 0.0"/>
      <geometry>
        <box size="0.013 0.013 0.173032"/>
      </geometry>
    </collision>
    <collision name="cabinet6_drawer1_handle_collision_1">
      <origin xyz="0.0164985 0.0 -0.08" rpy="0.0 -0.0 0.0"/>
      <geometry>
        <box size="0.02 0.013 0.013"/>
      </geometry>
    </collision>
  </link>
  <joint name="cabinet6_drawer2_joint" type="prismatic">
    <origin xyz="-0.05305686965584755 -0.0007439699838869274 0.13296878337860107" rpy="0.0 -0.0 0.0"/>
    <axis xyz="-1 0 0"/>
    <parent link="cabinet6"/>
    <child link="cabinet6_drawer2"/>
    <limit effort="1000" lower="0.0" upper="0.44999998807907104" velocity="1000"/>
  </joint>
  <link name="cabinet6_drawer2">
    <collision name="cabinet6_drawer2_collision_5">
      <origin xyz="0.260372 0.0 -0.037996" rpy="0.0 -0.0 0.0"/>
      <geometry>
        <box size="0.016 0.357644 0.168982"/>
      </geometry>
    </collision>
    <collision name="cabinet6_drawer2_collision_4">
      <origin xyz="-0.233977 0.0 0.0" rpy="0.0 -0.0 0.0"/>
      <geometry>
        <box size="0.019 0.397734 0.26275"/>
      </geometry>
    </collision>
    <collision name="cabinet6_drawer2_collision_2">
      <origin xyz="0.021031 0.170562 -0.078968" rpy="0.0 -0.0 0.0"/>
      <geometry>
        <box size="0.491014 0.016 0.083496"/>
      </geometry>
    </collision>
    <collision name="cabinet6_drawer2_collision_0">
      <origin xyz="0.021031 0.170562 0.041246" rpy="0.0 -0.0 0.0"/>
      <geometry>
        <box size="0.491014 0.016 0.023298"/>
      </geometry>
    </collision>
    <collision name="cabinet6_drawer2_collision_1">
      <origin xyz="0.021031 -0.170562 0.041246" rpy="0.0 -0.0 0.0"/>
      <geometry>
        <box size="0.491014 0.016 0.023298"/>
      </geometry>
    </collision>
    <collision name="cabinet6_drawer2_collision_6">
      <origin xyz="0.021031 0.0 -0.113735" rpy="0.0 -0.0 0.0"/>
      <geometry>
        <box size="0.491014 0.357644 0.016"/>
      </geometry>
    </collision>
    <collision name="cabinet6_drawer2_collision_3">
      <origin xyz="0.021031 -0.170562 -0.078968" rpy="0.0 -0.0 0.0"/>
      <geometry>
        <box size="0.491014 0.016 0.083496"/>
      </geometry>
    </collision>
  </link>
  <joint name="cabinet6_drawer2_handle_joint" type="fixed">
    <origin xyz="-0.26686237 -0.00397854 0.08541794" rpy="1.5707963267948966 -0.0 0.0"/>
    <parent link="cabinet6_drawer2"/>
    <child link="cabinet6_drawer2_handle"/>
  </joint>
  <link name="cabinet6_drawer2_handle">
    <collision name="cabinet6_drawer2_handle_collision_2">
      <origin xyz="0.0 0.0 0.0" rpy="0.0 -0.0 0.0"/>
      <geometry>
        <box size="0.013 0.013 0.173032"/>
      </geometry>
    </collision>
    <collision name="cabinet6_drawer2_handle_collision_0">
      <origin xyz="0.0164985 0.0 0.08" rpy="0.0 -0.0 0.0"/>
      <geometry>
        <box size="0.02 0.013 0.013"/>
      </geometry>
    </collision>
    <collision name="cabinet6_drawer2_handle_collision_1">
      <origin xyz="0.0164985 0.0 -0.08" rpy="0.0 -0.0 0.0"/>
      <geometry>
        <box size="0.02 0.013 0.013"/>
      </geometry>
    </collision>
  </link>
  <joint name="cabinet6_drawer3_joint" type="prismatic">
    <origin xyz="-0.05279761925339699 -0.0006945300265215337 -0.19690865278244019" rpy="0.0 -0.0 0.0"/>
    <axis xyz="-1 0 0"/>
    <parent link="cabinet6"/>
    <child link="cabinet6_drawer3"/>
    <limit effort="1000" lower="0.0" upper="0.44999998807907104" velocity="1000"/>
  </joint>
  <link name="cabinet6_drawer3">
    <collision name="cabinet6_drawer3_collision_6">
      <origin xyz="0.021031 0.0 -0.164582" rpy="0.0 -0.0 0.0"/>
      <geometry>
        <box size="0.491014 0.357644 0.016"/>
      </geometry>
    </collision>
    <collision name="cabinet6_drawer3_collision_4">
      <origin xyz="-0.233977 0.0 0.0" rpy="0.0 -0.0 0.0"/>
      <geometry>
        <box size="0.019 0.397734 0.395734"/>
      </geometry>
    </collision>
    <collision name="cabinet6_drawer3_collision_5">
      <origin xyz="0.260372 0.0 -0.088821" rpy="0.0 -0.0 0.0"/>
      <geometry>
        <box size="0.016 0.357644 0.16821"/>
      </geometry>
    </collision>
    <collision name="cabinet6_drawer3_collision_0">
      <origin xyz="0.021031 0.170562 -0.00926" rpy="0.0 -0.0 0.0"/>
      <geometry>
        <box size="0.491014 0.016 0.023276"/>
      </geometry>
    </collision>
    <collision name="cabinet6_drawer3_collision_3">
      <origin xyz="0.021031 -0.170562 -0.129424" rpy="0.0 -0.0 0.0"/>
      <geometry>
        <box size="0.491014 0.016 0.083422"/>
      </geometry>
    </collision>
    <collision name="cabinet6_drawer3_collision_2">
      <origin xyz="0.021031 0.170562 -0.129424" rpy="0.0 -0.0 0.0"/>
      <geometry>
        <box size="0.491014 0.016 0.083422"/>
      </geometry>
    </collision>
    <collision name="cabinet6_drawer3_collision_1">
      <origin xyz="0.021031 -0.170562 -0.00926" rpy="0.0 -0.0 0.0"/>
      <geometry>
        <box size="0.491014 0.016 0.023276"/>
      </geometry>
    </collision>
  </link>
  <joint name="cabinet6_drawer3_handle_joint" type="fixed">
    <origin xyz="-0.26712164 -0.00402777 0.15116583" rpy="1.5707963267948966 -0.0 0.0"/>
    <parent link="cabinet6_drawer3"/>
    <child link="cabinet6_drawer3_handle"/>
  </joint>
  <link name="cabinet6_drawer3_handle">
    <collision name="cabinet6_drawer3_handle_collision_0">
      <origin xyz="0.0164985 0.0 0.08" rpy="0.0 -0.0 0.0"/>
      <geometry>
        <box size="0.02 0.013 0.013"/>
      </geometry>
    </collision>
    <collision name="cabinet6_drawer3_handle_collision_1">
      <origin xyz="0.0164985 0.0 -0.08" rpy="0.0 -0.0 0.0"/>
      <geometry>
        <box size="0.02 0.013 0.013"/>
      </geometry>
    </collision>
    <collision name="cabinet6_drawer3_handle_collision_2">
      <origin xyz="0.0 0.0 0.0" rpy="0.0 -0.0 0.0"/>
      <geometry>
        <box size="0.013 0.013 0.173032"/>
      </geometry>
    </collision>
  </link>
  <joint name="island_cover4_joint" type="fixed">
    <origin xyz="0.27259209 3.79515656 0.44601677" rpy="0.0 -0.0 3.141592653589793"/>
    <parent link="kitchen1_root"/>
    <child link="island_cover4"/>
  </joint>
  <link name="island_cover4">
    <collision name="island_cover4_collision_0">
      <origin xyz="0.0 0.0 0.0" rpy="0.0 -0.0 0.0"/>
      <geometry>
        <box size="0.592148 0.019108 0.897013"/>
      </geometry>
    </collision>
  </link>
  <joint name="kitchen1_base_board_joint" type="fixed">
    <origin xyz="0.55976036 2.47825577 0.05168431" rpy="0.0 -0.0 3.141592653589793"/>
    <parent link="kitchen1_root"/>
    <child link="kitchen1_base_board"/>
  </joint>
  <link name="kitchen1_base_board">
    <collision name="kitchen1_base_board_collision_0">
      <origin xyz="0.0 0.0 0.0" rpy="0.0 -0.0 0.0"/>
      <geometry>
        <box size="0.019778 2.60316 0.1"/>
      </geometry>
    </collision>
  </link>
  <joint name="kitchen2_root_joint" type="fixed">
    <origin xyz="0.1 0.0 0.0" rpy="0.0 -0.0 0.0"/>
    <parent link="kitchen_root"/>
    <child link="kitchen2_root"/>
  </joint>
  <link name="kitchen2_root"/>
  <joint name="counter_sink_stove_joint" type="fixed">
    <origin xyz="2.65274353 2.70903961 0.46562927" rpy="0.0 -0.0 0.0"/>
    <parent link="kitchen2_root"/>
    <child link="counter_sink_stove"/>
  </joint>
  <link name="counter_sink_stove">
    <collision name="counter_sink_stove_collision_4">
      <origin xyz="0.0 -0.560551 0.453637" rpy="0.0 -0.0 0.0"/>
      <geometry>
        <box size="0.996 2.05608 0.03"/>
      </geometry>
    </collision>
    <collision name="counter_sink_stove_collision_0">
      <origin xyz="0.0 -1.5755 0.0" rpy="0.0 -0.0 0.0"/>
      <geometry>
        <box size="1.0 0.029 0.934462"/>
      </geometry>
    </collision>
    <collision name="counter_sink_stove_collision_1">
      <origin xyz="0.262968 0.0 0.453637" rpy="0.0 -0.0 0.0"/>
      <geometry>
        <box size="0.475062 3.17704 0.03"/>
      </geometry>
    </collision>
    <collision name="counter_sink_stove_collision_3">
      <origin xyz="0.0 1.22213 0.453637" rpy="0.0 -0.0 0.0"/>
      <geometry>
        <box size="0.996 0.735422 0.03"/>
      </geometry>
    </collision>
    <collision name="counter_sink_stove_collision_2">
      <origin xyz="-0.451058 0.0 0.453637" rpy="0.0 -0.0 0.0"/>
      <geometry>
        <box size="0.097634 3.17704 0.03"/>
      </geometry>
    </collision>
  </link>
  <joint name="stove_joint" type="fixed">
    <origin xyz="-0.15655746 -1.08145462 0.47160622" rpy="0.0 -0.0 0.0"/>
    <parent link="counter_sink_stove"/>
    <child link="stove"/>
  </joint>
  <link name="stove">
    <collision name="stove_collision_0">
      <origin xyz="0.0 0.0 0.0" rpy="0.0 -0.0 0.0"/>
      <geometry>
        <box size="0.516 0.795 0.004802"/>
      </geometry>
    </collision>
  </link>
  <joint name="counter_sink_joint" type="fixed">
    <origin xyz="-0.18887642 0.66553391 0.38240448" rpy="0.0 -0.0 0.0"/>
    <parent link="counter_sink_stove"/>
    <child link="counter_sink"/>
  </joint>
  <link name="counter_sink">
    <collision name="counter_sink_collision_2">
      <origin xyz="0.0 -0.192479 0.0" rpy="0.0 -0.0 0.0"/>
      <geometry>
        <box size="0.444618 0.02 0.177388"/>
      </geometry>
    </collision>
    <collision name="counter_sink_collision_4">
      <origin xyz="0.0 0.0 -0.074992" rpy="0.0 -0.0 0.0"/>
      <geometry>
        <box size="0.444618 0.404212 0.027402"/>
      </geometry>
    </collision>
    <collision name="counter_sink_collision_1">
      <origin xyz="-0.212477 0.0 0.0" rpy="0.0 -0.0 0.0"/>
      <geometry>
        <box size="0.02 0.404212 0.177388"/>
      </geometry>
    </collision>
    <collision name="counter_sink_collision_0">
      <origin xyz="0.18348 0.0 0.0" rpy="0.0 -0.0 0.0"/>
      <geometry>
        <box size="0.077992 0.404212 0.177388"/>
      </geometry>
    </collision>
    <collision name="counter_sink_collision_3">
      <origin xyz="0.0 0.192479 0.0" rpy="0.0 -0.0 0.0"/>
      <geometry>
        <box size="0.444618 0.02 0.177388"/>
      </geometry>
    </collision>
  </link>
  <joint name="counter_watertab_joint" type="fixed">
    <origin xyz="0.07677188 -0.01961838 0.2389875" rpy="0.0 -0.0 0.0"/>
    <parent link="counter_sink"/>
    <child link="counter_watertab"/>
  </joint>
  <link name="counter_watertab">
    <collision name="counter_watertab_collision_3">
      <origin xyz="0.113731 0.009 -0.073523" rpy="-1.5707963267948966 1.5707963267948963 0.0"/>
      <geometry>
        <cylinder radius="0.022466" length="0.08899"/>
      </geometry>
    </collision>
    <collision name="counter_watertab_collision_0">
      <origin xyz="0.113704 0.0195 -0.11162" rpy="0.0 -0.0 0.0"/>
      <geometry>
        <cylinder radius="0.022435" length="0.077478"/>
      </geometry>
    </collision>
    <collision name="counter_watertab_collision_2">
      <origin xyz="-0.116237 0.0195 0.121328" rpy="0.0 -0.0 0.0"/>
      <geometry>
        <cylinder radius="0.010966" length="0.007636"/>
      </geometry>
    </collision>
    <collision name="counter_watertab_collision_4">
      <origin xyz="0.113738 -0.035496 -0.073492" rpy="0.0 -0.0 0.0"/>
      <geometry>
        <sphere radius="0.018"/>
      </geometry>
    </collision>
    <collision name="counter_watertab_collision_1">
      <origin xyz="0.113704 0.0195 0.041404" rpy="0.0 -0.0 0.0"/>
      <geometry>
        <cylinder radius="0.014" length="0.21816"/>
      </geometry>
    </collision>
    <collision name="counter_watertab_collision_5">
      <origin xyz="-0.00425 0.019498 0.136485" rpy="1.5707963267948966 -0.0 1.5707963267948966"/>
      <geometry>
        <cylinder radius="0.014" length="0.263972"/>
      </geometry>
    </collision>
  </link>
  <joint name="counter_sink_tap_temperature_joint" type="revolute">
    <origin xyz="0.1137106865644455 -0.040552761405706406 -0.07370445132255554" rpy="0.0 -0.0 3.141592653589793"/>
    <axis xyz="0 -1 0"/>
    <parent link="counter_watertab"/>
    <child link="counter_sink_tap_switch"/>
    <limit effort="1000" lower="-1.5707963267948966" upper="1.5707963267948966" velocity="1000"/>
  </joint>
  <link name="counter_sink_tap_switch">
    <collision name="counter_sink_tap_switch_collision_0">
      <origin xyz="0.0 0.0 0.0" rpy="0.0 -0.0 0.0"/>
      <geometry>
        <box size="0.001 0.001 0.001"/>
      </geometry>
    </collision>
  </link>
  <joint name="counter_sink_switch_joint" type="revolute">
    <origin xyz="0.0 0.0 0.0" rpy="0.0 -0.0 0.0"/>
    <axis xyz="-1 0 0"/>
    <parent link="counter_sink_tap_switch"/>
    <child link="counter_sink_tap"/>
    <limit effort="1000" lower="0.0" upper="0.39269908169872414" velocity="1000"/>
  </joint>
  <link name="counter_sink_tap">
    <collision name="counter_sink_tap_collision_0">
      <origin xyz="0.0 0.007501 0.0" rpy="-1.5707963267948966 1.5707963267948963 0.0"/>
      <geometry>
        <cylinder radius="0.022432" length="0.024394"/>
      </geometry>
    </collision>
    <collision name="counter_sink_tap_collision_1">
      <origin xyz="0.0 0.012886 0.048989" rpy="0.0 -0.0 0.0"/>
      <geometry>
        <cylinder radius="0.005" length="0.055994"/>
      </geometry>
    </collision>
  </link>
  <joint name="dishwasher_joint" type="fixed">
    <origin xyz="2.32419296 3.96355377 0.16226444" rpy="0.0 -0.0 0.0"/>
    <parent link="kitchen2_root"/>
    <child link="dishwasher"/>
  </joint>
  <link name="dishwasher">
    <collision name="dishwasher_collision_0">
      <origin xyz="0.244142 0.291193 0.25785" rpy="0.0 -0.0 0.0"/>
      <geometry>
        <box size="0.395758 0.015448 0.841796"/>
      </geometry>
    </collision>
    <collision name="dishwasher_collision_1">
      <origin xyz="0.244142 -0.291193 0.25785" rpy="0.0 -0.0 0.0"/>
      <geometry>
        <box size="0.395758 0.015448 0.841796"/>
      </geometry>
    </collision>
    <collision name="dishwasher_collision_5">
      <origin xyz="0.183466 0.0 0.671998" rpy="0.0 -0.0 0.0"/>
      <geometry>
        <box size="0.516974 0.597834 0.013498"/>
      </geometry>
    </collision>
    <collision name="dishwasher_collision_3">
      <origin xyz="-0.018498 -0.291193 0.328806" rpy="0.0 -0.0 0.0"/>
      <geometry>
        <box size="0.129522 0.015448 0.703882"/>
      </geometry>
    </collision>
    <collision name="dishwasher_collision_6">
      <origin xyz="0.183466 0.0 -0.079608" rpy="0.0 -0.0 0.0"/>
      <geometry>
        <box size="0.516974 0.597834 0.167104"/>
      </geometry>
    </collision>
    <collision name="dishwasher_collision_2">
      <origin xyz="-0.018498 0.291193 0.328806" rpy="0.0 -0.0 0.0"/>
      <geometry>
        <box size="0.129522 0.015448 0.703882"/>
      </geometry>
    </collision>
    <collision name="dishwasher_collision_4">
      <origin xyz="0.439555 0.0 0.25785" rpy="0.0 -0.0 0.0"/>
      <geometry>
        <box size="0.004826 0.597834 0.841796"/>
      </geometry>
    </collision>
  </link>
  <joint name="dishwasher_front_joint" type="revolute">
    <origin xyz="-0.07612121105194092 0.00031149000278674066 0.007286449894309044" rpy="-1.5707963267948966 0.0 0.0"/>
    <axis xyz="0 0 -1"/>
    <parent link="dishwasher"/>
    <child link="dishwasher_front"/>
    <limit effort="1000" lower="0.0" upper="1.5707963267948966" velocity="1000"/>
  </joint>
  <link name="dishwasher_front">
    <collision name="dishwasher_front_collision_0">
      <origin xyz="-0.04 -0.329015 0.0" rpy="0.0 -0.0 0.0"/>
      <geometry>
        <box size="0.018888 0.794358 0.609974"/>
      </geometry>
    </collision>
    <collision name="dishwasher_front_collision_1">
      <origin xyz="-0.01 -0.334215 -0.015728" rpy="0.0 -0.0 0.0"/>
      <geometry>
        <box size="0.03 0.679206 0.574938"/>
      </geometry>
    </collision>
  </link>
  <joint name="dishwasher_front_handle_joint" type="fixed">
    <origin xyz="-0.07493519 -0.67884796 0.0" rpy="0.0 -0.0 0.0"/>
    <parent link="dishwasher_front"/>
    <child link="dishwasher_front_handle"/>
  </joint>
  <link name="dishwasher_front_handle">
    <collision name="dishwasher_front_handle_collision_2">
      <origin xyz="0.0 0.0 0.0" rpy="0.0 -0.0 0.0"/>
      <geometry>
        <box size="0.013 0.013 0.173032"/>
      </geometry>
    </collision>
    <collision name="dishwasher_front_handle_collision_1">
      <origin xyz="0.0164985 0.0 -0.08" rpy="0.0 -0.0 0.0"/>
      <geometry>
        <box size="0.02 0.013 0.013"/>
      </geometry>
    </collision>
    <collision name="dishwasher_front_handle_collision_0">
      <origin xyz="0.0164985 0.0 0.08" rpy="0.0 -0.0 0.0"/>
      <geometry>
        <box size="0.02 0.013 0.013"/>
      </geometry>
    </collision>
  </link>
  <joint name="dishwasher_tray1_joint" type="prismatic">
    <origin xyz="0.2240142673254013 0.007359260227531195 0.22713592648506165" rpy="0.0 -0.0 0.0"/>
    <axis xyz="-1 0 0"/>
    <parent link="dishwasher"/>
    <child link="dishwasher_tray1"/>
    <limit effort="1000" lower="0.0" upper="0.5" velocity="1000"/>
  </joint>
  <link name="dishwasher_tray1">
    <collision name="dishwasher_tray1_collision_2">
      <origin xyz="-0.03859 -0.255159 -0.035299" rpy="0.0 -0.0 0.0"/>
      <geometry>
        <box size="0.48427 0.010896 0.232972"/>
      </geometry>
    </collision>
    <collision name="dishwasher_tray1_collision_0">
      <origin xyz="-0.03859 0.0 -0.144673" rpy="0.0 -0.0 0.0"/>
      <geometry>
        <box size="0.48427 0.538406 0.014224"/>
      </geometry>
    </collision>
    <collision name="dishwasher_tray1_collision_3">
      <origin xyz="0.193489 0.0 -0.035299" rpy="0.0 -0.0 0.0"/>
      <geometry>
        <box size="0.008578 0.538406 0.232972"/>
      </geometry>
    </collision>
    <collision name="dishwasher_tray1_collision_1">
      <origin xyz="-0.03859 0.255159 -0.035299" rpy="0.0 -0.0 0.0"/>
      <geometry>
        <box size="0.48427 0.010896 0.232972"/>
      </geometry>
    </collision>
    <collision name="dishwasher_tray1_collision_4">
      <origin xyz="-0.280937 0.0 -0.035299" rpy="0.0 -0.0 0.0"/>
      <geometry>
        <box size="0.008578 0.538406 0.232972"/>
      </geometry>
    </collision>
  </link>
  <joint name="dishwasher_tray2_joint" type="prismatic">
    <origin xyz="0.20742002129554749 0.007357980124652386 0.40232783555984497" rpy="0.0 -0.0 0.0"/>
    <axis xyz="-1 0 0"/>
    <parent link="dishwasher"/>
    <child link="dishwasher_tray2"/>
    <limit effort="1000" lower="0.0" upper="0.30000001192092896" velocity="1000"/>
  </joint>
  <link name="dishwasher_tray2">
    <collision name="dishwasher_tray2_collision_2">
      <origin xyz="0.0 0.243352 0.023995" rpy="0.0 -0.0 0.0"/>
      <geometry>
        <box size="0.462628 0.017148 0.175624"/>
      </geometry>
    </collision>
    <collision name="dishwasher_tray2_collision_1">
      <origin xyz="0.0 -0.243352 0.023995" rpy="0.0 -0.0 0.0"/>
      <geometry>
        <box size="0.462628 0.017148 0.175624"/>
      </geometry>
    </collision>
    <collision name="dishwasher_tray2_collision_3">
      <origin xyz="-0.225859 0.0 0.023995" rpy="0.0 -0.0 0.0"/>
      <geometry>
        <box size="0.008364 0.47464 0.175624"/>
      </geometry>
    </collision>
    <collision name="dishwasher_tray2_collision_4">
      <origin xyz="0.225859 0.0 0.023995" rpy="0.0 -0.0 0.0"/>
      <geometry>
        <box size="0.008364 0.47464 0.175624"/>
      </geometry>
    </collision>
    <collision name="dishwasher_tray2_collision_0">
      <origin xyz="0.0 0.0 -0.051928" rpy="0.0 -0.0 0.0"/>
      <geometry>
        <box size="0.462628 0.47464 0.027588"/>
      </geometry>
    </collision>
  </link>
  <joint name="dishwasher_tray3_joint" type="prismatic">
    <origin xyz="0.2278721183538437 0.013125250115990639 0.61131352186203" rpy="0.0 -0.0 0.0"/>
    <axis xyz="-1 0 0"/>
    <parent link="dishwasher"/>
    <child link="dishwasher_tray3"/>
    <limit effort="1000" lower="0.0" upper="0.30000001192092896" velocity="1000"/>
  </joint>
  <link name="dishwasher_tray3">
    <collision name="dishwasher_tray3_collision_0">
      <origin xyz="0.0 0.0 0.0" rpy="0.0 -0.0 0.0"/>
      <geometry>
        <box size="0.44 0.54 0.072"/>
      </geometry>
    </collision>
  </link>
  <joint name="cabinet8_joint" type="fixed">
    <origin xyz="2.49268082 3.37232117 0.49448143" rpy="0.0 -0.0 0.0"/>
    <parent link="kitchen2_root"/>
    <child link="cabinet8"/>
  </joint>
  <link name="cabinet8">
    <collision name="cabinet8_collision_1">
      <origin xyz="0.0 -0.291912 0.0" rpy="0.0 -0.0 0.0"/>
      <geometry>
        <box size="0.55405 0.015884 0.79779"/>
      </geometry>
    </collision>
    <collision name="cabinet8_collision_4">
      <origin xyz="0.0 0.0 -0.391005" rpy="0.0 -0.0 0.0"/>
      <geometry>
        <box size="0.55405 0.568134 0.016"/>
      </geometry>
    </collision>
    <collision name="cabinet8_collision_3">
      <origin xyz="0.217476 0.0 0.39091" rpy="0.0 -0.0 0.0"/>
      <geometry>
        <box size="0.08 0.568134 0.016"/>
      </geometry>
    </collision>
    <collision name="cabinet8_collision_2">
      <origin xyz="0.26153 0.0 0.0" rpy="0.0 -0.0 0.0"/>
      <geometry>
        <box size="0.007888 0.568134 0.765818"/>
      </geometry>
    </collision>
    <collision name="cabinet8_collision_0">
      <origin xyz="0.0 0.291912 0.0" rpy="0.0 -0.0 0.0"/>
      <geometry>
        <box size="0.55405 0.015884 0.79779"/>
      </geometry>
    </collision>
  </link>
  <joint name="sink_drawer1_joint" type="prismatic">
    <origin xyz="-0.05086623877286911 0.00013534999743569642 0.0031999999191612005" rpy="0.0 -0.0 0.0"/>
    <axis xyz="-1 0 0"/>
    <parent link="cabinet8"/>
    <child link="sink_drawer1"/>
    <limit effort="1000" lower="0.0" upper="0.44999998807907104" velocity="1000"/>
  </joint>
  <link name="sink_drawer1">
    <collision name="sink_drawer1_collision_3">
      <origin xyz="0.025012 0.268047 -0.08949" rpy="0.0 -0.0 0.0"/>
      <geometry>
        <box size="0.498056 0.015 0.084"/>
      </geometry>
    </collision>
    <collision name="sink_drawer1_collision_18">
      <origin xyz="0.086505 -0.211412 -0.198155" rpy="0.0 -0.0 0.0"/>
      <geometry>
        <box size="0.149578 0.016852 0.34661"/>
      </geometry>
    </collision>
    <collision name="sink_drawer1_collision_10">
      <origin xyz="-0.213959 0.0 -0.04" rpy="0.0 -0.0 0.0"/>
      <geometry>
        <box size="0.021008 0.554092 0.016"/>
      </geometry>
    </collision>
    <collision name="sink_drawer1_collision_7">
      <origin xyz="0.025012 0.268047 -0.33085" rpy="0.0 -0.0 0.0"/>
      <geometry>
        <box size="0.498056 0.015 0.087218"/>
      </geometry>
    </collision>
    <collision name="sink_drawer1_collision_17">
      <origin xyz="0.086505 -0.00535 -0.198155" rpy="0.0 -0.0 0.0"/>
      <geometry>
        <box size="0.149578 0.016852 0.34661"/>
      </geometry>
    </collision>
    <collision name="sink_drawer1_collision_20">
      <origin xyz="0.02 -0.109826 -0.198155" rpy="0.0 -0.0 0.0"/>
      <geometry>
        <box size="0.016852 0.219652 0.34661"/>
      </geometry>
    </collision>
    <collision name="sink_drawer1_collision_11">
      <origin xyz="0.21583 0.0 -0.04" rpy="0.0 -0.0 0.0"/>
      <geometry>
        <box size="0.117306 0.554092 0.016"/>
      </geometry>
    </collision>
    <collision name="sink_drawer1_collision_15">
      <origin xyz="0.02 0.109826 -0.198155" rpy="0.0 -0.0 0.0"/>
      <geometry>
        <box size="0.016712 0.219652 0.34661"/>
      </geometry>
    </collision>
    <collision name="sink_drawer1_collision_28">
      <origin xyz="-0.098209 0.071323 -0.198155" rpy="0.0 -0.0 0.0"/>
      <geometry>
        <box size="0.219458 0.016852 0.34661"/>
      </geometry>
    </collision>
    <collision name="sink_drawer1_collision_29">
      <origin xyz="0.003041 -0.075302 -0.198155" rpy="0.0 -0.0 0.0"/>
      <geometry>
        <box size="0.016852 0.309498 0.34661"/>
      </geometry>
    </collision>
    <collision name="sink_drawer1_collision_24">
      <origin xyz="0.003041 0.155 -0.198155" rpy="0.0 -0.0 0.0"/>
      <geometry>
        <box size="0.016852 0.149382 0.34661"/>
      </geometry>
    </collision>
    <collision name="sink_drawer1_collision_23">
      <origin xyz="-0.098209 0.088435 -0.198155" rpy="0.0 -0.0 0.0"/>
      <geometry>
        <box size="0.219458 0.016852 0.34661"/>
      </geometry>
    </collision>
    <collision name="sink_drawer1_collision_13">
      <origin xyz="0.086505 0.211412 -0.198155" rpy="0.0 -0.0 0.0"/>
      <geometry>
        <box size="0.149578 0.016852 0.34661"/>
      </geometry>
    </collision>
    <collision name="sink_drawer1_collision_21">
      <origin xyz="0.086505 -0.109826 -0.372315" rpy="0.0 -0.0 0.0"/>
      <geometry>
        <box size="0.149578 0.219652 0.0017"/>
      </geometry>
    </collision>
    <collision name="sink_drawer1_collision_16">
      <origin xyz="0.086505 0.109826 -0.372315" rpy="0.0 -0.0 0.0"/>
      <geometry>
        <box size="0.149578 0.219652 0.0017"/>
      </geometry>
    </collision>
    <collision name="sink_drawer1_collision_2">
      <origin xyz="0.025012 -0.268047 -0.08949" rpy="0.0 -0.0 0.0"/>
      <geometry>
        <box size="0.498056 0.015 0.084"/>
      </geometry>
    </collision>
    <collision name="sink_drawer1_collision_12">
      <origin xyz="0.086505 0.00535 -0.198155" rpy="0.0 -0.0 0.0"/>
      <geometry>
        <box size="0.149578 0.016852 0.34661"/>
      </geometry>
    </collision>
    <collision name="sink_drawer1_collision_27">
      <origin xyz="-0.098209 -0.221355 -0.198155" rpy="0.0 -0.0 0.0"/>
      <geometry>
        <box size="0.219458 0.016852 0.34661"/>
      </geometry>
    </collision>
    <collision name="sink_drawer1_collision_0">
      <origin xyz="-0.233976 0.0 0.0" rpy="0.0 -0.0 0.0"/>
      <geometry>
        <box size="0.018776 0.596516 0.794026"/>
      </geometry>
    </collision>
    <collision name="sink_drawer1_collision_25">
      <origin xyz="-0.199821 0.155 -0.198155" rpy="0.0 -0.0 0.0"/>
      <geometry>
        <box size="0.016852 0.149382 0.34661"/>
      </geometry>
    </collision>
    <collision name="sink_drawer1_collision_26">
      <origin xyz="-0.098209 0.155 -0.372315" rpy="0.0 -0.0 0.0"/>
      <geometry>
        <box size="0.219458 0.149382 0.0017"/>
      </geometry>
    </collision>
    <collision name="sink_drawer1_collision_19">
      <origin xyz="0.152938 -0.109826 -0.198155" rpy="0.0 -0.0 0.0"/>
      <geometry>
        <box size="0.016852 0.219652 0.34661"/>
      </geometry>
    </collision>
    <collision name="sink_drawer1_collision_4">
      <origin xyz="0.025012 -0.268047 -0.208727" rpy="0.0 -0.0 0.0"/>
      <geometry>
        <box size="0.498056 0.015 0.023296"/>
      </geometry>
    </collision>
    <collision name="sink_drawer1_collision_31">
      <origin xyz="-0.098209 -0.075302 -0.372315" rpy="0.0 -0.0 0.0"/>
      <geometry>
        <box size="0.219458 0.309498 0.0017"/>
      </geometry>
    </collision>
    <collision name="sink_drawer1_collision_30">
      <origin xyz="-0.199821 -0.075302 -0.198155" rpy="0.0 -0.0 0.0"/>
      <geometry>
        <box size="0.016852 0.309498 0.34661"/>
      </geometry>
    </collision>
    <collision name="sink_drawer1_collision_8">
      <origin xyz="0.025012 -0.246033 -0.04" rpy="0.0 -0.0 0.0"/>
      <geometry>
        <box size="0.498056 0.062024 0.016"/>
      </geometry>
    </collision>
    <collision name="sink_drawer1_collision_5">
      <origin xyz="0.025012 0.268047 -0.208727" rpy="0.0 -0.0 0.0"/>
      <geometry>
        <box size="0.498056 0.015 0.023296"/>
      </geometry>
    </collision>
    <collision name="sink_drawer1_collision_22">
      <origin xyz="-0.098209 0.221355 -0.198155" rpy="0.0 -0.0 0.0"/>
      <geometry>
        <box size="0.219458 0.016852 0.34661"/>
      </geometry>
    </collision>
    <collision name="sink_drawer1_collision_9">
      <origin xyz="0.025012 0.246033 -0.04" rpy="0.0 -0.0 0.0"/>
      <geometry>
        <box size="0.498056 0.062024 0.016"/>
      </geometry>
    </collision>
    <collision name="sink_drawer1_collision_6">
      <origin xyz="0.025012 -0.268047 -0.33085" rpy="0.0 -0.0 0.0"/>
      <geometry>
        <box size="0.498056 0.015 0.087218"/>
      </geometry>
    </collision>
    <collision name="sink_drawer1_collision_1">
      <origin xyz="0.259483 0.0 -0.288887" rpy="0.0 -0.0 0.0"/>
      <geometry>
        <box size="0.018034 0.539508 0.169484"/>
      </geometry>
    </collision>
    <collision name="sink_drawer1_collision_14">
      <origin xyz="0.152938 0.109826 -0.198155" rpy="0.0 -0.0 0.0"/>
      <geometry>
        <box size="0.016712 0.219652 0.34661"/>
      </geometry>
    </collision>
  </link>
  <joint name="sink_drawer1_handle_joint" type="fixed">
    <origin xyz="-0.26900223 0.00331339 0.35071747" rpy="1.5707963267948966 -0.0 0.0"/>
    <parent link="sink_drawer1"/>
    <child link="sink_drawer1_handle"/>
  </joint>
  <link name="sink_drawer1_handle">
    <collision name="sink_drawer1_handle_collision_0">
      <origin xyz="0.0164985 0.0 0.08" rpy="0.0 -0.0 0.0"/>
      <geometry>
        <box size="0.02 0.013 0.013"/>
      </geometry>
    </collision>
    <collision name="sink_drawer1_handle_collision_1">
      <origin xyz="0.0164985 0.0 -0.08" rpy="0.0 -0.0 0.0"/>
      <geometry>
        <box size="0.02 0.013 0.013"/>
      </geometry>
    </collision>
    <collision name="sink_drawer1_handle_collision_2">
      <origin xyz="0.0 0.0 0.0" rpy="0.0 -0.0 0.0"/>
      <geometry>
        <box size="0.013 0.013 0.173032"/>
      </geometry>
    </collision>
  </link>
  <joint name="sink_drawer2_joint" type="prismatic">
    <origin xyz="-0.07299484312534332 0.0014234399423003197 0.1643771380186081" rpy="0.0 -0.0 0.0"/>
    <axis xyz="-1 0 0"/>
    <parent link="cabinet8"/>
    <child link="sink_drawer2"/>
    <limit effort="1000" lower="0.0" upper="0.30000001192092896" velocity="1000"/>
  </joint>
  <link name="sink_drawer2">
    <collision name="sink_drawer2_collision_6">
      <origin xyz="0.002535 0.0 -0.036496" rpy="0.0 -0.0 0.0"/>
      <geometry>
        <box size="0.376026 0.557356 0.016"/>
      </geometry>
    </collision>
    <collision name="sink_drawer2_collision_4">
      <origin xyz="-0.191981 0.0 -0.0015" rpy="0.0 -0.0 0.0"/>
      <geometry>
        <box size="0.017 0.433954 0.098"/>
      </geometry>
    </collision>
    <collision name="sink_drawer2_collision_3">
      <origin xyz="-0.191981 -0.248473 0.000834" rpy="0.0 -0.0 0.0"/>
      <geometry>
        <box size="0.017 0.064994 0.099322"/>
      </geometry>
    </collision>
    <collision name="sink_drawer2_collision_5">
      <origin xyz="0.184382 0.0 -0.0024" rpy="0.0 -0.0 0.0"/>
      <geometry>
        <box size="0.016 0.557356 0.083"/>
      </geometry>
    </collision>
    <collision name="sink_drawer2_collision_2">
      <origin xyz="-0.191981 0.248473 0.000834" rpy="0.0 -0.0 0.0"/>
      <geometry>
        <box size="0.017 0.064994 0.099322"/>
      </geometry>
    </collision>
    <collision name="sink_drawer2_collision_0">
      <origin xyz="0.002535 0.270604 -0.000733" rpy="0.0 -0.0 0.0"/>
      <geometry>
        <box size="0.376026 0.016 0.08221"/>
      </geometry>
    </collision>
    <collision name="sink_drawer2_collision_1">
      <origin xyz="0.002535 -0.270604 -0.000733" rpy="0.0 -0.0 0.0"/>
      <geometry>
        <box size="0.376026 0.016 0.08221"/>
      </geometry>
    </collision>
  </link>
  <joint name="cabinet9_joint" type="fixed">
    <origin xyz="2.49288239 2.77268799 0.49406776" rpy="0.0 -0.0 0.0"/>
    <parent link="kitchen2_root"/>
    <child link="cabinet9"/>
  </joint>
  <link name="cabinet9">
    <collision name="cabinet9_collision_3">
      <origin xyz="0.217476 0.0 0.39091" rpy="0.0 -0.0 0.0"/>
      <geometry>
        <box size="0.08 0.568134 0.016"/>
      </geometry>
    </collision>
    <collision name="cabinet9_collision_1">
      <origin xyz="0.0 -0.291912 0.0" rpy="0.0 -0.0 0.0"/>
      <geometry>
        <box size="0.55405 0.015884 0.79779"/>
      </geometry>
    </collision>
    <collision name="cabinet9_collision_0">
      <origin xyz="0.0 0.291912 0.0" rpy="0.0 -0.0 0.0"/>
      <geometry>
        <box size="0.55405 0.015884 0.79779"/>
      </geometry>
    </collision>
    <collision name="cabinet9_collision_2">
      <origin xyz="0.26153 0.0 0.0" rpy="0.0 -0.0 0.0"/>
      <geometry>
        <box size="0.007888 0.568134 0.765818"/>
      </geometry>
    </collision>
    <collision name="cabinet9_collision_4">
      <origin xyz="0.0 0.0 -0.391005" rpy="0.0 -0.0 0.0"/>
      <geometry>
        <box size="0.55405 0.568134 0.016"/>
      </geometry>
    </collision>
  </link>
  <joint name="cabinet9_drawer1_joint" type="prismatic">
    <origin xyz="-0.050795890390872955 -0.001753640011884272 0.33208441734313965" rpy="0.0 -0.0 0.0"/>
    <axis xyz="-1 0 0"/>
    <parent link="cabinet9"/>
    <child link="cabinet9_drawer1"/>
    <limit effort="1000" lower="0.0" upper="0.44999998807907104" velocity="1000"/>
  </joint>
  <link name="cabinet9_drawer1">
    <collision name="cabinet9_drawer1_collision_2">
      <origin xyz="-0.233977 0.0 0.0" rpy="0.0 -0.0 0.0"/>
      <geometry>
        <box size="0.019 0.596936 0.129986"/>
      </geometry>
    </collision>
    <collision name="cabinet9_drawer1_collision_4">
      <origin xyz="0.021031 0.0 -0.047595" rpy="0.0 -0.0 0.0"/>
      <geometry>
        <box size="0.491014 0.539608 0.015"/>
      </geometry>
    </collision>
    <collision name="cabinet9_drawer1_collision_1">
      <origin xyz="0.021031 -0.270267 -0.01336" rpy="0.0 -0.0 0.0"/>
      <geometry>
        <box size="0.491014 0.016 0.085266"/>
      </geometry>
    </collision>
    <collision name="cabinet9_drawer1_collision_0">
      <origin xyz="0.021031 0.270267 -0.01336" rpy="0.0 -0.0 0.0"/>
      <geometry>
        <box size="0.491014 0.016 0.085266"/>
      </geometry>
    </collision>
    <collision name="cabinet9_drawer1_collision_3">
      <origin xyz="0.260372 0.0 -0.01336" rpy="0.0 -0.0 0.0"/>
      <geometry>
        <box size="0.016 0.539608 0.085266"/>
      </geometry>
    </collision>
  </link>
  <joint name="cabinet9_drawer1_handle_joint" type="fixed">
    <origin xyz="-0.26980946 0.00142363 0.01676949" rpy="1.5707963267948966 -0.0 0.0"/>
    <parent link="cabinet9_drawer1"/>
    <child link="cabinet9_drawer1_handle"/>
  </joint>
  <link name="cabinet9_drawer1_handle">
    <collision name="cabinet9_drawer1_handle_collision_0">
      <origin xyz="0.0164985 0.0 0.08" rpy="0.0 -0.0 0.0"/>
      <geometry>
        <box size="0.02 0.013 0.013"/>
      </geometry>
    </collision>
    <collision name="cabinet9_drawer1_handle_collision_2">
      <origin xyz="0.0 0.0 0.0" rpy="0.0 -0.0 0.0"/>
      <geometry>
        <box size="0.013 0.013 0.173032"/>
      </geometry>
    </collision>
    <collision name="cabinet9_drawer1_handle_collision_1">
      <origin xyz="0.0164985 0.0 -0.08" rpy="0.0 -0.0 0.0"/>
      <geometry>
        <box size="0.02 0.013 0.013"/>
      </geometry>
    </collision>
  </link>
  <joint name="cabinet9_drawer2_joint" type="prismatic">
    <origin xyz="-0.050753019750118256 -0.0006519600283354521 0.13494464755058289" rpy="0.0 -0.0 0.0"/>
    <axis xyz="-1 0 0"/>
    <parent link="cabinet9"/>
    <child link="cabinet9_drawer2"/>
    <limit effort="1000" lower="0.0" upper="0.44999998807907104" velocity="1000"/>
  </joint>
  <link name="cabinet9_drawer2">
    <collision name="cabinet9_drawer2_collision_4">
      <origin xyz="-0.233977 0.0 0.0" rpy="0.0 -0.0 0.0"/>
      <geometry>
        <box size="0.019 0.596936 0.26275"/>
      </geometry>
    </collision>
    <collision name="cabinet9_drawer2_collision_1">
      <origin xyz="0.021031 -0.270267 0.041246" rpy="0.0 -0.0 0.0"/>
      <geometry>
        <box size="0.491014 0.016 0.023298"/>
      </geometry>
    </collision>
    <collision name="cabinet9_drawer2_collision_6">
      <origin xyz="0.021031 0.0 -0.113735" rpy="0.0 -0.0 0.0"/>
      <geometry>
        <box size="0.491014 0.539608 0.016"/>
      </geometry>
    </collision>
    <collision name="cabinet9_drawer2_collision_2">
      <origin xyz="0.021031 0.270267 -0.078968" rpy="0.0 -0.0 0.0"/>
      <geometry>
        <box size="0.491014 0.016 0.083496"/>
      </geometry>
    </collision>
    <collision name="cabinet9_drawer2_collision_0">
      <origin xyz="0.021031 0.270267 0.041246" rpy="0.0 -0.0 0.0"/>
      <geometry>
        <box size="0.491014 0.016 0.023298"/>
      </geometry>
    </collision>
    <collision name="cabinet9_drawer2_collision_3">
      <origin xyz="0.021031 -0.270267 -0.078968" rpy="0.0 -0.0 0.0"/>
      <geometry>
        <box size="0.491014 0.016 0.083496"/>
      </geometry>
    </collision>
    <collision name="cabinet9_drawer2_collision_5">
      <origin xyz="0.260372 0.0 -0.037996" rpy="0.0 -0.0 0.0"/>
      <geometry>
        <box size="0.016 0.539608 0.168982"/>
      </geometry>
    </collision>
  </link>
  <joint name="cabinet9_drawer2_handle_joint" type="fixed">
    <origin xyz="-0.2707106 0.00106413 0.08500843" rpy="1.5707963267948966 -0.0 0.0"/>
    <parent link="cabinet9_drawer2"/>
    <child link="cabinet9_drawer2_handle"/>
  </joint>
  <link name="cabinet9_drawer2_handle">
    <collision name="cabinet9_drawer2_handle_collision_2">
      <origin xyz="0.0 0.0 0.0" rpy="0.0 -0.0 0.0"/>
      <geometry>
        <box size="0.013 0.013 0.173032"/>
      </geometry>
    </collision>
    <collision name="cabinet9_drawer2_handle_collision_0">
      <origin xyz="0.0164985 0.0 0.08" rpy="0.0 -0.0 0.0"/>
      <geometry>
        <box size="0.02 0.013 0.013"/>
      </geometry>
    </collision>
    <collision name="cabinet9_drawer2_handle_collision_1">
      <origin xyz="0.0164985 0.0 -0.08" rpy="0.0 -0.0 0.0"/>
      <geometry>
        <box size="0.02 0.013 0.013"/>
      </geometry>
    </collision>
  </link>
  <joint name="cabinet9_drawer3_joint" type="prismatic">
    <origin xyz="-0.05045225843787193 -0.0016706299502402544 -0.19611331820487976" rpy="0.0 -0.0 0.0"/>
    <axis xyz="-1 0 0"/>
    <parent link="cabinet9"/>
    <child link="cabinet9_drawer3"/>
    <limit effort="1000" lower="0.0" upper="0.44999998807907104" velocity="1000"/>
  </joint>
  <link name="cabinet9_drawer3">
    <collision name="cabinet9_drawer3_collision_0">
      <origin xyz="0.021031 0.270267 -0.00926" rpy="0.0 -0.0 0.0"/>
      <geometry>
        <box size="0.491014 0.016 0.023276"/>
      </geometry>
    </collision>
    <collision name="cabinet9_drawer3_collision_2">
      <origin xyz="0.021031 0.270267 -0.129424" rpy="0.0 -0.0 0.0"/>
      <geometry>
        <box size="0.491014 0.016 0.083422"/>
      </geometry>
    </collision>
    <collision name="cabinet9_drawer3_collision_6">
      <origin xyz="0.021031 0.0 -0.164582" rpy="0.0 -0.0 0.0"/>
      <geometry>
        <box size="0.491014 0.539608 0.016"/>
      </geometry>
    </collision>
    <collision name="cabinet9_drawer3_collision_5">
      <origin xyz="0.260372 0.0 -0.088821" rpy="0.0 -0.0 0.0"/>
      <geometry>
        <box size="0.016 0.539608 0.16821"/>
      </geometry>
    </collision>
    <collision name="cabinet9_drawer3_collision_4">
      <origin xyz="-0.233977 0.0 0.0" rpy="0.0 -0.0 0.0"/>
      <geometry>
        <box size="0.019 0.596936 0.395734"/>
      </geometry>
    </collision>
    <collision name="cabinet9_drawer3_collision_1">
      <origin xyz="0.021031 -0.270267 -0.00926" rpy="0.0 -0.0 0.0"/>
      <geometry>
        <box size="0.491014 0.016 0.023276"/>
      </geometry>
    </collision>
    <collision name="cabinet9_drawer3_collision_3">
      <origin xyz="0.021031 -0.270267 -0.129424" rpy="0.0 -0.0 0.0"/>
      <geometry>
        <box size="0.491014 0.016 0.083422"/>
      </geometry>
    </collision>
  </link>
  <joint name="cabinet9_drawer3_handle_joint" type="fixed">
    <origin xyz="-0.26888186 0.00102875 0.15027037" rpy="1.5707963267948966 -0.0 0.0"/>
    <parent link="cabinet9_drawer3"/>
    <child link="cabinet9_drawer3_handle"/>
  </joint>
  <link name="cabinet9_drawer3_handle">
    <collision name="cabinet9_drawer3_handle_collision_0">
      <origin xyz="0.0164985 0.0 0.08" rpy="0.0 -0.0 0.0"/>
      <geometry>
        <box size="0.02 0.013 0.013"/>
      </geometry>
    </collision>
    <collision name="cabinet9_drawer3_handle_collision_1">
      <origin xyz="0.0164985 0.0 -0.08" rpy="0.0 -0.0 0.0"/>
      <geometry>
        <box size="0.02 0.013 0.013"/>
      </geometry>
    </collision>
    <collision name="cabinet9_drawer3_handle_collision_2">
      <origin xyz="0.0 0.0 0.0" rpy="0.0 -0.0 0.0"/>
      <geometry>
        <box size="0.013 0.013 0.173032"/>
      </geometry>
    </collision>
  </link>
  <joint name="cabinet10_joint" type="fixed">
    <origin xyz="2.49299103 2.2719194 0.5011195" rpy="0.0 -0.0 0.0"/>
    <parent link="kitchen2_root"/>
    <child link="cabinet10"/>
  </joint>
  <link name="cabinet10">
    <collision name="cabinet10_collision_4">
      <origin xyz="0.261473 0.0 0.0" rpy="0.0 -0.0 0.0"/>
      <geometry>
        <box size="0.008 0.369666 0.76582"/>
      </geometry>
    </collision>
    <collision name="cabinet10_collision_1">
      <origin xyz="0.0 -0.191779 0.0" rpy="0.0 -0.0 0.0"/>
      <geometry>
        <box size="0.55452 0.016 0.798012"/>
      </geometry>
    </collision>
    <collision name="cabinet10_collision_0">
      <origin xyz="0.0 0.191779 0.0" rpy="0.0 -0.0 0.0"/>
      <geometry>
        <box size="0.55452 0.016 0.798012"/>
      </geometry>
    </collision>
    <collision name="cabinet10_collision_3">
      <origin xyz="0.217476 0.0 0.390909" rpy="0.0 -0.0 0.0"/>
      <geometry>
        <box size="0.08 0.369666 0.016"/>
      </geometry>
    </collision>
    <collision name="cabinet10_collision_2">
      <origin xyz="0.0 0.0 -0.391006" rpy="0.0 -0.0 0.0"/>
      <geometry>
        <box size="0.55452 0.369666 0.016"/>
      </geometry>
    </collision>
  </link>
  <joint name="cabinet10_drawer1_joint" type="prismatic">
    <origin xyz="-0.05095718055963516 0.0006245899712666869 0.32565242052078247" rpy="0.0 -0.0 0.0"/>
    <axis xyz="-1 0 0"/>
    <parent link="cabinet10"/>
    <child link="cabinet10_drawer1"/>
    <limit effort="1000" lower="0.0" upper="0.44999998807907104" velocity="1000"/>
  </joint>
  <link name="cabinet10_drawer1">
    <collision name="cabinet10_drawer1_collision_0">
      <origin xyz="0.021031 0.170562 -0.01336" rpy="0.0 -0.0 0.0"/>
      <geometry>
        <box size="0.491014 0.016 0.085266"/>
      </geometry>
    </collision>
    <collision name="cabinet10_drawer1_collision_4">
      <origin xyz="0.021031 0.0 -0.047595" rpy="0.0 -0.0 0.0"/>
      <geometry>
        <box size="0.491014 0.357644 0.015"/>
      </geometry>
    </collision>
    <collision name="cabinet10_drawer1_collision_3">
      <origin xyz="0.260372 0.0 -0.01336" rpy="0.0 -0.0 0.0"/>
      <geometry>
        <box size="0.016 0.357644 0.085266"/>
      </geometry>
    </collision>
    <collision name="cabinet10_drawer1_collision_2">
      <origin xyz="-0.233977 0.0 0.0" rpy="0.0 -0.0 0.0"/>
      <geometry>
        <box size="0.019 0.397734 0.129986"/>
      </geometry>
    </collision>
    <collision name="cabinet10_drawer1_collision_1">
      <origin xyz="0.021031 -0.170562 -0.01336" rpy="0.0 -0.0 0.0"/>
      <geometry>
        <box size="0.491014 0.016 0.085266"/>
      </geometry>
    </collision>
  </link>
  <joint name="cabinet10_drawer1_handle_joint" type="fixed">
    <origin xyz="-0.26662336 -0.00124599 0.0172039" rpy="1.5707963267948966 -0.0 0.0"/>
    <parent link="cabinet10_drawer1"/>
    <child link="cabinet10_drawer1_handle"/>
  </joint>
  <link name="cabinet10_drawer1_handle">
    <collision name="cabinet10_drawer1_handle_collision_0">
      <origin xyz="0.0164985 0.0 0.08" rpy="0.0 -0.0 0.0"/>
      <geometry>
        <box size="0.02 0.013 0.013"/>
      </geometry>
    </collision>
    <collision name="cabinet10_drawer1_handle_collision_1">
      <origin xyz="0.0164985 0.0 -0.08" rpy="0.0 -0.0 0.0"/>
      <geometry>
        <box size="0.02 0.013 0.013"/>
      </geometry>
    </collision>
    <collision name="cabinet10_drawer1_handle_collision_2">
      <origin xyz="0.0 0.0 0.0" rpy="0.0 -0.0 0.0"/>
      <geometry>
        <box size="0.013 0.013 0.173032"/>
      </geometry>
    </collision>
  </link>
  <joint name="cabinet10_drawer2_joint" type="prismatic">
    <origin xyz="-0.05071379989385605 -6.861000292701647e-05 0.1280520260334015" rpy="0.0 -0.0 0.0"/>
    <axis xyz="-1 0 0"/>
    <parent link="cabinet10"/>
    <child link="cabinet10_drawer2"/>
    <limit effort="1000" lower="0.0" upper="0.44999998807907104" velocity="1000"/>
  </joint>
  <link name="cabinet10_drawer2">
    <collision name="cabinet10_drawer2_collision_1">
      <origin xyz="0.021031 -0.170562 0.041246" rpy="0.0 -0.0 0.0"/>
      <geometry>
        <box size="0.491014 0.016 0.023298"/>
      </geometry>
    </collision>
    <collision name="cabinet10_drawer2_collision_6">
      <origin xyz="0.021031 0.0 -0.113735" rpy="0.0 -0.0 0.0"/>
      <geometry>
        <box size="0.491014 0.357644 0.016"/>
      </geometry>
    </collision>
    <collision name="cabinet10_drawer2_collision_0">
      <origin xyz="0.021031 0.170562 0.041246" rpy="0.0 -0.0 0.0"/>
      <geometry>
        <box size="0.491014 0.016 0.023298"/>
      </geometry>
    </collision>
    <collision name="cabinet10_drawer2_collision_5">
      <origin xyz="0.260372 0.0 -0.037996" rpy="0.0 -0.0 0.0"/>
      <geometry>
        <box size="0.016 0.357644 0.168982"/>
      </geometry>
    </collision>
    <collision name="cabinet10_drawer2_collision_4">
      <origin xyz="-0.233977 0.0 0.0" rpy="0.0 -0.0 0.0"/>
      <geometry>
        <box size="0.019 0.397734 0.26275"/>
      </geometry>
    </collision>
    <collision name="cabinet10_drawer2_collision_3">
      <origin xyz="0.021031 -0.170562 -0.078968" rpy="0.0 -0.0 0.0"/>
      <geometry>
        <box size="0.491014 0.016 0.083496"/>
      </geometry>
    </collision>
    <collision name="cabinet10_drawer2_collision_2">
      <origin xyz="0.021031 0.170562 -0.078968" rpy="0.0 -0.0 0.0"/>
      <geometry>
        <box size="0.491014 0.016 0.083496"/>
      </geometry>
    </collision>
  </link>
  <joint name="cabinet10_drawer2_handle_joint" type="fixed">
    <origin xyz="-0.26686237 -0.00397854 0.08541794" rpy="1.5707963267948966 -0.0 0.0"/>
    <parent link="cabinet10_drawer2"/>
    <child link="cabinet10_drawer2_handle"/>
  </joint>
  <link name="cabinet10_drawer2_handle">
    <collision name="cabinet10_drawer2_handle_collision_0">
      <origin xyz="0.0164985 0.0 0.08" rpy="0.0 -0.0 0.0"/>
      <geometry>
        <box size="0.02 0.013 0.013"/>
      </geometry>
    </collision>
    <collision name="cabinet10_drawer2_handle_collision_2">
      <origin xyz="0.0 0.0 0.0" rpy="0.0 -0.0 0.0"/>
      <geometry>
        <box size="0.013 0.013 0.173032"/>
      </geometry>
    </collision>
    <collision name="cabinet10_drawer2_handle_collision_1">
      <origin xyz="0.0164985 0.0 -0.08" rpy="0.0 -0.0 0.0"/>
      <geometry>
        <box size="0.02 0.013 0.013"/>
      </geometry>
    </collision>
  </link>
  <joint name="cabinet10_drawer3_joint" type="prismatic">
    <origin xyz="-0.05040312930941582 -0.00036920999991707504 -0.20396724343299866" rpy="0.0 -0.0 0.0"/>
    <axis xyz="-1 0 0"/>
    <parent link="cabinet10"/>
    <child link="cabinet10_drawer3"/>
    <limit effort="1000" lower="0.0" upper="0.44999998807907104" velocity="1000"/>
  </joint>
  <link name="cabinet10_drawer3">
    <collision name="cabinet10_drawer3_collision_2">
      <origin xyz="0.021031 0.170562 -0.129424" rpy="0.0 -0.0 0.0"/>
      <geometry>
        <box size="0.491014 0.016 0.083422"/>
      </geometry>
    </collision>
    <collision name="cabinet10_drawer3_collision_1">
      <origin xyz="0.021031 -0.170562 -0.00926" rpy="0.0 -0.0 0.0"/>
      <geometry>
        <box size="0.491014 0.016 0.023276"/>
      </geometry>
    </collision>
    <collision name="cabinet10_drawer3_collision_0">
      <origin xyz="0.021031 0.170562 -0.00926" rpy="0.0 -0.0 0.0"/>
      <geometry>
        <box size="0.491014 0.016 0.023276"/>
      </geometry>
    </collision>
    <collision name="cabinet10_drawer3_collision_3">
      <origin xyz="0.021031 -0.170562 -0.129424" rpy="0.0 -0.0 0.0"/>
      <geometry>
        <box size="0.491014 0.016 0.083422"/>
      </geometry>
    </collision>
    <collision name="cabinet10_drawer3_collision_5">
      <origin xyz="0.260372 0.0 -0.088821" rpy="0.0 -0.0 0.0"/>
      <geometry>
        <box size="0.016 0.357644 0.16821"/>
      </geometry>
    </collision>
    <collision name="cabinet10_drawer3_collision_4">
      <origin xyz="-0.233977 0.0 0.0" rpy="0.0 -0.0 0.0"/>
      <geometry>
        <box size="0.019 0.397734 0.395734"/>
      </geometry>
    </collision>
    <collision name="cabinet10_drawer3_collision_6">
      <origin xyz="0.021031 0.0 -0.164582" rpy="0.0 -0.0 0.0"/>
      <geometry>
        <box size="0.491014 0.357644 0.016"/>
      </geometry>
    </collision>
  </link>
  <joint name="cabinet10_drawer3_handle_joint" type="fixed">
    <origin xyz="-0.26712164 -0.00402777 0.15116583" rpy="1.5707963267948966 -0.0 0.0"/>
    <parent link="cabinet10_drawer3"/>
    <child link="cabinet10_drawer3_handle"/>
  </joint>
  <link name="cabinet10_drawer3_handle">
    <collision name="cabinet10_drawer3_handle_collision_2">
      <origin xyz="0.0 0.0 0.0" rpy="0.0 -0.0 0.0"/>
      <geometry>
        <box size="0.013 0.013 0.173032"/>
      </geometry>
    </collision>
    <collision name="cabinet10_drawer3_handle_collision_1">
      <origin xyz="0.0164985 0.0 -0.08" rpy="0.0 -0.0 0.0"/>
      <geometry>
        <box size="0.02 0.013 0.013"/>
      </geometry>
    </collision>
    <collision name="cabinet10_drawer3_handle_collision_0">
      <origin xyz="0.0164985 0.0 0.08" rpy="0.0 -0.0 0.0"/>
      <geometry>
        <box size="0.02 0.013 0.013"/>
      </geometry>
    </collision>
  </link>
  <joint name="cabinet11_joint" type="fixed">
    <origin xyz="2.49293671 1.62155807 0.50984447" rpy="0.0 -0.0 0.0"/>
    <parent link="kitchen2_root"/>
    <child link="cabinet11"/>
  </joint>
  <link name="cabinet11">
    <collision name="cabinet11_collision_2">
      <origin xyz="0.0 0.0 -0.391006" rpy="0.0 -0.0 0.0"/>
      <geometry>
        <box size="0.55452 0.86788 0.016"/>
      </geometry>
    </collision>
    <collision name="cabinet11_collision_4">
      <origin xyz="0.261473 0.0 0.0" rpy="0.0 -0.0 0.0"/>
      <geometry>
        <box size="0.008 0.86788 0.76582"/>
      </geometry>
    </collision>
    <collision name="cabinet11_collision_1">
      <origin xyz="0.0 -0.441952 0.0" rpy="0.0 -0.0 0.0"/>
      <geometry>
        <box size="0.55452 0.016 0.798012"/>
      </geometry>
    </collision>
    <collision name="cabinet11_collision_3">
      <origin xyz="0.217476 0.0 0.390909" rpy="0.0 -0.0 0.0"/>
      <geometry>
        <box size="0.08 0.86788 0.016"/>
      </geometry>
    </collision>
    <collision name="cabinet11_collision_0">
      <origin xyz="0.0 -0.441952 0.0" rpy="0.0 -0.0 0.0"/>
      <geometry>
        <box size="0.55452 0.016 0.798012"/>
      </geometry>
    </collision>
  </link>
  <joint name="cabinet11_drawer1_joint" type="prismatic">
    <origin xyz="-0.05082244053483009 0.0006393900257535279 0.3181687593460083" rpy="0.0 -0.0 0.0"/>
    <axis xyz="-1 0 0"/>
    <parent link="cabinet11"/>
    <child link="cabinet11_drawer1"/>
    <limit effort="1000" lower="0.0" upper="0.44999998807907104" velocity="1000"/>
  </joint>
  <link name="cabinet11_drawer1">
    <collision name="cabinet11_drawer1_collision_1">
      <origin xyz="0.021031 -0.418233 -0.01336" rpy="0.0 -0.0 0.0"/>
      <geometry>
        <box size="0.491014 0.016 0.085266"/>
      </geometry>
    </collision>
    <collision name="cabinet11_drawer1_collision_2">
      <origin xyz="-0.233977 0.0 0.0" rpy="0.0 -0.0 0.0"/>
      <geometry>
        <box size="0.019 0.896682 0.129986"/>
      </geometry>
    </collision>
    <collision name="cabinet11_drawer1_collision_0">
      <origin xyz="0.021031 0.418233 -0.01336" rpy="0.0 -0.0 0.0"/>
      <geometry>
        <box size="0.491014 0.016 0.085266"/>
      </geometry>
    </collision>
    <collision name="cabinet11_drawer1_collision_3">
      <origin xyz="0.260372 0.0 -0.01336" rpy="0.0 -0.0 0.0"/>
      <geometry>
        <box size="0.016 0.839576 0.085266"/>
      </geometry>
    </collision>
    <collision name="cabinet11_drawer1_collision_4">
      <origin xyz="0.021031 0.0 -0.047595" rpy="0.0 -0.0 0.0"/>
      <geometry>
        <box size="0.491014 0.839576 0.015"/>
      </geometry>
    </collision>
  </link>
  <joint name="cabinet11_drawer1_handle_joint" type="fixed">
    <origin xyz="-0.26662336 -0.00124599 0.0172039" rpy="1.5707963267948966 -0.0 0.0"/>
    <parent link="cabinet11_drawer1"/>
    <child link="cabinet11_drawer1_handle"/>
  </joint>
  <link name="cabinet11_drawer1_handle">
    <collision name="cabinet11_drawer1_handle_collision_1">
      <origin xyz="0.0164985 0.0 -0.08" rpy="0.0 -0.0 0.0"/>
      <geometry>
        <box size="0.02 0.013 0.013"/>
      </geometry>
    </collision>
    <collision name="cabinet11_drawer1_handle_collision_0">
      <origin xyz="0.0164985 0.0 0.08" rpy="0.0 -0.0 0.0"/>
      <geometry>
        <box size="0.02 0.013 0.013"/>
      </geometry>
    </collision>
    <collision name="cabinet11_drawer1_handle_collision_2">
      <origin xyz="0.0 0.0 0.0" rpy="0.0 -0.0 0.0"/>
      <geometry>
        <box size="0.013 0.013 0.173032"/>
      </geometry>
    </collision>
  </link>
  <joint name="cabinet11_drawer2_joint" type="prismatic">
    <origin xyz="-0.05030883103609085 0.00045980000868439674 0.11917842924594879" rpy="0.0 -0.0 0.0"/>
    <axis xyz="-1 0 0"/>
    <parent link="cabinet11"/>
    <child link="cabinet11_drawer2"/>
    <limit effort="1000" lower="0.0" upper="0.44999998807907104" velocity="1000"/>
  </joint>
  <link name="cabinet11_drawer2">
    <collision name="cabinet11_drawer2_collision_3">
      <origin xyz="0.021031 -0.418233 -0.078968" rpy="0.0 -0.0 0.0"/>
      <geometry>
        <box size="0.491014 0.016 0.083496"/>
      </geometry>
    </collision>
    <collision name="cabinet11_drawer2_collision_1">
      <origin xyz="0.021031 -0.418233 0.041246" rpy="0.0 -0.0 0.0"/>
      <geometry>
        <box size="0.491014 0.016 0.023298"/>
      </geometry>
    </collision>
    <collision name="cabinet11_drawer2_collision_0">
      <origin xyz="0.021031 0.418233 0.041246" rpy="0.0 -0.0 0.0"/>
      <geometry>
        <box size="0.491014 0.016 0.023298"/>
      </geometry>
    </collision>
    <collision name="cabinet11_drawer2_collision_4">
      <origin xyz="-0.233977 0.0 0.0" rpy="0.0 -0.0 0.0"/>
      <geometry>
        <box size="0.019 0.896682 0.26275"/>
      </geometry>
    </collision>
    <collision name="cabinet11_drawer2_collision_6">
      <origin xyz="0.021031 0.0 -0.113735" rpy="0.0 -0.0 0.0"/>
      <geometry>
        <box size="0.491014 0.839576 0.016"/>
      </geometry>
    </collision>
    <collision name="cabinet11_drawer2_collision_5">
      <origin xyz="0.260372 0.0 -0.037996" rpy="0.0 -0.0 0.0"/>
      <geometry>
        <box size="0.016 0.839576 0.168982"/>
      </geometry>
    </collision>
    <collision name="cabinet11_drawer2_collision_2">
      <origin xyz="0.021031 0.418233 -0.078968" rpy="0.0 -0.0 0.0"/>
      <geometry>
        <box size="0.491014 0.016 0.083496"/>
      </geometry>
    </collision>
  </link>
  <joint name="cabinet11_drawer2_handle_joint" type="fixed">
    <origin xyz="-0.26686237 -0.00397854 0.08541794" rpy="1.5707963267948966 -0.0 0.0"/>
    <parent link="cabinet11_drawer2"/>
    <child link="cabinet11_drawer2_handle"/>
  </joint>
  <link name="cabinet11_drawer2_handle">
    <collision name="cabinet11_drawer2_handle_collision_1">
      <origin xyz="0.0164985 0.0 -0.08" rpy="0.0 -0.0 0.0"/>
      <geometry>
        <box size="0.02 0.013 0.013"/>
      </geometry>
    </collision>
    <collision name="cabinet11_drawer2_handle_collision_2">
      <origin xyz="0.0 0.0 0.0" rpy="0.0 -0.0 0.0"/>
      <geometry>
        <box size="0.013 0.013 0.173032"/>
      </geometry>
    </collision>
    <collision name="cabinet11_drawer2_handle_collision_0">
      <origin xyz="0.0164985 0.0 0.08" rpy="0.0 -0.0 0.0"/>
      <geometry>
        <box size="0.02 0.013 0.013"/>
      </geometry>
    </collision>
  </link>
  <joint name="cabinet11_drawer3_joint" type="prismatic">
    <origin xyz="-0.05077515169978142 0.001463519991375506 -0.21330785751342773" rpy="0.0 -0.0 0.0"/>
    <axis xyz="-1 0 0"/>
    <parent link="cabinet11"/>
    <child link="cabinet11_drawer3"/>
    <limit effort="1000" lower="0.0" upper="0.44999998807907104" velocity="1000"/>
  </joint>
  <link name="cabinet11_drawer3">
    <collision name="cabinet11_drawer3_collision_3">
      <origin xyz="0.021031 -0.418233 -0.129424" rpy="0.0 -0.0 0.0"/>
      <geometry>
        <box size="0.491014 0.016 0.083422"/>
      </geometry>
    </collision>
    <collision name="cabinet11_drawer3_collision_6">
      <origin xyz="0.021031 0.0 -0.164582" rpy="0.0 -0.0 0.0"/>
      <geometry>
        <box size="0.491014 0.839576 0.016"/>
      </geometry>
    </collision>
    <collision name="cabinet11_drawer3_collision_5">
      <origin xyz="0.260372 0.0 -0.088821" rpy="0.0 -0.0 0.0"/>
      <geometry>
        <box size="0.016 0.839576 0.16821"/>
      </geometry>
    </collision>
    <collision name="cabinet11_drawer3_collision_4">
      <origin xyz="-0.233977 0.0 0.0" rpy="0.0 -0.0 0.0"/>
      <geometry>
        <box size="0.019 0.896682 0.395734"/>
      </geometry>
    </collision>
    <collision name="cabinet11_drawer3_collision_1">
      <origin xyz="0.021031 -0.418233 -0.00926" rpy="0.0 -0.0 0.0"/>
      <geometry>
        <box size="0.491014 0.016 0.023276"/>
      </geometry>
    </collision>
    <collision name="cabinet11_drawer3_collision_2">
      <origin xyz="0.021031 0.418233 -0.129424" rpy="0.0 -0.0 0.0"/>
      <geometry>
        <box size="0.491014 0.016 0.083422"/>
      </geometry>
    </collision>
    <collision name="cabinet11_drawer3_collision_0">
      <origin xyz="0.021031 0.418233 -0.00926" rpy="0.0 -0.0 0.0"/>
      <geometry>
        <box size="0.491014 0.016 0.023276"/>
      </geometry>
    </collision>
  </link>
  <joint name="cabinet11_drawer3_handle_joint" type="fixed">
    <origin xyz="-0.26712164 -0.00402777 0.15116583" rpy="1.5707963267948966 -0.0 0.0"/>
    <parent link="cabinet11_drawer3"/>
    <child link="cabinet11_drawer3_handle"/>
  </joint>
  <link name="cabinet11_drawer3_handle">
    <collision name="cabinet11_drawer3_handle_collision_2">
      <origin xyz="0.0 0.0 0.0" rpy="0.0 -0.0 0.0"/>
      <geometry>
        <box size="0.013 0.013 0.173032"/>
      </geometry>
    </collision>
    <collision name="cabinet11_drawer3_handle_collision_0">
      <origin xyz="0.0164985 0.0 0.08" rpy="0.0 -0.0 0.0"/>
      <geometry>
        <box size="0.02 0.013 0.013"/>
      </geometry>
    </collision>
    <collision name="cabinet11_drawer3_handle_collision_1">
      <origin xyz="0.0164985 0.0 -0.08" rpy="0.0 -0.0 0.0"/>
      <geometry>
        <box size="0.02 0.013 0.013"/>
      </geometry>
    </collision>
  </link>
  <joint name="kitchen2_base_board_joint" type="fixed">
    <origin xyz="2.21094345 2.40967743 0.04963645" rpy="0.0 -0.0 0.0"/>
    <parent link="kitchen2_root"/>
    <child link="kitchen2_base_board"/>
  </joint>
  <link name="kitchen2_base_board">
    <collision name="kitchen2_base_board_collision_0">
      <origin xyz="0.0 0.3023 0.0" rpy="0.0 -0.0 0.0"/>
      <geometry>
        <box size="0.02 3.11248 0.1"/>
      </geometry>
    </collision>
  </link>
  <joint name="island_cover1_joint" type="fixed">
    <origin xyz="2.86824768 2.71960388 0.4503175" rpy="0.0 -0.0 0.0"/>
    <parent link="kitchen2_root"/>
    <child link="island_cover1"/>
  </joint>
  <link name="island_cover1">
    <collision name="island_cover1_collision_0">
      <origin xyz="0.0 0.0 0.0" rpy="0.0 -0.0 0.0"/>
      <geometry>
        <box size="0.01925 3.13566 0.90361"/>
      </geometry>
    </collision>
  </link>
  <joint name="island_cover3_joint" type="fixed">
    <origin xyz="2.53831085 4.27729736 0.45175999" rpy="0.0 -0.0 0.0"/>
    <parent link="kitchen2_root"/>
    <child link="island_cover3"/>
  </joint>
  <link name="island_cover3">
    <collision name="island_cover3_collision_0">
      <origin xyz="0.0 0.0 0.0" rpy="0.0 -0.0 0.0"/>
      <geometry>
        <box size="0.678888 0.02 0.90361"/>
      </geometry>
    </collision>
  </link>
  <joint name="island_cover5_joint" type="fixed">
    <origin xyz="2.53749664 1.16088593 0.44601364" rpy="0.0 -0.0 0.0"/>
    <parent link="kitchen2_root"/>
    <child link="island_cover5"/>
  </joint>
  <link name="island_cover5">
    <collision name="island_cover5_collision_0">
      <origin xyz="0.0 0.0 0.0" rpy="0.0 -0.0 0.0"/>
      <geometry>
        <box size="0.678888 0.02 0.90361"/>
      </geometry>
    </collision>
  </link>
</robot>