<?xml version="1.0" ?>
<robot name="base_footprint" version="1.0">
  <link name="base_footprint"/>
  <joint name="base_link_joint" type="fixed">
    <origin xyz="0.0 0.0 0.051" rpy="0.0 -0.0 0.0"/>
    <parent link="base_footprint"/>
    <child link="base_link"/>
  </joint>
  <link name="base_link">
    <collision name="base_L">
      <origin xyz="0.0 0.0 0.0" rpy="0.0 -0.0 0.0"/>
      <geometry>
        <mesh filename="package://pycram/resources/pr2/stl/base_L.stl" scale="1.0 1.0 1.0"/>
      </geometry>
    </collision>
  </link>
  <joint name="base_bellow_link_joint" type="fixed">
    <origin xyz="-0.29 0.0 0.8" rpy="0.0 -0.0 0.0"/>
    <parent link="base_link"/>
    <child link="base_bellow_link"/>
  </joint>
  <link name="base_bellow_link">
    <collision name="base_bellow_link_collision_0">
      <origin xyz="0.0 0.0 0.0" rpy="0.0 -0.0 0.0"/>
      <geometry>
        <box size="0.05 0.37 0.3"/>
      </geometry>
    </collision>
  </link>
  <joint name="base_laser_link_joint" type="fixed">
    <origin xyz="0.275 0.0 0.252" rpy="0.0 -0.0 0.0"/>
    <parent link="base_link"/>
    <child link="base_laser_link"/>
  </joint>
  <link name="base_laser_link"/>
  <joint name="fl_caster_rotation_joint" type="continuous">
    <origin xyz="0.22460000216960907 0.22460000216960907 0.028200000524520874" rpy="0.0 -0.0 0.0"/>
    <axis xyz="0 0 1"/>
    <parent link="base_link"/>
    <child link="fl_caster_rotation_link"/>
  </joint>
  <link name="fl_caster_rotation_link">
    <collision name="caster_L">
      <origin xyz="0.0 0.0 0.0" rpy="0.0 -0.0 0.0"/>
      <geometry>
        <mesh filename="package://pycram/resources/pr2/stl/caster_L.stl" scale="1.0 1.0 1.0"/>
      </geometry>
    </collision>
  </link>
  <joint name="fl_caster_l_wheel_joint" type="continuous">
    <origin xyz="0.0 0.04899999871850014 0.0" rpy="0.0 -0.0 0.0"/>
    <axis xyz="0 1 0"/>
    <parent link="fl_caster_rotation_link"/>
    <child link="fl_caster_l_wheel_link"/>
  </joint>
  <link name="fl_caster_l_wheel_link">
    <collision name="fl_caster_l_wheel_link_collision_0">
      <origin xyz="0.0 0.0 0.0" rpy="1.57079632679 -0.0 0.0"/>
      <geometry>
        <cylinder radius="0.074792" length="0.034"/>
      </geometry>
    </collision>
  </link>
  <joint name="fl_caster_r_wheel_joint" type="continuous">
    <origin xyz="0.0 -0.04899999871850014 0.0" rpy="0.0 -0.0 0.0"/>
    <axis xyz="0 1 0"/>
    <parent link="fl_caster_rotation_link"/>
    <child link="fl_caster_r_wheel_link"/>
  </joint>
  <link name="fl_caster_r_wheel_link">
    <collision name="fl_caster_r_wheel_link_collision_0">
      <origin xyz="0.0 0.0 0.0" rpy="1.57079632679 -0.0 0.0"/>
      <geometry>
        <cylinder radius="0.074792" length="0.034"/>
      </geometry>
    </collision>
  </link>
  <joint name="fr_caster_rotation_joint" type="continuous">
    <origin xyz="0.22460000216960907 -0.22460000216960907 0.028200000524520874" rpy="0.0 -0.0 0.0"/>
    <axis xyz="0 0 1"/>
    <parent link="base_link"/>
    <child link="fr_caster_rotation_link"/>
  </joint>
  <link name="fr_caster_rotation_link">
    <collision name="caster_L">
      <origin xyz="0.0 0.0 0.0" rpy="0.0 -0.0 0.0"/>
      <geometry>
        <mesh filename="package://pycram/resources/pr2/stl/caster_L.stl" scale="1.0 1.0 1.0"/>
      </geometry>
    </collision>
  </link>
  <joint name="fr_caster_l_wheel_joint" type="continuous">
    <origin xyz="0.0 0.04899999871850014 0.0" rpy="0.0 -0.0 0.0"/>
    <axis xyz="0 1 0"/>
    <parent link="fr_caster_rotation_link"/>
    <child link="fr_caster_l_wheel_link"/>
  </joint>
  <link name="fr_caster_l_wheel_link">
    <collision name="fr_caster_l_wheel_link_collision_0">
      <origin xyz="0.0 0.0 0.0" rpy="1.57079632679 -0.0 0.0"/>
      <geometry>
        <cylinder radius="0.074792" length="0.034"/>
      </geometry>
    </collision>
  </link>
  <joint name="fr_caster_r_wheel_joint" type="continuous">
    <origin xyz="0.0 -0.04899999871850014 0.0" rpy="0.0 -0.0 0.0"/>
    <axis xyz="0 1 0"/>
    <parent link="fr_caster_rotation_link"/>
    <child link="fr_caster_r_wheel_link"/>
  </joint>
  <link name="fr_caster_r_wheel_link">
    <collision name="fr_caster_r_wheel_link_collision_0">
      <origin xyz="0.0 0.0 0.0" rpy="1.57079632679 -0.0 0.0"/>
      <geometry>
        <cylinder radius="0.074792" length="0.034"/>
      </geometry>
    </collision>
  </link>
  <joint name="bl_caster_rotation_joint" type="continuous">
    <origin xyz="-0.22460000216960907 0.22460000216960907 0.028200000524520874" rpy="0.0 -0.0 0.0"/>
    <axis xyz="0 0 1"/>
    <parent link="base_link"/>
    <child link="bl_caster_rotation_link"/>
  </joint>
  <link name="bl_caster_rotation_link">
    <collision name="caster_L">
      <origin xyz="0.0 0.0 0.0" rpy="0.0 -0.0 0.0"/>
      <geometry>
        <mesh filename="package://pycram/resources/pr2/stl/caster_L.stl" scale="1.0 1.0 1.0"/>
      </geometry>
    </collision>
  </link>
  <joint name="bl_caster_l_wheel_joint" type="continuous">
    <origin xyz="0.0 0.04899999871850014 0.0" rpy="0.0 -0.0 0.0"/>
    <axis xyz="0 1 0"/>
    <parent link="bl_caster_rotation_link"/>
    <child link="bl_caster_l_wheel_link"/>
  </joint>
  <link name="bl_caster_l_wheel_link">
    <collision name="bl_caster_l_wheel_link_collision_0">
      <origin xyz="0.0 0.0 0.0" rpy="1.57079632679 -0.0 0.0"/>
      <geometry>
        <cylinder radius="0.074792" length="0.034"/>
      </geometry>
    </collision>
  </link>
  <joint name="bl_caster_r_wheel_joint" type="continuous">
    <origin xyz="0.0 -0.04899999871850014 0.0" rpy="0.0 -0.0 0.0"/>
    <axis xyz="0 1 0"/>
    <parent link="bl_caster_rotation_link"/>
    <child link="bl_caster_r_wheel_link"/>
  </joint>
  <link name="bl_caster_r_wheel_link">
    <collision name="bl_caster_r_wheel_link_collision_0">
      <origin xyz="0.0 0.0 0.0" rpy="1.57079632679 -0.0 0.0"/>
      <geometry>
        <cylinder radius="0.074792" length="0.034"/>
      </geometry>
    </collision>
  </link>
  <joint name="br_caster_rotation_joint" type="continuous">
    <origin xyz="-0.22460000216960907 -0.22460000216960907 0.028200000524520874" rpy="0.0 -0.0 0.0"/>
    <axis xyz="0 0 1"/>
    <parent link="base_link"/>
    <child link="br_caster_rotation_link"/>
  </joint>
  <link name="br_caster_rotation_link">
    <collision name="caster_L">
      <origin xyz="0.0 0.0 0.0" rpy="0.0 -0.0 0.0"/>
      <geometry>
        <mesh filename="package://pycram/resources/pr2/stl/caster_L.stl" scale="1.0 1.0 1.0"/>
      </geometry>
    </collision>
  </link>
  <joint name="br_caster_l_wheel_joint" type="continuous">
    <origin xyz="0.0 0.04899999871850014 0.0" rpy="0.0 -0.0 0.0"/>
    <axis xyz="0 1 0"/>
    <parent link="br_caster_rotation_link"/>
    <child link="br_caster_l_wheel_link"/>
  </joint>
  <link name="br_caster_l_wheel_link">
    <collision name="br_caster_l_wheel_link_collision_0">
      <origin xyz="0.0 0.0 0.0" rpy="1.57079632679 -0.0 0.0"/>
      <geometry>
        <cylinder radius="0.074792" length="0.034"/>
      </geometry>
    </collision>
  </link>
  <joint name="br_caster_r_wheel_joint" type="continuous">
    <origin xyz="0.0 -0.04899999871850014 0.0" rpy="0.0 -0.0 0.0"/>
    <axis xyz="0 1 0"/>
    <parent link="br_caster_rotation_link"/>
    <child link="br_caster_r_wheel_link"/>
  </joint>
  <link name="br_caster_r_wheel_link">
    <collision name="br_caster_r_wheel_link_collision_0">
      <origin xyz="0.0 0.0 0.0" rpy="1.57079632679 -0.0 0.0"/>
      <geometry>
        <cylinder radius="0.074792" length="0.034"/>
      </geometry>
    </collision>
  </link>
  <joint name="torso_lift_joint" type="prismatic">
    <origin xyz="-0.05000000074505806 0.0 0.739674985408783" rpy="0.0 -0.0 0.0"/>
    <axis xyz="0 0 1"/>
    <parent link="base_link"/>
    <child link="torso_lift_link"/>
    <limit effort="1000" lower="0.0" upper="0.33000001311302185" velocity="1000"/>
  </joint>
  <link name="torso_lift_link">
    <collision name="torso_lift_L">
      <origin xyz="0.0 0.0 0.0" rpy="0.0 -0.0 0.0"/>
      <geometry>
        <mesh filename="package://pycram/resources/pr2/stl/torso_lift_L.stl" scale="1.0 1.0 1.0"/>
      </geometry>
    </collision>
  </link>
  <joint name="l_torso_lift_side_plate_link_joint" type="fixed">
    <origin xyz="0.0535 0.209285 0.176625" rpy="0.0 -0.0 0.0"/>
    <parent link="torso_lift_link"/>
    <child link="l_torso_lift_side_plate_link"/>
  </joint>
  <link name="l_torso_lift_side_plate_link"/>
  <joint name="r_torso_lift_side_plate_link_joint" type="fixed">
    <origin xyz="0.0535 -0.209285 0.176625" rpy="0.0 -0.0 0.0"/>
    <parent link="torso_lift_link"/>
    <child link="r_torso_lift_side_plate_link"/>
  </joint>
  <link name="r_torso_lift_side_plate_link"/>
  <joint name="imu_link_joint" type="fixed">
    <origin xyz="-0.02977 -0.1497 0.164" rpy="3.141592653589793 -2.0682310711021437e-13 3.141592653589793"/>
    <parent link="torso_lift_link"/>
    <child link="imu_link"/>
  </joint>
  <link name="imu_link"/>
  <joint name="head_pan_joint" type="revolute">
    <origin xyz="-0.017069999128580093 0.0 0.38144999742507935" rpy="0.0 -0.0 0.0"/>
    <axis xyz="0 0 1"/>
    <parent link="torso_lift_link"/>
    <child link="head_pan_link"/>
    <limit effort="1000" lower="-3.0069999542066057" upper="3.0069999542066057" velocity="1000"/>
  </joint>
  <link name="head_pan_link">
    <collision name="head_pan_L">
      <origin xyz="0.0 0.0 0.0" rpy="0.0 -0.0 0.0"/>
      <geometry>
        <mesh filename="package://pycram/resources/pr2/stl/head_pan_L.stl" scale="1.0 1.0 1.0"/>
      </geometry>
    </collision>
  </link>
  <joint name="head_tilt_joint" type="revolute">
    <origin xyz="0.06800000369548798 0.0 0.0" rpy="0.0 -0.0 0.0"/>
    <axis xyz="0 1 0"/>
    <parent link="head_pan_link"/>
    <child link="head_tilt_link"/>
    <limit effort="1000" lower="-0.4712379992216011" upper="1.3962599394860464" velocity="1000"/>
  </joint>
  <link name="head_tilt_link">
    <collision name="head_tilt_L">
      <origin xyz="0.0 0.0 0.0" rpy="0.0 -0.0 0.0"/>
      <geometry>
        <mesh filename="package://pycram/resources/pr2/stl/head_tilt_L.stl" scale="1.0 1.0 1.0"/>
      </geometry>
    </collision>
  </link>
  <joint name="head_plate_frame_joint" type="fixed">
    <origin xyz="0.0232 0.0 0.0645" rpy="0.0 -0.0 0.0"/>
    <parent link="head_tilt_link"/>
    <child link="head_plate_frame"/>
  </joint>
  <link name="head_plate_frame">
    <collision name="head_plate_frame_collision_0">
      <origin xyz="0.0 0.0 0.0" rpy="0.0 -0.0 0.0"/>
      <geometry>
        <box size="0.01 0.01 0.01"/>
      </geometry>
    </collision>
  </link>
  <joint name="sensor_mount_link_joint" type="fixed">
    <origin xyz="0.0 0.0 0.0" rpy="0.0 -0.0 0.0"/>
    <parent link="head_plate_frame"/>
    <child link="sensor_mount_link"/>
  </joint>
  <link name="sensor_mount_link"/>
  <joint name="high_def_frame_joint" type="fixed">
    <origin xyz="0.046457 -0.11 0.0546" rpy="0.0 -0.0 0.0"/>
    <parent link="sensor_mount_link"/>
    <child link="high_def_frame"/>
  </joint>
  <link name="high_def_frame"/>
  <joint name="high_def_optical_frame_joint" type="fixed">
    <origin xyz="0.0 0.0 0.0" rpy="-1.5707963267900003 -0.0 -1.5707963267900003"/>
    <parent link="high_def_frame"/>
    <child link="high_def_optical_frame"/>
  </joint>
  <link name="high_def_optical_frame"/>
  <joint name="double_stereo_link_joint" type="fixed">
    <origin xyz="0.0 0.0 0.0" rpy="0.0 -0.0 0.0"/>
    <parent link="sensor_mount_link"/>
    <child link="double_stereo_link"/>
  </joint>
  <link name="double_stereo_link"/>
  <joint name="wide_stereo_link_joint" type="fixed">
    <origin xyz="0.045 0.03 0.0501" rpy="0.0 -0.0 0.0"/>
    <parent link="double_stereo_link"/>
    <child link="wide_stereo_link"/>
  </joint>
  <link name="wide_stereo_link"/>
  <joint name="wide_stereo_optical_frame_joint" type="fixed">
    <origin xyz="0.0 0.0 0.0" rpy="-1.5707963267900003 -0.0 -1.5707963267900003"/>
    <parent link="wide_stereo_link"/>
    <child link="wide_stereo_optical_frame"/>
  </joint>
  <link name="wide_stereo_optical_frame"/>
  <joint name="wide_stereo_l_stereo_camera_frame_joint" type="fixed">
    <origin xyz="0.0 0.0 0.0" rpy="0.0 -0.0 0.0"/>
    <parent link="wide_stereo_link"/>
    <child link="wide_stereo_l_stereo_camera_frame"/>
  </joint>
  <link name="wide_stereo_l_stereo_camera_frame"/>
  <joint name="wide_stereo_l_stereo_camera_optical_frame_joint" type="fixed">
    <origin xyz="0.0 0.0 0.0" rpy="-1.5707963267900003 -0.0 -1.5707963267900003"/>
    <parent link="wide_stereo_l_stereo_camera_frame"/>
    <child link="wide_stereo_l_stereo_camera_optical_frame"/>
  </joint>
  <link name="wide_stereo_l_stereo_camera_optical_frame"/>
  <joint name="wide_stereo_r_stereo_camera_frame_joint" type="fixed">
    <origin xyz="0.0 -0.09 0.0" rpy="0.0 -0.0 0.0"/>
    <parent link="wide_stereo_l_stereo_camera_frame"/>
    <child link="wide_stereo_r_stereo_camera_frame"/>
  </joint>
  <link name="wide_stereo_r_stereo_camera_frame"/>
  <joint name="wide_stereo_r_stereo_camera_optical_frame_joint" type="fixed">
    <origin xyz="0.0 0.0 0.0" rpy="-1.5707963267900003 -0.0 -1.5707963267900003"/>
    <parent link="wide_stereo_r_stereo_camera_frame"/>
    <child link="wide_stereo_r_stereo_camera_optical_frame"/>
  </joint>
  <link name="wide_stereo_r_stereo_camera_optical_frame"/>
  <joint name="narrow_stereo_link_joint" type="fixed">
    <origin xyz="0.045 0.06 0.0501" rpy="0.0 -0.0 0.0"/>
    <parent link="double_stereo_link"/>
    <child link="narrow_stereo_link"/>
  </joint>
  <link name="narrow_stereo_link"/>
  <joint name="narrow_stereo_optical_frame_joint" type="fixed">
    <origin xyz="0.0 0.0 0.0" rpy="-1.5707963267900003 -0.0 -1.5707963267900003"/>
    <parent link="narrow_stereo_link"/>
    <child link="narrow_stereo_optical_frame"/>
  </joint>
  <link name="narrow_stereo_optical_frame"/>
  <joint name="narrow_stereo_l_stereo_camera_frame_joint" type="fixed">
    <origin xyz="0.0 0.0 0.0" rpy="0.0 -0.0 0.0"/>
    <parent link="narrow_stereo_link"/>
    <child link="narrow_stereo_l_stereo_camera_frame"/>
  </joint>
  <link name="narrow_stereo_l_stereo_camera_frame"/>
  <joint name="narrow_stereo_l_stereo_camera_optical_frame_joint" type="fixed">
    <origin xyz="0.0 0.0 0.0" rpy="-1.5707963267900003 -0.0 -1.5707963267900003"/>
    <parent link="narrow_stereo_l_stereo_camera_frame"/>
    <child link="narrow_stereo_l_stereo_camera_optical_frame"/>
  </joint>
  <link name="narrow_stereo_l_stereo_camera_optical_frame"/>
  <joint name="narrow_stereo_r_stereo_camera_frame_joint" type="fixed">
    <origin xyz="0.0 -0.09 0.0" rpy="0.0 -0.0 0.0"/>
    <parent link="narrow_stereo_l_stereo_camera_frame"/>
    <child link="narrow_stereo_r_stereo_camera_frame"/>
  </joint>
  <link name="narrow_stereo_r_stereo_camera_frame"/>
  <joint name="narrow_stereo_r_stereo_camera_optical_frame_joint" type="fixed">
    <origin xyz="0.0 0.0 0.0" rpy="-1.5707963267900003 -0.0 -1.5707963267900003"/>
    <parent link="narrow_stereo_r_stereo_camera_frame"/>
    <child link="narrow_stereo_r_stereo_camera_optical_frame"/>
  </joint>
  <link name="narrow_stereo_r_stereo_camera_optical_frame"/>
  <joint name="projector_wg6802418_frame_joint" type="fixed">
    <origin xyz="0.0 0.11 0.0546" rpy="0.0 -0.0 0.0"/>
    <parent link="head_plate_frame"/>
    <child link="projector_wg6802418_frame"/>
  </joint>
  <link name="projector_wg6802418_frame"/>
  <joint name="projector_wg6802418_child_frame_joint" type="fixed">
    <origin xyz="0.0 0.0 0.0" rpy="0.0 -1.57079632679 0.0"/>
    <parent link="projector_wg6802418_frame"/>
    <child link="projector_wg6802418_child_frame"/>
  </joint>
  <link name="projector_wg6802418_child_frame"/>
  <joint name="laser_tilt_mount_joint" type="revolute">
    <origin xyz="0.0989300012588501 0.0 0.22699999809265137" rpy="0.0 -0.0 0.0"/>
    <axis xyz="0 1 0"/>
    <parent link="torso_lift_link"/>
    <child link="laser_tilt_mount_link"/>
    <limit effort="1000" lower="-0.7854000276102113" upper="1.4835299973532345" velocity="1000"/>
  </joint>
  <link name="laser_tilt_mount_link">
    <collision name="tilting_hokuyo_L">
      <origin xyz="0.0 0.0 0.0" rpy="0.0 -0.0 0.0"/>
      <geometry>
        <mesh filename="package://pycram/resources/pr2/stl/tilting_hokuyo_L.stl" scale="1.0 1.0 1.0"/>
      </geometry>
    </collision>
  </link>
  <joint name="laser_tilt_link_joint" type="fixed">
    <origin xyz="0.0 0.0 0.03" rpy="0.0 -0.0 0.0"/>
    <parent link="laser_tilt_mount_link"/>
    <child link="laser_tilt_link"/>
  </joint>
  <link name="laser_tilt_link"/>
  <joint name="r_shoulder_pan_joint" type="revolute">
    <origin xyz="0.0 -0.18799999356269836 0.0" rpy="0.0 -0.0 0.0"/>
    <axis xyz="0 0 1"/>
    <parent link="torso_lift_link"/>
    <child link="r_shoulder_pan_link"/>
    <limit effort="1000" lower="-2.2853980810381143" upper="0.7146018208222451" velocity="1000"/>
  </joint>
  <link name="r_shoulder_pan_link">
    <collision name="shoulder_pan">
      <origin xyz="0.0 0.0 0.0" rpy="0.0 -0.0 0.0"/>
      <geometry>
        <mesh filename="package://pycram/resources/pr2/stl/shoulder_pan.stl" scale="1.0 1.0 1.0"/>
      </geometry>
    </collision>
  </link>
  <joint name="r_shoulder_lift_joint" type="revolute">
    <origin xyz="0.10000000149011612 0.0 0.0" rpy="0.0 -0.0 0.0"/>
    <axis xyz="0 1 0"/>
    <parent link="r_shoulder_pan_link"/>
    <child link="r_shoulder_lift_link"/>
    <limit effort="1000" lower="-0.523600007310303" upper="1.3963000200604523" velocity="1000"/>
  </joint>
  <link name="r_shoulder_lift_link">
    <collision name="shoulder_lift">
      <origin xyz="0.0 0.0 0.0" rpy="0.0 -0.0 0.0"/>
      <geometry>
        <mesh filename="package://pycram/resources/pr2/stl/shoulder_lift.stl" scale="1.0 1.0 1.0"/>
      </geometry>
    </collision>
  </link>
  <joint name="r_upper_arm_roll_joint" type="revolute">
    <origin xyz="0.0 0.0 0.0" rpy="0.0 -0.0 0.0"/>
    <axis xyz="1 0 0"/>
    <parent link="r_shoulder_lift_link"/>
    <child link="r_upper_arm_roll_link"/>
    <limit effort="1000" lower="-3.8999999456553973" upper="0.8000000093382438" velocity="1000"/>
  </joint>
  <link name="r_upper_arm_roll_link">
    <collision name="upper_arm_roll_L">
      <origin xyz="0.0 0.0 0.0" rpy="0.0 -0.0 0.0"/>
      <geometry>
        <mesh filename="package://pycram/resources/pr2/stl/upper_arm_roll_L.stl" scale="1.0 1.0 1.0"/>
      </geometry>
    </collision>
  </link>
  <joint name="r_upper_arm_link_joint" type="fixed">
    <origin xyz="0.0 0.0 0.0" rpy="0.0 -0.0 0.0"/>
    <parent link="r_upper_arm_roll_link"/>
    <child link="r_upper_arm_link"/>
  </joint>
  <link name="r_upper_arm_link">
    <collision name="upper_arm">
      <origin xyz="0.0 0.0 0.0" rpy="0.0 -0.0 0.0"/>
      <geometry>
        <mesh filename="package://pycram/resources/pr2/stl/upper_arm.stl" scale="1.0 1.0 1.0"/>
      </geometry>
    </collision>
  </link>
  <joint name="r_elbow_flex_joint" type="revolute">
    <origin xyz="0.4000000059604645 0.0 0.0" rpy="0.0 -0.0 0.0"/>
    <axis xyz="0 1 0"/>
    <parent link="r_upper_arm_link"/>
    <child link="r_elbow_flex_link"/>
    <limit effort="1000" lower="-2.3212998893773635" upper="0.0" velocity="1000"/>
  </joint>
  <link name="r_elbow_flex_link">
    <collision name="elbow_flex">
      <origin xyz="0.0 0.0 0.0" rpy="0.0 -0.0 0.0"/>
      <geometry>
        <mesh filename="package://pycram/resources/pr2/stl/elbow_flex.stl" scale="1.0 1.0 1.0"/>
      </geometry>
    </collision>
  </link>
  <joint name="r_forearm_roll_joint" type="continuous">
    <origin xyz="0.0 0.0 0.0" rpy="0.0 -0.0 0.0"/>
    <axis xyz="1 0 0"/>
    <parent link="r_elbow_flex_link"/>
    <child link="r_forearm_roll_link"/>
  </joint>
  <link name="r_forearm_roll_link">
    <collision name="forearm_roll_L">
      <origin xyz="0.0 0.0 0.0" rpy="0.0 -0.0 0.0"/>
      <geometry>
        <mesh filename="package://pycram/resources/pr2/stl/forearm_roll_L.stl" scale="1.0 1.0 1.0"/>
      </geometry>
    </collision>
  </link>
  <joint name="r_forearm_link_joint" type="fixed">
    <origin xyz="0.0 0.0 0.0" rpy="0.0 -0.0 0.0"/>
    <parent link="r_forearm_roll_link"/>
    <child link="r_forearm_link"/>
  </joint>
  <link name="r_forearm_link">
    <collision name="forearm">
      <origin xyz="0.0 0.0 0.0" rpy="0.0 -0.0 0.0"/>
      <geometry>
        <mesh filename="package://pycram/resources/pr2/stl/forearm.stl" scale="1.0 1.0 1.0"/>
      </geometry>
    </collision>
  </link>
  <joint name="r_wrist_flex_joint" type="revolute">
    <origin xyz="0.32100000977516174 0.0 0.0" rpy="0.0 -0.0 0.0"/>
    <axis xyz="0 1 0"/>
    <parent link="r_forearm_link"/>
    <child link="r_wrist_flex_link"/>
    <limit effort="1000" lower="-2.1800000187888116" upper="0.0" velocity="1000"/>
  </joint>
  <link name="r_wrist_flex_link">
    <collision name="wrist_flex">
      <origin xyz="0.0 0.0 0.0" rpy="0.0 -0.0 0.0"/>
      <geometry>
        <mesh filename="package://pycram/resources/pr2/stl/wrist_flex.stl" scale="1.0 1.0 1.0"/>
      </geometry>
    </collision>
  </link>
  <joint name="r_wrist_roll_joint" type="continuous">
    <origin xyz="0.0 0.0 0.0" rpy="0.0 -0.0 0.0"/>
    <axis xyz="1 0 0"/>
    <parent link="r_wrist_flex_link"/>
    <child link="r_wrist_roll_link"/>
  </joint>
  <link name="r_wrist_roll_link">
    <collision name="wrist_roll_L">
      <origin xyz="0.0 0.0 0.0" rpy="0.0 -0.0 0.0"/>
      <geometry>
        <mesh filename="package://pycram/resources/pr2/stl/wrist_roll_L.stl" scale="1.0 1.0 1.0"/>
      </geometry>
    </collision>
  </link>
  <joint name="r_gripper_palm_link_joint" type="fixed">
    <origin xyz="0.0 0.0 0.0" rpy="0.0 -0.0 0.0"/>
    <parent link="r_wrist_roll_link"/>
    <child link="r_gripper_palm_link"/>
  </joint>
  <link name="r_gripper_palm_link">
    <collision name="gripper_palm">
      <origin xyz="0.0 0.0 0.0" rpy="0.0 -0.0 0.0"/>
      <geometry>
        <mesh filename="package://pycram/resources/pr2/stl/gripper_palm.stl" scale="1.0 1.0 1.0"/>
      </geometry>
    </collision>
  </link>
  <joint name="r_gripper_led_frame_joint" type="fixed">
    <origin xyz="0.0513 0.0 0.0244" rpy="0.0 -0.0 0.0"/>
    <parent link="r_gripper_palm_link"/>
    <child link="r_gripper_led_frame"/>
  </joint>
  <link name="r_gripper_led_frame"/>
  <joint name="r_gripper_motor_accelerometer_link_joint" type="fixed">
    <origin xyz="0.0 0.0 0.0" rpy="0.0 -0.0 0.0"/>
    <parent link="r_gripper_palm_link"/>
    <child link="r_gripper_motor_accelerometer_link"/>
  </joint>
  <link name="r_gripper_motor_accelerometer_link">
    <collision name="r_gripper_motor_accelerometer_link_collision_0">
      <origin xyz="0.0 0.0 0.0" rpy="0.0 -0.0 0.0"/>
      <geometry>
        <box size="0.001 0.001 0.001"/>
      </geometry>
    </collision>
  </link>
  <joint name="r_gripper_tool_frame_joint" type="fixed">
    <origin xyz="0.18 0.0 0.0" rpy="0.0 -0.0 0.0"/>
    <parent link="r_gripper_palm_link"/>
    <child link="r_gripper_tool_frame"/>
  </joint>
  <link name="r_gripper_tool_frame"/>
  <joint name="r_gripper_motor_slider_joint" type="prismatic">
    <origin xyz="0.1682800054550171 0.0 0.0" rpy="0.0 -0.0 0.0"/>
    <axis xyz="1 0 0"/>
    <parent link="r_gripper_palm_link"/>
    <child link="r_gripper_motor_slider_link"/>
    <limit effort="1000" lower="-0.10000000149011612" upper="0.10000000149011612" velocity="1000"/>
  </joint>
  <link name="r_gripper_motor_slider_link"/>
  <joint name="r_gripper_motor_screw_joint" type="continuous">
    <origin xyz="0.0 0.0 0.0" rpy="0.0 -0.0 0.0"/>
    <axis xyz="0 1 0"/>
    <parent link="r_gripper_motor_slider_link"/>
    <child link="r_gripper_motor_screw_link"/>
  </joint>
  <link name="r_gripper_motor_screw_link"/>
  <joint name="r_gripper_l_finger_joint" type="revolute">
    <origin xyz="0.07690999656915665 0.009999999776482582 0.0" rpy="0.0 -0.0 0.0"/>
    <axis xyz="0 0 1"/>
    <parent link="r_gripper_palm_link"/>
    <child link="r_gripper_l_finger_link"/>
    <limit effort="1000" lower="0.0" upper="0.5479999890861499" velocity="1000"/>
  </joint>
  <link name="r_gripper_l_finger_link">
    <collision name="l_finger">
      <origin xyz="0.0 0.0 0.0" rpy="0.0 -0.0 0.0"/>
      <geometry>
        <mesh filename="package://pycram/resources/pr2/stl/l_finger.stl" scale="1.0 1.0 1.0"/>
      </geometry>
    </collision>
  </link>
  <joint name="r_gripper_l_finger_tip_joint" type="revolute">
    <mimic joint="r_gripper_l_finger_joint" multiplier="1" offset="0"/>
    <origin xyz="0.09137000143527985 0.00494999997317791 0.0" rpy="0.0 -0.0 0.0"/>
    <axis xyz="0 0 -1"/>
    <parent link="r_gripper_l_finger_link"/>
    <child link="r_gripper_l_finger_tip_link"/>
    <limit effort="1000" lower="0.0" upper="0.5479999890861499" velocity="1000"/>
  </joint>
  <link name="r_gripper_l_finger_tip_link">
    <collision name="l_finger_tip">
      <origin xyz="0.0 0.0 0.0" rpy="0.0 -0.0 0.0"/>
      <geometry>
        <mesh filename="package://pycram/resources/pr2/stl/l_finger_tip.stl" scale="1.0 1.0 1.0"/>
      </geometry>
    </collision>
  </link>
  <joint name="r_gripper_r_finger_joint" type="revolute">
    <mimic joint="r_gripper_l_finger_joint" multiplier="1" offset="0"/>
    <origin xyz="0.07690999656915665 -0.009999999776482582 0.0" rpy="0.0 -0.0 0.0"/>
    <axis xyz="0 0 -1"/>
    <parent link="r_gripper_palm_link"/>
    <child link="r_gripper_r_finger_link"/>
    <limit effort="1000" lower="0.0" upper="0.5479999890861499" velocity="1000"/>
  </joint>
  <link name="r_gripper_r_finger_link">
    <collision name="l_finger">
      <origin xyz="0.0 0.0 0.0" rpy="-3.1415926535895866 -0.0 0.0"/>
      <geometry>
        <mesh filename="package://pycram/resources/pr2/stl/l_finger.stl" scale="1.0 1.0 1.0"/>
      </geometry>
    </collision>
  </link>
  <joint name="r_gripper_r_finger_tip_joint" type="revolute">
    <mimic joint="r_gripper_l_finger_joint" multiplier="1" offset="0"/>
    <origin xyz="0.09137000143527985 -0.00494999997317791 0.0" rpy="0.0 -0.0 0.0"/>
    <axis xyz="0 0 1"/>
    <parent link="r_gripper_r_finger_link"/>
    <child link="r_gripper_r_finger_tip_link"/>
    <limit effort="1000" lower="0.0" upper="0.5479999890861499" velocity="1000"/>
  </joint>
  <link name="r_gripper_r_finger_tip_link">
    <collision name="l_finger_tip">
      <origin xyz="0.0 0.0 0.0" rpy="-3.1415926535895866 -0.0 0.0"/>
      <geometry>
        <mesh filename="package://pycram/resources/pr2/stl/l_finger_tip.stl" scale="1.0 1.0 1.0"/>
      </geometry>
    </collision>
  </link>
  <joint name="r_gripper_joint" type="prismatic">
    <origin xyz="0.0 0.0 0.0" rpy="0.0 -0.0 0.0"/>
    <axis xyz="0 1 0"/>
    <parent link="r_gripper_r_finger_tip_link"/>
    <child link="r_gripper_l_finger_tip_frame"/>
    <limit effort="1000" lower="0.0" upper="0.09000000357627869" velocity="1000"/>
  </joint>
  <link name="r_gripper_l_finger_tip_frame"/>
  <joint name="r_forearm_cam_frame_joint" type="fixed">
    <origin xyz="0.135 0.0 0.044" rpy="1.570796326789999 -0.5628686837679997 1.9691140508801486e-16"/>
    <parent link="r_forearm_roll_link"/>
    <child link="r_forearm_cam_frame"/>
  </joint>
  <link name="r_forearm_cam_frame"/>
  <joint name="r_forearm_cam_optical_frame_joint" type="fixed">
    <origin xyz="0.0 0.0 0.0" rpy="-1.5707963267900003 -0.0 -1.5707963267900003"/>
    <parent link="r_forearm_cam_frame"/>
    <child link="r_forearm_cam_optical_frame"/>
  </joint>
  <link name="r_forearm_cam_optical_frame"/>
  <joint name="l_shoulder_pan_joint" type="revolute">
    <origin xyz="0.0 0.18799999356269836 0.0" rpy="0.0 -0.0 0.0"/>
    <axis xyz="0 0 1"/>
    <parent link="torso_lift_link"/>
    <child link="l_shoulder_pan_link"/>
    <limit effort="1000" lower="-0.7146018208222451" upper="2.2853980810381143" velocity="1000"/>
  </joint>
  <link name="l_shoulder_pan_link">
    <collision name="shoulder_pan">
      <origin xyz="0.0 0.0 0.0" rpy="0.0 -0.0 0.0"/>
      <geometry>
        <mesh filename="package://pycram/resources/pr2/stl/shoulder_pan.stl" scale="1.0 1.0 1.0"/>
      </geometry>
    </collision>
  </link>
  <joint name="l_shoulder_lift_joint" type="revolute">
    <origin xyz="0.10000000149011612 0.0 0.0" rpy="0.0 -0.0 0.0"/>
    <axis xyz="0 1 0"/>
    <parent link="l_shoulder_pan_link"/>
    <child link="l_shoulder_lift_link"/>
    <limit effort="1000" lower="-0.523600007310303" upper="1.3963000200604523" velocity="1000"/>
  </joint>
  <link name="l_shoulder_lift_link">
    <collision name="shoulder_lift">
      <origin xyz="0.0 0.0 0.0" rpy="0.0 -0.0 0.0"/>
      <geometry>
        <mesh filename="package://pycram/resources/pr2/stl/shoulder_lift.stl" scale="1.0 1.0 1.0"/>
      </geometry>
    </collision>
  </link>
  <joint name="l_upper_arm_roll_joint" type="revolute">
    <origin xyz="0.0 0.0 0.0" rpy="0.0 -0.0 0.0"/>
    <axis xyz="1 0 0"/>
    <parent link="l_shoulder_lift_link"/>
    <child link="l_upper_arm_roll_link"/>
    <limit effort="1000" lower="-0.8000000093382438" upper="3.8999999456553973" velocity="1000"/>
  </joint>
  <link name="l_upper_arm_roll_link">
    <collision name="upper_arm_roll_L">
      <origin xyz="0.0 0.0 0.0" rpy="0.0 -0.0 0.0"/>
      <geometry>
        <mesh filename="package://pycram/resources/pr2/stl/upper_arm_roll_L.stl" scale="1.0 1.0 1.0"/>
      </geometry>
    </collision>
  </link>
  <joint name="l_upper_arm_link_joint" type="fixed">
    <origin xyz="0.0 0.0 0.0" rpy="0.0 -0.0 0.0"/>
    <parent link="l_upper_arm_roll_link"/>
    <child link="l_upper_arm_link"/>
  </joint>
  <link name="l_upper_arm_link">
    <collision name="upper_arm">
      <origin xyz="0.0 0.0 0.0" rpy="0.0 -0.0 0.0"/>
      <geometry>
        <mesh filename="package://pycram/resources/pr2/stl/upper_arm.stl" scale="1.0 1.0 1.0"/>
      </geometry>
    </collision>
  </link>
  <joint name="l_elbow_flex_joint" type="revolute">
    <origin xyz="0.4000000059604645 0.0 0.0" rpy="0.0 -0.0 0.0"/>
    <axis xyz="0 1 0"/>
    <parent link="l_upper_arm_link"/>
    <child link="l_elbow_flex_link"/>
    <limit effort="1000" lower="-2.3212998893773635" upper="0.0" velocity="1000"/>
  </joint>
  <link name="l_elbow_flex_link">
    <collision name="elbow_flex">
      <origin xyz="0.0 0.0 0.0" rpy="0.0 -0.0 0.0"/>
      <geometry>
        <mesh filename="package://pycram/resources/pr2/stl/elbow_flex.stl" scale="1.0 1.0 1.0"/>
      </geometry>
    </collision>
  </link>
  <joint name="l_forearm_roll_joint" type="continuous">
    <origin xyz="0.0 0.0 0.0" rpy="0.0 -0.0 0.0"/>
    <axis xyz="1 0 0"/>
    <parent link="l_elbow_flex_link"/>
    <child link="l_forearm_roll_link"/>
  </joint>
  <link name="l_forearm_roll_link">
    <collision name="forearm_roll_L">
      <origin xyz="0.0 0.0 0.0" rpy="0.0 -0.0 0.0"/>
      <geometry>
        <mesh filename="package://pycram/resources/pr2/stl/forearm_roll_L.stl" scale="1.0 1.0 1.0"/>
      </geometry>
    </collision>
  </link>
  <joint name="l_forearm_link_joint" type="fixed">
    <origin xyz="0.0 0.0 0.0" rpy="0.0 -0.0 0.0"/>
    <parent link="l_forearm_roll_link"/>
    <child link="l_forearm_link"/>
  </joint>
  <link name="l_forearm_link">
    <collision name="forearm">
      <origin xyz="0.0 0.0 0.0" rpy="0.0 -0.0 0.0"/>
      <geometry>
        <mesh filename="package://pycram/resources/pr2/stl/forearm.stl" scale="1.0 1.0 1.0"/>
      </geometry>
    </collision>
  </link>
  <joint name="l_wrist_flex_joint" type="revolute">
    <origin xyz="0.32100000977516174 0.0 0.0" rpy="0.0 -0.0 0.0"/>
    <axis xyz="0 1 0"/>
    <parent link="l_forearm_link"/>
    <child link="l_wrist_flex_link"/>
    <limit effort="1000" lower="-2.1800000187888116" upper="0.0" velocity="1000"/>
  </joint>
  <link name="l_wrist_flex_link">
    <collision name="wrist_flex">
      <origin xyz="0.0 0.0 0.0" rpy="0.0 -0.0 0.0"/>
      <geometry>
        <mesh filename="package://pycram/resources/pr2/stl/wrist_flex.stl" scale="1.0 1.0 1.0"/>
      </geometry>
    </collision>
  </link>
  <joint name="l_wrist_roll_joint" type="continuous">
    <origin xyz="0.0 0.0 0.0" rpy="0.0 -0.0 0.0"/>
    <axis xyz="1 0 0"/>
    <parent link="l_wrist_flex_link"/>
    <child link="l_wrist_roll_link"/>
  </joint>
  <link name="l_wrist_roll_link">
    <collision name="wrist_roll_L">
      <origin xyz="0.0 0.0 0.0" rpy="0.0 -0.0 0.0"/>
      <geometry>
        <mesh filename="package://pycram/resources/pr2/stl/wrist_roll_L.stl" scale="1.0 1.0 1.0"/>
      </geometry>
    </collision>
  </link>
  <joint name="l_gripper_palm_link_joint" type="fixed">
    <origin xyz="0.0 0.0 0.0" rpy="0.0 -0.0 0.0"/>
    <parent link="l_wrist_roll_link"/>
    <child link="l_gripper_palm_link"/>
  </joint>
  <link name="l_gripper_palm_link">
    <collision name="gripper_palm">
      <origin xyz="0.0 0.0 0.0" rpy="0.0 -0.0 0.0"/>
      <geometry>
        <mesh filename="package://pycram/resources/pr2/stl/gripper_palm.stl" scale="1.0 1.0 1.0"/>
      </geometry>
    </collision>
  </link>
  <joint name="l_gripper_led_frame_joint" type="fixed">
    <origin xyz="0.0513 0.0 0.0244" rpy="0.0 -0.0 0.0"/>
    <parent link="l_gripper_palm_link"/>
    <child link="l_gripper_led_frame"/>
  </joint>
  <link name="l_gripper_led_frame"/>
  <joint name="l_gripper_motor_accelerometer_link_joint" type="fixed">
    <origin xyz="0.0 0.0 0.0" rpy="0.0 -0.0 0.0"/>
    <parent link="l_gripper_palm_link"/>
    <child link="l_gripper_motor_accelerometer_link"/>
  </joint>
  <link name="l_gripper_motor_accelerometer_link">
    <collision name="l_gripper_motor_accelerometer_link_collision_0">
      <origin xyz="0.0 0.0 0.0" rpy="0.0 -0.0 0.0"/>
      <geometry>
        <box size="0.001 0.001 0.001"/>
      </geometry>
    </collision>
  </link>
  <joint name="l_gripper_tool_frame_joint" type="fixed">
    <origin xyz="0.18 0.0 0.0" rpy="0.0 -0.0 0.0"/>
    <parent link="l_gripper_palm_link"/>
    <child link="l_gripper_tool_frame"/>
  </joint>
  <link name="l_gripper_tool_frame"/>
  <joint name="l_gripper_motor_slider_joint" type="prismatic">
    <origin xyz="0.1682800054550171 0.0 0.0" rpy="0.0 -0.0 0.0"/>
    <axis xyz="1 0 0"/>
    <parent link="l_gripper_palm_link"/>
    <child link="l_gripper_motor_slider_link"/>
    <limit effort="1000" lower="-0.10000000149011612" upper="0.10000000149011612" velocity="1000"/>
  </joint>
  <link name="l_gripper_motor_slider_link"/>
  <joint name="l_gripper_motor_screw_joint" type="continuous">
    <origin xyz="0.0 0.0 0.0" rpy="0.0 -0.0 0.0"/>
    <axis xyz="0 1 0"/>
    <parent link="l_gripper_motor_slider_link"/>
    <child link="l_gripper_motor_screw_link"/>
  </joint>
  <link name="l_gripper_motor_screw_link"/>
  <joint name="l_gripper_l_finger_joint" type="revolute">
    <origin xyz="0.07690999656915665 0.009999999776482582 0.0" rpy="0.0 -0.0 0.0"/>
    <axis xyz="0 0 1"/>
    <parent link="l_gripper_palm_link"/>
    <child link="l_gripper_l_finger_link"/>
    <limit effort="1000" lower="0.0" upper="0.5479999890861499" velocity="1000"/>
  </joint>
  <link name="l_gripper_l_finger_link">
    <collision name="l_finger">
      <origin xyz="0.0 0.0 0.0" rpy="0.0 -0.0 0.0"/>
      <geometry>
        <mesh filename="package://pycram/resources/pr2/stl/l_finger.stl" scale="1.0 1.0 1.0"/>
      </geometry>
    </collision>
  </link>
  <joint name="l_gripper_l_finger_tip_joint" type="revolute">
    <mimic joint="l_gripper_l_finger_joint" multiplier="1" offset="0"/>
    <origin xyz="0.09137000143527985 0.00494999997317791 0.0" rpy="0.0 -0.0 0.0"/>
    <axis xyz="0 0 -1"/>
    <parent link="l_gripper_l_finger_link"/>
    <child link="l_gripper_l_finger_tip_link"/>
    <limit effort="1000" lower="0.0" upper="0.5479999890861499" velocity="1000"/>
  </joint>
  <link name="l_gripper_l_finger_tip_link">
    <collision name="l_finger_tip">
      <origin xyz="0.0 0.0 0.0" rpy="0.0 -0.0 0.0"/>
      <geometry>
        <mesh filename="package://pycram/resources/pr2/stl/l_finger_tip.stl" scale="1.0 1.0 1.0"/>
      </geometry>
    </collision>
  </link>
  <joint name="l_gripper_r_finger_joint" type="revolute">
    <mimic joint="l_gripper_l_finger_joint" multiplier="1" offset="0"/>
    <origin xyz="0.07690999656915665 -0.009999999776482582 0.0" rpy="0.0 -0.0 0.0"/>
    <axis xyz="0 0 -1"/>
    <parent link="l_gripper_palm_link"/>
    <child link="l_gripper_r_finger_link"/>
    <limit effort="1000" lower="0.0" upper="0.5479999890861499" velocity="1000"/>
  </joint>
  <link name="l_gripper_r_finger_link">
    <collision name="l_finger">
      <origin xyz="0.0 0.0 0.0" rpy="-3.1415926535895866 -0.0 0.0"/>
      <geometry>
        <mesh filename="package://pycram/resources/pr2/stl/l_finger.stl" scale="1.0 1.0 1.0"/>
      </geometry>
    </collision>
  </link>
  <joint name="l_gripper_r_finger_tip_joint" type="revolute">
    <mimic joint="l_gripper_l_finger_joint" multiplier="1" offset="0"/>
    <origin xyz="0.09137000143527985 -0.00494999997317791 0.0" rpy="0.0 -0.0 0.0"/>
    <axis xyz="0 0 1"/>
    <parent link="l_gripper_r_finger_link"/>
    <child link="l_gripper_r_finger_tip_link"/>
    <limit effort="1000" lower="0.0" upper="0.5479999890861499" velocity="1000"/>
  </joint>
  <link name="l_gripper_r_finger_tip_link">
    <collision name="l_finger_tip">
      <origin xyz="0.0 0.0 0.0" rpy="-3.1415926535895866 -0.0 0.0"/>
      <geometry>
        <mesh filename="package://pycram/resources/pr2/stl/l_finger_tip.stl" scale="1.0 1.0 1.0"/>
      </geometry>
    </collision>
  </link>
  <joint name="l_gripper_joint" type="prismatic">
    <origin xyz="0.0 0.0 0.0" rpy="0.0 -0.0 0.0"/>
    <axis xyz="0 1 0"/>
    <parent link="l_gripper_r_finger_tip_link"/>
    <child link="l_gripper_l_finger_tip_frame"/>
    <limit effort="1000" lower="0.0" upper="0.09000000357627869" velocity="1000"/>
  </joint>
  <link name="l_gripper_l_finger_tip_frame"/>
  <joint name="l_forearm_cam_frame_joint" type="fixed">
    <origin xyz="0.135 0.0 0.044" rpy="-1.570796326789999 -0.5628686837679997 -1.9691140508801486e-16"/>
    <parent link="l_forearm_roll_link"/>
    <child link="l_forearm_cam_frame"/>
  </joint>
  <link name="l_forearm_cam_frame"/>
  <joint name="l_forearm_cam_optical_frame_joint" type="fixed">
    <origin xyz="0.0 0.0 0.0" rpy="-1.5707963267900003 -0.0 -1.5707963267900003"/>
    <parent link="l_forearm_cam_frame"/>
    <child link="l_forearm_cam_optical_frame"/>
  </joint>
  <link name="l_forearm_cam_optical_frame"/>
  <joint name="torso_lift_motor_screw_joint" type="continuous">
    <origin xyz="-0.15000000596046448 0.0 0.699999988079071" rpy="0.0 -0.0 0.0"/>
    <axis xyz="0 0 1"/>
    <parent link="base_link"/>
    <child link="torso_lift_motor_screw_link"/>
  </joint>
  <link name="torso_lift_motor_screw_link"/>
</robot>