<robot name="tiago_dual" version="1.0">
  <link name="base_footprint" />
  <joint name="base_laser_joint" type="fixed">
    <origin xyz="0.202 0.0 -0.004" rpy="0.0 0.0 0.0" />
    <axis xyz="0.0 1.0 0.0" />
    <parent link="base_link" />
    <child link="base_laser_link" />
  </joint>
  <link name="base_laser_link">
    <inertial>
      <origin xyz="-0.02559 -0.00056 -0.05732" rpy="0.0 0.0 0.0" />
      <mass value="0.28922" />
      <inertia ixx="2.628919e-05" ixy="2.4298e-07" ixz="-3.68129e-06" iyy="3.374542e-05" iyz="-1.33e-08" izz="5.832599e-05" />
    </inertial>
    <visual>
      <origin xyz="0.0 0.0 0.0" rpy="0.0 0.0 0.0" />
      <geometry>
        <mesh filename="package://tiago_dual_description/urdf/tiago_dual/obj/sick_tim551.obj" />
      </geometry>
      </visual>
  </link>
  <joint name="base_sonar_03_joint" type="fixed">
    <origin xyz="-0.183 0.183 0.173" rpy="0.0 0.0 2.356194490192345" />
    <axis xyz="0.0 0.0 1.0" />
    <parent link="base_link" />
    <child link="base_sonar_03_link" />
  </joint>
  <link name="base_sonar_03_link">
    <inertial>
      <origin xyz="0.0 0.0 0.0" rpy="0.0 0.0 0.0" />
      <mass value="0.001" />
      <inertia ixx="1e-06" ixy="0.0" ixz="0.0" iyy="1e-06" iyz="0.0" izz="1e-06" />
    </inertial>
    <visual>
      <origin xyz="0.0 0.0 0.0" rpy="0.0 0.0 0.0" />
      <geometry>
        <mesh filename="package://tiago_dual_description/urdf/tiago_dual/obj/srf05.obj" />
      </geometry>
      </visual>
  </link>
  <joint name="base_sonar_02_joint" type="fixed">
    <origin xyz="-0.259 0.0 0.173" rpy="0.0 0.0 3.141592653589793" />
    <axis xyz="0.0 0.0 1.0" />
    <parent link="base_link" />
    <child link="base_sonar_02_link" />
  </joint>
  <link name="base_sonar_02_link">
    <inertial>
      <origin xyz="0.0 0.0 0.0" rpy="0.0 0.0 0.0" />
      <mass value="0.001" />
      <inertia ixx="1e-06" ixy="0.0" ixz="0.0" iyy="1e-06" iyz="0.0" izz="1e-06" />
    </inertial>
    <visual>
      <origin xyz="0.0 0.0 0.0" rpy="0.0 0.0 0.0" />
      <geometry>
        <mesh filename="package://tiago_dual_description/urdf/tiago_dual/obj/srf05.obj" />
      </geometry>
      </visual>
  </link>
  <joint name="base_sonar_01_joint" type="fixed">
    <origin xyz="-0.183 -0.183 0.173" rpy="0.0 0.0 3.9269908169872414" />
    <axis xyz="0.0 0.0 1.0" />
    <parent link="base_link" />
    <child link="base_sonar_01_link" />
  </joint>
  <link name="base_sonar_01_link">
    <inertial>
      <origin xyz="0.0 0.0 0.0" rpy="0.0 0.0 0.0" />
      <mass value="0.001" />
      <inertia ixx="1e-06" ixy="0.0" ixz="0.0" iyy="1e-06" iyz="0.0" izz="1e-06" />
    </inertial>
    <visual>
      <origin xyz="0.0 0.0 0.0" rpy="0.0 0.0 0.0" />
      <geometry>
        <mesh filename="package://tiago_dual_description/urdf/tiago_dual/obj/srf05.obj" />
      </geometry>
      </visual>
  </link>
  <joint name="base_mic_front_left_joint" type="fixed">
    <origin xyz="0.23182 0.03902 0.195" rpy="0.0 0.0 0.0" />
    <parent link="base_link" />
    <child link="base_mic_front_left_link" />
  </joint>
  <link name="base_mic_front_left_link" />
  <joint name="base_mic_front_right_joint" type="fixed">
    <origin xyz="0.23182 -0.03902 0.195" rpy="0.0 0.0 0.0" />
    <parent link="base_link" />
    <child link="base_mic_front_right_link" />
  </joint>
  <link name="base_mic_front_right_link" />
  <joint name="base_mic_back_left_joint" type="fixed">
    <origin xyz="-0.1082 -0.0599 0.195" rpy="0.0 0.0 0.0" />
    <parent link="base_link" />
    <child link="base_mic_back_left_link" />
  </joint>
  <link name="base_mic_back_left_link" />
  <joint name="base_mic_back_right_joint" type="fixed">
    <origin xyz="-0.1082 -0.13789 0.195" rpy="0.0 0.0 0.0" />
    <parent link="base_link" />
    <child link="base_mic_back_right_link" />
  </joint>
  <link name="base_mic_back_right_link" />
  <joint name="base_footprint_joint" type="fixed">
    <origin xyz="0.0 0.0 0.0985" rpy="0.0 0.0 0.0" />
    <parent link="base_footprint" />
    <child link="base_link" />
  </joint>
  <link name="base_link">
    <inertial>
      <origin xyz="-1.06e-06 1.09e-06 3.87e-05" rpy="0.0 0.0 0.0" />
      <mass value="28.26649" />
      <inertia ixx="0.465408937" ixy="0.002160024" ixz="-0.001760255" iyy="0.483193291" iyz="-0.000655952" izz="0.550939703" />
    </inertial>
    <visual>
      <origin xyz="0.0 0.0 0.0" rpy="0.0 0.0 0.0" />
      <geometry>
        <mesh filename="package://tiago_dual_description/urdf/tiago_dual/obj/base.obj" />
      </geometry>
      </visual>
    <collision>
      <origin xyz="0.0 0.0 0.0" rpy="0.0 0.0 0.0" />
      <geometry>
        <mesh filename="package://tiago_dual_description/urdf/tiago_dual/stl/base_collision.stl" />
      </geometry>
    </collision>
  </link>
  <joint name="cover_joint" type="fixed">
    <origin xyz="0.0 0.0 0.13" rpy="0.0 0.0 0.0" />
    <parent link="base_footprint" />
    <child link="base_cover_link" />
  </joint>
  <link name="base_cover_link">
    <inertial>
      <origin xyz="0.22414 2e-05 0.04681" rpy="0.0 0.0 0.0" />
      <mass value="0.25821" />
      <inertia ixx="0.00023719188" ixy="6.119e-08" ixz="-1.1799e-07" iyy="0.00028335052" iyz="7.74e-09" izz="0.00038497063" />
    </inertial>
    <visual>
      <origin xyz="0.0 0.0 0.0" rpy="0.0 0.0 0.0" />
      <geometry>
        <mesh filename="package://tiago_dual_description/urdf/tiago_dual/obj/base_ring.obj" />
      </geometry>
      </visual>
  </link>
  <joint name="base_antenna_left_joint" type="fixed">
    <origin xyz="-0.201 0.1062 0.195" rpy="0.0 0.0 0.0" />
    <parent link="base_link" />
    <child link="base_antenna_left_link" />
  </joint>
  <link name="base_antenna_left_link">
    <inertial>
      <origin xyz="0.0 0.0 0.0" rpy="0.0 0.0 0.0" />
      <mass value="1e-06" />
      <inertia ixx="2.371e-08" ixy="6.119e-08" ixz="1.179e-08" iyy="2.833e-08" iyz="7.74e-09" izz="3.849e-08" />
    </inertial>
    <visual>
      <origin xyz="0.0 0.0 0.0" rpy="0.0 0.0 0.0" />
      <geometry>
        <mesh filename="package://tiago_dual_description/urdf/tiago_dual/obj/antenna.obj" />
      </geometry>
      </visual>
    <collision>
      <origin xyz="0.0 0.0 0.085" rpy="0.0 0.0 0.0" />
      <geometry>
        <cylinder radius="0.005" length="0.17" />
      </geometry>
    </collision>
  </link>
  <joint name="base_antenna_right_joint" type="fixed">
    <origin xyz="-0.201 -0.1062 0.195" rpy="0.0 0.0 0.0" />
    <parent link="base_link" />
    <child link="base_antenna_right_link" />
  </joint>
  <link name="base_antenna_right_link">
    <inertial>
      <origin xyz="0.0 0.0 0.0" rpy="0.0 0.0 0.0" />
      <mass value="1e-06" />
      <inertia ixx="2.371e-08" ixy="6.119e-08" ixz="1.179e-08" iyy="2.833e-08" iyz="7.74e-09" izz="3.849e-08" />
    </inertial>
    <visual>
      <origin xyz="0.0 0.0 0.0" rpy="0.0 0.0 0.0" />
      <geometry>
        <mesh filename="package://tiago_dual_description/urdf/tiago_dual/obj/antenna.obj" />
      </geometry>
      </visual>
    <collision>
      <origin xyz="0.0 0.0 0.085" rpy="0.0 0.0 0.0" />
      <geometry>
        <cylinder radius="0.005" length="0.17" />
      </geometry>
    </collision>
  </link>
  <joint name="base_imu_joint" type="fixed">
    <origin xyz="0.10171 0.0 0.11282" rpy="0.0 0.0 -1.5707963267948966" />
    <parent link="base_link" />
    <child link="base_imu_link" />
  </joint>
  <link name="base_imu_link">
    <inertial>
      <origin xyz="0.0 0.0 0.0" rpy="0 0 0" />
      <mass value="0.01" />
      <inertia ixx="1e-06" ixy="0.0" ixz="0.0" iyy="1e-06" iyz="0.0" izz="1e-06" />
    </inertial>
  </link>
  <joint name="suspension_right_joint" type="prismatic">
    <origin xyz="0.0 0.0 0.0" rpy="0.0 0.0 0.0" />
    <axis xyz="0.0 0.0 1.0" />
    <parent link="base_link" />
    <child link="suspension_right_link" />
    <limit effort="100.0" lower="-0.005" upper="0.005" velocity="1.0" />
    <dynamics damping="100.0" />
    <safety_controller k_velocity="10.0" k_position="0.0" soft_lower_limit="-0.005" soft_upper_limit="0.005" />
    <calibration rising="0.0" falling="0" />
  </joint>
  <link name="suspension_right_link">
    <inertial>
      <origin xyz="0.0 0.0 -0.02" rpy="0.0 0.0 0.0" />
      <mass value="10.0" />
      <inertia ixx="1.0" ixy="0.0" ixz="0.0" iyy="1.0" iyz="0.0" izz="1.0" />
    </inertial>
  </link>
  <joint name="wheel_right_joint" type="continuous">
    <origin xyz="0.0 -0.2022 0.0" rpy="-1.5707963267948966 0.0 0.0" />
    <axis xyz="0.0 0.0 1.0" />
    <parent link="suspension_right_link" />
    <child link="wheel_right_link" />
    <limit effort="6.0" lower="0" upper="0" velocity="10.152284263959391" />
  </joint>
  <link name="wheel_right_link">
    <inertial>
      <origin xyz="0.0 0.0 -0.00207" rpy="0.0 0.0 0.0" />
      <mass value="1.82362" />
      <inertia ixx="0.00499743171" ixy="4.464e-08" ixz="-2.245e-08" iyy="0.00499741733" iyz="-1.64e-09" izz="0.00839239692" />
    </inertial>
    <visual>
      <origin xyz="0.0 0.0 0.0" rpy="-0.0 0.0 0.0" />
      <geometry>
        <mesh filename="package://tiago_dual_description/urdf/tiago_dual/obj/wheel.obj" />
      </geometry>
      </visual>
    <collision>
      <origin xyz="0.0 0.0 0.0" rpy="0.0 0.0 0.0" />
      <geometry>
        <sphere radius="0.0985" />
      </geometry>
    </collision>
  </link>
  <joint name="suspension_left_joint" type="prismatic">
    <origin xyz="0.0 0.0 0.0" rpy="0.0 0.0 0.0" />
    <axis xyz="0.0 0.0 1.0" />
    <parent link="base_link" />
    <child link="suspension_left_link" />
    <limit effort="100.0" lower="-0.005" upper="0.005" velocity="1.0" />
    <dynamics damping="100.0" />
    <safety_controller k_velocity="10.0" k_position="0.0" soft_lower_limit="-0.005" soft_upper_limit="0.005" />
    <calibration rising="0.0" falling="0" />
  </joint>
  <link name="suspension_left_link">
    <inertial>
      <origin xyz="0.0 0.0 -0.02" rpy="0.0 0.0 0.0" />
      <mass value="10.0" />
      <inertia ixx="1.0" ixy="0.0" ixz="0.0" iyy="1.0" iyz="0.0" izz="1.0" />
    </inertial>
  </link>
  <joint name="wheel_left_joint" type="continuous">
    <origin xyz="0.0 0.2022 0.0" rpy="-1.5707963267948966 0.0 0.0" />
    <axis xyz="0.0 0.0 1.0" />
    <parent link="suspension_left_link" />
    <child link="wheel_left_link" />
    <limit effort="6.0" lower="0" upper="0" velocity="10.152284263959391" />
  </joint>
  <link name="wheel_left_link">
    <inertial>
      <origin xyz="0.0 0.0 0.00207" rpy="0.0 0.0 0.0" />
      <mass value="1.82362" />
      <inertia ixx="0.00499743171" ixy="-4.464e-08" ixz="-2.245e-08" iyy="0.00499741733" iyz="1.64e-09" izz="0.00839239692" />
    </inertial>
    <visual>
      <origin xyz="0.0 0.0 0.0" rpy="-3.141592653589793 0.0 0.0" />
      <geometry>
        <mesh filename="package://tiago_dual_description/urdf/tiago_dual/obj/wheel.obj" />
      </geometry>
      </visual>
    <collision>
      <origin xyz="0.0 0.0 0.0" rpy="0.0 0.0 0.0" />
      <geometry>
        <sphere radius="0.0985" />
      </geometry>
    </collision>
  </link>
  <joint name="caster_front_right_1_joint" type="continuous">
    <origin xyz="0.1695 -0.102 -0.0335" rpy="0.0 0.0 0.0" />
    <axis xyz="0.0 0.0 1.0" />
    <parent link="base_link" />
    <child link="caster_front_right_1_link" />
    <dynamics damping="0.005" friction="0.0" />
  </joint>
  <link name="caster_front_right_1_link">
    <inertial>
      <origin xyz="-0.00634599 5.347e-05 -0.02037519" rpy="0.0 0.0 0.0" />
      <mass value="0.05144761" />
      <inertia ixx="1.513e-05" ixy="-3e-08" ixz="2.67e-06" iyy="1.309e-05" iyz="-5e-08" izz="1.198e-05" />
    </inertial>
    <visual>
      <origin xyz="0.0 0.0 0.0" rpy="0.0 0.0 0.0" />
      <geometry>
        <mesh filename="package://tiago_dual_description/urdf/tiago_dual/obj/caster_1.obj" />
      </geometry>
      </visual>
  </link>
  <joint name="caster_front_right_2_joint" type="continuous">
    <origin xyz="-0.016 0.0 -0.04" rpy="-1.5707963267948966 0.0 0.0" />
    <axis xyz="0.0 0.0 1.0" />
    <parent link="caster_front_right_1_link" />
    <child link="caster_front_right_2_link" />
  </joint>
  <link name="caster_front_right_2_link">
    <inertial>
      <origin xyz="0.0 0.0 0.0" rpy="0.0 0.0 0.0" />
      <mass value="0.08855784" />
      <inertia ixx="1.075e-05" ixy="0.0" ixz="0.0" iyy="1.541e-05" iyz="0.0" izz="1.075e-05" />
    </inertial>
    <visual>
      <origin xyz="0.0 0.0 0.0" rpy="0.0 0.0 0.0" />
      <geometry>
        <mesh filename="package://tiago_dual_description/urdf/tiago_dual/obj/caster_2.obj" />
      </geometry>
      </visual>
    <collision>
      <origin xyz="0.0 0.0 0.0" rpy="0.0 0.0 0.0" />
      <geometry>
        <sphere radius="0.025" />
      </geometry>
    </collision>
  </link>
  <joint name="caster_front_left_1_joint" type="continuous">
    <origin xyz="0.1695 0.102 -0.0335" rpy="0.0 0.0 0.0" />
    <axis xyz="0.0 0.0 1.0" />
    <parent link="base_link" />
    <child link="caster_front_left_1_link" />
    <dynamics damping="0.005" friction="0.0" />
  </joint>
  <link name="caster_front_left_1_link">
    <inertial>
      <origin xyz="-0.00634599 5.347e-05 -0.02037519" rpy="0.0 0.0 0.0" />
      <mass value="0.05144761" />
      <inertia ixx="1.513e-05" ixy="-3e-08" ixz="2.67e-06" iyy="1.309e-05" iyz="-5e-08" izz="1.198e-05" />
    </inertial>
    <visual>
      <origin xyz="0.0 0.0 0.0" rpy="0.0 0.0 0.0" />
      <geometry>
        <mesh filename="package://tiago_dual_description/urdf/tiago_dual/obj/caster_1.obj" />
      </geometry>
      </visual>
  </link>
  <joint name="caster_front_left_2_joint" type="continuous">
    <origin xyz="-0.016 0.0 -0.04" rpy="-1.5707963267948966 0.0 0.0" />
    <axis xyz="0.0 0.0 1.0" />
    <parent link="caster_front_left_1_link" />
    <child link="caster_front_left_2_link" />
  </joint>
  <link name="caster_front_left_2_link">
    <inertial>
      <origin xyz="0.0 0.0 0.0" rpy="0.0 0.0 0.0" />
      <mass value="0.08855784" />
      <inertia ixx="1.075e-05" ixy="0.0" ixz="0.0" iyy="1.541e-05" iyz="0.0" izz="1.075e-05" />
    </inertial>
    <visual>
      <origin xyz="0.0 0.0 0.0" rpy="0.0 0.0 0.0" />
      <geometry>
        <mesh filename="package://tiago_dual_description/urdf/tiago_dual/obj/caster_2.obj" />
      </geometry>
      </visual>
    <collision>
      <origin xyz="0.0 0.0 0.0" rpy="0.0 0.0 0.0" />
      <geometry>
        <sphere radius="0.025" />
      </geometry>
    </collision>
  </link>
  <joint name="caster_back_right_1_joint" type="continuous">
    <origin xyz="-0.17350000000000002 -0.102 -0.0335" rpy="0.0 0.0 0.0" />
    <axis xyz="0.0 0.0 1.0" />
    <parent link="base_link" />
    <child link="caster_back_right_1_link" />
    <dynamics damping="0.005" friction="0.0" />
  </joint>
  <link name="caster_back_right_1_link">
    <inertial>
      <origin xyz="-0.00634599 5.347e-05 -0.02037519" rpy="0.0 0.0 0.0" />
      <mass value="0.05144761" />
      <inertia ixx="1.513e-05" ixy="-3e-08" ixz="2.67e-06" iyy="1.309e-05" iyz="-5e-08" izz="1.198e-05" />
    </inertial>
    <visual>
      <origin xyz="0.0 0.0 0.0" rpy="0.0 0.0 0.0" />
      <geometry>
        <mesh filename="package://tiago_dual_description/urdf/tiago_dual/obj/caster_1.obj" />
      </geometry>
      </visual>
  </link>
  <joint name="caster_back_right_2_joint" type="continuous">
    <origin xyz="-0.016 0.0 -0.04" rpy="-1.5707963267948966 0.0 0.0" />
    <axis xyz="0.0 0.0 1.0" />
    <parent link="caster_back_right_1_link" />
    <child link="caster_back_right_2_link" />
  </joint>
  <link name="caster_back_right_2_link">
    <inertial>
      <origin xyz="0.0 0.0 0.0" rpy="0.0 0.0 0.0" />
      <mass value="0.08855784" />
      <inertia ixx="1.075e-05" ixy="0.0" ixz="0.0" iyy="1.541e-05" iyz="0.0" izz="1.075e-05" />
    </inertial>
    <visual>
      <origin xyz="0.0 0.0 0.0" rpy="0.0 0.0 0.0" />
      <geometry>
        <mesh filename="package://tiago_dual_description/urdf/tiago_dual/obj/caster_2.obj" />
      </geometry>
      </visual>
    <collision>
      <origin xyz="0.0 0.0 0.0" rpy="0.0 0.0 0.0" />
      <geometry>
        <sphere radius="0.025" />
      </geometry>
    </collision>
  </link>
  <joint name="caster_back_left_1_joint" type="continuous">
    <origin xyz="-0.17350000000000002 0.102 -0.0335" rpy="0.0 0.0 0.0" />
    <axis xyz="0.0 0.0 1.0" />
    <parent link="base_link" />
    <child link="caster_back_left_1_link" />
    <dynamics damping="0.005" friction="0.0" />
  </joint>
  <link name="caster_back_left_1_link">
    <inertial>
      <origin xyz="-0.00634599 5.347e-05 -0.02037519" rpy="0.0 0.0 0.0" />
      <mass value="0.05144761" />
      <inertia ixx="1.513e-05" ixy="-3e-08" ixz="2.67e-06" iyy="1.309e-05" iyz="-5e-08" izz="1.198e-05" />
    </inertial>
    <visual>
      <origin xyz="0.0 0.0 0.0" rpy="0.0 0.0 0.0" />
      <geometry>
        <mesh filename="package://tiago_dual_description/urdf/tiago_dual/obj/caster_1.obj" />
      </geometry>
      </visual>
  </link>
  <joint name="caster_back_left_2_joint" type="continuous">
    <origin xyz="-0.016 0.0 -0.04" rpy="-1.5707963267948966 0.0 0.0" />
    <axis xyz="0.0 0.0 1.0" />
    <parent link="caster_back_left_1_link" />
    <child link="caster_back_left_2_link" />
  </joint>
  <link name="caster_back_left_2_link">
    <inertial>
      <origin xyz="0.0 0.0 0.0" rpy="0.0 0.0 0.0" />
      <mass value="0.08855784" />
      <inertia ixx="1.075e-05" ixy="0.0" ixz="0.0" iyy="1.541e-05" iyz="0.0" izz="1.075e-05" />
    </inertial>
    <visual>
      <origin xyz="0.0 0.0 0.0" rpy="0.0 0.0 0.0" />
      <geometry>
        <mesh filename="package://tiago_dual_description/urdf/tiago_dual/obj/caster_2.obj" />
      </geometry>
      </visual>
    <collision>
      <origin xyz="0.0 0.0 0.0" rpy="0.0 0.0 0.0" />
      <geometry>
        <sphere radius="0.025" />
      </geometry>
    </collision>
  </link>
  <joint name="torso_fixed_joint" type="fixed">
    <origin xyz="-0.062 0.0 0.193" rpy="0.0 0.0 0.0" />
    <axis xyz="0.0 0.0 0.0" />
    <parent link="base_link" />
    <child link="torso_fixed_link" />
  </joint>
  <link name="torso_fixed_link">
    <inertial>
      <origin xyz="0.02435 -0.00464 0.159" rpy="0.0 0.0 0.0" />
      <mass value="14.0136" />
      <inertia ixx="0.383411" ixy="0.000364" ixz="-0.024389" iyy="0.405773" iyz="-0.000782" izz="0.076998" />
    </inertial>
    <visual>
      <origin xyz="0.0 0.0 0.0" rpy="0.0 0.0 0.0" />
      <geometry>
        <mesh filename="package://tiago_dual_description/urdf/tiago_dual/obj/torso_fix.obj" scale="1.0 1.0 1.0" />
      </geometry>
      </visual>
    <collision>
      <origin xyz="0.085 0.0 0.02" rpy="0.0 0.0 0.0" />
      <geometry>
        <box size="0.4 0.25 0.04" />
      </geometry>
    </collision>
    <collision>
      <origin xyz="0.0 0.0 0.05" rpy="0.0 0.0 0.0" />
      <geometry>
        <box size="0.25 0.25 0.1" />
      </geometry>
    </collision>
  </link>
  <joint name="torso_fixed_column_joint" type="fixed">
    <origin xyz="-0.062 0.0 0.195" rpy="0.0 0.0 0.0" />
    <axis xyz="0.0 0.0 0.0" />
    <parent link="base_link" />
    <child link="torso_fixed_column_link" />
  </joint>
  <link name="torso_fixed_column_link">
    <inertial>
      <origin xyz="0.0 0.0 0.0" rpy="0.0 0.0 0.0" />
      <mass value="0.01" />
      <inertia ixx="1e-06" ixy="0.0" ixz="0.0" iyy="1e-06" iyz="0.0" izz="1e-06" />
    </inertial>
    <visual>
      <origin xyz="0.0 0.0 0.275" rpy="0.0 0.0 0.0" />
      <geometry>
        <box size="0.18 0.2 0.55" />
      </geometry>
      </visual>
    <collision>
      <origin xyz="0.0 0.0 0.275" rpy="0.0 0.0 0.0" />
      <geometry>
        <box size="0.23 0.23 0.55" />
      </geometry>
    </collision>
  </link>
  <joint name="torso_lift_joint" type="prismatic">
    <origin xyz="0.0 0.0 0.597" rpy="0.0 0.0 0.0" />
    <axis xyz="0.0 0.0 1.0" />
    <parent link="torso_fixed_link" />
    <child link="torso_lift_link" />
    <limit effort="2000.0" lower="0.0" upper="0.35" velocity="0.07" />
    <dynamics damping="1000.0" />
    <safety_controller k_velocity="20.0" k_position="20.0" soft_lower_limit="0.0" soft_upper_limit="0.35" />
    <calibration rising="0.0" falling="0" />
  </joint>
  <link name="torso_lift_link">
    <inertial>
      <origin xyz="0.04361 -0.00116 -0.17334" rpy="0.0 0.0 0.0" />
      <mass value="9.594213" />
      <inertia ixx="0.326395" ixy="-0.000844" ixz="-0.018905" iyy="0.235332" iyz="0.009042" izz="0.176168" />
    </inertial>
    <visual>
      <origin xyz="0.0 0.0 0.0" rpy="0.0 0.0 0.0" />
      <geometry>
        <mesh filename="package://tiago_dual_description/urdf/tiago_dual/obj/torso_lift_dual_arm.obj" scale="1.0 1.0 1.0" />
      </geometry>
      </visual>
    <collision>
      <origin xyz="0.0 0.0 0.0" rpy="0.0 0.0 0.0" />
      <geometry>
        <mesh filename="package://tiago_dual_description/urdf/tiago_dual/stl/torso_lift_collision_core.stl" scale="1.0 1.0 1.0" />
      </geometry>
    </collision>
    <collision>
      <origin xyz="-0.131 0.17 -0.02556" rpy="0.0 0.0 0.0" />
      <geometry>
        <mesh filename="package://tiago_dual_description/urdf/tiago_dual/stl/torso_lift_collision_shoulder.stl" scale="1.0 1.0 1.0" />
      </geometry>
    </collision>
    <collision>
      <origin xyz="-0.131 -0.19 -0.02556" rpy="0.0 0.0 0.0" />
      <geometry>
        <mesh filename="package://tiago_dual_description/urdf/tiago_dual/stl/torso_lift_collision_shoulder.stl" scale="1.0 1.0 1.0" />
      </geometry>
    </collision>
    <collision>
      <origin xyz="0.0 0.0 0.0" rpy="0.0 0.0 0.0" />
      <geometry>
        <mesh filename="package://tiago_dual_description/urdf/tiago_dual/stl/torso_lift_collision_neck.stl" scale="1.0 1.0 1.0" />
      </geometry>
    </collision>
  </link>
  <joint name="head_1_joint" type="revolute">
    <origin xyz="0.182 0.0 0.0" rpy="0.0 0.0 0.0" />
    <axis xyz="0.0 0.0 1.0" />
    <parent link="torso_lift_link" />
    <child link="head_1_link" />
    <limit effort="5.197" lower="-1.3089969389957472" upper="1.3089969389957472" velocity="3.0" />
    <dynamics damping="0.5" friction="1.0" />
    <safety_controller k_velocity="20.0" k_position="20.0" soft_lower_limit="-1.2389969389957471" soft_upper_limit="1.2389969389957471" />
  </joint>
  <link name="head_1_link">
    <inertial>
      <origin xyz="-0.00508 0.00237 0.07229" rpy="0.0 0.0 0.0" />
      <mass value="0.6222" />
      <inertia ixx="0.001192" ixy="-7e-06" ixz="9.6e-05" iyy="0.001402" iyz="4e-06" izz="0.000889" />
    </inertial>
    <visual>
      <origin xyz="0.0 0.0 0.0" rpy="0.0 0.0 0.0" />
      <geometry>
        <mesh filename="package://tiago_dual_description/urdf/tiago_dual/obj/head_1.obj" scale="1.0 1.0 1.0" />
      </geometry>
      </visual>
    <collision>
      <origin xyz="0.0 0.0 0.0" rpy="0.0 0.0 0.0" />
      <geometry>
        <mesh filename="package://tiago_dual_description/urdf/tiago_dual/stl/head_1_collision.stl" scale="1.0 1.0 1.0" />
      </geometry>
    </collision>
  </link>
  <joint name="head_2_joint" type="revolute">
    <origin xyz="0.005 0.0 0.098" rpy="1.5707963267948966 0.0 0.0" />
    <axis xyz="0.0 0.0 1.0" />
    <parent link="head_1_link" />
    <child link="head_2_link" />
    <limit effort="2.77" lower="-1.0471975511965976" upper="0.7853981633974483" velocity="3.0" />
    <dynamics damping="0.5" friction="1.0" />
    <safety_controller k_velocity="20.0" k_position="20.0" soft_lower_limit="-0.9771975511965976" soft_upper_limit="0.7153981633974482" />
  </joint>
  <link name="head_2_link">
    <inertial>
      <origin xyz="0.047 0.05542 0.00022" rpy="0.0 0.0 0.0" />
      <mass value="0.66123" />
      <inertia ixx="0.00462" ixy="0.000689" ixz="6e-06" iyy="0.004861" iyz="6e-06" izz="0.003132" />
    </inertial>
    <visual>
      <origin xyz="0.0 0.0 0.0" rpy="0.0 0.0 0.0" />
      <geometry>
        <mesh filename="package://tiago_dual_description/urdf/tiago_dual/obj/head_2.obj" scale="1.0 1.0 1.0" />
      </geometry>
      </visual>
    <collision>
      <origin xyz="0.0 0.0 0.0" rpy="0.0 0.0 0.0" />
      <geometry>
        <mesh filename="package://tiago_dual_description/urdf/tiago_dual/stl/head_2_collision.stl" scale="1.0 1.0 1.0" />
      </geometry>
    </collision>
  </link>
  <joint name="xtion_joint" type="fixed">
    <origin xyz="0.0908 0.08 0.0" rpy="-1.5707963267948966 0.0 0.0" />
    <parent link="head_2_link" />
    <child link="xtion_link" />
  </joint>
  <link name="xtion_link">
    <inertial>
      <origin xyz="-0.00936 -3e-05 -0.00273" rpy="0.0 0.0 0.0" />
      <mass value="0.2197" />
      <inertia ixx="4.29247e-06" ixy="0.0" ixz="2.565e-08" iyy="8.027e-08" iyz="0.0" izz="4.27339e-06" />
    </inertial>
  </link>
  <joint name="xtion_optical_joint" type="fixed">
    <origin xyz="0.0 0.0 0.0" rpy="-1.5707963267948966 0.0 -1.5707963267948966" />
    <parent link="xtion_link" />
    <child link="xtion_optical_frame" />
  </joint>
  <link name="xtion_optical_frame">
    <inertial>
      <origin xyz="0.0 0.0 0.0" rpy="0.0 0.0 0.0" />
      <mass value="0.001" />
      <inertia ixx="1e-05" ixy="0.0" ixz="0.0" iyy="1e-05" iyz="0.0" izz="1e-05" />
    </inertial>
  </link>
  <joint name="xtion_orbbec_aux_joint" type="fixed">
    <origin xyz="0.0 0.0 0.0" rpy="0.0 0.0 0.0" />
    <parent link="xtion_link" />
    <child link="xtion_orbbec_aux_joint_frame" />
  </joint>
  <link name="xtion_orbbec_aux_joint_frame">
    <inertial>
      <origin xyz="0.0 0.0 0.0" rpy="0.0 0.0 0.0" />
      <mass value="0.001" />
      <inertia ixx="1e-05" ixy="0.0" ixz="0.0" iyy="1e-05" iyz="0.0" izz="1e-05" />
    </inertial>
  </link>
  <joint name="xtion_depth_joint" type="fixed">
    <origin xyz="0.0 0.025 0.0" rpy="0.0 0.0 0.0" />
    <parent link="xtion_rgb_frame" />
    <child link="xtion_depth_frame" />
  </joint>
  <link name="xtion_depth_frame">
    <inertial>
      <origin xyz="0.0 0.0 0.0" rpy="0.0 0.0 0.0" />
      <mass value="0.001" />
      <inertia ixx="1e-05" ixy="0.0" ixz="0.0" iyy="1e-05" iyz="0.0" izz="1e-05" />
    </inertial>
  </link>
  <joint name="xtion_depth_optical_joint" type="fixed">
    <origin xyz="0.0 0.0 0.0" rpy="-1.5707963267948966 0.0 -1.5707963267948966" />
    <parent link="xtion_depth_frame" />
    <child link="xtion_depth_optical_frame" />
  </joint>
  <link name="xtion_depth_optical_frame">
    <inertial>
      <origin xyz="0.0 0.0 0.0" rpy="0.0 0.0 0.0" />
      <mass value="0.001" />
      <inertia ixx="1e-05" ixy="0.0" ixz="0.0" iyy="1e-05" iyz="0.0" izz="1e-05" />
    </inertial>
  </link>
  <joint name="xtion_rgb_joint" type="fixed">
    <origin xyz="0.0 0.022 0.0" rpy="0.0 0.0 0.0" />
    <parent link="xtion_orbbec_aux_joint_frame" />
    <child link="xtion_rgb_frame" />
  </joint>
  <link name="xtion_rgb_frame">
    <inertial>
      <origin xyz="0.0 0.0 0.0" rpy="0.0 0.0 0.0" />
      <mass value="0.001" />
      <inertia ixx="1e-05" ixy="0.0" ixz="0.0" iyy="1e-05" iyz="0.0" izz="1e-05" />
    </inertial>
  </link>
  <joint name="xtion_rgb_optical_joint" type="fixed">
    <origin xyz="0.0 0.0 0.0" rpy="-1.5707963267948966 0.0 -1.5707963267948966" />
    <parent link="xtion_rgb_frame" />
    <child link="xtion_rgb_optical_frame" />
  </joint>
  <link name="xtion_rgb_optical_frame">
    <inertial>
      <origin xyz="0.0 0.0 0.0" rpy="0.0 0.0 0.0" />
      <mass value="0.001" />
      <inertia ixx="1e-05" ixy="0.0" ixz="0.0" iyy="1e-05" iyz="0.0" izz="1e-05" />
    </inertial>
  </link>
  <joint name="arm_left_1_joint" type="revolute">
    <origin xyz="0.02556 0.19 -0.171" rpy="3.141592653589793 0.0 1.5707963267948966" />
    <axis xyz="0.0 0.0 1.0" />
    <parent link="torso_lift_link" />
    <child link="arm_left_1_link" />
    <limit effort="43.0" lower="-1.1780972450961724" upper="1.5707963267948966" velocity="1.95" />
    <dynamics damping="1.0" friction="1.0" />
    <safety_controller k_velocity="20.0" k_position="20.0" soft_lower_limit="-1.1080972450961724" soft_upper_limit="1.5007963267948965" />
  </joint>
  <link name="arm_left_1_link">
    <inertial>
      <origin xyz="0.061191 -0.022397 0.012835" rpy="0.0 0.0 0.0" />
      <mass value="1.563428" />
      <inertia ixx="0.002471" ixy="0.001809" ixz="-0.001202" iyy="0.006132" iyz="-0.000494" izz="0.006704" />
    </inertial>
    <visual>
      <origin xyz="0.0 0.0 0.0" rpy="0.0 0.0 0.0" />
      <geometry>
        <mesh filename="package://tiago_dual_description/urdf/tiago_dual/obj/arm_1.obj" scale="1.0 -1.0 -1.0" />
      </geometry>
      </visual>
    <collision>
      <origin xyz="0.0 0.0 0.0" rpy="0.0 0.0 0.0" />
      <geometry>
        <mesh filename="package://tiago_dual_description/urdf/tiago_dual/stl/arm_1_collision.stl" scale="1.0 -1.0 -1.0" />
      </geometry>
    </collision>
  </link>
  <joint name="arm_left_2_joint" type="revolute">
    <origin xyz="0.125 -0.0195 0.031" rpy="1.5707963267948966 0.0 0.0" />
    <axis xyz="0.0 0.0 1.0" />
    <parent link="arm_left_1_link" />
    <child link="arm_left_2_link" />
    <limit effort="43.0" lower="-1.1780972450961724" upper="1.5707963267948966" velocity="1.95" />
    <dynamics damping="1.0" friction="1.0" />
    <safety_controller k_velocity="20.0" k_position="20.0" soft_lower_limit="-1.1080972450961724" soft_upper_limit="1.5007963267948965" />
  </joint>
  <link name="arm_left_2_link">
    <inertial>
      <origin xyz="0.030432 0.000229 0.005942" rpy="0.0 0.0 0.0" />
      <mass value="1.800397" />
      <inertia ixx="0.001809" ixy="-1.5e-05" ixz="-0.000254" iyy="0.004333" iyz="-1.4e-05" izz="0.004341" />
    </inertial>
    <visual>
      <origin xyz="0.0 0.0 0.0" rpy="0.0 0.0 0.0" />
      <geometry>
        <mesh filename="package://tiago_dual_description/urdf/tiago_dual/obj/arm_2.obj" scale="1.0 1.0 -1.0" />
      </geometry>
      </visual>
    <collision>
      <origin xyz="0.0 0.0 0.0" rpy="0.0 0.0 0.0" />
      <geometry>
        <mesh filename="package://tiago_dual_description/urdf/tiago_dual/stl/arm_2_collision.stl" scale="1.0 1.0 -1.0" />
      </geometry>
    </collision>
  </link>
  <joint name="arm_left_3_joint" type="revolute">
    <origin xyz="0.0895 0.0 -0.0015" rpy="-1.5707963267948966 3.141592653589793 -1.5707963267948966" />
    <axis xyz="0.0 0.0 1.0" />
    <parent link="arm_left_2_link" />
    <child link="arm_left_3_link" />
    <limit effort="26.0" lower="-0.7853981633974483" upper="3.9269908169872414" velocity="2.35" />
    <dynamics damping="1.0" friction="1.0" />
    <safety_controller k_velocity="20.0" k_position="20.0" soft_lower_limit="-0.7153981633974482" soft_upper_limit="3.8569908169872416" />
  </joint>
  <link name="arm_left_3_link">
    <inertial>
      <origin xyz="0.007418 -0.004361 0.134194" rpy="0.0 0.0 0.0" />
      <mass value="1.8" />
      <inertia ixx="0.019541" ixy="-0.000105" ixz="-0.001717" iyy="0.019936" iyz="-0.000852" izz="0.002864" />
    </inertial>
    <visual>
      <origin xyz="0.0 0.0 0.0" rpy="0.0 0.0 0.0" />
      <geometry>
        <mesh filename="package://tiago_dual_description/urdf/tiago_dual/obj/arm_3.obj" scale="1.0 1.0 -1.0" />
      </geometry>
      </visual>
    <collision>
      <origin xyz="0.0 0.0 0.0" rpy="0.0 0.0 0.0" />
      <geometry>
        <mesh filename="package://tiago_dual_description/urdf/tiago_dual/stl/arm_3_collision.stl" scale="1.0 1.0 -1.0" />
      </geometry>
    </collision>
  </link>
  <joint name="arm_left_4_joint" type="revolute">
    <origin xyz="-0.02 -0.027 0.222" rpy="1.5707963267948966 -1.5707963267948966 0.0" />
    <axis xyz="0.0 0.0 1.0" />
    <parent link="arm_left_3_link" />
    <child link="arm_left_4_link" />
    <limit effort="26.0" lower="-0.39269908169872414" upper="2.356194490192345" velocity="2.35" />
    <dynamics damping="1.0" friction="1.0" />
    <safety_controller k_velocity="20.0" k_position="20.0" soft_lower_limit="-0.32269908169872413" soft_upper_limit="2.286194490192345" />
  </joint>
  <link name="arm_left_4_link">
    <inertial>
      <origin xyz="0.095658 -0.014666 -0.018133" rpy="0.0 0.0 0.0" />
      <mass value="1.432697" />
      <inertia ixx="0.00204" ixy="-0.000725" ixz="0.00115" iyy="0.008424" iyz="-0.000204" izz="0.008686" />
    </inertial>
    <visual>
      <origin xyz="0.0 0.0 0.0" rpy="0.0 0.0 0.0" />
      <geometry>
        <mesh filename="package://tiago_dual_description/urdf/tiago_dual/obj/arm_4.obj" scale="-1.0 -1.0 -1.0" />
      </geometry>
      </visual>
    <collision>
      <origin xyz="0.0 0.0 0.0" rpy="0.0 0.0 0.0" />
      <geometry>
        <mesh filename="package://tiago_dual_description/urdf/tiago_dual/stl/arm_4_collision.stl" scale="-1.0 -1.0 -1.0" />
      </geometry>
    </collision>
  </link>
  <joint name="arm_left_5_joint" type="revolute">
    <origin xyz="0.162 -0.02 -0.027" rpy="1.5707963267948966 -1.5707963267948966 -1.5707963267948966" />
    <axis xyz="0.0 0.0 1.0" />
    <parent link="arm_left_4_link" />
    <child link="arm_left_5_link" />
    <limit effort="3.0" lower="-2.0943951023931953" upper="2.0943951023931953" velocity="1.95" />
    <dynamics damping="1.0" friction="1.0" />
    <safety_controller k_velocity="20.0" k_position="20.0" soft_lower_limit="-2.0743951023931952" soft_upper_limit="2.0743951023931952" />
  </joint>
  <link name="arm_left_5_link">
    <inertial>
      <origin xyz="0.001078 -0.000151 0.077173" rpy="0.0 0.0 0.0" />
      <mass value="0.9359143689" />
      <inertia ixx="0.001036187977" ixy="1.0622321e-07" ixz="1.9920336e-06" iyy="0.000794527176366096" iyz="-2.56396106998404e-07" izz="0.000439831229979178" />
    </inertial>
    <visual>
      <origin xyz="0.0 0.0 0.0" rpy="0.0 0.0 0.0" />
      <geometry>
        <mesh filename="package://tiago_dual_description/urdf/tiago_dual/obj/arm_5-wrist-2017.obj" scale="-1.0 -1.0 -1.0" />
      </geometry>
      </visual>
    <collision>
      <origin xyz="0.0 0.0 0.0" rpy="0.0 0.0 0.0" />
      <geometry>
        <mesh filename="package://tiago_dual_description/urdf/tiago_dual/stl/arm_5_collision-wrist-2017.stl" scale="-1.0 -1.0 -1.0" />
      </geometry>
    </collision>
  </link>
  <joint name="arm_left_6_joint" type="revolute">
    <origin xyz="0.0 0.0 -0.15" rpy="0.0 -1.5707963267948966 -1.5707963267948966" />
    <axis xyz="0.0 0.0 1.0" />
    <parent link="arm_left_5_link" />
    <child link="arm_left_6_link" />
    <limit effort="6.6" lower="-1.413716694115407" upper="1.413716694115407" velocity="1.76" />
    <dynamics damping="1.0" friction="1.0" />
    <safety_controller k_velocity="20.0" k_position="20.0" soft_lower_limit="-1.3937166941154069" soft_upper_limit="1.3937166941154069" />
  </joint>
  <link name="arm_left_6_link">
    <inertial>
      <origin xyz="-0.000153 -0.003122 0.000183" rpy="0.0 0.0 0.0" />
      <mass value="0.30275767222" />
      <inertia ixx="3.29233557e-05" ixy="6.31537395e-08" ixz="-4.567124912e-11" iyy="3.85334410118923e-05" iyz="-2.01613082836742e-07" izz="3.33282849168039e-05" />
    </inertial>
    <visual>
      <origin xyz="0.0 0.0 0.0" rpy="0.0 0.0 0.0" />
      <geometry>
        <mesh filename="package://tiago_dual_description/urdf/tiago_dual/obj/arm_6-wrist-2017.obj" scale="-1.0 1.0 1.0" />
      </geometry>
      </visual>
    <collision>
      <origin xyz="0.0 0.0 0.0" rpy="0.0 0.0 0.0" />
      <geometry>
        <mesh filename="package://tiago_dual_description/urdf/tiago_dual/stl/arm_6_collision-wrist-2017.stl" scale="-1.0 1.0 1.0" />
      </geometry>
    </collision>
  </link>
  <joint name="arm_left_7_joint" type="revolute">
    <origin xyz="0.0 0.0 0.0" rpy="1.5707963267948966 0.0 1.5707963267948966" />
    <axis xyz="0.0 0.0 1.0" />
    <parent link="arm_left_6_link" />
    <child link="arm_left_7_link" />
    <limit effort="6.6" lower="-2.0943951023931953" upper="2.0943951023931953" velocity="1.76" />
    <dynamics damping="1.0" friction="1.0" />
    <safety_controller k_velocity="20.0" k_position="20.0" soft_lower_limit="-2.0743951023931952" soft_upper_limit="2.0743951023931952" />
  </joint>
  <link name="arm_left_7_link">
    <inertial>
      <origin xyz="1e-05 -3e-06 -0.007774" rpy="0.0 0.0 0.0" />
      <mass value="0.1" />
      <inertia ixx="1.14959795e-05" ixy="-1.390727219e-07" ixz="5.930207406e-09" iyy="1.13594084240734e-05" iyz="-1.78396260812528e-08" izz="2.01898984804048e-05" />
    </inertial>
  </link>
  <joint name="arm_left_tool_joint" type="fixed">
    <origin xyz="0.0 0.0 -0.046" rpy="1.5707963267948966 1.5707963267948966 3.141592653589793" />
    <parent link="arm_left_7_link" />
    <child link="arm_left_tool_link" />
  </joint>
  <link name="arm_left_tool_link">
    <inertial>
      <mass value="0.1" />
      <inertia ixx="8.33e-07" ixy="0.0" ixz="0.0" iyy="8.33e-07" iyz="0.0" izz="1.25e-06" />
    </inertial>
    <visual>
      <origin xyz="0.001 0.0 0.0" rpy="0.0 1.5707963267948966 0.0" />
      <geometry>
        <cylinder radius="0.005" length="0.005" />
      </geometry>
      </visual>
    <collision>
      <origin xyz="0.001 0.0 0.0" rpy="0.0 1.5707963267948966 0.0" />
      <geometry>
        <cylinder radius="0.005" length="0.005" />
      </geometry>
    </collision>
  </link>
  <joint name="wrist_left_ft_joint" type="fixed">
    <origin xyz="0.00785 0.0 0.0" rpy="1.5707963267948966 0.0 1.5707963267948966" />
    <parent link="arm_left_tool_link" />
    <child link="wrist_left_ft_link" />
  </joint>
  <link name="wrist_left_ft_link">
    <inertial>
      <mass value="0.1" />
      <inertia ixx="1.6e-05" ixy="-2e-06" ixz="0.0" iyy="1.6e-05" iyz="0.0" izz="2.7e-05" />
    </inertial>
    <visual>
      <origin xyz="0.0 0.0 0.0" rpy="0.0 0.0 0.0" />
      <geometry>
        <cylinder radius="0.0225" length="0.0157" />
      </geometry>
      </visual>
    <collision>
      <origin xyz="0.0 0.0 0.0" rpy="0.0 0.0 0.0" />
      <geometry>
        <cylinder radius="0.0225" length="0.0157" />
      </geometry>
    </collision>
  </link>
  <joint name="wrist_left_tool_joint" type="fixed">
    <origin xyz="0.0 0.0 0.012725" rpy="-1.5707963267948966 -1.5707963267948966 0.0" />
    <parent link="wrist_left_ft_link" />
    <child link="wrist_left_ft_tool_link" />
  </joint>
  <link name="wrist_left_ft_tool_link">
    <inertial>
      <mass value="0.1" />
      <inertia ixx="1.64e-05" ixy="0.0" ixz="0.0" iyy="1.64e-05" iyz="0.0" izz="3.125e-05" />
    </inertial>
    <visual>
      <origin xyz="0.0 0.0 0.0" rpy="0.0 1.5707963267948966 0.0" />
      <geometry>
        <cylinder radius="0.025" length="0.00975" />
      </geometry>
      </visual>
    <collision>
      <origin xyz="0.0 0.0 0.0" rpy="0.0 1.5707963267948966 0.0" />
      <geometry>
        <cylinder radius="0.025" length="0.00975" />
      </geometry>
    </collision>
  </link>
  <joint name="gripper_left_tool_joint" type="fixed">
    <origin xyz="0.01 0.0 0.0" rpy="1.5707963267948966 1.5707963267948966 -1.5707963267948966" />
    <axis xyz="0.0 0.0 0.0" />
    <parent link="wrist_left_ft_tool_link" />
    <child link="gripper_left_tool_link" />
  </joint>
  <link name="gripper_left_tool_link">
    <inertial>
      <origin xyz="0.0 0.0 0.0" rpy="0.0 0.0 0.0" />
      <mass value="0.0001" />
      <inertia ixx="1e-05" ixy="0.0" ixz="0.0" iyy="1e-05" iyz="0.0" izz="1e-05" />
    </inertial>
  </link>
  <joint name="gripper_left_joint" type="fixed">
    <origin xyz="0.01 0.0 0.0" rpy="1.5707963267948966 1.5707963267948966 -1.5707963267948966" />
    <axis xyz="0.0 0.0 0.0" />
    <parent link="wrist_left_ft_tool_link" />
    <child link="gripper_left_link" />
  </joint>
  <link name="gripper_left_link">
    <inertial>
      <origin xyz="-0.000294 0.000291 -0.033086" rpy="0.0 0.0 0.0" />
      <mass value="0.60266" />
      <inertia ixx="0.000693" ixy="4.5e-05" ixz="-0.0" iyy="0.001024" iyz="0.0" izz="0.000672" />
    </inertial>
    <visual>
      <origin xyz="0.0 0.0 0.0" rpy="0.0 0.0 0.0" />
      <geometry>
        <mesh filename="package://tiago_dual_description/urdf/tiago_dual/obj/gripper_link.obj" />
      </geometry>
      </visual>
    <collision>
      <origin xyz="0.0 0.0 0.0" rpy="0.0 0.0 0.0" />
      <geometry>
        <mesh filename="package://tiago_dual_description/urdf/tiago_dual/stl/gripper_link_collision.stl" />
      </geometry>
    </collision>
  </link>
  <joint name="gripper_left_right_finger_joint" type="prismatic">
    <origin xyz="0.0 0.0 0.0" rpy="0.0 0.0 0.0" />
    <axis xyz="1.0 0.0 0.0" />
    <parent link="gripper_left_link" />
    <child link="gripper_left_right_finger_link" />
    <limit effort="16.0" lower="0.0" upper="0.045" velocity="0.05" />
    <dynamics damping="80.0" />
    <safety_controller k_velocity="20.0" k_position="20.0" soft_lower_limit="0.001" soft_upper_limit="0.044" />
    <calibration rising="0.0" falling="0" />
  </joint>
  <link name="gripper_left_right_finger_link">
    <inertial>
      <origin xyz="-0.00447 0.010766 -0.121013" rpy="0.0 0.0 0.0" />
      <mass value="0.10998" />
      <inertia ixx="0.000232" ixy="-5e-06" ixz="-3.2e-05" iyy="0.000224" iyz="3.6e-05" izz="2.9e-05" />
    </inertial>
    <visual>
      <origin xyz="0.0 0.0 0.0" rpy="0.0 0.0 3.1415" />
      <geometry>
        <mesh filename="package://tiago_dual_description/urdf/tiago_dual/obj/gripper_finger_link.obj" scale="-1.0 -1.0 1.0" />
      </geometry>
      </visual>
    <collision>
      <origin xyz="0.005 0.0 -0.165" rpy="0.0 0.0 3.1415" />
      <geometry>
        <box size="0.01 0.05 0.11" />
      </geometry>
    </collision>
  </link>
  <joint name="gripper_left_left_finger_joint" type="prismatic">
    <origin xyz="0.0 0.0 0.0" rpy="0.0 0.0 0.0" />
    <axis xyz="-1.0 0.0 0.0" />
    <parent link="gripper_left_link" />
    <child link="gripper_left_left_finger_link" />
    <limit effort="16.0" lower="0.0" upper="0.045" velocity="0.05" />
    <dynamics damping="80.0" />
    <safety_controller k_velocity="20.0" k_position="20.0" soft_lower_limit="0.001" soft_upper_limit="0.044" />
    <calibration rising="0.0" falling="0" />
  </joint>
  <link name="gripper_left_left_finger_link">
    <inertial>
      <origin xyz="-0.00447 0.010766 -0.121013" rpy="0.0 0.0 0.0" />
      <mass value="0.10998" />
      <inertia ixx="0.000232" ixy="-5e-06" ixz="-3.2e-05" iyy="0.000224" iyz="3.6e-05" izz="2.9e-05" />
    </inertial>
    <visual>
      <origin xyz="0.0 0.0 0.0" rpy="0.0 0.0 3.1415" />
      <geometry>
        <mesh filename="package://tiago_dual_description/urdf/tiago_dual/obj/gripper_finger_link.obj" />
      </geometry>
      </visual>
    <collision>
      <origin xyz="-0.005 0.0 -0.165" rpy="0.0 0.0 3.1415" />
      <geometry>
        <box size="0.01 0.05 0.11" />
      </geometry>
    </collision>
  </link>
  <joint name="gripper_left_grasping_frame_joint" type="fixed">
    <origin xyz="0.0 0.0 -0.12" rpy="-1.5708 1.5708 0.0" />
    <parent link="gripper_left_link" />
    <child link="gripper_left_grasping_frame" />
  </joint>
  <link name="gripper_left_grasping_frame">
    <inertial>
      <origin xyz="0.0 0.0 0.0" rpy="0.0 0.0 0.0" />
      <mass value="0.0001" />
      <inertia ixx="1e-05" ixy="0.0" ixz="0.0" iyy="1e-05" iyz="0.0" izz="1e-05" />
    </inertial>
  </link>
  <joint name="arm_right_1_joint" type="revolute">
    <origin xyz="0.02556 -0.19 -0.171" rpy="0.0 0.0 -1.5707963267948966" />
    <axis xyz="0.0 0.0 1.0" />
    <parent link="torso_lift_link" />
    <child link="arm_right_1_link" />
    <limit effort="43.0" lower="-1.1780972450961724" upper="1.5707963267948966" velocity="1.95" />
    <dynamics damping="1.0" friction="1.0" />
    <safety_controller k_velocity="20.0" k_position="20.0" soft_lower_limit="-1.1080972450961724" soft_upper_limit="1.5007963267948965" />
  </joint>
  <link name="arm_right_1_link">
    <inertial>
      <origin xyz="0.061191 -0.022397 -0.012835" rpy="0.0 0.0 0.0" />
      <mass value="1.563428" />
      <inertia ixx="0.002471" ixy="-0.001809" ixz="-0.001202" iyy="0.006132" iyz="0.000494" izz="0.006704" />
    </inertial>
    <visual>
      <origin xyz="0.0 0.0 0.0" rpy="0.0 0.0 0.0" />
      <geometry>
        <mesh filename="package://tiago_dual_description/urdf/tiago_dual/obj/arm_1.obj" scale="1.0 -1.0 1.0" />
      </geometry>
      </visual>
    <collision>
      <origin xyz="0.0 0.0 0.0" rpy="0.0 0.0 0.0" />
      <geometry>
        <mesh filename="package://tiago_dual_description/urdf/tiago_dual/stl/arm_1_collision.stl" scale="1.0 -1.0 1.0" />
      </geometry>
    </collision>
  </link>
  <joint name="arm_right_2_joint" type="revolute">
    <origin xyz="0.125 -0.0195 -0.031" rpy="-1.5707963267948966 0.0 0.0" />
    <axis xyz="0.0 0.0 1.0" />
    <parent link="arm_right_1_link" />
    <child link="arm_right_2_link" />
    <limit effort="43.0" lower="-1.1780972450961724" upper="1.5707963267948966" velocity="1.95" />
    <dynamics damping="1.0" friction="1.0" />
    <safety_controller k_velocity="20.0" k_position="20.0" soft_lower_limit="-1.1080972450961724" soft_upper_limit="1.5007963267948965" />
  </joint>
  <link name="arm_right_2_link">
    <inertial>
      <origin xyz="0.030432 0.000229 -0.005942" rpy="0.0 0.0 0.0" />
      <mass value="1.800397" />
      <inertia ixx="0.001809" ixy="1.5e-05" ixz="0.000254" iyy="0.004333" iyz="1.4e-05" izz="0.004341" />
    </inertial>
    <visual>
      <origin xyz="0.0 0.0 0.0" rpy="0.0 0.0 0.0" />
      <geometry>
        <mesh filename="package://tiago_dual_description/urdf/tiago_dual/obj/arm_2.obj" scale="1.0 1.0 1.0" />
      </geometry>
      </visual>
    <collision>
      <origin xyz="0.0 0.0 0.0" rpy="0.0 0.0 0.0" />
      <geometry>
        <mesh filename="package://tiago_dual_description/urdf/tiago_dual/stl/arm_2_collision.stl" scale="1.0 1.0 1.0" />
      </geometry>
    </collision>
  </link>
  <joint name="arm_right_3_joint" type="revolute">
    <origin xyz="0.0895 0.0 -0.0015" rpy="-1.5707963267948966 0.0 1.5707963267948966" />
    <axis xyz="0.0 0.0 1.0" />
    <parent link="arm_right_2_link" />
    <child link="arm_right_3_link" />
    <limit effort="26.0" lower="-0.7853981633974483" upper="3.9269908169872414" velocity="2.35" />
    <dynamics damping="1.0" friction="1.0" />
    <safety_controller k_velocity="20.0" k_position="20.0" soft_lower_limit="-0.7153981633974482" soft_upper_limit="3.8569908169872416" />
  </joint>
  <link name="arm_right_3_link">
    <inertial>
      <origin xyz="0.007418 -0.004361 -0.134194" rpy="0.0 0.0 0.0" />
      <mass value="1.8" />
      <inertia ixx="0.019541" ixy="-0.000105" ixz="-0.001717" iyy="0.019936" iyz="0.000852" izz="0.002864" />
    </inertial>
    <visual>
      <origin xyz="0.0 0.0 0.0" rpy="0.0 0.0 0.0" />
      <geometry>
        <mesh filename="package://tiago_dual_description/urdf/tiago_dual/obj/arm_3.obj" scale="1.0 1.0 1.0" />
      </geometry>
      </visual>
    <collision>
      <origin xyz="0.0 0.0 0.0" rpy="0.0 0.0 0.0" />
      <geometry>
        <mesh filename="package://tiago_dual_description/urdf/tiago_dual/stl/arm_3_collision.stl" scale="1.0 1.0 1.0" />
      </geometry>
    </collision>
  </link>
  <joint name="arm_right_4_joint" type="revolute">
    <origin xyz="-0.02 -0.027 -0.222" rpy="-1.5707963267948966 -1.5707963267948966 0.0" />
    <axis xyz="0.0 0.0 1.0" />
    <parent link="arm_right_3_link" />
    <child link="arm_right_4_link" />
    <limit effort="26.0" lower="-0.39269908169872414" upper="2.356194490192345" velocity="2.35" />
    <dynamics damping="1.0" friction="1.0" />
    <safety_controller k_velocity="20.0" k_position="20.0" soft_lower_limit="-0.32269908169872413" soft_upper_limit="2.286194490192345" />
  </joint>
  <link name="arm_right_4_link">
    <inertial>
      <origin xyz="-0.095658 0.014666 0.018133" rpy="0.0 0.0 0.0" />
      <mass value="1.432697" />
      <inertia ixx="0.00204" ixy="0.000725" ixz="-0.00115" iyy="0.008424" iyz="-0.000204" izz="0.008686" />
    </inertial>
    <visual>
      <origin xyz="0.0 0.0 0.0" rpy="0.0 0.0 0.0" />
      <geometry>
        <mesh filename="package://tiago_dual_description/urdf/tiago_dual/obj/arm_4.obj" scale="1.0 1.0 1.0" />
      </geometry>
      </visual>
    <collision>
      <origin xyz="0.0 0.0 0.0" rpy="0.0 0.0 0.0" />
      <geometry>
        <mesh filename="package://tiago_dual_description/urdf/tiago_dual/stl/arm_4_collision.stl" scale="1.0 1.0 1.0" />
      </geometry>
    </collision>
  </link>
  <joint name="arm_right_5_joint" type="revolute">
    <origin xyz="-0.162 0.02 0.027" rpy="1.5707963267948966 -1.5707963267948966 -1.5707963267948966" />
    <axis xyz="0.0 0.0 1.0" />
    <parent link="arm_right_4_link" />
    <child link="arm_right_5_link" />
    <limit effort="3.0" lower="-2.0943951023931953" upper="2.0943951023931953" velocity="1.95" />
    <dynamics damping="1.0" friction="1.0" />
    <safety_controller k_velocity="20.0" k_position="20.0" soft_lower_limit="-2.0743951023931952" soft_upper_limit="2.0743951023931952" />
  </joint>
  <link name="arm_right_5_link">
    <inertial>
      <origin xyz="0.001078 -0.000151 -0.077173" rpy="0.0 0.0 0.0" />
      <mass value="0.9359143689" />
      <inertia ixx="0.001036187977" ixy="1.0622321e-07" ixz="1.9920336e-06" iyy="0.000794527176366096" iyz="-2.56396106998404e-07" izz="0.000439831229979178" />
    </inertial>
    <visual>
      <origin xyz="0.0 0.0 0.0" rpy="0.0 0.0 0.0" />
      <geometry>
        <mesh filename="package://tiago_dual_description/urdf/tiago_dual/obj/arm_5-wrist-2017.obj" scale="1.0 1.0 1.0" />
      </geometry>
      </visual>
    <collision>
      <origin xyz="0.0 0.0 0.0" rpy="0.0 0.0 0.0" />
      <geometry>
        <mesh filename="package://tiago_dual_description/urdf/tiago_dual/stl/arm_5_collision-wrist-2017.stl" scale="1.0 1.0 1.0" />
      </geometry>
    </collision>
  </link>
  <joint name="arm_right_6_joint" type="revolute">
    <origin xyz="0.0 0.0 0.15" rpy="0.0 -1.5707963267948966 -1.5707963267948966" />
    <axis xyz="0.0 0.0 1.0" />
    <parent link="arm_right_5_link" />
    <child link="arm_right_6_link" />
    <limit effort="6.6" lower="-1.413716694115407" upper="1.413716694115407" velocity="1.76" />
    <dynamics damping="1.0" friction="1.0" />
    <safety_controller k_velocity="20.0" k_position="20.0" soft_lower_limit="-1.3937166941154069" soft_upper_limit="1.3937166941154069" />
  </joint>
  <link name="arm_right_6_link">
    <inertial>
      <origin xyz="-0.000153 -0.003122 0.000183" rpy="0.0 0.0 0.0" />
      <mass value="0.30275767222" />
      <inertia ixx="3.29233557e-05" ixy="6.31537395e-08" ixz="-4.567124912e-11" iyy="3.85334410118923e-05" iyz="-2.01613082836742e-07" izz="3.33282849168039e-05" />
    </inertial>
    <visual>
      <origin xyz="0.0 0.0 0.0" rpy="0.0 0.0 0.0" />
      <geometry>
        <mesh filename="package://tiago_dual_description/urdf/tiago_dual/obj/arm_6-wrist-2017.obj" scale="1.0 1.0 1.0" />
      </geometry>
      </visual>
    <collision>
      <origin xyz="0.0 0.0 0.0" rpy="0.0 0.0 0.0" />
      <geometry>
        <mesh filename="package://tiago_dual_description/urdf/tiago_dual/stl/arm_6_collision-wrist-2017.stl" scale="1.0 1.0 1.0" />
      </geometry>
    </collision>
  </link>
  <joint name="arm_right_7_joint" type="revolute">
    <origin xyz="0.0 0.0 0.0" rpy="1.5707963267948966 0.0 1.5707963267948966" />
    <axis xyz="0.0 0.0 1.0" />
    <parent link="arm_right_6_link" />
    <child link="arm_right_7_link" />
    <limit effort="6.6" lower="-2.0943951023931953" upper="2.0943951023931953" velocity="1.76" />
    <dynamics damping="1.0" friction="1.0" />
    <safety_controller k_velocity="20.0" k_position="20.0" soft_lower_limit="-2.0743951023931952" soft_upper_limit="2.0743951023931952" />
  </joint>
  <link name="arm_right_7_link">
    <inertial>
      <origin xyz="1e-05 -3e-06 -0.007774" rpy="0.0 0.0 0.0" />
      <mass value="0.1" />
      <inertia ixx="1.14959795e-05" ixy="-1.390727219e-07" ixz="5.930207406e-09" iyy="1.13594084240734e-05" iyz="-1.78396260812528e-08" izz="2.01898984804048e-05" />
    </inertial>
  </link>
  <joint name="arm_right_tool_joint" type="fixed">
    <origin xyz="0.0 0.0 0.046" rpy="1.5707963267948966 -1.5707963267948966 3.141592653589793" />
    <parent link="arm_right_7_link" />
    <child link="arm_right_tool_link" />
  </joint>
  <link name="arm_right_tool_link">
    <inertial>
      <mass value="0.1" />
      <inertia ixx="8.33e-07" ixy="0.0" ixz="0.0" iyy="8.33e-07" iyz="0.0" izz="1.25e-06" />
    </inertial>
    <visual>
      <origin xyz="0.001 0.0 0.0" rpy="0.0 1.5707963267948966 0.0" />
      <geometry>
        <cylinder radius="0.005" length="0.005" />
      </geometry>
      </visual>
    <collision>
      <origin xyz="0.001 0.0 0.0" rpy="0.0 1.5707963267948966 0.0" />
      <geometry>
        <cylinder radius="0.005" length="0.005" />
      </geometry>
    </collision>
  </link>
  <joint name="wrist_right_ft_joint" type="fixed">
    <origin xyz="0.00785 0.0 0.0" rpy="1.5707963267948966 0.0 1.5707963267948966" />
    <parent link="arm_right_tool_link" />
    <child link="wrist_right_ft_link" />
  </joint>
  <link name="wrist_right_ft_link">
    <inertial>
      <mass value="0.1" />
      <inertia ixx="1.6e-05" ixy="-2e-06" ixz="0.0" iyy="1.6e-05" iyz="0.0" izz="2.7e-05" />
    </inertial>
    <visual>
      <origin xyz="0.0 0.0 0.0" rpy="0.0 0.0 0.0" />
      <geometry>
        <cylinder radius="0.0225" length="0.0157" />
      </geometry>
      </visual>
    <collision>
      <origin xyz="0.0 0.0 0.0" rpy="0.0 0.0 0.0" />
      <geometry>
        <cylinder radius="0.0225" length="0.0157" />
      </geometry>
    </collision>
  </link>
  <joint name="wrist_right_tool_joint" type="fixed">
    <origin xyz="0.0 0.0 0.012725" rpy="-1.5707963267948966 -1.5707963267948966 0.0" />
    <parent link="wrist_right_ft_link" />
    <child link="wrist_right_ft_tool_link" />
  </joint>
  <link name="wrist_right_ft_tool_link">
    <inertial>
      <mass value="0.1" />
      <inertia ixx="1.64e-05" ixy="0.0" ixz="0.0" iyy="1.64e-05" iyz="0.0" izz="3.125e-05" />
    </inertial>
    <visual>
      <origin xyz="0.0 0.0 0.0" rpy="0.0 1.5707963267948966 0.0" />
      <geometry>
        <cylinder radius="0.025" length="0.00975" />
      </geometry>
      </visual>
    <collision>
      <origin xyz="0.0 0.0 0.0" rpy="0.0 1.5707963267948966 0.0" />
      <geometry>
        <cylinder radius="0.025" length="0.00975" />
      </geometry>
    </collision>
  </link>
  <joint name="gripper_right_tool_joint" type="fixed">
    <origin xyz="0.01 0.0 0.0" rpy="1.5707963267948966 1.5707963267948966 -1.5707963267948966" />
    <axis xyz="0.0 0.0 0.0" />
    <parent link="wrist_right_ft_tool_link" />
    <child link="gripper_right_tool_link" />
  </joint>
  <link name="gripper_right_tool_link">
    <inertial>
      <origin xyz="0.0 0.0 0.0" rpy="0.0 0.0 0.0" />
      <mass value="0.0001" />
      <inertia ixx="1e-05" ixy="0.0" ixz="0.0" iyy="1e-05" iyz="0.0" izz="1e-05" />
    </inertial>
  </link>
  <joint name="gripper_right_joint" type="fixed">
    <origin xyz="0.01 0.0 0.0" rpy="1.5707963267948966 1.5707963267948966 -1.5707963267948966" />
    <axis xyz="0.0 0.0 0.0" />
    <parent link="wrist_right_ft_tool_link" />
    <child link="gripper_right_link" />
  </joint>
  <link name="gripper_right_link">
    <inertial>
      <origin xyz="-0.000294 0.000291 -0.033086" rpy="0.0 0.0 0.0" />
      <mass value="0.60266" />
      <inertia ixx="0.000693" ixy="4.5e-05" ixz="-0.0" iyy="0.001024" iyz="0.0" izz="0.000672" />
    </inertial>
    <visual>
      <origin xyz="0.0 0.0 0.0" rpy="0.0 0.0 0.0" />
      <geometry>
        <mesh filename="package://tiago_dual_description/urdf/tiago_dual/obj/gripper_link.obj" />
      </geometry>
      </visual>
    <collision>
      <origin xyz="0.0 0.0 0.0" rpy="0.0 0.0 0.0" />
      <geometry>
        <mesh filename="package://tiago_dual_description/urdf/tiago_dual/stl/gripper_link_collision.stl" />
      </geometry>
    </collision>
  </link>
  <joint name="gripper_right_right_finger_joint" type="prismatic">
    <origin xyz="0.0 0.0 0.0" rpy="0.0 0.0 0.0" />
    <axis xyz="1.0 0.0 0.0" />
    <parent link="gripper_right_link" />
    <child link="gripper_right_right_finger_link" />
    <limit effort="16.0" lower="0.0" upper="0.045" velocity="0.05" />
    <dynamics damping="80.0" />
    <safety_controller k_velocity="20.0" k_position="20.0" soft_lower_limit="0.001" soft_upper_limit="0.044" />
    <calibration rising="0.0" falling="0" />
  </joint>
  <link name="gripper_right_right_finger_link">
    <inertial>
      <origin xyz="-0.00447 0.010766 -0.121013" rpy="0.0 0.0 0.0" />
      <mass value="0.10998" />
      <inertia ixx="0.000232" ixy="-5e-06" ixz="-3.2e-05" iyy="0.000224" iyz="3.6e-05" izz="2.9e-05" />
    </inertial>
    <visual>
      <origin xyz="0.0 0.0 0.0" rpy="0.0 0.0 3.1415" />
      <geometry>
        <mesh filename="package://tiago_dual_description/urdf/tiago_dual/obj/gripper_finger_link.obj" scale="-1.0 -1.0 1.0" />
      </geometry>
      </visual>
    <collision>
      <origin xyz="0.005 0.0 -0.165" rpy="0.0 0.0 3.1415" />
      <geometry>
        <box size="0.01 0.05 0.11" />
      </geometry>
    </collision>
  </link>
  <joint name="gripper_right_left_finger_joint" type="prismatic">
    <origin xyz="0.0 0.0 0.0" rpy="0.0 0.0 0.0" />
    <axis xyz="-1.0 0.0 0.0" />
    <parent link="gripper_right_link" />
    <child link="gripper_right_left_finger_link" />
    <limit effort="16.0" lower="0.0" upper="0.045" velocity="0.05" />
    <dynamics damping="80.0" />
    <safety_controller k_velocity="20.0" k_position="20.0" soft_lower_limit="0.001" soft_upper_limit="0.044" />
    <calibration rising="0.0" falling="0" />
  </joint>
  <link name="gripper_right_left_finger_link">
    <inertial>
      <origin xyz="-0.00447 0.010766 -0.121013" rpy="0.0 0.0 0.0" />
      <mass value="0.10998" />
      <inertia ixx="0.000232" ixy="-5e-06" ixz="-3.2e-05" iyy="0.000224" iyz="3.6e-05" izz="2.9e-05" />
    </inertial>
    <visual>
      <origin xyz="0.0 0.0 0.0" rpy="0.0 0.0 3.1415" />
      <geometry>
        <mesh filename="package://tiago_dual_description/urdf/tiago_dual/obj/gripper_finger_link.obj" />
      </geometry>
      </visual>
    <collision>
      <origin xyz="-0.005 0.0 -0.165" rpy="0.0 0.0 3.1415" />
      <geometry>
        <box size="0.01 0.05 0.11" />
      </geometry>
    </collision>
  </link>
  <joint name="gripper_right_grasping_frame_joint" type="fixed">
    <origin xyz="0.0 0.0 -0.12" rpy="-1.5708 1.5708 0.0" />
    <parent link="gripper_right_link" />
    <child link="gripper_right_grasping_frame" />
  </joint>
  <link name="gripper_right_grasping_frame">
    <inertial>
      <origin xyz="0.0 0.0 0.0" rpy="0.0 0.0 0.0" />
      <mass value="0.0001" />
      <inertia ixx="1e-05" ixy="0.0" ixz="0.0" iyy="1e-05" iyz="0.0" izz="1e-05" />
    </inertial>
  </link>
  <joint name="rgbd_laser_joint" type="fixed">
    <origin xyz="-0.9 0.0 0.0" rpy="0.0 0.0 0.0" />
    <parent link="base_footprint" />
    <child link="rgbd_laser_link" />
  </joint>
  <link name="rgbd_laser_link">
    <inertial>
      <origin xyz="0.0 0.0 0.0" rpy="0.0 0.0 0.0" />
      <mass value="0.0001" />
      <inertia ixx="0.0001" ixy="0.0" ixz="0.0" iyy="0.0001" iyz="0.0" izz="0.0001" />
    </inertial>
  </link>
</robot>