<?xml version="1.0" ?>
<robot name="tiago_dual" version="1.0">
  <link name="base_footprint"/>
  <joint name="base_link_joint" type="fixed">
    <origin xyz="0.0 0.0 0.0985" rpy="0.0 -0.0 0.0"/>
    <parent link="base_footprint"/>
    <child link="base_link"/>
  </joint>
  <link name="base_link">
    <collision name="base_collision">
      <origin xyz="0.0 0.0 0.0" rpy="0.0 -0.0 0.0"/>
      <geometry>
        <mesh filename="package://pycram/resources/tiago_dual/stl/base_collision.stl" scale="1.0 1.0 1.0"/>
      </geometry>
    </collision>
  </link>
  <joint name="base_laser_link_joint" type="fixed">
    <origin xyz="0.202 0.0 -0.004" rpy="0.0 -0.0 0.0"/>
    <parent link="base_link"/>
    <child link="base_laser_link"/>
  </joint>
  <link name="base_laser_link"/>
  <joint name="base_sonar_03_link_joint" type="fixed">
    <origin xyz="-0.183 0.183 0.173" rpy="0.0 -0.0 2.356194490192345"/>
    <parent link="base_link"/>
    <child link="base_sonar_03_link"/>
  </joint>
  <link name="base_sonar_03_link"/>
  <joint name="base_sonar_02_link_joint" type="fixed">
    <origin xyz="-0.259 0.0 0.173" rpy="0.0 -0.0 3.141592653589793"/>
    <parent link="base_link"/>
    <child link="base_sonar_02_link"/>
  </joint>
  <link name="base_sonar_02_link"/>
  <joint name="base_sonar_01_link_joint" type="fixed">
    <origin xyz="-0.183 -0.183 0.173" rpy="0.0 -0.0 -2.356194490192345"/>
    <parent link="base_link"/>
    <child link="base_sonar_01_link"/>
  </joint>
  <link name="base_sonar_01_link"/>
  <joint name="base_mic_front_left_link_joint" type="fixed">
    <origin xyz="0.23182 0.03902 0.195" rpy="0.0 -0.0 0.0"/>
    <parent link="base_link"/>
    <child link="base_mic_front_left_link"/>
  </joint>
  <link name="base_mic_front_left_link"/>
  <joint name="base_mic_front_right_link_joint" type="fixed">
    <origin xyz="0.23182 -0.03902 0.195" rpy="0.0 -0.0 0.0"/>
    <parent link="base_link"/>
    <child link="base_mic_front_right_link"/>
  </joint>
  <link name="base_mic_front_right_link"/>
  <joint name="base_mic_back_left_link_joint" type="fixed">
    <origin xyz="-0.1082 -0.0599 0.195" rpy="0.0 -0.0 0.0"/>
    <parent link="base_link"/>
    <child link="base_mic_back_left_link"/>
  </joint>
  <link name="base_mic_back_left_link"/>
  <joint name="base_mic_back_right_link_joint" type="fixed">
    <origin xyz="-0.1082 -0.13789 0.195" rpy="0.0 -0.0 0.0"/>
    <parent link="base_link"/>
    <child link="base_mic_back_right_link"/>
  </joint>
  <link name="base_mic_back_right_link"/>
  <joint name="base_antenna_left_link_joint" type="fixed">
    <origin xyz="-0.201 0.1062 0.195" rpy="0.0 -0.0 0.0"/>
    <parent link="base_link"/>
    <child link="base_antenna_left_link"/>
  </joint>
  <link name="base_antenna_left_link">
    <collision name="base_antenna_left_link_collision_0">
      <origin xyz="0.0 0.0 0.085" rpy="0.0 -0.0 0.0"/>
      <geometry>
        <cylinder radius="0.005" length="0.17"/>
      </geometry>
    </collision>
  </link>
  <joint name="base_antenna_right_link_joint" type="fixed">
    <origin xyz="-0.201 -0.1062 0.195" rpy="0.0 -0.0 0.0"/>
    <parent link="base_link"/>
    <child link="base_antenna_right_link"/>
  </joint>
  <link name="base_antenna_right_link">
    <collision name="base_antenna_right_link_collision_0">
      <origin xyz="0.0 0.0 0.085" rpy="0.0 -0.0 0.0"/>
      <geometry>
        <cylinder radius="0.005" length="0.17"/>
      </geometry>
    </collision>
  </link>
  <joint name="base_imu_link_joint" type="fixed">
    <origin xyz="0.10171 0.0 0.11282" rpy="0.0 0.0 -1.5707963267948966"/>
    <parent link="base_link"/>
    <child link="base_imu_link"/>
  </joint>
  <link name="base_imu_link"/>
  <joint name="suspension_right_joint" type="prismatic">
    <origin xyz="0.0 0.0 0.0" rpy="0.0 -0.0 0.0"/>
    <axis xyz="0 0 1"/>
    <parent link="base_link"/>
    <child link="suspension_right_link"/>
    <limit effort="1000" lower="-0.004999999888241291" upper="0.004999999888241291" velocity="1000"/>
  </joint>
  <link name="suspension_right_link"/>
  <joint name="wheel_right_joint" type="continuous">
    <origin xyz="0.0 -0.2021999955177307 0.0" rpy="-1.5707963267948966 0.0 0.0"/>
    <axis xyz="0 0 1"/>
    <parent link="suspension_right_link"/>
    <child link="wheel_right_link"/>
  </joint>
  <link name="wheel_right_link">
    <collision name="wheel_right_link_collision_0">
      <origin xyz="0.0 0.0 0.0" rpy="0.0 -0.0 0.0"/>
      <geometry>
        <sphere radius="0.0985"/>
      </geometry>
    </collision>
  </link>
  <joint name="suspension_left_joint" type="prismatic">
    <origin xyz="0.0 0.0 0.0" rpy="0.0 -0.0 0.0"/>
    <axis xyz="0 0 1"/>
    <parent link="base_link"/>
    <child link="suspension_left_link"/>
    <limit effort="1000" lower="-0.004999999888241291" upper="0.004999999888241291" velocity="1000"/>
  </joint>
  <link name="suspension_left_link"/>
  <joint name="wheel_left_joint" type="continuous">
    <origin xyz="0.0 0.2021999955177307 0.0" rpy="-1.5707963267948966 0.0 0.0"/>
    <axis xyz="0 0 1"/>
    <parent link="suspension_left_link"/>
    <child link="wheel_left_link"/>
  </joint>
  <link name="wheel_left_link">
    <collision name="wheel_left_link_collision_0">
      <origin xyz="0.0 0.0 0.0" rpy="0.0 -0.0 0.0"/>
      <geometry>
        <sphere radius="0.0985"/>
      </geometry>
    </collision>
  </link>
  <joint name="caster_front_right_1_joint" type="continuous">
    <origin xyz="0.16949999332427979 -0.10199999809265137 -0.03350000083446503" rpy="0.0 -0.0 0.0"/>
    <axis xyz="0 0 1"/>
    <parent link="base_link"/>
    <child link="caster_front_right_1_link"/>
  </joint>
  <link name="caster_front_right_1_link"/>
  <joint name="caster_front_right_2_joint" type="continuous">
    <origin xyz="-0.01600000075995922 0.0 -0.03999999910593033" rpy="-1.5707963267948966 0.0 0.0"/>
    <axis xyz="0 0 1"/>
    <parent link="caster_front_right_1_link"/>
    <child link="caster_front_right_2_link"/>
  </joint>
  <link name="caster_front_right_2_link">
    <collision name="caster_front_right_2_link_collision_0">
      <origin xyz="0.0 0.0 0.0" rpy="0.0 -0.0 0.0"/>
      <geometry>
        <sphere radius="0.025"/>
      </geometry>
    </collision>
  </link>
  <joint name="caster_front_left_1_joint" type="continuous">
    <origin xyz="0.16949999332427979 0.10199999809265137 -0.03350000083446503" rpy="0.0 -0.0 0.0"/>
    <axis xyz="0 0 1"/>
    <parent link="base_link"/>
    <child link="caster_front_left_1_link"/>
  </joint>
  <link name="caster_front_left_1_link"/>
  <joint name="caster_front_left_2_joint" type="continuous">
    <origin xyz="-0.01600000075995922 0.0 -0.03999999910593033" rpy="-1.5707963267948966 0.0 0.0"/>
    <axis xyz="0 0 1"/>
    <parent link="caster_front_left_1_link"/>
    <child link="caster_front_left_2_link"/>
  </joint>
  <link name="caster_front_left_2_link">
    <collision name="caster_front_left_2_link_collision_0">
      <origin xyz="0.0 0.0 0.0" rpy="0.0 -0.0 0.0"/>
      <geometry>
        <sphere radius="0.025"/>
      </geometry>
    </collision>
  </link>
  <joint name="caster_back_right_1_joint" type="continuous">
    <origin xyz="-0.17350000143051147 -0.10199999809265137 -0.03350000083446503" rpy="0.0 -0.0 0.0"/>
    <axis xyz="0 0 1"/>
    <parent link="base_link"/>
    <child link="caster_back_right_1_link"/>
  </joint>
  <link name="caster_back_right_1_link"/>
  <joint name="caster_back_right_2_joint" type="continuous">
    <origin xyz="-0.01600000075995922 0.0 -0.03999999910593033" rpy="-1.5707963267948966 0.0 0.0"/>
    <axis xyz="0 0 1"/>
    <parent link="caster_back_right_1_link"/>
    <child link="caster_back_right_2_link"/>
  </joint>
  <link name="caster_back_right_2_link">
    <collision name="caster_back_right_2_link_collision_0">
      <origin xyz="0.0 0.0 0.0" rpy="0.0 -0.0 0.0"/>
      <geometry>
        <sphere radius="0.025"/>
      </geometry>
    </collision>
  </link>
  <joint name="caster_back_left_1_joint" type="continuous">
    <origin xyz="-0.17350000143051147 0.10199999809265137 -0.03350000083446503" rpy="0.0 -0.0 0.0"/>
    <axis xyz="0 0 1"/>
    <parent link="base_link"/>
    <child link="caster_back_left_1_link"/>
  </joint>
  <link name="caster_back_left_1_link"/>
  <joint name="caster_back_left_2_joint" type="continuous">
    <origin xyz="-0.01600000075995922 0.0 -0.03999999910593033" rpy="-1.5707963267948966 0.0 0.0"/>
    <axis xyz="0 0 1"/>
    <parent link="caster_back_left_1_link"/>
    <child link="caster_back_left_2_link"/>
  </joint>
  <link name="caster_back_left_2_link">
    <collision name="caster_back_left_2_link_collision_0">
      <origin xyz="0.0 0.0 0.0" rpy="0.0 -0.0 0.0"/>
      <geometry>
        <sphere radius="0.025"/>
      </geometry>
    </collision>
  </link>
  <joint name="torso_fixed_link_joint" type="fixed">
    <origin xyz="-0.062 0.0 0.193" rpy="0.0 -0.0 0.0"/>
    <parent link="base_link"/>
    <child link="torso_fixed_link"/>
  </joint>
  <link name="torso_fixed_link">
    <collision name="torso_fixed_link_collision_0">
      <origin xyz="0.085 0.0 0.02" rpy="0.0 -0.0 0.0"/>
      <geometry>
        <box size="0.4 0.25 0.04"/>
      </geometry>
    </collision>
    <collision name="torso_fixed_link_collision_1">
      <origin xyz="0.0 0.0 0.05" rpy="0.0 -0.0 0.0"/>
      <geometry>
        <box size="0.25 0.25 0.1"/>
      </geometry>
    </collision>
  </link>
  <joint name="torso_lift_joint" type="prismatic">
    <origin xyz="0.0 0.0 0.597000002861023" rpy="0.0 -0.0 0.0"/>
    <axis xyz="0 0 1"/>
    <parent link="torso_fixed_link"/>
    <child link="torso_lift_link"/>
    <limit effort="1000" lower="0.0" upper="0.3499999940395355" velocity="1000"/>
  </joint>
  <link name="torso_lift_link">
    <collision name="torso_lift_collision_core">
      <origin xyz="0.0 0.0 0.0" rpy="0.0 -0.0 0.0"/>
      <geometry>
        <mesh filename="package://pycram/resources/tiago_dual/stl/torso_lift_collision_core.stl" scale="1.0 1.0 1.0"/>
      </geometry>
    </collision>
    <collision name="torso_lift_collision_neck">
      <origin xyz="0.0 0.0 0.0" rpy="0.0 -0.0 0.0"/>
      <geometry>
        <mesh filename="package://pycram/resources/tiago_dual/stl/torso_lift_collision_neck.stl" scale="1.0 1.0 1.0"/>
      </geometry>
    </collision>
    <collision name="torso_lift_collision_shoulder">
      <origin xyz="-0.131 -0.19 -0.02556" rpy="0.0 -0.0 0.0"/>
      <geometry>
        <mesh filename="package://pycram/resources/tiago_dual/stl/torso_lift_collision_shoulder.stl" scale="1.0 1.0 1.0"/>
      </geometry>
    </collision>
    <collision name="torso_lift_collision_shoulder">
      <origin xyz="-0.131 0.17 -0.02556" rpy="0.0 -0.0 0.0"/>
      <geometry>
        <mesh filename="package://pycram/resources/tiago_dual/stl/torso_lift_collision_shoulder.stl" scale="1.0 1.0 1.0"/>
      </geometry>
    </collision>
  </link>
  <joint name="head_1_joint" type="revolute">
    <origin xyz="0.18199999630451202 0.0 0.0" rpy="0.0 -0.0 0.0"/>
    <axis xyz="0 0 1"/>
    <parent link="torso_lift_link"/>
    <child link="head_1_link"/>
    <limit effort="1000" lower="-1.3089969389957472" upper="1.3089969389957472" velocity="1000"/>
  </joint>
  <link name="head_1_link">
    <collision name="head_1_collision">
      <origin xyz="0.0 0.0 0.0" rpy="0.0 -0.0 0.0"/>
      <geometry>
        <mesh filename="package://pycram/resources/tiago_dual/stl/head_1_collision.stl" scale="1.0 1.0 1.0"/>
      </geometry>
    </collision>
  </link>
  <joint name="head_2_joint" type="revolute">
    <origin xyz="0.004999999888241291 0.0 0.09799999743700027" rpy="1.5707963267948966 -0.0 0.0"/>
    <axis xyz="0 0 1"/>
    <parent link="head_1_link"/>
    <child link="head_2_link"/>
    <limit effort="1000" lower="-1.0471975511965976" upper="0.7853981633974483" velocity="1000"/>
  </joint>
  <link name="head_2_link">
    <collision name="head_2_collision">
      <origin xyz="0.0 0.0 0.0" rpy="0.0 -0.0 0.0"/>
      <geometry>
        <mesh filename="package://pycram/resources/tiago_dual/stl/head_2_collision.stl" scale="1.0 1.0 1.0"/>
      </geometry>
    </collision>
  </link>
  <joint name="xtion_link_joint" type="fixed">
    <origin xyz="0.0908 0.08 0.0" rpy="-1.5707963267948966 0.0 0.0"/>
    <parent link="head_2_link"/>
    <child link="xtion_link"/>
  </joint>
  <link name="xtion_link"/>
  <joint name="xtion_optical_frame_joint" type="fixed">
    <origin xyz="0.0 0.0 0.0" rpy="-1.5707963267948966 -0.0 -1.5707963267948966"/>
    <parent link="xtion_link"/>
    <child link="xtion_optical_frame"/>
  </joint>
  <link name="xtion_optical_frame"/>
  <joint name="xtion_orbbec_aux_joint_frame_joint" type="fixed">
    <origin xyz="0.0 0.0 0.0" rpy="0.0 -0.0 0.0"/>
    <parent link="xtion_link"/>
    <child link="xtion_orbbec_aux_joint_frame"/>
  </joint>
  <link name="xtion_orbbec_aux_joint_frame"/>
  <joint name="xtion_rgb_frame_joint" type="fixed">
    <origin xyz="0.0 0.022 0.0" rpy="0.0 -0.0 0.0"/>
    <parent link="xtion_orbbec_aux_joint_frame"/>
    <child link="xtion_rgb_frame"/>
  </joint>
  <link name="xtion_rgb_frame"/>
  <joint name="xtion_depth_frame_joint" type="fixed">
    <origin xyz="0.0 0.025 0.0" rpy="0.0 -0.0 0.0"/>
    <parent link="xtion_rgb_frame"/>
    <child link="xtion_depth_frame"/>
  </joint>
  <link name="xtion_depth_frame"/>
  <joint name="xtion_depth_optical_frame_joint" type="fixed">
    <origin xyz="0.0 0.0 0.0" rpy="-1.5707963267948966 -0.0 -1.5707963267948966"/>
    <parent link="xtion_depth_frame"/>
    <child link="xtion_depth_optical_frame"/>
  </joint>
  <link name="xtion_depth_optical_frame"/>
  <joint name="xtion_rgb_optical_frame_joint" type="fixed">
    <origin xyz="0.0 0.0 0.0" rpy="-1.5707963267948966 -0.0 -1.5707963267948966"/>
    <parent link="xtion_rgb_frame"/>
    <child link="xtion_rgb_optical_frame"/>
  </joint>
  <link name="xtion_rgb_optical_frame"/>
  <joint name="arm_left_1_joint" type="revolute">
    <origin xyz="0.02556000091135502 0.1899999976158142 -0.17100000381469727" rpy="3.141592653589793 -0.0 1.5707963267948966"/>
    <axis xyz="0 0 1"/>
    <parent link="torso_lift_link"/>
    <child link="arm_left_1_link"/>
    <limit effort="1000" lower="-1.1780972450961724" upper="1.5707963267948966" velocity="1000"/>
  </joint>
  <link name="arm_left_1_link">
    <collision name="arm_1_collision">
      <origin xyz="0.0 0.0 0.0" rpy="3.141592653589793 -0.0 0.0"/>
      <geometry>
        <mesh filename="package://pycram/resources/tiago_dual/stl/arm_1_collision.stl" scale="1.0 1.0000000000000004 1.0000000000000004"/>
      </geometry>
    </collision>
  </link>
  <joint name="arm_left_2_joint" type="revolute">
    <origin xyz="0.125 -0.019500000402331352 0.03099999949336052" rpy="1.5707963267948966 0.0 0.0"/>
    <axis xyz="0 0 1"/>
    <parent link="arm_left_1_link"/>
    <child link="arm_left_2_link"/>
    <limit effort="1000" lower="-1.1780972450961724" upper="1.5707963267948966" velocity="1000"/>
  </joint>
  <link name="arm_left_2_link">
    <collision name="arm_2_collision">
      <origin xyz="0.0 0.0 0.0" rpy="3.141592653589793 -0.0 3.141592653589793"/>
      <geometry>
        <mesh filename="package://pycram/resources/tiago_dual/stl/arm_2_collision.stl" scale="-0.9999999999999996 1.0 0.9999999999999996"/>
      </geometry>
    </collision>
  </link>
  <joint name="arm_left_3_joint" type="revolute">
    <origin xyz="0.08950000256299973 3.0814879110195774e-33 -0.001500000013038516" rpy="1.5707963267948968 -0.0 1.5707963267948968"/>
    <axis xyz="0 0 1"/>
    <parent link="arm_left_2_link"/>
    <child link="arm_left_3_link"/>
    <limit effort="1000" lower="-0.7853981633974483" upper="3.9269908169872414" velocity="1000"/>
  </joint>
  <link name="arm_left_3_link">
    <collision name="arm_3_collision">
      <origin xyz="0.0 0.0 0.0" rpy="3.141592653589793 -0.0 3.141592653589793"/>
      <geometry>
        <mesh filename="package://pycram/resources/tiago_dual/stl/arm_3_collision.stl" scale="-0.9999999999999996 1.0 0.9999999999999996"/>
      </geometry>
    </collision>
  </link>
  <joint name="arm_left_4_joint" type="revolute">
    <origin xyz="-0.019999999552965164 -0.027000000700354576 0.22200000286102295" rpy="1.5707963267948968 -1.5707963267948963 0.0"/>
    <axis xyz="0 0 1"/>
    <parent link="arm_left_3_link"/>
    <child link="arm_left_4_link"/>
    <limit effort="1000" lower="-0.39269908169872414" upper="2.356194490192345" velocity="1000"/>
  </joint>
  <link name="arm_left_4_link">
    <collision name="arm_4_collision">
      <origin xyz="0.0 0.0 0.0" rpy="0.0 -0.0 3.141592653589793"/>
      <geometry>
        <mesh filename="package://pycram/resources/tiago_dual/stl/arm_4_collision.stl" scale="0.9999999999999996 0.9999999999999996 -1.0"/>
      </geometry>
    </collision>
  </link>
  <joint name="arm_left_5_joint" type="revolute">
    <origin xyz="0.16200000047683716 -0.019999999552965164 -0.027000000700354576" rpy="-0.0 -1.5707963267948966 0.0"/>
    <axis xyz="0 0 1"/>
    <parent link="arm_left_4_link"/>
    <child link="arm_left_5_link"/>
    <limit effort="1000" lower="-2.0943951023931953" upper="2.0943951023931953" velocity="1000"/>
  </joint>
  <link name="arm_left_5_link">
    <collision name="arm_5_collision_wrist_2017">
      <origin xyz="0.0 0.0 0.0" rpy="0.0 -0.0 3.141592653589793"/>
      <geometry>
        <mesh filename="package://pycram/resources/tiago_dual/stl/arm_5_collision_wrist_2017.stl" scale="0.9999999999999996 0.9999999999999996 -1.0"/>
      </geometry>
    </collision>
  </link>
  <joint name="arm_left_6_joint" type="revolute">
    <origin xyz="0.0 0.0 -0.15000000596046448" rpy="-1.5707963267948968 -1.5707963267948963 0.0"/>
    <axis xyz="0 0 1"/>
    <parent link="arm_left_5_link"/>
    <child link="arm_left_6_link"/>
    <limit effort="1000" lower="-1.413716694115407" upper="1.413716694115407" velocity="1000"/>
  </joint>
  <link name="arm_left_6_link">
    <collision name="arm_6_collision_wrist_2017">
      <origin xyz="0.0 0.0 0.0" rpy="0.0 -0.0 3.141592653589793"/>
      <geometry>
        <mesh filename="package://pycram/resources/tiago_dual/stl/arm_6_collision_wrist_2017.stl" scale="0.9999999999999996 -0.9999999999999996 1.0"/>
      </geometry>
    </collision>
  </link>
  <joint name="arm_left_7_joint" type="revolute">
    <origin xyz="0.0 0.0 0.0" rpy="1.5707963267948968 -0.0 1.5707963267948968"/>
    <axis xyz="0 0 1"/>
    <parent link="arm_left_6_link"/>
    <child link="arm_left_7_link"/>
    <limit effort="1000" lower="-2.0943951023931953" upper="2.0943951023931953" velocity="1000"/>
  </joint>
  <link name="arm_left_7_link"/>
  <joint name="arm_left_tool_link_joint" type="fixed">
    <origin xyz="0.0 0.0 -0.046" rpy="-1.5707963267948968 1.5707963267948963 0.0"/>
    <parent link="arm_left_7_link"/>
    <child link="arm_left_tool_link"/>
  </joint>
  <link name="arm_left_tool_link">
    <collision name="arm_left_tool_link_collision_0">
      <origin xyz="0.001 0.0 0.0" rpy="-0.0 1.5707963267948966 0.0"/>
      <geometry>
        <cylinder radius="0.005" length="0.005"/>
      </geometry>
    </collision>
  </link>
  <joint name="wrist_left_ft_link_joint" type="fixed">
    <origin xyz="0.00785 0.0 0.0" rpy="1.5707963267948966 -0.0 1.5707963267948966"/>
    <parent link="arm_left_tool_link"/>
    <child link="wrist_left_ft_link"/>
  </joint>
  <link name="wrist_left_ft_link">
    <collision name="wrist_left_ft_link_collision_0">
      <origin xyz="0.0 0.0 0.0" rpy="0.0 -0.0 0.0"/>
      <geometry>
        <cylinder radius="0.0225" length="0.0157"/>
      </geometry>
    </collision>
  </link>
  <joint name="wrist_left_ft_tool_link_joint" type="fixed">
    <origin xyz="0.0 0.0 0.012725" rpy="-1.5707963267948966 -1.5707963267948966 0.0"/>
    <parent link="wrist_left_ft_link"/>
    <child link="wrist_left_ft_tool_link"/>
  </joint>
  <link name="wrist_left_ft_tool_link">
    <collision name="wrist_left_ft_tool_link_collision_0">
      <origin xyz="0.0 0.0 0.0" rpy="-0.0 1.5707963267948966 0.0"/>
      <geometry>
        <cylinder radius="0.025" length="0.00975"/>
      </geometry>
    </collision>
  </link>
  <joint name="gripper_left_tool_link_joint" type="fixed">
    <origin xyz="0.01 0.0 0.0" rpy="3.141592653589793 1.5707963267948966 0.0"/>
    <parent link="wrist_left_ft_tool_link"/>
    <child link="gripper_left_tool_link"/>
  </joint>
  <link name="gripper_left_tool_link"/>
  <joint name="gripper_left_link_joint" type="fixed">
    <origin xyz="0.01 0.0 0.0" rpy="3.141592653589793 1.5707963267948966 0.0"/>
    <parent link="wrist_left_ft_tool_link"/>
    <child link="gripper_left_link"/>
  </joint>
  <link name="gripper_left_link">
    <collision name="gripper_link_collision">
      <origin xyz="0.0 0.0 0.0" rpy="0.0 -0.0 0.0"/>
      <geometry>
        <mesh filename="package://pycram/resources/tiago_dual/stl/gripper_link_collision.stl" scale="1.0 1.0 1.0"/>
      </geometry>
    </collision>
  </link>
  <joint name="gripper_left_right_finger_joint" type="prismatic">
    <origin xyz="0.0 -6.162975822039155e-33 0.0" rpy="1.3454695115200456e-32 3.316838427515549e-64 -4.930380657631325e-32"/>
    <axis xyz="1 0 0"/>
    <parent link="gripper_left_link"/>
    <child link="gripper_left_right_finger_link"/>
    <limit effort="1000" lower="0.0" upper="0.04500000178813934" velocity="1000"/>
  </joint>
  <link name="gripper_left_right_finger_link">
    <collision name="gripper_left_right_finger_link_collision_0">
      <origin xyz="0.005 0.0 -0.165" rpy="0.0 -0.0 3.141587529888982"/>
      <geometry>
        <box size="0.010000000000000002 0.05 0.11"/>
      </geometry>
    </collision>
  </link>
  <joint name="gripper_left_left_finger_joint" type="prismatic">
    <origin xyz="0.0 -6.162975822039155e-33 0.0" rpy="1.3454695115200456e-32 3.316838427515549e-64 -4.930380657631325e-32"/>
    <axis xyz="-1 0 0"/>
    <parent link="gripper_left_link"/>
    <child link="gripper_left_left_finger_link"/>
    <limit effort="1000" lower="0.0" upper="0.04500000178813934" velocity="1000"/>
  </joint>
  <link name="gripper_left_left_finger_link">
    <collision name="gripper_left_left_finger_link_collision_0">
      <origin xyz="-0.005 0.0 -0.165" rpy="0.0 -0.0 3.141587529888982"/>
      <geometry>
        <box size="0.010000000000000002 0.05 0.11"/>
      </geometry>
    </collision>
  </link>
  <joint name="gripper_left_grasping_frame_joint" type="fixed">
    <origin xyz="0.0 0.0 -0.12" rpy="1.5707926535159558 1.5707926535897936 3.1415926535595684"/>
    <parent link="gripper_left_link"/>
    <child link="gripper_left_grasping_frame"/>
  </joint>
  <link name="gripper_left_grasping_frame"/>
  <joint name="arm_right_1_joint" type="revolute">
    <origin xyz="0.02556000091135502 -0.1899999976158142 -0.17100000381469727" rpy="0.0 0.0 -1.5707963267948966"/>
    <axis xyz="0 0 1"/>
    <parent link="torso_lift_link"/>
    <child link="arm_right_1_link"/>
    <limit effort="1000" lower="-1.1780972450961724" upper="1.5707963267948966" velocity="1000"/>
  </joint>
  <link name="arm_right_1_link">
    <collision name="arm_1_collision">
      <origin xyz="0.0 0.0 0.0" rpy="0.0 -0.0 3.141592653589793"/>
      <geometry>
        <mesh filename="package://pycram/resources/tiago_dual/stl/arm_1_collision.stl" scale="-0.9999999999999996 0.9999999999999996 1.0"/>
      </geometry>
    </collision>
  </link>
  <joint name="arm_right_2_joint" type="revolute">
    <origin xyz="0.125 -0.019500000402331352 -0.03099999949336052" rpy="-1.5707963267948966 0.0 0.0"/>
    <axis xyz="0 0 1"/>
    <parent link="arm_right_1_link"/>
    <child link="arm_right_2_link"/>
    <limit effort="1000" lower="-1.1780972450961724" upper="1.5707963267948966" velocity="1000"/>
  </joint>
  <link name="arm_right_2_link">
    <collision name="arm_2_collision">
      <origin xyz="0.0 0.0 0.0" rpy="0.0 -0.0 0.0"/>
      <geometry>
        <mesh filename="package://pycram/resources/tiago_dual/stl/arm_2_collision.stl" scale="1.0 1.0 1.0"/>
      </geometry>
    </collision>
  </link>
  <joint name="arm_right_3_joint" type="revolute">
    <origin xyz="0.08950000256299973 0.0 -0.001500000013038516" rpy="-1.5707963267948968 -0.0 1.5707963267948968"/>
    <axis xyz="0 0 1"/>
    <parent link="arm_right_2_link"/>
    <child link="arm_right_3_link"/>
    <limit effort="1000" lower="-0.7853981633974483" upper="3.9269908169872414" velocity="1000"/>
  </joint>
  <link name="arm_right_3_link">
    <collision name="arm_3_collision">
      <origin xyz="0.0 0.0 0.0" rpy="0.0 -0.0 0.0"/>
      <geometry>
        <mesh filename="package://pycram/resources/tiago_dual/stl/arm_3_collision.stl" scale="1.0 1.0 1.0"/>
      </geometry>
    </collision>
  </link>
  <joint name="arm_right_4_joint" type="revolute">
    <origin xyz="-0.019999999552965164 -0.027000000700354576 -0.22200000286102295" rpy="-1.5707963267948968 -1.5707963267948963 0.0"/>
    <axis xyz="0 0 1"/>
    <parent link="arm_right_3_link"/>
    <child link="arm_right_4_link"/>
    <limit effort="1000" lower="-0.39269908169872414" upper="2.356194490192345" velocity="1000"/>
  </joint>
  <link name="arm_right_4_link">
    <collision name="arm_4_collision">
      <origin xyz="0.0 0.0 0.0" rpy="0.0 -0.0 0.0"/>
      <geometry>
        <mesh filename="package://pycram/resources/tiago_dual/stl/arm_4_collision.stl" scale="1.0 1.0 1.0"/>
      </geometry>
    </collision>
  </link>
  <joint name="arm_right_5_joint" type="revolute">
    <origin xyz="-0.16200000047683716 0.019999999552965164 0.027000000700354576" rpy="-0.0 -1.5707963267948966 0.0"/>
    <axis xyz="0 0 1"/>
    <parent link="arm_right_4_link"/>
    <child link="arm_right_5_link"/>
    <limit effort="1000" lower="-2.0943951023931953" upper="2.0943951023931953" velocity="1000"/>
  </joint>
  <link name="arm_right_5_link">
    <collision name="arm_5_collision_wrist_2017">
      <origin xyz="0.0 0.0 0.0" rpy="0.0 -0.0 0.0"/>
      <geometry>
        <mesh filename="package://pycram/resources/tiago_dual/stl/arm_5_collision_wrist_2017.stl" scale="1.0 1.0 1.0"/>
      </geometry>
    </collision>
  </link>
  <joint name="arm_right_6_joint" type="revolute">
    <origin xyz="-0.0 -0.0 0.15000000596046448" rpy="-1.5707963267948968 -1.5707963267948963 0.0"/>
    <axis xyz="0 0 1"/>
    <parent link="arm_right_5_link"/>
    <child link="arm_right_6_link"/>
    <limit effort="1000" lower="-1.413716694115407" upper="1.413716694115407" velocity="1000"/>
  </joint>
  <link name="arm_right_6_link">
    <collision name="arm_6_collision_wrist_2017">
      <origin xyz="0.0 0.0 0.0" rpy="0.0 -0.0 0.0"/>
      <geometry>
        <mesh filename="package://pycram/resources/tiago_dual/stl/arm_6_collision_wrist_2017.stl" scale="1.0 1.0 1.0"/>
      </geometry>
    </collision>
  </link>
  <joint name="arm_right_7_joint" type="revolute">
    <origin xyz="0.0 0.0 0.0" rpy="1.5707963267948968 -0.0 1.5707963267948968"/>
    <axis xyz="0 0 1"/>
    <parent link="arm_right_6_link"/>
    <child link="arm_right_7_link"/>
    <limit effort="1000" lower="-2.0943951023931953" upper="2.0943951023931953" velocity="1000"/>
  </joint>
  <link name="arm_right_7_link"/>
  <joint name="arm_right_tool_link_joint" type="fixed">
    <origin xyz="0.0 0.0 0.046" rpy="-1.570796326794897 -1.5707963267948966 0.0"/>
    <parent link="arm_right_7_link"/>
    <child link="arm_right_tool_link"/>
  </joint>
  <link name="arm_right_tool_link">
    <collision name="arm_right_tool_link_collision_0">
      <origin xyz="0.001 0.0 0.0" rpy="-0.0 1.5707963267948966 0.0"/>
      <geometry>
        <cylinder radius="0.005" length="0.005"/>
      </geometry>
    </collision>
  </link>
  <joint name="wrist_right_ft_link_joint" type="fixed">
    <origin xyz="0.00785 0.0 0.0" rpy="1.5707963267948966 -0.0 1.5707963267948966"/>
    <parent link="arm_right_tool_link"/>
    <child link="wrist_right_ft_link"/>
  </joint>
  <link name="wrist_right_ft_link">
    <collision name="wrist_right_ft_link_collision_0">
      <origin xyz="0.0 0.0 0.0" rpy="0.0 -0.0 0.0"/>
      <geometry>
        <cylinder radius="0.0225" length="0.0157"/>
      </geometry>
    </collision>
  </link>
  <joint name="wrist_right_ft_tool_link_joint" type="fixed">
    <origin xyz="0.0 0.0 0.012725" rpy="-1.5707963267948966 -1.5707963267948966 0.0"/>
    <parent link="wrist_right_ft_link"/>
    <child link="wrist_right_ft_tool_link"/>
  </joint>
  <link name="wrist_right_ft_tool_link">
    <collision name="wrist_right_ft_tool_link_collision_0">
      <origin xyz="0.0 0.0 0.0" rpy="-0.0 1.5707963267948966 0.0"/>
      <geometry>
        <cylinder radius="0.025" length="0.00975"/>
      </geometry>
    </collision>
  </link>
  <joint name="gripper_right_tool_link_joint" type="fixed">
    <origin xyz="0.01 0.0 0.0" rpy="3.141592653589793 1.5707963267948966 0.0"/>
    <parent link="wrist_right_ft_tool_link"/>
    <child link="gripper_right_tool_link"/>
  </joint>
  <link name="gripper_right_tool_link"/>
  <joint name="gripper_right_link_joint" type="fixed">
    <origin xyz="0.01 0.0 0.0" rpy="3.141592653589793 1.5707963267948966 0.0"/>
    <parent link="wrist_right_ft_tool_link"/>
    <child link="gripper_right_link"/>
  </joint>
  <link name="gripper_right_link">
    <collision name="gripper_link_collision">
      <origin xyz="0.0 0.0 0.0" rpy="0.0 -0.0 0.0"/>
      <geometry>
        <mesh filename="package://pycram/resources/tiago_dual/stl/gripper_link_collision.stl" scale="1.0 1.0 1.0"/>
      </geometry>
    </collision>
  </link>
  <joint name="gripper_right_right_finger_joint" type="prismatic">
    <origin xyz="0.0 0.0 0.0" rpy="-2.9907775833605145e-33 1.8432089935347544e-65 1.2325951644078312e-32"/>
    <axis xyz="1 0 0"/>
    <parent link="gripper_right_link"/>
    <child link="gripper_right_right_finger_link"/>
    <limit effort="1000" lower="0.0" upper="0.04500000178813934" velocity="1000"/>
  </joint>
  <link name="gripper_right_right_finger_link">
    <collision name="gripper_right_right_finger_link_collision_0">
      <origin xyz="0.005 0.0 -0.165" rpy="0.0 -0.0 3.141587529888982"/>
      <geometry>
        <box size="0.010000000000000002 0.05 0.11"/>
      </geometry>
    </collision>
  </link>
  <joint name="gripper_right_left_finger_joint" type="prismatic">
    <origin xyz="0.0 0.0 0.0" rpy="-2.9907775833605145e-33 1.8432089935347544e-65 1.2325951644078312e-32"/>
    <axis xyz="-1 0 0"/>
    <parent link="gripper_right_link"/>
    <child link="gripper_right_left_finger_link"/>
    <limit effort="1000" lower="0.0" upper="0.04500000178813934" velocity="1000"/>
  </joint>
  <link name="gripper_right_left_finger_link">
    <collision name="gripper_right_left_finger_link_collision_0">
      <origin xyz="-0.005 0.0 -0.165" rpy="0.0 -0.0 3.141587529888982"/>
      <geometry>
        <box size="0.010000000000000002 0.05 0.11"/>
      </geometry>
    </collision>
  </link>
  <joint name="gripper_right_grasping_frame_joint" type="fixed">
    <origin xyz="0.0 0.0 -0.12" rpy="1.5707926535159558 1.5707926535897936 3.1415926535595684"/>
    <parent link="gripper_right_link"/>
    <child link="gripper_right_grasping_frame"/>
  </joint>
  <link name="gripper_right_grasping_frame"/>
  <joint name="torso_fixed_column_link_joint" type="fixed">
    <origin xyz="-0.062 0.0 0.195" rpy="0.0 -0.0 0.0"/>
    <parent link="base_link"/>
    <child link="torso_fixed_column_link"/>
  </joint>
  <link name="torso_fixed_column_link">
    <collision name="torso_fixed_column_link_collision_0">
      <origin xyz="0.0 0.0 0.275" rpy="0.0 -0.0 0.0"/>
      <geometry>
        <box size="0.23 0.23 0.55"/>
      </geometry>
    </collision>
  </link>
  <joint name="base_cover_link_joint" type="fixed">
    <origin xyz="0.0 0.0 0.13" rpy="0.0 -0.0 0.0"/>
    <parent link="base_footprint"/>
    <child link="base_cover_link"/>
  </joint>
  <link name="base_cover_link"/>
  <joint name="rgbd_laser_link_joint" type="fixed">
    <origin xyz="-0.9 0.0 0.0" rpy="0.0 -0.0 0.0"/>
    <parent link="base_footprint"/>
    <child link="rgbd_laser_link"/>
  </joint>
  <link name="rgbd_laser_link"/>
</robot>